Workbook

Sheet الرواتب
B2: الرواتب
C4: الموظف | D4: الراتب الأسمي بالساعات | E4: الراتب الأسمي | F4: الساعات الاضافيه | G4: الحوافز | H4: القطوعات | I4: المستلم | J4: الأجمالي
C6: يوسف يعقوب | D6: 2250 | E6: =(#REF!)*D6 -> #REF! | F6: =(#REF!)*1.25*D6 -> #REF! | H6: ='السلف و الغرامات'!C7 -> 0 | J6: =SUM(E6:I6)-2*(H6) -> #REF!
C7: يونس يعقوب | D7: 1750 | E7: =(#REF!)*D7 -> #REF! | F7: =(#REF!)*1.25*D7 -> #REF! | H7: =#REF! -> #REF! | J7: =SUM(E7:I7)-2*(H7) -> #REF!
C8: منتظر عبد الكريم | D8: 1750 | E8: =(#REF!)*D8 -> #REF! | F8: =(#REF!)*1.25*D8 -> #REF! | H8: =#REF! -> #REF! | J8: =SUM(E8:I8)-2*(H8) -> #REF!
C9: حيدر الصباغ | D9: 2000 | E9: =(#REF!)*D9 -> #REF! | F9: =(#REF!)*1.25*D9 -> #REF! | H9: ='السلف و الغرامات'!C10 -> 35000 | J9: =SUM(E9:I9)-2*(H9) -> #REF!
C10: حيدر الكهربائي | D10: 2000 | E10: =(#REF!)*D10 -> #REF! | F10: =(#REF!)*1.25*D10 -> #REF! | H10: ='السلف و الغرامات'!C13 -> 170000 | J10: =SUM(E10:I10)-2*(H10) -> #REF!
C11: علي الكهربائي | D11: 1750 | E11: =(#REF!)*D11 -> #REF! | F11: =(#REF!)*1.25*D11 -> #REF! | H11: ='السلف و الغرامات'!C12 -> 108000 | J11: =SUM(E11:I11)-2*(H11) -> #REF!
C12: اسماعيل | D12: 1750 | E12: =(#REF!)*D12 -> #REF! | F12: =(#REF!)*1.25*D12 -> #REF! | H12: =#REF! -> #REF! | J12: =SUM(E12:I12)-2*(H12) -> #REF!
C13: علي هادي | D13: 1750 | E13: =(#REF!)*D13 -> #REF! | F13: =(#REF!)*1.25*D13 -> #REF! | H13: =#REF! -> #REF! | J13: =SUM(E13:I13)-2*(H13) -> #REF!
C14: نبيل | D14: 1750 | E14: =(#REF!)*D14 -> #REF! | F14: =(#REF!)*1.25*D14 -> #REF! | H14: =#REF! -> #REF! | J14: =SUM(E14:I14)-2*(H14) -> #REF!
C15: حسين | D15: 1750 | E15: =(#REF!)*D15 -> #REF! | F15: =(#REF!)*1.25*D15 -> #REF! | H15: =#REF! -> #REF! | J15: =SUM(E15:I15)-2*(H15) -> #REF!
C16: محمد | D16: 2500 | E16: =(#REF!)*D16 -> #REF! | F16: =(#REF!)*1.25*D16 -> #REF! | H16: =#REF! -> #REF! | J16: =SUM(E16:I16)-2*(H16) -> #REF!
C17: محمد السوري | D17: 1750 | E17: =(#REF!)*D17 -> #REF! | F17: =(#REF!)*1.25*D17 -> #REF! | H17: ='السلف و الغرامات'!C9 -> 50000 | J17: =SUM(E17:I17)-2*(H17) -> #REF!
C18: عبد الرضا عقيل | D18: 1750 | E18: =(#REF!)*D18 -> #REF! | F18: =(#REF!)*1.25*D18 -> #REF! | H18: ='السلف و الغرامات'!C8 -> 150000 | J18: =SUM(E18:I18)-2*(H18) -> #REF!
C19: سجاد | D19: 1750 | E19: =(#REF!)*D19 -> #REF! | F19: =(#REF!)*1.25*D19 -> #REF! | H19: =#REF! -> #REF! | J19: =SUM(E19:I19)-2*(H19) -> #REF!
C20: معتصم | D20: 1750 | E20: =(#REF!)*D20 -> #REF! | F20: =(#REF!)*1.25*D20 -> #REF! | H20: =#REF! -> #REF! | J20: =SUM(E20:I20)-2*(H20) -> #REF!
C21: عبدالله الصباغ | D21: 1750 | E21: =(#REF!)*D21 -> #REF! | F21: =(#REF!)*1.25*D21 -> #REF! | H21: =#REF! -> #REF! | J21: =SUM(E21:I21)-2*(H21) -> #REF!
C22: علي جزيره | D22: 1750 | E22: =(#REF!)*D22 -> #REF! | F22: =(#REF!)*1.25*D22 -> #REF! | H22: =#REF! -> #REF! | J22: =SUM(E22:I22)-2*(H22) -> #REF!
C23: اشرف الادقاني | D23: 3000 | E23: =(#REF!)*D23 -> #REF! | F23: =(#REF!)*1.25*D23 -> #REF! | H23: =#REF! -> #REF! | J23: =SUM(E23:I23)-2*(H23) -> #REF!

Sheet Sheet10

Sheet Sheet9

Sheet Sheet11

Sheet جدول الخصومات 
A1: التكرار | B1: قيمة الخصم

Sheet Sheet13

Sheet الحظور
X1: =iferror(concatenate(" Enter ", 'Attendance key'!$B$7, " for ",'Attendance key'!$C$7, ", ", 'Attendance key'!$B$8, " for ", 'Attendance key'!$C$8, ", ", 'Attendance key'!$B$9, " for ", 'Attendance key'!$C$9, ", and ", 'Attendance key'!$B$10, " for ", 'Attendance key'!$C$10, ". Use the 'Attendance key' tab to customize. "),"") | GL1: hhg
B2: تاريخ | E2: 45521 | F2: 45522 | G2: 45523 | H2: 45524 | I2: 45525 | J2: 45526 | K2: 45527 | L2: 45528 | M2: 45529 | N2: 45530 | O2: 45531 | P2: 45532 | Q2: 45533 | R2: 45534 | S2: 45535 | T2: 45536 | U2: 45537 | V2: 45538 | W2: 45539 | X2: 45540 | Y2: 45541 | Z2: 45542 | AA2: 45543 | AB2: 45544 | AC2: 45545 | AD2: 45546 | AE2: 45547 | AF2: 45548 | AG2: 45549 | AH2: 45550 | AI2: 45551 | AJ2: 45552 | AK2: 45553 | AL2: 45554 | AM2: 45555 | AN2: 45556 | AO2: 45557 | AP2: 45558 | AQ2: 45559 | AR2: 45560 | AS2: 45561 | AT2: 45562 | AU2: 45563 | AW2: 45565 | AX2: 45566 | AY2: 45567 | AZ2: 45568 | BA2: 45569 | BB2: 45570 | BC2: 45571 | BD2: 45572 | BE2: 45573 | BF2: 45574 | BG2: 45575 | BH2: 45576 | BI2: 45577 | BJ2: 45578 | BK2: 45579 | BL2: 45580 | BM2: 45581 | BN2: 45582 | BO2: 45583 | BP2: 45584 | BQ2: 45585 | BR2: 45586 | BS2: 45587 | BT2: 45588 | BU2: 45589 | BV2: 45590 | BW2: 45591 | BX2: 45592 | BY2: 45593 | BZ2: 45594 | CA2: 45595 | CB2: 45596 | CC2: 45597 | CD2: 45598 | CE2: 45599 | CF2: 45600 | CG2: 45601 | CH2: 45602 | CI2: 45603 | CJ2: 45604 | CK2: 45605 | CL2: 45606 | CM2: 45607 | CN2: 45608 | CO2: 45609 | CP2: 45610 | CQ2: 45611 | CR2: 45612 | CS2: 45613 | CT2: 45614 | CU2: 45615 | CV2: 45616 | CW2: 45617 | CX2: 45618 | CY2: 45619 | CZ2: 45620 | DA2: 45621 | DB2: 45622 | DC2: 45623 | DD2: 45624 | DE2: 45625 | DF2: 45626 | DG2: 45627 | DH2: 45628 | DI2: 45629 | DJ2: 45630 | DK2: 45631 | DL2: 45632 | DM2: 45633 | DN2: 45634 | DO2: 45635 | DP2: 45636 | DQ2: 45637 | DR2: 45638 | DS2: 45639 | DT2: 45640 | DU2: 45641 | DV2: 45642 | DW2: 45643 | DX2: 45644 | DY2: 45645 | DZ2: 45646 | EA2: 45647 | EB2: 45648 | EC2: 45649 | ED2: 45650 | EE2: 45651 | EF2: 45652 | EG2: 45653 | EH2: 45654 | EI2: 45655 | EJ2: 45656 | EK2: 45657 | EL2: 45658 | EM2: 45659 | EN2: 45660 | EO2: 45661 | EP2: 45662 | EQ2: 45663 | ER2: 45664 | ES2: 45665 | ET2: 45666 | EU2: 45667 | EV2: 45668 | EW2: 45669 | EX2: 45670 | EY2: 45671 | EZ2: 45672 | FA2: 45673 | FB2: 45674 | FC2: 45675 | FD2: 45676 | FE2: 45677 | FF2: 45678 | FG2: 45679 | FH2: 45680 | FI2: 45681 | FJ2: 45682 | FK2: 45683 | FL2: 45684 | FM2: 45685 | FN2: 45686 | FO2: 45687 | FP2: 45688 | FQ2: 45689 | FR2: 45690 | FS2: 45691 | FT2: 45692 | FU2: 45693 | FV2: 45694 | FW2: 45695 | FX2: 45696 | FY2: 45697 | FZ2: 45698 | GA2: 45699 | GB2: 45700 | GC2: 45701 | GD2: 45702 | GE2: 45703 | GF2: 45704 | GG2: 45705 | GH2: 45706 | GI2: 45707 | GJ2: 45708 | GK2: 45709 | GL2: 45710 | GM2: 45711 | GN2: 45712 | GO2: 45713 | GP2: 45714 | GQ2: 45715 | GR2: 45716 | GS2: 45717 | GT2: 45718 | GU2: 45719 | GV2: 45720 | GW2: 45721 | GX2: 45722 | GY2: 45723 | GZ2: 45724 | HA2: 45725 | HB2: 45726 | HC2: 45727 | HD2: 45728 | HE2: 45729 | HF2: 45730 | HG2: 45731 | HH2: 45732 | HI2: 45733 | HJ2: 45734 | HK2: 45735 | HL2: 45736 | HM2: 45737 | HN2: 45738 | HO2: 45739 | HP2: 45740 | HQ2: 45741 | HR2: 45742 | HS2: 45743 | HT2: 45744 | HU2: 45745 | HV2: 45746 | HW2: 45747 | HX2: 45748 | HY2: 45749 | HZ2: 45750 | IA2: 45751 | IB2: 45752 | IC2: 45753 | ID2: 45754 | IE2: 45755 | IF2: 45756 | IG2: 45757 | IH2: 45758 | II2: 45759 | IJ2: 45760 | IK2: 45761 | IL2: 45762 | IM2: 45763 | IN2: 45764 | IO2: 45765 | IP2: 45766 | IQ2: 45767 | IR2: 45768 | IS2: 45769 | IT2: 45770 | IU2: 45771 | IV2: 45772 | IW2: 45773 | IX2: 45774 | IY2: 45775 | IZ2: 45776 | JA2: 45777 | JC2: 45778 | JD2: 45779 | JE2: 45780 | JF2: 45781 | JG2: 45782 | JH2: 45783 | JI2: 45784 | JJ2: 45785 | JK2: 45786 | JL2: 45787 | JM2: 45788 | JN2: 45789 | JO2: 45790 | JP2: 45791 | JQ2: 45792 | JR2: 45793 | JS2: 45794 | JT2: 45795 | JU2: 45796 | JV2: 45797 | JW2: 45798 | JX2: 45799 | JY2: 45800 | JZ2: 45801 | KA2: 45802 | KB2: 45803 | KC2: 45804 | KD2: 45805 | KE2: 45806 | KF2: 45807 | KG2: 45808 | KI2: 45809 | KJ2: 45810 | KK2: 45811 | KL2: 45812 | KM2: 45813 | KN2: 45814 | KO2: 45815 | KP2: 45816 | KQ2: 45817 | KR2: 45818 | KS2: 45819 | KT2: 45820 | KU2: 45821 | KV2: 45822 | KW2: 45823 | KX2: 45824 | KY2: 45825 | KZ2: 45826 | LA2: 45827 | LB2: 45828 | LC2: 45829 | LD2: 45830 | LE2: 45831 | LF2: 45832 | LG2: 45833 | LH2: 45834 | LI2: 45835 | LJ2: 45836 | LK2: 45837 | LL2: 45838 | LM2: الساعات | LO2: 45839 | LP2: 45840 | LQ2: 45841 | LR2: 45842 | LS2: 45843 | LT2: 45844 | LU2: 45845 | LV2: 45846 | LW2: 45847 | LX2: 45848 | LY2: 45849 | LZ2: 45850 | MA2: 45851 | MB2: 45852 | MC2: 45853 | MD2: 45854 | ME2: 45855 | MF2: 45856 | MG2: 45857 | MH2: 45858 | MI2: 45859 | MJ2: 45860 | MK2: 45861 | ML2: 45862 | MM2: 45863 | MN2: 45864 | MO2: 45865 | MP2: 45866 | MQ2: 45867 | MR2: 45868 | MS2: 45869 | MU2: 45839 | MV2: 45840 | MW2: 45841 | MX2: 45842 | MY2: 45843 | MZ2: 45844 | NA2: 45845 | NB2: 45846 | NC2: 45847 | ND2: 45848 | NE2: 45849 | NF2: 45850 | NG2: 45851 | NH2: 45852 | NI2: 45853 | NJ2: 45854 | NK2: 45855 | NL2: 45856 | NM2: 45857 | NN2: 45858 | NO2: 45859 | NP2: 45860 | NQ2: 45861 | NR2: 45862 | NS2: 45863 | NT2: 45864 | NU2: 45865 | NV2: 45866 | NW2: 45867 | NX2: 45868 | NY2: 45869 | OA2: 45901 | OB2: 45902 | OC2: 45903 | OD2: 45904 | OE2: 45905 | OF2: 45906 | OG2: 45907 | OH2: 45908 | OI2: 45909 | OJ2: 45910 | OK2: 45911 | OL2: 45912
B3: اليوم | C3: الحضور | D3: الاضافي | E3: =E2 -> 45521 | F3: =F2 -> 45522 | G3: =G2 -> 45523 | H3: =H2 -> 45524 | I3: =I2 -> 45525 | J3: =J2 -> 45526 | K3: =K2 -> 45527 | L3: =L2 -> 45528 | ... JA3: =JA2 -> 45777 | JC3: =JC2 -> 45778 | JD3: =JD2 -> 45779 | JE3: =JE2 -> 45780 | JF3: =JF2 -> 45781 | JG3: =JG2 -> 45782 | JH3: =JH2 -> 45783 | JI3: =JI2 -> 45784 | JJ3: =JJ2 -> 45785 | ... KG3: =KG2 -> 45808 | KI3: =KI2 -> 45809 | KJ3: =KJ2 -> 45810 | KK3: =KK2 -> 45811 | KL3: =KL2 -> 45812 | KM3: =KM2 -> 45813 | KN3: =KN2 -> 45814 | KO3: =KO2 -> 45815 | KP3: =KP2 -> 45816 | ... LL3: =LL2 -> 45838 | LM3: الاضافية | LO3: =LO2 -> 45839 | LP3: =LP2 -> 45840 | LQ3: =LQ2 -> 45841 | LR3: =LR2 -> 45842 | LS3: =LS2 -> 45843 | LT3: =LT2 -> 45844 | LU3: =LU2 -> 45845 | LV3: =LV2 -> 45846 | ... MS3: =MS2 -> 45869 | MU3: =MU2 -> 45839 | MV3: =MV2 -> 45840 | MW3: =MW2 -> 45841 | MX3: =MX2 -> 45842 | MY3: =MY2 -> 45843 | MZ3: =MZ2 -> 45844 | NA3: =NA2 -> 45845 | NB3: =NB2 -> 45846 | ... NY3: =NY2 -> 45869 | OA3: =OA2 -> 45901 | OB3: =OB2 -> 45902 | OC3: =OC2 -> 45903 | OD3: =OD2 -> 45904 | OE3: =OE2 -> 45905 | OF3: =OF2 -> 45906 | OG3: =OG2 -> 45907 | OH3: =OH2 -> 45908 | ... OL3: =OL2 -> 45912
B4: الاسم | C4: الحضور | D4: الاضافي
C5: الحضور | D5: الاضافي
A6: =sum(GW6:MR6)*3000 -> 3532950 | B6: حيدر المحاسب | C6: =SUM(LO6:MS6) -> 88.2 | D6: =SUM(MU6:NY6) -> 33.25 | GW6: 10 | GX6: 10 | GY6: 10 | GZ6: 10 | HA6: 6 | HB6: 6 | HC6: 8.5 | HD6: 11 | HE6: 7 | HF6: 10 | HG6: 8 | HH6: 7.5 | HI6: 11 | HJ6: 8.5 | HK6: 7 | HL6: 6 | HM6: 7 | HN6: 13 | HO6: 10 | HP6: 10.5 | HQ6: 8.5 | HR6: 8.5 | HS6: 12 | HT6: 0 | HU6: 3 | HV6: 7 | HW6: 0 | HX6: 11 | HY6: 7 | HZ6: 10 | IA6: 11 | IB6: 11.5 | IC6: 12.5 | ID6: 9 | IE6: 11 | IF6: 13 | IG6: 8 | IH6: 0 | II6: 10 | IJ6: 11 | IK6: 9 | IL6: 13 | IM6: 9 | IN6: 10.5 | IO6: 0 | IP6: 10 | IQ6: 9 | IR6: 9 | IS6: 10 | IT6: 9 | IU6: 9 | IV6: 9.5 | IW6: 9 | IX6: 8 | IY6: 10 | IZ6: 10 | JA6: 13 | JC6: 13 | JD6: 6 | JE6: 10 | JF6: 9 | JG6: 9 | JH6: 8 | JI6: 0 | JJ6: 0 | JK6: 9 | JL6: 12 | JM6: 9 | JN6: 17 | JO6: 10 | JP6: 13 | JQ6: 15 | JR6: 9 | JS6: 14 | JT6: 11 | JU6: 10 | JV6: 9 | JW6: 11 | JX6: 12 | JY6: 10 | JZ6: 11 | KA6: 13 | KB6: 11 | KC6: 6.7 | KD6: 10 | KE6: 11 | KF6: 10 | KG6: 10 | KI6: 10 | KJ6: 10 | KK6: 10 | KL6: 7 | KM6: 10 | KN6: 7 | KO6: 2.5 | KP6: 9 | KQ6: 9.25 | KR6: 5 | KS6: 10 | KT6: 8 | KU6: 8 | KV6: 17 | KW6: 6 | KX6: 7 | KY6: 7.5 | KZ6: 10 | LA6: 10 | LB6: 6.5 | LC6: 14 | LD6: 9 | LE6: 8 | LF6: 12 | LG6: 12 | LH6: 3 | LI6: x | LJ6: 10 | LK6: 10 | LL6: 5 | LM6: 30 | LO6: 9 | LP6: 9 | LQ6: 9 | LU6: 9 | LV6: 9 | LW6: 8 | LX6: 9 | LZ6: 9 | MA6: 9 | MB6: 8.2 | MV6: 5 | MW6: 1.75 | MX6: 10 | NA6: 2 | NB6: 1 | ND6: 0.5 | NE6: 7.5 | NF6: 0.25 | NG6: 5.25
A7: 6458000 | B7: يوسف يعقوب | C7: =SUM(LO7:MS7) -> 67 | D7: =SUM(MU7:NY7) -> 30.5 | P7: 9 | Q7: 11.5 | R7: 11 | S7: 12.5 | T7: 11.5 | U7: 13.5 | V7: 18 | W7: 5 | X7: 11.5 | Y7: 14 | Z7: 13 | AA7: 22 | AB7: 11 | AC7: 5 | AD7: 13.5 | AE7: 20 | AG7: 15 | AH7: 16 | AI7: 2 | AJ7: 20 | AK7: 15 | AL7: 3 | AM7: 10 | AN7: 15 | AO7: 11 | AP7: 12.5 | AQ7: 13 | AR7: 13 | AS7: 11 | AT7: 24 | AU7: 5 | AV7: 11 | AW7: 15 | AX7: 10.3 | AY7: 5 | AZ7: 13 | BA7: 5 | BB7: 12 | BC7: 11.3 | BD7: 13 | BE7: 11 | BF7: 12.3 | BG7: 13 | BH7: 4 | BI7: 12 | BJ7: 13 | BK7: 12 | BL7: 7 | BS7: 13 | BT7: 15.3 | BU7: 16.3 | BV7: 15.3 | BW7: 13 | BX7: 14 | BY7: 10.3 | BZ7: 15 | CA7: 12 | CB7: 14 | CC7: 9 | CD7: 13 | CE7: 12 | CF7: 11.3 | CG7: 14 | CH7: 9 | CI7: 11 | CJ7: 1.3 | CK7: 10 | CL7: 14 | CM7: 12 | CN7: 21 | CO7: 4 | CP7: 15 | CQ7: 0 | CR7: 6 | CS7: 0 | CT7: 9 | CU7: 15 | CV7: 0 | CW7: 10 | CX7: 10 | CY7: 11 | CZ7: 14 | DA7: 10 | DB7: 11 | DC7: 11 | DD7: 11 | DE7: 6 | DF7: 0 | DK7: 6 | DL7: 9 | DM7: 8 | EH7: 6 | EI7: 5.5 | EJ7: 7.5 | EL7: 7 | EO7: 10.5 | EP7: 7 | EQ7: 8 | ER7: 5 | EW7: 10 | EX7: 8 | EY7: 11 | EZ7: 11 | FA7: 13 | FC7: 10.5 | FD7: 11 | FE7: 11 | FF7: 11 | FG7: 8.5 | FH7: 11 | FI7: 15 | FJ7: 8 | FK7: 10 | FL7: 10 | FM7: 10.5 | FN7: 11.5 | FO7: 10.5 | FP7: 9 | FQ7: 8 | FR7: 11 | FS7: 10 | FT7: 9 | FU7: 13 | FX7: 10 | FY7: 11 | FZ7: 7 | GA7: 9 | GB7: 8 | GC7: 12 | GD7: 14 | GE7: 7.5 | GG7: 10 | GH7: 12 | GI7: 9 | GJ7: 8 | GL7: 11 | GM7: 12 | GN7: 7 | GP7: 11.5 | GQ7: 10 | GR7: 16 | GS7: 8 | GT7: 6.5 | GU7: 16 | GV7: 6 | GW7: 7 | GX7: 9 | GY7: 11.5 | GZ7: 10.5 | HA7: 6 | HB7: 11 | HC7: 10 | HD7: 10 | HE7: 9 | HF7: 10 | HG7: 11.5 | HH7: 11 | HI7: 8 | HJ7: 9,5 | HK7: 11 | HL7: 9 | HN7: 10.5 | HO7: 10.5 | HP7: 9 | HQ7: 10.5 | HR7: 6 | HV7: 9 | HX7: 0 | HY7: 10 | HZ7: 13 | IA7: 3 | IB7: 9.5 | IC7: 10.5 | ID7: 11 | IE7: 0 | IF7: 0 | IG7: 0 | IH7: 10 | II7: 9 | IJ7: 11 | IK7: 10.5 | IL7: 7 | IM7: 11 | IN7: 12 | IO7: 4 | IP7: 10 | IQ7: 12 | IR7: 10 | IS7: 10 | IT7: 14 | IU7: 9 | IV7: 4 | IW7: 10 | IX7: 9 | IY7: 12 | IZ7: 9 | JA7: 8 | JC7: 10 | JD7: 10 | JE7: 10 | JF7: 10 | JG7: 10 | JH7: 11 | JI7: 9 | JJ7: 10 | JK7: 10 | JR7: 10 | JS7: 17.25 | JT7: 10 | JU7: 12 | JV7: 8.75 | JW7: 10 | JX7: 9 | JY7: 10 | JZ7: 11.5 | KA7: 10 | KB7: 12.5 | KC7: 12 | KD7: 15 | KE7: 6 | KF7: 7 | KG7: 9 | KI7: 11.5 | KJ7: 9 | KK7: 10 | KL7: 10 | KM7: 10 | KN7: x | KO7: 10 | KP7: 10 | KQ7: 10 | KR7: x | KS7: 10 | KT7: 10 | KU7: 10 | KV7: x | KW7: 10 | KX7: 10 | KY7: 10 | KZ7: x | LA7: 10 | LB7: 10 | LC7: 10 | LD7: 10 | LE7: 10 | LF7: 10 | LG7: 10 | LH7: 10 | LI7: 10 | LJ7: 10 | LK7: 10 | LL7: 10 | LO7: 9 | LP7: 9 | LQ7: 9 | LS7: 9 | LU7: 9 | LV7: 8 | LX7: 5 | LZ7: 9 | MU7: 2 | MV7: 2 | MW7: 2 | MX7: 8 | MY7: 2 | NA7: 2 | NE7: 7.5 | NF7: 5
B8: عبد الرضا عقيل | C8: =SUM(LO8:MS8) -> 72 | D8: =SUM(MU8:NY8) -> 14.85 | AX8: 10 | AY8: 5 | AZ8: 12 | BB8: 9.3 | BC8: 9 | BD8: 11 | BF8: 9 | BJ8: 10 | BK8: 10 | BL8: 9.3 | BM8: 9 | BN8: 12 | BP8: 7.3 | BQ8: 9 | BR8: 10.3 | BS8: 9.3 | BU8: 5 | BV8: 12 | BW8: 10.3 | BX8: 10 | BY8: 10.3 | BZ8: 8 | CA8: 13 | CB8: 9 | CC8: 3 | CD8: 11.3 | CE8: 11 | CF8: 10 | CG8: 13 | CH8: 9 | CI8: 10 | CK8: 8.3 | CL8: 8 | CM8: 9 | CN8: 12 | CO8: 11 | CP8: 0 | CQ8: 0 | CR8: 7 | CS8: 7 | CT8: 0 | CU8: 13 | CY8: 9 | CZ8: 8 | DA8: 11.3 | DB8: 9 | DC8: 12 | DD8: 12 | DE8: 9.15 | DF8: 11 | DG8: 9 | DH8: 10 | DI8: 8 | DJ8: 13 | DK8: 8 | DL8: 13 | DM8: 8 | DN8: 11 | DO8: 12 | DP8: 11 | DQ8: 8 | DR8: 12 | DT8: 11 | DU8: 9.5 | DV8: 11.5 | DW8: 10 | DX8: 9.5 | DY8: 14 | EA8: 11 | EB8: 7.5 | EC8: 8 | ED8: 10 | EE8: 11.5 | EF8: 10 | EH8: 10 | EI8: 8.5 | EJ8: 8 | EK8: 8 | EM8: 13.5 | EN8: 10.5 | EO8: 13.5 | EP8: 9 | EQ8: 12 | ER8: 12 | ES8: 8.3 | ET8: 10 | EV8: 9 | EW8: 9.5 | EX8: 11.5 | EY8: 18 | EZ8: 6.5 | FA8: 11 | FB8: 3.5 | FC8: 9 | FD8: 10 | FE8: 3 | FF8: 12 | FG8: 9 | FH8: 9 | FJ8: 9.5 | FK8: 9 | FL8: 11.75 | FM8: 11 | FN8: 9 | FO8: 8.5 | FQ8: 8 | FR8: 11 | FS8: 9 | FT8: 16 | FU8: 8 | FV8: 10 | FW8: 10 | FX8: 9 | FY8: 10 | FZ8: 15 | GA8: 12 | GB8: 11 | GC8: 9 | GD8: 10 | GE8: 14 | GF8: 13 | GG8: 10 | GI8: 11 | GJ8: 8 | GK8: 11 | GL8: 12 | GM8: 9 | GN8: 12 | GO8: 16 | GP8: 15 | GQ8: 14 | GR8: 20 | GS8: x | GT8: 8 | GU8: 4 | GV8: x | GW8: 5 | GX8: 5.5 | GY8: 8.5 | GZ8: 3.5 | HA8: x | HB8: 8 | HC8: 12 | HD8: 3 | HE8: 11 | HF8: x | HG8: 12 | HH8: 12 | HI8: 5 | HJ8: 2 | HK8: 7.5 | HL8: 7 | HM8: 7 | HN8: 5 | HO8: 12 | HP8: 11 | HQ8: 4.5 | HR8: x | HS8: 4.5 | HT8: 6.5 | HU8: 1.5 | HV8: 5 | HW8: x | HX8: مجاز | HY8: 3 | HZ8: 8 | IA8: 7 | IB8: 6 | IC8: 8.75 | ID8: 10.75 | IE8: 9 | IF8: 9.25 | IG8: 7.75 | IH8: 9.25 | II8: 9.5 | IJ8: 7.25 | IK8: x | IL8: 6.5 | IM8: 9 | IN8: 11.5 | IO8: 12.5 | IP8: 9.5 | IQ8: 9 | IR8: 9.25 | IS8: 12.5 | IT8: 10.75 | IU8: 19 | IV8: 3 | IW8: 11 | IX8: 6.5 | IY8: 10 | IZ8: 0 | JA8: 10 | JC8: 11 | JE8: 10.5 | JF8: 14.5 | JG8: 10 | JH8: 15 | JI8: 10.5 | JJ8: 11 | JL8: 12 | JM8: 14 | JN8: 10 | JO8: 8 | JP8: 2 | JQ8: 3 | JU8: 10 | JW8: 4 | JX8: 11 | JZ8: 11 | KA8: 8.5 | KB8: 8 | KC8: 12 | KD8: 14.75 | KE8: 12.5 | KF8: 11 | KG8: 10 | KI8: 16.5 | KJ8: 9 | KK8: 12.5 | KL8: 16.5 | KM8: 9 | KN8: 16 | KO8: x | KP8: 7 | KQ8: 14.5 | KR8: 4.5 | KS8: 13 | KT8: 3 | KU8: 5 | KV8: 6.5 | KW8: 8 | KX8: x | KY8: 6.5 | KZ8: x | LA8: x | LB8: x | LC8: 8 | LD8: 6.5 | LE8: 9 | LF8: 9 | LG8: x | LH8: 9 | LI8: x | LJ8: 11 | LK8: 9.5 | LL8: 5.5 | LM8: 21 | LP8: 9 | LQ8: 9 | LS8: 9 | LU8: 9 | LV8: 9 | LW8: 9 | LX8: 9 | LZ8: 9 | MV8: 3 | ND8: 1.1 | NE8: 9.25 | NF8: 1.5
B9: محمد رشيد | C9: =SUM(LO9:MS9) -> 0 | D9: =SUM(MU9:NY9) -> 0 | AR9: 10 | AS9: 10 | AT9: 10 | AU9: 12 | AW9: 14 | AX9: 11 | AY9: 10 | AZ9: 11 | BB9: 11 | BC9: 11.3 | BD9: 13 | BE9: 13 | BF9: 12 | BG9: 16 | BH9: 3 | BI9: 10.3 | BJ9: 13 | BK9: 13 | BL9: 16 | BM9: 12 | BN9: 13 | BO9: 9 | BP9: 13 | BQ9: 11 | BR9: 12 | BS9: 10.3 | BT9: 12.3 | BU9: 10.3 | BV9: 9.3 | BW9: 10.3 | BX9: 15 | BY9: 10.3 | BZ9: 12 | CA9: 12 | CB9: 13.3 | CC9: 9 | CD9: 11.3 | CE9: 11 | CF9: 14 | CG9: 14 | CI9: 12.3 | CJ9: 0 | CK9: 10.3 | CL9: 18 | CM9: 6 | CN9: 14 | CO9: 12 | CP9: 13 | CQ9: 6 | CR9: 11 | CS9: 11 | CT9: 13.3 | CU9: 10 | CV9: 7 | CW9: 7 | CX9: 11 | CY9: 10.3 | CZ9: 8.3 | DA9: 12 | DB9: 9 | DC9: 11 | DD9: 12 | DE9: 7 | DF9: 11.45 | DG9: 14.3 | DH9: 16 | DI9: 11 | DK9: 14.5 | DL9: 9.5 | DM9: 8 | DN9: 12 | DO9: 10.5 | DP9: 13 | DQ9: 12 | DR9: 7.5 | DS9: 6 | DT9: 9 | DU9: 9 | DV9: 12 | DW9: 13.5 | DX9: 12 | DY9: 8.5 | EA9: 16.5 | EB9: 12 | EC9: 12 | ED9: 11 | EE9: 12 | EF9: 9.5 | EG9: 11.5 | EH9: 11.5 | EI9: 11 | EJ9: 11 | EK9: 7.5 | EL9: 5 | EM9: 10.75 | EN9: 10 | EO9: 9.5 | EP9: 9 | EQ9: 10.75 | ER9: 12.2 | ES9: 5 | ET9: 12 | EU9: 10 | EV9: 9.5 | EW9: 8.75 | EX9: 10.6 | EY9: 10.25 | EZ9: 13 | FA9: 9.5 | FB9: 9.5 | FC9: 11.2 | FD9: 11.7 | FE9: 10 | FF9: 12.45 | FG9: 16 | FH9: 14 | FI9: 7.6 | FK9: 16 | FL9: 11.2 | FM9: 10 | FN9: 11.2 | FO9: 12 | FP9: 9.5 | FQ9: 11 | FR9: 12 | FS9: 10.5 | FT9: 12 | FU9: 11 | FV9: 12 | FW9: 10 | FX9: 11 | FY9: 9.5 | FZ9: 11 | GA9: 10 | GB9: 10.5 | GC9: 13.5 | GD9: 5 | GE9: 14 | GF9: 11 | GG9: 10.5 | GH9: 10 | GI9: 10.5 | GJ9: 10.5 | GK9: 12 | GM9: 11 | GN9: 10.5 | GO9: 9 | GP9: 12 | GQ9: 116 | GS9: 15 | GT9: 10 | GU9: 12 | GV9: 9 | GW9: 10.5 | GX9: 8 | GY9: 12.5 | GZ9: 10 | HA9: 22 | HB9: 8 | HC9: 10.5 | HD9: 15.5 | HE9: 12 | HF9: 7 | HG9: 11 | HH9: 8 | HI9: 10 | HJ9: 8.5 | HK9: x | HL9: 4.5 | HM9: 7 | HN9: 9.5 | HO9: 15 | HP9: 7.5 | HQ9: 8.5 | HR9: 8 | HS9: 8 | HT9: 8.5 | HU9: 17.5 | HV9: 3 | HW9: 13 | HX9: 13 | HY9: 9 | HZ9: 12 | IA9: 11 | IB9: 17 | IC9: 6 | ID9: 10.5 | IE9: 10 | IF9: 11 | IG9: 5.5 | IH9: 10.5 | II9: 5.5 | IJ9: 10 | IK9: 11.5 | IL9: 11 | IM9: 9.5 | IN9: 10.25 | IO9: 9 | IP9: 12 | IQ9: 12 | IR9: 10 | IS9: 10 | IT9: 3.25 | IU9: 10 | IV9: 7 | IW9: 7.5 | IX9: 12 | IY9: 8.5 | IZ9: 9 | JA9: 14.5 | JC9: 2.5 | JD9: 9 | JE9: 8 | JF9: 11.5 | JG9: 9 | JI9: 11.25 | JJ9: 11 | JK9: 8.5 | JL9: 10.5 | JM9: 9.5 | JN9: 9 | JO9: 8.5 | JP9: 11.25 | JQ9: 8.5 | JR9: 10 | JS9: 7.75 | JT9: 7.5 | JU9: 9 | JV9: 9 | JW9: 8 | JX9: 9.25 | JY9: 7 | JZ9: 5 | KA9: 5 | KB9: 7.25 | KC9: 8.5 | KG9: 7 | KI9: 6 | KJ9: 4.5 | KK9: 5 | KL9: 8 | KM9: 8.5 | KN9: 8 | KO9: x | KP9: 1 | KQ9: 8.75 | KR9: 14 | KS9: 9 | KT9: 13.25 | KU9: 4 | KV9: 12 | KW9: 5 | KX9: 11 | KY9: 7 | KZ9: 6 | LA9: 5 | LB9: x | LC9: 1.5 | LD9: 0 | LE9: 0 | LF9: 0 | LG9: 0 | LH9: 5 | LI9: 8 | LJ9: 4.5 | LK9: 8 | LL9: x
B10: حيدر الصباغ | C10: =SUM(LO10:MS10) -> 24.5 | D10: =SUM(MU10:NY10) -> 10.5 | AC10: 11 | AD10: 11.5 | AE10: 16 | AG10: 21 | AI10: 11 | AJ10: 12 | AK10: 10.5 | AL10: 9.5 | AM10: 9.5 | AN10: 9.5 | AO10: 6.5 | AP10: 10 | AR10: 14 | AS10: 10.3 | AT10: 2.3 | AU10: 13 | AV10: 11 | AW10: 10 | AY10: 5 | AZ10: 12 | BB10: 9.3 | BC10: 14 | BE10: 12.3 | BF10: 9 | BI10: 14 | BK10: 12 | BN10: 12 | BO10: 4 | BP10: 10 | BQ10: 10.3 | BR10: 11 | BS10: 8.3 | BT10: 12 | BU10: 11 | BV10: 14 | BW10: 5.3 | BY10: 11 | BZ10: 12 | CA10: 9 | CB10: 12.3 | CD10: 6,3 | CE10: 13 | CF10: 12 | CH10: 9 | CI10: 9 | CK10: 11 | CL10: 10 | CM10: 11.3 | CN10: 22 | CO10: 10.3 | CP10: 11 | CQ10: 4.3 | CR10: 2 | CS10: 9.3 | CT10: 21 | CX10: 11 | CZ10: 9 | DA10: 10 | DB10: 9 | DC10: 10 | DD10: 11 | DF10: 12 | DG10: 9 | DH10: 9 | DI10: 9 | DJ10: 11 | DK10: 4 | DL10: 12 | DN10: 12 | DO10: 12 | DP10: 12 | DQ10: 12 | DR10: 12 | DT10: 13 | DU10: 7 | DV10: 8.5 | DW10: 8 | DX10: 7.5 | EA10: 8 | EB10: 8 | EC10: 9.2 | ED10: 9 | EE10: 9 | EF10: 8 | EH10: 7 | EI10: 6 | EJ10: 7 | EK10: 5 | EM10: 8 | EN10: 7 | EO10: 9 | EP10: 8.5 | EQ10: 8.5 | ER10: 9 | ES10: 9.25 | ET10: 9 | EU10: 5 | EV10: 8.5 | EX10: 6 | EY10: 16 | FA10: 9 | FC10: 10 | FD10: 10 | FE10: 8.25 | FF10: 9.5 | FG10: 8 | FH10: 8.5 | FJ10: 5.3 | FK10: 7 | FN10: 10 | FO10: 5 | FP10: 7.5 | FQ10: 9 | FR10: 12 | FS10: 9 | FU10: 10 | FV10: 8 | FX10: 10 | FY10: 11 | FZ10: 11 | GA10: 21 | GB10: 6 | GC10: 10 | GD10: 9 | GG10: 16 | GH10: 6 | GI10: 8.5 | GJ10: 5.5 | GK10: 5.5 | GL10: 9 | GM10: 7.5 | GN10: 15 | GO10: 6 | GP10: 8.5 | GQ10: 7 | GR10: 7 | GS10: 4 | GT10: 3.5 | GU10: 6.5 | GV10: 5 | GW10: 8 | GX10: 8.5 | GY10: x | GZ10: 11 | HA10: 6 | HB10: 7.5 | HC10: 5.5 | HD10: 7 | HE10: 6.5 | HF10: 16 | HG10: 5.5 | HH10: 5 | HI10: 5 | HJ10: 7 | HK10: 3.5 | HL10: 5 | HM10: x | HN10: 3.5 | HO10: 13.5 | HP10: 3.5 | HQ10: 6 | HR10: 6 | HS10: x | HT10: 7 | HU10: 5 | HV10: 13 | HW10: x | HX10: 0 | HY10: 6 | HZ10: 10 | IA10: 8 | IB10: 13 | IC10: 13.5 | ID10: 9 | IE10: 9.5 | IF10: 6 | IG10: 0 | IH10: 0 | II10: 8 | IL10: 12 | IM10: 10 | IN10: 8 | IO10: 11 | IP10: 5 | IQ10: 12 | IR10: 10.5 | IS10: 4.5 | IT10: 12 | IU10: 8 | IV10: 5 | IW10: 13 | IX10: 9 | IZ10: 8 | JA10: 3.5 | JC10: 6 | JD10: 10 | JG10: 10 | JH10: 11 | JI10: 10 | JL10: 12 | JM10: 14.5 | JN10: 9 | JO10: 10 | JQ10: 9.5 | JR10: 9.5 | JS10: 16 | JT10: 9 | JU10: 8.25 | JV10: 8.75 | JX10: 11 | JZ10: 10.5 | KA10: 9 | KB10: 10 | KD10: 11 | KI10: 8.5 | KJ10: 11.5 | KK10: 12 | KL10: 10 | KM10: x | KN10: 16 | KO10: x | KP10: x | KQ10: x | KR10: 9.5 | KS10: 6 | KT10: x | KU10: x | KV10: x | KW10: 5.25 | KX10: 6.5 | KY10: 9.5 | KZ10: 6.5 | LA10: x | LB10: 10 | LC10: x | LD10: 7 | LE10: x | LF10: 8.25 | LG10: 6 | LH10: x | LI10: 10 | LJ10: 7 | LK10: x | LL10: x | LM10: 3.4 | LU10: 7 | LW10: 8.5 | LX10: 9 | NE10: 10.5
B11: وليد | C11: =SUM(LO11:MS11) -> 52.75 | D11: =SUM(MU11:NY11) -> 0.6 | DH11: 6 | DI11: 6 | DJ11: 6 | DK11: 6 | DL11: 7 | DM11: 8 | DN11: 10 | DO11: 10 | DP11: 10 | DQ11: 10 | DR11: 10 | DS11: 9 | DT11: 9 | DU11: 9 | DV11: 9 | DW11: 9 | DX11: 9 | DY11: 9 | EA11: 12 | EB11: 12 | EC11: 12 | ED11: 14 | EE11: 8 | EF11: 9 | EG11: 14 | EH11: 13 | EI11: 11 | EJ11: 12 | EK11: 4 | EL11: 9.6 | EM11: 14 | EN11: 15 | EO11: 13 | EP11: 10 | EQ11: 11.2 | ER11: 13 | ES11: 11.5 | ET11: 13.5 | EU11: 4.5 | EV11: 9 | EW11: 10.25 | EX11: 11 | EY11: 9.75 | EZ11: 14.25 | FA11: 13 | FC11: 13 | FD11: 12 | FE11: 12 | FF11: 11.7 | FG11: 15.1 | FH11: 13 | FI11: 8 | FJ11: 10 | FK11: 13 | FL11: 10.2 | FM11: 11 | FN11: 11 | FO11: 10 | FP11: 11 | FQ11: 12 | FR11: 10 | FS11: 11.5 | FT11: 12 | FU11: 10.5 | FV11: 13.5 | FW11: 7 | FX11: 12 | FY11: 12 | FZ11: 13.5 | GA11: 11 | GB11: 10 | GC11: 8.5 | GD11: 6.5 | GE11: 12 | GF11: 11 | GG11: 10 | GH11: 10 | GK11: 9 | GL11: 9.5 | GM11: 6 | GN11: 10.5 | GO11: 13.5 | GP11: 13 | GQ11: 12 | GR11: 12 | GS11: 9.5 | GT11: 9 | GU11: 16 | GV11: 9.5 | GW11: 9.5 | GX11: 6.5 | GY11: 6.5 | GZ11: 9 | HA11: 10 | HB11: 11.5 | HC11: 8.5 | HD11: 6 | HE11: 12 | HF11: 10 | HG11: 7 | HH11: 8 | HI11: 5 | HJ11: 4.5 | HK11: 10 | HL11: 16.5 | HM11: 6.5 | HN11: 10 | HO11: 8.5 | HP11: 7 | HQ11: 5 | HR11: 11 | HS11: 6.5 | HT11: 9.5 | HU11: 9.5 | HV11: 9 | HW11: 4 | HX11: 8.5 | HY11: 8 | HZ11: 10.5 | IA11: 8.5 | IB11: 11 | IC11: 9.5 | ID11: 11.5 | IE11: 3 | IF11: 15.5 | IG11: 16 | IH11: 9 | II11: 9.5 | IJ11: 9.5 | IK11: 12 | IL11: 14 | IM11: 13.5 | IN11: 14 | IO11: 5 | IP11: 8 | IQ11: 9.5 | IR11: 14 | IS11: 12.5 | IT11: 6.5 | IU11: 11 | IV11: 0 | IW11: 10 | IX11: 8 | IY11: 8.5 | IZ11: 11 | JA11: 13 | JC11: 11 | JE11: 8 | JF11: 11.5 | JG11: 6.5 | JH11: 9 | JI11: 6.5 | JJ11: 8.5 | JK11: 5 | JL11: 6 | JM11: 9 | JN11: 11.5 | JO11: 8.5 | JP11: 11 | JQ11: 7 | JR11: 7 | JS11: 7 | JT11: 9.25 | JU11: 7 | JV11: 7 | JW11: 7 | KE11: 9 | KF11: 5 | KI11: 5 | KJ11: 5 | KK11: 7 | KL11: 8 | KM11: 10 | KN11: 9 | KO11: 10 | KP11: 7 | KQ11: 8 | KR11: 5.5 | KS11: 12 | KT11: 3 | KU11: 3 | KV11: 8.5 | KW11: 4 | KX11: 8 | KY11: 10 | KZ11: 5 | LA11: 9 | LB11: 16.5 | LC11: 8 | LD11: 6 | LE11: 9 | LF11: 6 | LG11: 15 | LH11: 8 | LI11: 7 | LJ11: 11 | LK11: 7 | LL11: 6.25 | LM11: 10 | LO11: 7 | LP11: 6.75 | LU11: 9 | LV11: 9 | LW11: 7.5 | LX11: 9 | LZ11: 4.5 | NF11: 0.6
B12: علي الكهربائي | C12: =SUM(LO12:MS12) -> 44 | D12: =SUM(MU12:NY12) -> 6.1 | AA12: 13 | AB12: 10 | AC12: 10 | AD12: 11.5 | AE12: 12 | AF12: 11 | AG12: 11 | AH12: 19 | AI12: 9.5 | AJ12: 10.5 | AK12: 9.5 | AL12: 16 | AM12: 10.5 | AN12: 10 | AQ12: 12.5 | AR12: 13.3 | AS12: 12.3 | AT12: 15 | AU12: 8.3 | AV12: 11.3 | AW12: 14.3 | AX12: 10.3 | AY12: 5 | AZ12: 14 | BB12: 11.3 | BC12: 11.3 | BD12: 10 | BE12: 11 | BF12: 9 | BG12: 12 | BI12: 14 | BK12: 10.3 | BL12: 11.3 | BM12: 9.3 | BN12: 15.3 | BO12: 2 | BP12: 10.3 | BQ12: 10.3 | BR12: 10 | BS12: 12.3 | BT12: 10 | BU12: 12.3 | BV12: 12 | BX12: 10 | BY12: 11.3 | BZ12: 10.3 | CA12: 11.3 | CB12: 12 | CC12: 4 | CD12: 13 | CE12: 11 | CF12: 11 | CG12: 14 | CH12: 7 | CI12: 11 | CK12: 11 | CL12: 10 | CM12: 10 | CN12: 11 | CO12: 11 | CP12: 11 | CQ12: 4.3 | CR12: 10 | CS12: 10.3 | CT12: 11 | CU12: 12 | CX12: 11 | CY12: 9.3 | CZ12: 10 | DA12: 11.3 | DB12: 10 | DC12: 10.3 | DD12: 12 | DE12: 7.3 | DF12: 11 | DG12: 10.3 | DH12: 10 | DI12: 8.3 | DJ12: 12 | DK12: 12 | DL12: 13 | DM12: 10 | DN12: 12 | DO12: 10 | DP12: 12 | DQ12: 13 | DR12: 12 | DS12: 15 | DT12: 8 | DU12: 12 | DW12: 11 | DX12: 12 | DY12: 11 | EA12: 12 | EB12: 12 | EC12: 12 | ED12: 14 | EG12: 9.3 | EH12: 9 | EI12: 8 | EL12: 6.25 | EM12: 8 | EN12: 10 | EO12: 12 | EP12: 9 | EQ12: 9.5 | ER12: 8 | ES12: 9 | ET12: 9.25 | EU12: 3 | EV12: 9.1 | EW12: 10 | EX12: 13 | EY12: 10 | EZ12: 7.5 | FA12: 13 | FC12: 10.5 | FD12: 12 | FE12: 8 | FF12: 10.5 | FG12: 9 | FH12: 10 | FI12: 10.5 | FJ12: 6 | FK12: 7 | FL12: 9 | FM12: 9 | FN12: 10.3 | FO12: 10 | FP12: 9 | FQ12: 9 | FR12: 10 | FS12: 9 | FT12: 8 | FV12: 10 | FW12: 11 | FX12: 12 | FY12: 8 | FZ12: 9 | GA12: 6 | GB12: 12 | GC12: 2 | GD12: 15 | GE12: 12 | GF12: 13 | GG12: 10 | GH12: 10 | GI12: 10 | GJ12: 5.5 | GK12: 11.5 | GL12: 8 | GM12: 7.5 | GN12: 5.5 | GO12: 6 | GP12: 9.25 | GQ12: 8 | GR12: 16 | GS12: 13 | GT12: 9.5 | GU12: 4 | GV12: 4.5 | GW12: 7 | GX12: 11 | GY12: 11 | GZ12: 4.5 | HA12: 5.5 | HB12: 8 | HC12: 14 | HD12: 8 | HE12: 7 | HF12: 8 | HG12: 7 | HH12: 7.5 | HI12: 4.5 | HJ12: 7.5 | HK12: 6 | HL12: X | HM12: 7 | HN12: 6.5 | HO12: 9 | HP12: 12 | HQ12: 7 | HR12: 6.5 | HS12: 6.5 | HT12: 4.5 | HU12: 7.5 | HV12: 4 | HW12: x | HX12: 0 | HY12: 8 | HZ12: 12 | IA12: 9.5 | IB12: 11.5 | IC12: 9.5 | ID12: 18 | IE12: 5 | IF12: 8.5 | IG12: 10.5 | IH12: 11.5 | II12: 10 | IJ12: x | IK12: 10.5 | IL12: 9 | IM12: 10 | IN12: 11.5 | IO12: 9.5 | IP12: 7.5 | IQ12: 10.5 | IR12: 9.5 | IS12: 9.5 | IT12: 15 | IU12: 17 | IV12: x | IW12: 11 | IX12: 12 | IY12: 6.5 | IZ12: 8 | JA12: 8 | JC12: 6.5 | JE12: 8.5 | JF12: 9 | JG12: 16 | JI12: 9 | JJ12: 12.25 | JL12: 15.5 | JM12: 17.5 | JO12: 11 | JP12: 4.5 | JQ12: 8.5 | JR12: 6.5 | JS12: 15.25 | JT12: 9 | JU12: 6.5 | JV12: 11.5 | JW12: 17.5 | JX12: 3 | JZ12: 11 | KA12: 14 | KB12: 5 | KD12: 17 | KF12: 7 | KG12: 7 | KI12: 11 | KJ12: 11 | KK12: 11.75 | KL12: 17 | KM12: 11 | KN12: 16 | KO12: x | KP12: 7 | KQ12: 14 | KR12: 4.5 | KS12: 6.5 | KT12: x | KU12: x | KV12: 18.5 | KW12: 8.75 | KX12: 9.5 | KY12: 10.25 | KZ12: 8 | LA12: x | LB12: 7.5 | LC12: 6.5 | LD12: x | LE12: 6.5 | LF12: x | LG12: 7 | LH12: 8.5 | LI12: 15 | LJ12: 5 | LK12: 5.5 | LL12: x | LM12: 25 | LU12: 9 | LV12: 9 | LW12: 8 | LX12: 9 | LZ12: 9 | NA12: 0.6 | NB12: 0.25 | NE12: 5.25
B13: حيدر يافوز | C13: =SUM(LO13:MS13) -> 60.25 | D13: =SUM(MU13:NY13) -> 7.5 | AN13: 10 | AO13: 14 | AP13: 11 | AQ13: 12 | AR13: 13.3 | AS13: 12.3 | AT13: 15 | AU13: 8.3 | AV13: 11.3 | AW13: 14.3 | AX13: 10.3 | AY13: 5 | BB13: 11.3 | BC13: 11.3 | BD13: 10 | BE13: 11 | BF13: 9 | BG13: 12 | BI13: 14 | BK13: 10.3 | BL13: 11.3 | BM13: 9.3 | BN13: 15.3 | BP13: 10.3 | BQ13: 10.3 | BR13: 10 | BS13: 12.3 | BT13: 10 | BV13: 12 | BX13: 10 | BY13: 11.3 | BZ13: 10.3 | CA13: 11.3 | CB13: 12 | CD13: 13 | CG13: 8 | CH13: 11 | CI13: 11 | CK13: 11 | CL13: 10 | CM13: 11.3 | CN13: 22 | CO13: 10.3 | CP13: 0 | CQ13: 0 | CR13: 10 | CS13: 10.3 | CT13: 11 | CU13: 12 | CX13: 11 | CY13: 6.3 | CZ13: 10.3 | DA13: 13 | DB13: 9 | DC13: 9.5 | DE13: 6 | DF13: 11 | DG13: 10.3 | DH13: 10.3 | DI13: 8.5 | DJ13: 11.45 | DK13: 11 | DL13: 9 | DM13: 9 | DN13: 12 | DO13: 12 | DP13: 12 | DQ13: 12 | DR13: 12 | DV13: 11 | DW13: 10 | DX13: 11 | EA13: 8 | EB13: 7 | ED13: 9.15 | EE13: 6 | EF13: 8 | EH13: 8 | EI13: 9.5 | EJ13: 8 | EK13: 9 | EL13: 5 | EM13: 13.25 | EN13: 12 | EO13: 12 | EP13: 9 | EQ13: 9.5 | ER13: 8 | ES13: 9 | ET13: 9.25 | EV13: 9.2 | EW13: 10 | EX13: 12 | FA13: 12 | FC13: 10.5 | FD13: 10 | FE13: 8.25 | FF13: 10.5 | FG13: 8 | FH13: 10 | FI13: 8 | FJ13: 5.25 | FK13: 7 | FL13: 9 | FM13: 9 | FN13: 9.5 | FO13: 10 | FP13: 8.5 | FR13: 12 | FT13: 10 | FU13: 10 | FV13: 10 | FW13: 8 | FX13: 11 | FY13: 12 | FZ13: 11 | GA13: 11 | GB13: 13 | GC13: 15 | GD13: 8 | GE13: 14 | GF13: 12 | GG13: 12 | GH13: 9 | GI13: 10.5 | GJ13: 6.5 | GK13: 6 | GL13: 11.5 | GM13: 16 | GN13: 13 | GO13: 16 | GP13: 16 | GQ13: 12 | GR13: 18 | GS13: 15 | GT13: 11 | GU13: 6.5 | GV13: 9 | GW13: 10 | GX13: 17 | GY13: X | GZ13: X | HA13: X | HB13: 5 | HC13: X | HD13: X | HE13: 9 | HF13: 4.5 | HG13: 11 | HH13: 9 | HI13: 13 | HJ13: 6 | HK13: 11 | HL13: 10 | HM13: 7 | HN13: 6 | HO13: 12 | HP13: 10.5 | HQ13: 10 | HR13: 10.5 | HS13: 6.5 | HT13: 6.5 | HU13: x | HV13: 5.5 | HW13: x | HX13: 0 | HY13: 10 | IA13: 8 | IB13: 11.5 | IC13: 9.5 | ID13: 8 | IE13: 14 | IF13: 13 | IG13: 11.5 | IH13: 11 | II13: 6.5 | IJ13: 0 | IK13: 13 | IL13: 11.5 | IM13: 12 | IN13: 14 | IO13: 9.5 | IP13: 0 | IQ13: 5.5 | IR13: 4.5 | IS13: 15.5 | IT13: 10 | IU13: 10 | IV13: 17.5 | IW13: 20.5 | IX13: 17.5 | IY13: 17.5 | IZ13: 8 | JA13: 7.5 | JC13: 10 | JF13: 15 | JG13: 17 | JH13: 14.5 | JI13: 11 | JJ13: 8.5 | JK13: 9 | JL13: 16.5 | JM13: 16.5 | JN13: 11 | JO13: 10.5 | JP13: 11 | JQ13: 10.5 | JR13: 11 | JS13: 9.75 | JT13: 10.25 | JU13: 14 | JV13: 14.5 | JW13: 12.75 | JX13: 11 | JY13: 5.5 | JZ13: 13.5 | KA13: 13 | KB13: 11.5 | KC13: 13 | KD13: 12 | KE13: 7 | KF13: 11.5 | KG13: 10 | KI13: 13 | KJ13: 11 | KK13: 11 | KL13: 16.5 | KM13: 7 | KN13: 9 | KO13: 9 | KP13: 4.75 | KQ13: 10 | KR13: x | KS13: 12 | KT13: 4 | KU13: 3.75 | KV13: 13.5 | KW13: x | KX13: 11 | KY13: 12.5 | KZ13: 10.75 | LA13: 14.5 | LB13: 15 | LC13: 5 | LD13: 4.45 | LE13: 11 | LF13: 8 | LG13: 10 | LH13: 8 | LI13: 9 | LJ13: 8 | LK13: 5 | LL13: 2 | LM13: 15 | LO13: 6.25 | LP13: 4 | LQ13: 8 | LU13: 8 | LV13: 8 | LW13: 8 | LX13: 9 | LZ13: 9 | ND13: 1.5 | NE13: 5.5 | NF13: 0.5
B14: عبدالله الصباغ | C14: =SUM(LO14:MS14) -> 52 | D14: =SUM(MU14:NY14) -> 13.75 | HY14: 11 | HZ14: 9.5 | IA14: 6.5 | IB14: 16 | IC14: 10 | ID14: 18 | IE14: 4 | II14: 8.5 | IJ14: 4.5 | IK14: 9 | IL14: 10.5 | IM14: 9.5 | IN14: 11 | IO14: 9.5 | IQ14: 9 | IR14: 10 | IS14: 9.5 | IT14: 10 | IU14: 17 | IV14: 7.5 | IW14: 12.5 | IX14: 8 | IY14: 14.5 | IZ14: 9 | JA14: 8 | JC14: 5 | JD14: 10.5 | JE14: 6.5 | JG14: 14.25 | JH14: 12.5 | JI14: 9.75 | JJ14: 8 | JL14: 10.5 | JM14: 10 | JN14: 8 | JO14: 15.5 | JQ14: 6.5 | JR14: 10 | JS14: 9.25 | JT14: 6 | JU14: 4 | JV14: 9 | JW14: 9 | JX14: 6 | JY14: 6 | JZ14: 7 | KA14: 10 | KB14: 9.5 | KC14: 10 | KD14: 10 | KI14: 10.5 | KJ14: 8.5 | KK14: 10 | KL14: 12 | KM14: 19 | KN14: 7 | KO14: 7 | KP14: 6 | KQ14: 11.5 | KR14: 12 | KS14: 4.5 | KT14: 7 | KU14: 9.5 | KV14: 1.5 | KW14: x | KX14: 11 | KY14: 6 | KZ14: 6 | LA14: x | LB14: 11 | LC14: 6 | LD14: 6 | LE14: 8 | LF14: x | LG14: x | LH14: 11.5 | LI14: 1 | LJ14: 6.5 | LK14: x | LL14: x | LM14: 21 | LO14: 3 | LP14: 5 | LU14: 9 | LV14: 8 | LW14: 9 | LX14: 9 | MB14: 9 | NC14: 2 | NE14: 10.5 | NH14: 1.25
B15: أنوار كريم جواد | C15: =SUM(LO15:MS15) -> 51.4 | D15: =SUM(MU15:NY15) -> 4 | LU15: 7.1 | LV15: 7.1 | LW15: 7.1 | LX15: 7.5 | LZ15: 7.6 | MA15: 7.5 | MB15: 7.5 | NE15: 4
B16: حسين مصطفى | C16: =SUM(LO16:MS16) -> 22.7 | D16: =SUM(MU16:NY16) -> 9.5 | LX16: 6 | LZ16: 9 | MA16: 7.7 | NE16: 7.5 | NF16: 2

Sheet salary calculations
A1: Task | B1: Hourly Rate (IQD) | C1: Hours Worked | D1: Checkbox (Selected) | E1: Subtotal (IQD) | F1: Column 1 | H1: Task | I1: Hourly Rate (IQD) | J1: Hours Worked | K1: Checkbox (Selected) | L1: Subtotal (IQD)
A2: حضور | B2: 1000 | C2: 1 | D2: TRUE | E2: =IF(D2=TRUE, B2, 0) -> 1000 | H2: حضور | I2: 1000 | J2: 1 | K2: TRUE | L2: =IF(K2=TRUE, I2, 0) -> 1000
A3: مسؤولية | B3: 250 | C3: 1 | D3: TRUE | E3: =IF(D3=TRUE, B3, 0) -> 250 | H3: مسؤولية | I3: 250 | J3: 1 | K3: TRUE | L3: =IF(K3=TRUE, I3, 0) -> 250
A4: خطورة | B4: 250 | C4: 1 | D4: TRUE | E4: =IF(D4=TRUE, B4, 0) -> 250 | H4: خطورة | I4: 250 | J4: 1 | K4: FALSE | L4: =IF(K4=TRUE, I4, 0) -> 0
A5: نقل | B5: 250 | C5: 1 | D5: TRUE | E5: =IF(D5=TRUE, B5, 0) -> 250 | H5: نقل | I5: 250 | J5: 1 | K5: TRUE | L5: =IF(K5=TRUE, I5, 0) -> 250
A6: طعام | B6: 250 | C6: 1 | D6: TRUE | E6: =IF(D6=TRUE, B6, 0) -> 250 | H6: طعام | I6: 250 | J6: 1 | K6: TRUE | L6: =IF(K6=TRUE, I6, 0) -> 250
A7: موقع خارجي | B7: 250 | C7: 1 | D7: FALSE | E7: =IF(D7=TRUE, B7, 0) -> 0 | H7: موقع خارجي | I7: 250 | J7: 1 | K7: FALSE | L7: =IF(K7=TRUE, I7, 0) -> 0
A8: خطورة خارجية | B8: 250 | C8: 1 | D8: FALSE | E8: =IF(D8=TRUE, B8, 0) -> 0 | H8: خطورة خارجية | I8: 250 | J8: 1 | K8: FALSE | L8: =IF(K8=TRUE, I8, 0) -> 0
A9: حدادة | B9: 250 | C9: 1 | D9: FALSE | E9: =IF(D9=TRUE, B9, 0) -> 0 | H9: حدادة | I9: 250 | J9: 1 | K9: TRUE | L9: =IF(K9=TRUE, I9, 0) -> 250
A10: صبغ | B10: 250 | C10: 1 | D10: FALSE | E10: =IF(D10=TRUE, B10, 0) -> 0 | H10: صبغ | I10: 250 | J10: 1 | K10: TRUE | L10: =IF(K10=TRUE, I10, 0) -> 250
A11: نجارة | B11: 250 | C11: 1 | D11: TRUE | E11: =IF(D11=TRUE, B11, 0) -> 250 | H11: نجارة | I11: 250 | J11: 1 | K11: FALSE | L11: =IF(K11=TRUE, I11, 0) -> 0
A12: تشغيل مكائن | B12: 250 | C12: 1 | D12: FALSE | E12: =IF(D12=TRUE, B12, 0) -> 0 | H12: تشغيل مكائن | I12: 250 | J12: 1 | K12: FALSE | L12: =IF(K12=TRUE, I12, 0) -> 0 | N12: =IFERROR(__xludf.DUMMYFUNCTION("IMPORTRANGE( ""https://docs.google.com/spreadsheets/d/1DwfNhxfCYJYwBjeiPqn3xZyjMmzDkpS9634bVMHLYJQ/edit?usp=sharing"" , ""CUTS!C6"")"),"#REF!") -> #REF!
A13: تصميم | B13: 250 | C13: 1 | D13: FALSE | E13: =IF(D13=TRUE, B13, 0) -> 0 | H13: تصميم | I13: 250 | J13: 1 | K13: FALSE | L13: =IF(K13=TRUE, I13, 0) -> 0
A14: بدل سكن | B14: 250 | C14: 1 | D14: FALSE | E14: =IF(D14=TRUE, B14, 0) -> 0 | H14: بدل سكن | I14: 250 | J14: 1 | K14: FALSE | L14: =IF(K14=TRUE, I14, 0) -> 0
A15: إدارة | B15: 250 | C15: 1 | D15: FALSE | E15: =IF(D15=TRUE, B15, 0) -> 0 | H15: إدارة | I15: 250 | J15: 1 | K15: FALSE | L15: =IF(K15=TRUE, I15, 0) -> 0
A16: إشراف | B16: 250 | C16: 1 | D16: FALSE | E16: =IF(D16=TRUE, B16, 0) -> 0 | H16: إشراف | I16: 250 | J16: 1 | K16: TRUE | L16: =IF(K16=TRUE, I16, 0) -> 250
A17: حسابات | B17: 250 | C17: 1 | D17: FALSE | E17: =IF(D17=TRUE, B17, 0) -> 0 | H17: حسابات | I17: 250 | J17: 1 | K17: FALSE | L17: =IF(K17=TRUE, I17, 0) -> 0
A18: إدارة زبائن | B18: 250 | C18: 1 | D18: FALSE | E18: =IF(D18=TRUE, B18, 0) -> 0 | H18: إدارة زبائن | I18: 250 | J18: 1 | K18: FALSE | L18: =IF(K18=TRUE, I18, 0) -> 0
A19: كهربائيات | B19: 250 | C19: 1 | D19: TRUE | E19: =IF(D19=TRUE, B19, 0) -> 250 | H19: كهربائيات | I19: 250 | J19: 1 | K19: FALSE | L19: =IF(K19=TRUE, I19, 0) -> 0
A20: مخصص اضافي | B20: 250 | C20: 1 | D20: FALSE | E20: =IF(D20=TRUE, B20, 0) -> 0 | H20: مخصص اضافي | I20: 250 | J20: 1 | K20: FALSE | L20: =IF(K20=TRUE, I20, 0) -> 0
A21: الإجمالي | E21: =SUM(E2:E20) -> 2500 | H21: الإجمالي | L21: =SUM(L2:L20) -> 2500
A24: Task | B24: Hourly Rate (IQD) | C24: Hours Worked | D24: Checkbox (Selected) | E24: Subtotal (IQD) | H24: Task | I24: Hourly Rate (IQD) | J24: Hours Worked | K24: Checkbox (Selected) | L24: Subtotal (IQD)
A25: حضور | B25: 1000 | C25: 1 | D25: TRUE | E25: =IF(D25=TRUE, B25, 0) -> 1000 | H25: حضور | I25: 1000 | J25: 1 | K25: TRUE | L25: =IF(K25=TRUE, I25, 0) -> 1000
A26: مسؤولية | B26: 250 | C26: 1 | D26: TRUE | E26: =IF(D26=TRUE, B26, 0) -> 250 | H26: مسؤولية | I26: 250 | J26: 1 | K26: TRUE | L26: =IF(K26=TRUE, I26, 0) -> 250
A27: خطورة | B27: 250 | C27: 1 | D27: TRUE | E27: =IF(D27=TRUE, B27, 0) -> 250 | H27: خطورة | I27: 250 | J27: 1 | K27: FALSE | L27: =IF(K27=TRUE, I27, 0) -> 0
A28: نقل | B28: 250 | C28: 1 | D28: TRUE | E28: =IF(D28=TRUE, B28, 0) -> 250 | H28: نقل | I28: 250 | J28: 1 | K28: TRUE | L28: =IF(K28=TRUE, I28, 0) -> 250
A29: طعام | B29: 250 | C29: 1 | D29: TRUE | E29: =IF(D29=TRUE, B29, 0) -> 250 | H29: طعام | I29: 250 | J29: 1 | K29: TRUE | L29: =IF(K29=TRUE, I29, 0) -> 250
A30: موقع خارجي | B30: 250 | C30: 1 | D30: TRUE | E30: =IF(D30=TRUE, B30, 0) -> 250 | H30: موقع خارجي | I30: 250 | J30: 1 | K30: FALSE | L30: =IF(K30=TRUE, I30, 0) -> 0
A31: خطورة خارجية | B31: 250 | C31: 1 | D31: FALSE | E31: =IF(D31=TRUE, B31, 0) -> 0 | H31: خطورة خارجية | I31: 250 | J31: 1 | K31: FALSE | L31: =IF(K31=TRUE, I31, 0) -> 0
A32: حدادة | B32: 250 | C32: 1 | D32: TRUE | E32: =IF(D32=TRUE, B32, 0) -> 250 | H32: حدادة | I32: 250 | J32: 1 | K32: FALSE | L32: =IF(K32=TRUE, I32, 0) -> 0
A33: صبغ | B33: 250 | C33: 1 | D33: FALSE | E33: =IF(D33=TRUE, B33, 0) -> 0 | H33: صبغ | I33: 250 | J33: 1 | K33: FALSE | L33: =IF(K33=TRUE, I33, 0) -> 0
A34: نجارة | B34: 250 | C34: 1 | D34: FALSE | E34: =IF(D34=TRUE, B34, 0) -> 0 | H34: نجارة | I34: 250 | J34: 1 | K34: FALSE | L34: =IF(K34=TRUE, I34, 0) -> 0
A35: تشغيل مكائن | B35: 250 | C35: 1 | D35: TRUE | E35: =IF(D35=TRUE, B35, 0) -> 250 | H35: تشغيل مكائن | I35: 250 | J35: 1 | K35: TRUE | L35: =IF(K35=TRUE, I35, 0) -> 250
A36: تصميم | B36: 250 | C36: 1 | D36: TRUE | E36: =IF(D36=TRUE, B36, 0) -> 250 | H36: تصميم | I36: 250 | J36: 1 | K36: TRUE | L36: =IF(K36=TRUE, I36, 0) -> 250
... A43: مخصص اضافي | B43: 250 | C43: 1 | D43: FALSE | E43: =IF(D43=TRUE, B43, 0) -> 0 | H43: مخصص اضافي | I43: 250 | J43: 1 | K43: FALSE | L43: =IF(K43=TRUE, I43, 0) -> 0
A44: الإجمالي | E44: =SUM(E25:E43) -> 3000 | H44: الإجمالي | L44: =SUM(L25:L43) -> 2750
A47: Task | B47: Hourly Rate (IQD) | C47: Hours Worked | D47: Checkbox (Selected) | E47: Subtotal (IQD) | H47: Task | I47: Hourly Rate (IQD) | J47: Hours Worked | K47: Checkbox (Selected) | L47: Subtotal (IQD)
A48: حضور | B48: 1000 | C48: 1 | D48: TRUE | E48: =IF(D48=TRUE, B48, 0) -> 1000 | H48: حضور | I48: 1000 | J48: 1 | K48: TRUE | L48: =IF(K48=TRUE, I48, 0) -> 1000
A49: مسؤولية | B49: 250 | C49: 1 | D49: TRUE | E49: =IF(D49=TRUE, B49, 0) -> 250 | H49: مسؤولية | I49: 250 | J49: 1 | K49: TRUE | L49: =IF(K49=TRUE, I49, 0) -> 250
A50: خطورة | B50: 250 | C50: 1 | D50: FALSE | E50: =IF(D50=TRUE, B50, 0) -> 0 | H50: خطورة | I50: 250 | J50: 1 | K50: TRUE | L50: =IF(K50=TRUE, I50, 0) -> 250
...

Sheet رواتب شهر السابع
A4: الموظف | B4: الراتب الأسمي بالساعات | D4: الراتب الأسمي | E4: الحوافز | F4: القطوعات | G4: المستلم | H4: الأجمالي
C5: TIME
A6: حيدر المحاسب
A7: يوسف يعقوب
A8: عبد الرضا عقيل
A9: محمد رشيد | B9: 2750 | C9: =SUM('الحظور'!LO9:MR9) -> 0 | D9: =(B9)*C9 -> 0 | E9: 0 | F9: ='السلف و الغرامات'!C9 -> 50000 | G9: 0 | H9: =(B9)*C9+E9-F9-G9 -> -50000
A10: حيدر الصباغ
A11: وليد
A12: علي الكهربائي
A13: حيدر يافوز
A14: يونس يعقوب
A15: عبدالله الصباغ
A16: أنوار كريم جواد
A17: كرار رمضان | B17: 1750 | C17: =SUM(#REF!) -> #REF! | D17: =(B17)*C17 -> #REF! | E17: 0 | F17: =#REF! -> #REF! | G17: 0 | H17: =(B17)*C17+E17-F17-G17 -> #REF!

Sheet رواتب شهر السادس
A4: الموظف | B4: الراتب الأسمي بالساعات | D4: الراتب الأسمي | E4: الحوافز | F4: القطوعات | G4: المستلم | H4: الأجمالي
C5: TIME
A6: حيدر المحاسب | B6: 3000 | C6: =SUM('الحظور'!KI6:LM6) -> 282.75 | D6: =(B6)*C6 -> 848250 | E6: 9250 | F6: =SUM('السلف و الغرامات'!AI6:BL6) -> 157500 | G6: 700000 | H6: =(B6)*C6+E6-F6-G6 -> 0
A7: يوسف يعقوب | B7: 3000 | C7: =SUM('الحظور'!KI7:LM7) -> 260.5 | D7: =(B7)*C7 -> 781500 | E7: 0 | F7: =SUM('السلف و الغرامات'!AI7:BL7) -> 342000 | G7: 439500 | H7: =(B7)*C7+E7-F7-G7 -> 0
A8: عبد الرضا عقيل | B8: 3000 | C8: =SUM('الحظور'!KI8:LM8) -> 236 | D8: =(B8)*C8 -> 708000 | E8: 3000 | F8: =SUM('السلف و الغرامات'!AI8:BL8) -> 405666 | G8: 305334 | H8: =(B8)*C8+E8-F8-G8 -> 0
A9: محمد رشيد | B9: 2750 | C9: =SUM('الحظور'!KI9:LM9) -> 163 | D9: =(B9)*C9 -> 448250 | E9: 187000 | F9: =SUM('السلف و الغرامات'!AI9:BL9) -> 395416 | G9: 239834 | H9: =(B9)*C9+E9-F9-G9 -> 0
A10: حيدر الصباغ | B10: 2500 | C10: =SUM('الحظور'!KI10:LM10) -> 152.9 | D10: =(B10)*C10 -> 382250 | E10: 100000 | F10: =SUM('السلف و الغرامات'!AI10:BL10) -> 117250 | G10: 365000 | H10: =(B10)*C10+E10-F10-G10 -> 0
A11: وليد | B11: 2500 | C11: =SUM('الحظور'!KI11:LM11) -> 246.75 | D11: =(B11)*C11 -> 616875 | E11: 101000 | F11: =SUM('السلف و الغرامات'!AI11:BL11) -> 681417 | G11: 150542 | H11: =(B11)*C11+E11-F11-G11 -> -114084
A12: علي الكهربائي | B12: 2500 | C12: =SUM('الحظور'!KI12:LM12) -> 251.25 | D12: =(B12)*C12 -> 628125 | E12: 0 | F12: =SUM('السلف و الغرامات'!AI12:BL12) -> 682000 | G12: 0 | H12: =(B12)*C12+E12-F12-G12 -> -53875
A13: حيدر يافوز | B13: 2250 | C13: =SUM('الحظور'!KI13:LM13) -> 273.7 | D13: =(B13)*C13 -> 615825 | E13: 2591 | F13: =SUM('السلف و الغرامات'!AI13:BL13) -> 358416 | G13: 260000 | H13: =(B13)*C13+E13-F13-G13 -> 0
A14: يونس يعقوب | B14: 2000 | C14: =SUM(#REF!) -> #REF! | D14: =(B14)*C14 -> #REF! | E14: 6000 | F14: =SUM(#REF!) -> #REF! | G14: 0 | H14: =(B14)*C14+E14-F14-G14 -> #REF!
A15: عبدالله الصباغ | B15: 2000 | C15: =SUM('الحظور'!KI14:LM14) -> 220 | D15: =(B15)*C15 -> 440000 | E15: 0 | F15: =SUM('السلف و الغرامات'!AI14:BL14) -> 172418 | G15: 267582 | H15: =(B15)*C15+E15-F15-G15 -> 0
A16: أنوار كريم جواد | B16: 2000 | C16: =SUM(#REF!) -> #REF! | D16: =(B16)*C16 -> #REF! | E16: 0 | F16: =SUM('السلف و الغرامات'!AI15:BL15) -> 0 | G16: 346000 | H16: =(B16)*C16+E16-F16-G16 -> #REF!

Sheet السلف و الغرامات
D2: 45778 | E2: 45779 | F2: 45780 | G2: 45781 | H2: 45782 | I2: 45783 | J2: 45784 | K2: 45785 | L2: 45786 | M2: 45787 | N2: 45788 | O2: 45789 | P2: 45790 | Q2: 45791 | R2: 45792 | S2: 45793 | T2: 45794 | U2: 45795 | V2: 45796 | W2: 45797 | X2: 45798 | Y2: 45799 | Z2: 45800 | AA2: 45801 | AB2: 45802 | AC2: 45803 | AD2: 45804 | AE2: 45805 | AF2: 45806 | AG2: 45807 | AH2: 45808 | AI2: 45809 | AJ2: 45810 | AK2: 45811 | AL2: 45812 | AM2: 45813 | AN2: 45814 | AO2: 45815 | AP2: 45816 | AQ2: 45817 | AR2: 45818 | AS2: 45819 | AT2: 45820 | AU2: 45821 | AV2: 45822 | AW2: 45823 | AX2: 45824 | AY2: 45825 | AZ2: 45826 | BA2: 45827 | BB2: 45828 | BC2: 45829 | BD2: 45830 | BE2: 45831 | BF2: 45832 | BG2: 45833 | BH2: 45834 | BI2: 45835 | BJ2: 45836 | BK2: 45837 | BL2: 45838 | BM2: ديون | BN2: 45839 | BO2: 45840 | BP2: 45841 | BQ2: 45842 | BR2: 45843 | BS2: 45844 | BT2: 45845 | BU2: 45846 | BV2: 45847 | BW2: 45848 | BX2: 45849 | BY2: 45850 | BZ2: 45851 | CA2: 45852 | CB2: 45853 | CC2: 45854 | CD2: 45855 | CE2: 45856 | CF2: 45857 | CG2: 45858 | CH2: 45859 | CI2: 45860 | CJ2: 45861 | CK2: 45862 | CL2: 45863 | CM2: 45864 | CN2: 45865 | CO2: 45866 | CP2: 45867 | CQ2: 45868 | CR2: 45869 | CS2: 45870 | CT2: 45871 | CU2: 45872 | CV2: 45873 | CW2: 45874 | CX2: 45875 | CY2: 45876 | CZ2: 45877 | DA2: 45878 | DB2: 45879 | DC2: 45880 | DD2: 45881 | DE2: 45882 | DF2: 45883 | DG2: 45884 | DH2: 45885 | DI2: 45886 | DJ2: 45887 | DK2: 45888 | DL2: 45889 | DM2: 45890 | DN2: 45891 | DO2: 45892 | DP2: 45893 | DQ2: 45894 | DR2: 45895 | DS2: 45896 | DT2: 45897 | DU2: 45898 | DV2: 45899 | DW2: 45900 | DX2: 45901 | DY2: 45902 | DZ2: 45903 | EA2: 45904 | EB2: 45905 | EC2: 45906 | ED2: 45907 | EE2: 45908 | EF2: 45909 | EG2: 45910 | EH2: 45911 | EI2: 45912 | EJ2: 45913 | EK2: 45914 | EL2: 45915 | EM2: 45916 | EN2: 45917 | EO2: 45918 | EP2: 45919 | EQ2: 45920 | ER2: 45921 | ES2: 45922 | ET2: 45923 | EU2: 45924 | EV2: 45925 | EW2: 45926 | EX2: 45927 | EY2: 45928 | EZ2: 45929 | FA2: 45930 | FB2: 45931 | FC2: 45932 | FD2: 45933 | FE2: 45934 | FF2: 45935 | FG2: 45936 | FH2: 45937 | FI2: 45938 | FJ2: 45939 | FK2: 45940 | FL2: 45941 | FM2: 45942 | FN2: 45943 | FO2: 45944 | FP2: 45945 | FQ2: 45946 | FR2: 45947 | FS2: 45948 | FT2: 45949 | FU2: 45950 | FV2: 45951 | FW2: 45952 | FX2: 45953 | FY2: 45954 | FZ2: 45955 | GA2: 45956
BM3: الشهر
D4: =D2 -> 45778 | E4: =E2 -> 45779 | F4: =F2 -> 45780 | G4: =G2 -> 45781 | H4: =H2 -> 45782 | I4: =I2 -> 45783 | J4: =J2 -> 45784 | K4: =K2 -> 45785 | ... BL4: =BL2 -> 45838 | BM4: السابق | BN4: =BN2 -> 45839 | BO4: =BO2 -> 45840 | BP4: =BP2 -> 45841 | BQ4: =BQ2 -> 45842 | BR4: =BR2 -> 45843 | BS4: =BS2 -> 45844 | BT4: =BT2 -> 45845 | BU4: =BU2 -> 45846 | ... GA4: =GA2 -> 45956
C5: المجموع
B6: حيدر المحاسب | C6: =sum(BM6:CQ6) -> 0 | D6: 20000 | F6: 27000 | G6: 36000 | L6: 150000 | M6: 25000 | Q6: 13000 | R6: 33000 | Z6: 35000 | AA6: 100000 | AF6: 26100 | AG6: 35000 | AH6: 287000 | AK6: 5000 | AL6: 20000 | AM6: 5000 | AQ6: 30000 | AR6: 26500 | AT6: 34000 | BF6: 12000 | BK6: 25000
B7: يوسف يعقوب | C7: =sum(BM7:CQ7) -> 0 | G7: 150000 | Q7: 150000 | AK7: 2000 | AQ7: 140000 | AV7: 10000 | AW7: 190000
B8: عبد الرضا عقيل | C8: =sum(BM8:CQ8) -> 150000 | D8: 75000 | H8: 25000 | N8: 35000 | P8: 5000 | Q8: 52000 | R8: 75000 | X8: 25000 | AB8: 2500 | AF8: 10000 | AG8: 25000 | AH8: 34000 | AI8: 140000 | AJ8: 15000 | AK8: 12500 | AQ8: 22000 | AR8: 57000 | AS8: 25000 | AT8: 10000 | AV8: 25000 | AW8: 10000 | AX8: 4166 | BA8: 25000 | BB8: 25000 | BG8: 25000 | BK8: 10000 | BN8: 25000 | BW8: 75000 | BX8: 15000 | BY8: 35000
B9: محمد رشيد | C9: =sum(BM9:CQ9) -> 50000 | Q9: 2000 | U9: 15000 | X9: 25000 | Z9: 25000 | AB9: 100000 | AE9: 250000 | AG9: 25000 | AH9: 25000 | AK9: 10000 | AO9: 5000 | AQ9: 10000 | AT9: 25000 | AX9: 4166 | AY9: 25000 | BA9: 5000 | BB9: 25000 | BC9: 50000 | BE9: 5000 | BF9: 50000 | BG9: 150000 | BJ9: 25000 | BL9: 6250 | BR9: 25000 | BV9: 25000
B10: حيدر الصباغ | C10: =sum(BM10:CQ10) -> 35000 | N10: 100000 | R10: 10000 | AB10: 12500 | AE10: 75000 | AH10: 34000 | AJ10: 20000 | AK10: 2000 | AM10: 10000 | AR10: 25000 | AT10: 25000 | BA10: 25000 | BB10: 2000 | BE10: 2000 | BL10: 6250 | BY10: 35000
B11: وليد | C11: =sum(BM11:CQ11) -> 313000 | O11: 10000 | Q11: 47000 | S11: 15000 | AA11: 100000 | AG11: 5000 | AH11: 39000 | AJ11: 75000 | AM11: 75000 | AQ11: 10000 | AR11: 152000 | AX11: 4167 | BA11: 10000 | BB11: 2000 | BC11: 25000 | BD11: 10000 | BE11: 2000 | BG11: 70000 | BH11: 140000 | BK11: 100000 | BL11: 6250 | BM11: 113000 | BQ11: 50000 | BX11: 150000
B12: علي الكهربائي | C12: =sum(BM12:CQ12) -> 108000 | M12: 5000 | N12: 25000 | V12: 75000 | Y12: 5000 | AD12: 50000 | AG12: 208000 | AH12: 46000 | AO12: 5000 | AT12: 85000 | AV12: 10000 | AY12: 75000 | AZ12: 500000 | BA12: 3000 | BB12: 2000 | BE12: 2000 | BM12: 53000 | BQ12: 50000 | BX12: 5000
B13: حيدر يافوز | C13: =sum(BM13:CQ13) -> 170000 | D13: 10000 | L13: 30000 | Q13: 202000 | T13: 5000 | W13: 2000 | AA13: 5000 | AE13: 20000 | AF13: 263000 | AG13: 10000 | AH13: 46000 | AL13: 5000 | AM13: 10000 | AQ13: 85000 | AU13: 15000 | AV13: 15000 | AX13: 4166 | AY13: 25000 | AZ13: 25000 | BA13: 4000 | BB13: 2000 | BE13: 2000 | BF13: 110000 | BI13: 50000 | BL13: 6250 | BU13: 150000 | BZ13: 5000 | CA13: 15000
B14: عبدالله الصباغ | C14: =sum(BM14:CQ14) -> 35000 | H14: 50000 | O14: 10000 | S14: 20000 | T14: 10000 | V14: 10000 | X14: 25000 | Y14: 25000 | AB14: 25000 | AE14: 75000 | AH14: 47000 | AJ14: 13000 | AK14: 2000 | AL14: 15000 | AR14: 50000 | AX14: 4168 | BB14: 2000 | BC14: 25000 | BE14: 25000 | BJ14: 30000 | BL14: 6250 | BY14: 35000
B15: أنوار كريم جواد | C15: =sum(BM15:CQ15) -> 0
B16: حسين مصطفى | C16: =sum(BM16:CQ16) -> 0
B17: واردات سيف عدنان | C17: =sum(D17:FZ17) -> 11541000 | D17: 4250000 | E17: 3000000 | F17: 250000 | J17: 875000 | M17: 500000 | V17: 255000 | AI17: 50000 | AJ17: 500000 | AM17: 500000 | AO17: 45000 | AW17: 500000 | BB17: 15000 | BI17: 270000 | BK17: 50000 | BN17: 126000 | BP17: 330000 | BR17: 25000
B18: يوسف يعقوب قرض | C18: =sum(D18:FZ18) -> 43356500 | D18: 5000000 | E18: 5000000 | F18: 1090000 | G18: 12675000 | H18: 1000000 | I18: 1000000 | T18: 325000 | U18: 595000 | V18: 485000 | AJ18: 292000 | AK18: 128000 | AY18: 1375000 | BA18: 25000 | BB18: 750000 | BI18: 430000 | BJ18: 355000 | BK18: 2500000 | BL18: 6019000 | BN18: 850000 | BO18: 493500 | BP18: 200000 | BQ18: 100000 | BT18: 1831000 | BU18: 40000 | BV18: 123000 | BW18: 550000 | BX18: 125000

Sheet ٧ السلف و الغرامات
A1: haidermudher28@gmail.com
D2: 45778 | E2: 45779 | F2: 45780 | G2: 45781 | H2: 45782 | I2: 45783 | J2: 45784 | K2: 45785 | L2: 45786 | M2: 45787 | N2: 45788 | O2: 45789 | P2: 45790 | Q2: 45791 | R2: 45792 | S2: 45793 | T2: 45794 | U2: 45795 | V2: 45796 | W2: 45797 | X2: 45798 | Y2: 45799 | Z2: 45800 | AA2: 45801 | AB2: 45802 | AC2: 45803 | AD2: 45804 | AE2: 45805 | AF2: 45806 | AG2: 45807 | AH2: 45808 | AI2: 45809 | AJ2: 45810 | AK2: 45811 | AL2: 45812 | AM2: 45813 | AN2: 45814 | AO2: 45815 | AP2: 45816 | AQ2: 45817 | AR2: 45818 | AS2: 45819 | AT2: 45820 | AU2: 45821 | AV2: 45822 | AW2: 45823 | AX2: 45824 | AY2: 45825 | AZ2: 45826 | BA2: 45827 | BB2: 45828 | BC2: 45829 | BD2: 45830 | BE2: 45831 | BF2: 45832 | BG2: 45833 | BH2: 45834 | BI2: 45835 | BJ2: 45836 | BK2: 45837 | BL2: 45838 | BM2: ديون | BN2: 45839 | BO2: 45840 | BP2: 45841 | BQ2: 45842 | BR2: 45843 | BS2: 45844 | BT2: 45845 | BU2: 45846 | BV2: 45847 | BW2: 45848 | BX2: 45849 | BY2: 45850 | BZ2: 45851 | CA2: 45852 | CB2: 45853 | CC2: 45854 | CD2: 45855 | CE2: 45856 | CF2: 45857 | CG2: 45858 | CH2: 45859 | CI2: 45860 | CJ2: 45861 | CK2: 45862 | CL2: 45863 | CM2: 45864 | CN2: 45865 | CO2: 45866 | CP2: 45867 | CQ2: 45868 | CR2: 45869 | CS2: 45870 | CT2: 45871 | CU2: 45872 | CV2: 45873 | CW2: 45874 | CX2: 45875 | CY2: 45876 | CZ2: 45877 | DA2: 45878 | DB2: 45879 | DC2: 45880 | DD2: 45881 | DE2: 45882 | DF2: 45883 | DG2: 45884 | DH2: 45885 | DI2: 45886 | DJ2: 45887 | DK2: 45888 | DL2: 45889 | DM2: 45890 | DN2: 45891 | DO2: 45892 | DP2: 45893 | DQ2: 45894 | DR2: 45895 | DS2: 45896 | DT2: 45897 | DU2: 45898 | DV2: 45899 | DW2: 45900 | DX2: 45901 | DY2: 45902 | DZ2: 45903 | EA2: 45904 | EB2: 45905 | EC2: 45906 | ED2: 45907 | EE2: 45908 | EF2: 45909 | EG2: 45910 | EH2: 45911 | EI2: 45912 | EJ2: 45913 | EK2: 45914 | EL2: 45915 | EM2: 45916 | EN2: 45917 | EO2: 45918 | EP2: 45919 | EQ2: 45920 | ER2: 45921 | ES2: 45922 | ET2: 45923 | EU2: 45924 | EV2: 45925 | EW2: 45926 | EX2: 45927 | EY2: 45928 | EZ2: 45929 | FA2: 45930 | FB2: 45931 | FC2: 45932 | FD2: 45933 | FE2: 45934 | FF2: 45935 | FG2: 45936 | FH2: 45937 | FI2: 45938 | FJ2: 45939 | FK2: 45940 | FL2: 45941 | FM2: 45942 | FN2: 45943 | FO2: 45944 | FP2: 45945 | FQ2: 45946 | FR2: 45947 | FS2: 45948 | FT2: 45949 | FU2: 45950 | FV2: 45951 | FW2: 45952 | FX2: 45953 | FY2: 45954 | FZ2: 45955 | GA2: 45956
BM3: الشهر
D4: =D2 -> 45778 | E4: =E2 -> 45779 | F4: =F2 -> 45780 | G4: =G2 -> 45781 | H4: =H2 -> 45782 | I4: =I2 -> 45783 | J4: =J2 -> 45784 | K4: =K2 -> 45785 | ... BL4: =BL2 -> 45838 | BM4: السابق | BN4: =BN2 -> 45839 | BO4: =BO2 -> 45840 | BP4: =BP2 -> 45841 | BQ4: =BQ2 -> 45842 | BR4: =BR2 -> 45843 | BS4: =BS2 -> 45844 | BT4: =BT2 -> 45845 | BU4: =BU2 -> 45846 | ... GA4: =GA2 -> 45956
C5: المجموع
B6: حيدر المحاسب | C6: =sum(BM6:CQ6) -> 0 | D6: 20000 | F6: 27000 | G6: 36000 | L6: 150000 | M6: 25000 | Q6: 13000 | R6: 33000 | Z6: 35000 | AA6: 100000 | AF6: 26100 | AG6: 35000 | AH6: 287000 | AK6: 5000 | AL6: 20000 | AM6: 5000 | AQ6: 30000 | AR6: 26500 | AT6: 34000 | BF6: 12000 | BK6: 25000
B7: يوسف يعقوب | C7: =sum(BM7:CQ7) -> 0 | G7: 150000 | Q7: 150000 | AK7: 2000 | AQ7: 140000 | AV7: 10000 | AW7: 190000
B8: عبد الرضا عقيل | C8: =sum(BM8:CQ8) -> 150000 | D8: 75000 | H8: 25000 | N8: 35000 | P8: 5000 | Q8: 52000 | R8: 75000 | X8: 25000 | AB8: 2500 | AF8: 10000 | AG8: 25000 | AH8: 34000 | AI8: 140000 | AJ8: 15000 | AK8: 12500 | AQ8: 22000 | AR8: 57000 | AS8: 25000 | AT8: 10000 | AV8: 25000 | AW8: 10000 | AX8: 4166 | BA8: 25000 | BB8: 25000 | BG8: 25000 | BK8: 10000 | BN8: 25000 | BW8: 75000 | BX8: 15000 | BY8: 35000
B9: محمد رشيد | C9: =sum(BM9:CQ9) -> 50000 | Q9: 2000 | U9: 15000 | X9: 25000 | Z9: 25000 | AB9: 100000 | AE9: 250000 | AG9: 25000 | AH9: 25000 | AK9: 10000 | AO9: 5000 | AQ9: 10000 | AT9: 25000 | AX9: 4166 | AY9: 25000 | BA9: 5000 | BB9: 25000 | BC9: 50000 | BE9: 5000 | BF9: 50000 | BG9: 150000 | BJ9: 25000 | BL9: 6250 | BR9: 25000 | BV9: 25000
B10: حيدر الصباغ | C10: =sum(BM10:CQ10) -> 35000 | N10: 100000 | R10: 10000 | AB10: 12500 | AE10: 75000 | AH10: 34000 | AJ10: 20000 | AK10: 2000 | AM10: 10000 | AR10: 25000 | AT10: 25000 | BA10: 25000 | BB10: 2000 | BE10: 2000 | BL10: 6250 | BY10: 35000
B11: وليد | C11: =sum(BM11:CQ11) -> 313000 | O11: 10000 | Q11: 47000 | S11: 15000 | AA11: 100000 | AG11: 5000 | AH11: 39000 | AJ11: 75000 | AM11: 75000 | AQ11: 10000 | AR11: 152000 | AX11: 4167 | BA11: 10000 | BB11: 2000 | BC11: 25000 | BD11: 10000 | BE11: 2000 | BG11: 70000 | BH11: 140000 | BK11: 100000 | BL11: 6250 | BM11: 113000 | BQ11: 50000 | BX11: 150000
B12: علي الكهربائي | C12: =sum(BM12:CQ12) -> 108000 | M12: 5000 | N12: 25000 | V12: 75000 | Y12: 5000 | AD12: 50000 | AG12: 208000 | AH12: 46000 | AO12: 5000 | AT12: 85000 | AV12: 10000 | AY12: 75000 | AZ12: 500000 | BA12: 3000 | BB12: 2000 | BE12: 2000 | BM12: 53000 | BQ12: 50000 | BX12: 5000
B13: حيدر يافوز | C13: =sum(BM13:CQ13) -> 170000 | D13: 10000 | L13: 30000 | Q13: 202000 | T13: 5000 | W13: 2000 | AA13: 5000 | AE13: 20000 | AF13: 263000 | AG13: 10000 | AH13: 46000 | AL13: 5000 | AM13: 10000 | AQ13: 85000 | AU13: 15000 | AV13: 15000 | AX13: 4166 | AY13: 25000 | AZ13: 25000 | BA13: 4000 | BB13: 2000 | BE13: 2000 | BF13: 110000 | BI13: 50000 | BL13: 6250 | BU13: 150000 | BZ13: 5000 | CA13: 15000
B14: عبدالله الصباغ | C14: =sum(BM14:CQ14) -> 35000 | H14: 50000 | O14: 10000 | S14: 20000 | T14: 10000 | V14: 10000 | X14: 25000 | Y14: 25000 | AB14: 25000 | AE14: 75000 | AH14: 47000 | AJ14: 13000 | AK14: 2000 | AL14: 15000 | AR14: 50000 | AX14: 4168 | BB14: 2000 | BC14: 25000 | BE14: 25000 | BJ14: 30000 | BL14: 6250 | BY14: 35000
B15: أنوار كريم جواد | C15: =sum(BM15:CQ15) -> 0
B16: حسين مصطفى | C16: =sum(BM16:CQ16) -> 0
B17: واردات سيف عدنان | C17: =sum(D17:FZ17) -> 11541000 | D17: 4250000 | E17: 3000000 | F17: 250000 | J17: 875000 | M17: 500000 | V17: 255000 | AI17: 50000 | AJ17: 500000 | AM17: 500000 | AO17: 45000 | AW17: 500000 | BB17: 15000 | BI17: 270000 | BK17: 50000 | BN17: 126000 | BP17: 330000 | BR17: 25000
B18: يوسف يعقوب قرض | C18: =sum(D18:FZ18) -> 43356500 | D18: 5000000 | E18: 5000000 | F18: 1090000 | G18: 12675000 | H18: 1000000 | I18: 1000000 | T18: 325000 | U18: 595000 | V18: 485000 | AJ18: 292000 | AK18: 128000 | AY18: 1375000 | BA18: 25000 | BB18: 750000 | BI18: 430000 | BJ18: 355000 | BK18: 2500000 | BL18: 6019000 | BN18: 850000 | BO18: 493500 | BP18: 200000 | BQ18: 100000 | BT18: 1831000 | BU18: 40000 | BV18: 123000 | BW18: 550000 | BX18: 125000

Sheet الحضور 1
X1: =iferror(concatenate(" Enter ", 'Attendance key'!$B$7, " for ",'Attendance key'!$C$7, ", ", 'Attendance key'!$B$8, " for ", 'Attendance key'!$C$8, ", ", 'Attendance key'!$B$9, " for ", 'Attendance key'!$C$9, ", and ", 'Attendance key'!$B$10, " for ", 'Attendance key'!$C$10, ". Use the 'Attendance key' tab to customize. "),"") | GL1: hhg
