Workbook

Sheet الرواتب
B2: الرواتب
C4: الموظف | D4: الراتب الأسمي بالساعات | E4: الراتب الأسمي | F4: الساعات الاضافيه | G4: الحوافز | H4: القطوعات | I4: المستلم | J4: الأجمالي
C6: يوسف يعقوب | D6: 2250 | E6: =(#REF!)*D6 -> #REF! | F6: =(#REF!)*1.25*D6 -> #REF! | H6: ='السلف و الغرامات'!C7 -> 0 | J6: =SUM(E6:I6)-2*(H6) -> #REF!
C7: يونس يعقوب | D7: 1750 | E7: =(#REF!)*D7 -> #REF! | F7: =(#REF!)*1.25*D7 -> #REF! | H7: =#REF! -> #REF! | J7: =SUM(E7:I7)-2*(H7) -> #REF!
C8: منتظر عبد الكريم | D8: 1750 | E8: =(#REF!)*D8 -> #REF! | F8: =(#REF!)*1.25*D8 -> #REF! | H8: =#REF! -> #REF! | J8: =SUM(E8:I8)-2*(H8) -> #REF!
C9: حيدر الصباغ | D9: 2000 | E9: =(#REF!)*D9 -> #REF! | F9: =(#REF!)*1.25*D9 -> #REF! | H9: ='السلف و الغرامات'!C10 -> 35000 | J9: =SUM(E9:I9)-2*(H9) -> #REF!
C10: حيدر الكهربائي | D10: 2000 | E10: =(#REF!)*D10 -> #REF! | F10: =(#REF!)*1.25*D10 -> #REF! | H10: ='السلف و الغرامات'!C13 -> 170000 | J10: =SUM(E10:I10)-2*(H10) -> #REF!
C11: علي الكهربائي | D11: 1750 | E11: =(#REF!)*D11 -> #REF! | F11: =(#REF!)*1.25*D11 -> #REF! | H11: ='السلف و الغرامات'!C12 -> 108000 | J11: =SUM(E11:I11)-2*(H11) -> #REF!
C12: اسماعيل | D12: 1750 | E12: =(#REF!)*D12 -> #REF! | F12: =(#REF!)*1.25*D12 -> #REF! | H12: =#REF! -> #REF! | J12: =SUM(E12:I12)-2*(H12) -> #REF!
C13: علي هادي | D13: 1750 | E13: =(#REF!)*D13 -> #REF! | F13: =(#REF!)*1.25*D13 -> #REF! | H13: =#REF! -> #REF! | J13: =SUM(E13:I13)-2*(H13) -> #REF!
C14: نبيل | D14: 1750 | E14: =(#REF!)*D14 -> #REF! | F14: =(#REF!)*1.25*D14 -> #REF! | H14: =#REF! -> #REF! | J14: =SUM(E14:I14)-2*(H14) -> #REF!
C15: حسين | D15: 1750 | E15: =(#REF!)*D15 -> #REF! | F15: =(#REF!)*1.25*D15 -> #REF! | H15: =#REF! -> #REF! | J15: =SUM(E15:I15)-2*(H15) -> #REF!
C16: محمد | D16: 2500 | E16: =(#REF!)*D16 -> #REF! | F16: =(#REF!)*1.25*D16 -> #REF! | H16: =#REF! -> #REF! | J16: =SUM(E16:I16)-2*(H16) -> #REF!
C17: محمد السوري | D17: 1750 | E17: =(#REF!)*D17 -> #REF! | F17: =(#REF!)*1.25*D17 -> #REF! | H17: ='السلف و الغرامات'!C9 -> 50000 | J17: =SUM(E17:I17)-2*(H17) -> #REF!
C18: عبد الرضا عقيل | D18: 1750 | E18: =(#REF!)*D18 -> #REF! | F18: =(#REF!)*1.25*D18 -> #REF! | H18: ='السلف و الغرامات'!C8 -> 150000 | J18: =SUM(E18:I18)-2*(H18) -> #REF!
C19: سجاد | D19: 1750 | E19: =(#REF!)*D19 -> #REF! | F19: =(#REF!)*1.25*D19 -> #REF! | H19: =#REF! -> #REF! | J19: =SUM(E19:I19)-2*(H19) -> #REF!
C20: معتصم | D20: 1750 | E20: =(#REF!)*D20 -> #REF! | F20: =(#REF!)*1.25*D20 -> #REF! | H20: =#REF! -> #REF! | J20: =SUM(E20:I20)-2*(H20) -> #REF!
C21: عبدالله الصباغ | D21: 1750 | E21: =(#REF!)*D21 -> #REF! | F21: =(#REF!)*1.25*D21 -> #REF! | H21: =#REF! -> #REF! | J21: =SUM(E21:I21)-2*(H21) -> #REF!
C22: علي جزيره | D22: 1750 | E22: =(#REF!)*D22 -> #REF! | F22: =(#REF!)*1.25*D22 -> #REF! | H22: =#REF! -> #REF! | J22: =SUM(E22:I22)-2*(H22) -> #REF!
C23: اشرف الادقاني | D23: 3000 | E23: =(#REF!)*D23 -> #REF! | F23: =(#REF!)*1.25*D23 -> #REF! | H23: =#REF! -> #REF! | J23: =SUM(E23:I23)-2*(H23) -> #REF!

Sheet الحظور
X1: =iferror(concatenate(" Enter ", 'Attendance key'!$B$7, " for ",'Attendance key'!$C$7, ", ", 'Attendance key'!$B$8, " for ", 'Attendance key'!$C$8, ", ", 'Attendance key'!$B$9, " for ", 'Attendance key'!$C$9, ", and ", 'Attendance key'!$B$10, " for ", 'Attendance key'!$C$10, ". Use the 'Attendance key' tab to customize. "),"") | GL1: hhg
B2: تاريخ | E2: 45521 | F2: 45522 | G2: 45523 | H2: 45524 | I2: 45525 | J2: 45526 | K2: 45527 | L2: 45528 | M2: 45529 | N2: 45530 | O2: 45531 | P2: 45532 | Q2: 45533 | R2: 45534 | S2: 45535 | T2: 45536 | U2: 45537 | V2: 45538 | W2: 45539 | X2: 45540 | Y2: 45541 | Z2: 45542 | AA2: 45543 | AB2: 45544 | AC2: 45545 | AD2: 45546 | AE2: 45547 | AF2: 45548 | AG2: 45549 | AH2: 45550 | AI2: 45551 | AJ2: 45552 | AK2: 45553 | AL2: 45554 | AM2: 45555 | AN2: 45556 | AO2: 45557 | AP2: 45558 | AQ2: 45559 | AR2: 45560 | AS2: 45561 | AT2: 45562 | AU2: 45563 | AW2: 45565 | AX2: 45566 | AY2: 45567 | AZ2: 45568 | BA2: 45569 | BB2: 45570 | BC2: 45571 | BD2: 45572 | BE2: 45573 | BF2: 45574 | BG2: 45575 | BH2: 45576 | BI2: 45577 | BJ2: 45578 | BK2: 45579 | BL2: 45580 | BM2: 45581 | BN2: 45582 | BO2: 45583 | BP2: 45584 | BQ2: 45585 | BR2: 45586 | BS2: 45587 | BT2: 45588 | BU2: 45589 | BV2: 45590 | BW2: 45591 | BX2: 45592 | BY2: 45593 | BZ2: 45594 | CA2: 45595 | CB2: 45596 | CC2: 45597 | CD2: 45598 | CE2: 45599 | CF2: 45600 | CG2: 45601 | CH2: 45602 | CI2: 45603 | CJ2: 45604 | CK2: 45605 | CL2: 45606 | CM2: 45607 | CN2: 45608 | CO2: 45609 | CP2: 45610 | CQ2: 45611 | CR2: 45612 | CS2: 45613 | CT2: 45614 | CU2: 45615 | CV2: 45616 | CW2: 45617 | CX2: 45618 | CY2: 45619 | CZ2: 45620 | DA2: 45621 | DB2: 45622 | DC2: 45623 | DD2: 45624 | DE2: 45625 | DF2: 45626 | DG2: 45627 | DH2: 45628 | DI2: 45629 | DJ2: 45630 | DK2: 45631 | DL2: 45632 | DM2: 45633 | DN2: 45634 | DO2: 45635 | DP2: 45636 | DQ2: 45637 | DR2: 45638 | DS2: 45639 | DT2: 45640 | DU2: 45641 | DV2: 45642 | DW2: 45643 | DX2: 45644 | DY2: 45645 | DZ2: 45646 | EA2: 45647 | EB2: 45648 | EC2: 45649 | ED2: 45650 | EE2: 45651 | EF2: 45652 | EG2: 45653 | EH2: 45654 | EI2: 45655 | EJ2: 45656 | EK2: 45657 | EL2: 45658 | EM2: 45659 | EN2: 45660 | EO2: 45661 | EP2: 45662 | EQ2: 45663 | ER2: 45664 | ES2: 45665 | ET2: 45666 | EU2: 45667 | EV2: 45668 | EW2: 45669 | EX2: 45670 | EY2: 45671 | EZ2: 45672 | FA2: 45673 | FB2: 45674 | FC2: 45675 | FD2: 45676 | FE2: 45677 | FF2: 45678 | FG2: 45679 | FH2: 45680 | FI2: 45681 | FJ2: 45682 | FK2: 45683 | FL2: 45684 | FM2: 45685 | FN2: 45686 | FO2: 45687 | FP2: 45688 | FQ2: 45689 | FR2: 45690 | FS2: 45691 | FT2: 45692 | FU2: 45693 | FV2: 45694 | FW2: 45695 | FX2: 45696 | FY2: 45697 | FZ2: 45698 | GA2: 45699 | GB2: 45700 | GC2: 45701 | GD2: 45702 | GE2: 45703 | GF2: 45704 | GG2: 45705 | GH2: 45706 | GI2: 45707 | GJ2: 45708 | GK2: 45709 | GL2: 45710 | GM2: 45711 | GN2: 45712 | GO2: 45713 | GP2: 45714 | GQ2: 45715 | GR2: 45716 | GS2: 45717 | GT2: 45718 | GU2: 45719 | GV2: 45720 | GW2: 45721 | GX2: 45722 | GY2: 45723 | GZ2: 45724 | HA2: 45725 | HB2: 45726 | HC2: 45727 | HD2: 45728 | HE2: 45729 | HF2: 45730 | HG2: 45731 | HH2: 45732 | HI2: 45733 | HJ2: 45734 | HK2: 45735 | HL2: 45736 | HM2: 45737 | HN2: 45738 | HO2: 45739 | HP2: 45740 | HQ2: 45741 | HR2: 45742 | HS2: 45743 | HT2: 45744 | HU2: 45745 | HV2: 45746 | HW2: 45747 | HX2: 45748 | HY2: 45749 | HZ2: 45750 | IA2: 45751 | IB2: 45752 | IC2: 45753 | ID2: 45754 | IE2: 45755 | IF2: 45756 | IG2: 45757 | IH2: 45758 | II2: 45759 | IJ2: 45760 | IK2: 45761 | IL2: 45762 | IM2: 45763 | IN2: 45764 | IO2: 45765 | IP2: 45766 | IQ2: 45767 | IR2: 45768 | IS2: 45769 | IT2: 45770 | IU2: 45771 | IV2: 45772 | IW2: 45773 | IX2: 45774 | IY2: 45775 | IZ2: 45776 | JA2: 45777 | JC2: 45778 | JD2: 45779 | JE2: 45780 | JF2: 45781 | JG2: 45782 | JH2: 45783 | JI2: 45784 | JJ2: 45785 | JK2: 45786 | JL2: 45787 | JM2: 45788 | JN2: 45789 | JO2: 45790 | JP2: 45791 | JQ2: 45792 | JR2: 45793 | JS2: 45794 | JT2: 45795 | JU2: 45796 | JV2: 45797 | JW2: 45798 | JX2: 45799 | JY2: 45800 | JZ2: 45801 | KA2: 45802 | KB2: 45803 | KC2: 45804 | KD2: 45805 | KE2: 45806 | KF2: 45807 | KG2: 45808 | KI2: 45809 | KJ2: 45810 | KK2: 45811 | KL2: 45812 | KM2: 45813 | KN2: 45814 | KO2: 45815 | KP2: 45816 | KQ2: 45817 | KR2: 45818 | KS2: 45819 | KT2: 45820 | KU2: 45821 | KV2: 45822 | KW2: 45823 | KX2: 45824 | KY2: 45825 | KZ2: 45826 | LA2: 45827 | LB2: 45828 | LC2: 45829 | LD2: 45830 | LE2: 45831 | LF2: 45832 | LG2: 45833 | LH2: 45834 | LI2: 45835 | LJ2: 45836 | LK2: 45837 | LL2: 45838 | LM2: الساعات | LO2: 45839 | LP2: 45840 | LQ2: 45841 | LR2: 45842 | LS2: 45843 | LT2: 45844 | LU2: 45845 | LV2: 45846 | LW2: 45847 | LX2: 45848 | LY2: 45849 | LZ2: 45850 | MA2: 45851 | MB2: 45852 | MC2: 45853 | MD2: 45854 | ME2: 45855 | MF2: 45856 | MG2: 45857 | MH2: 45858 | MI2: 45859 | MJ2: 45860 | MK2: 45861 | ML2: 45862 | MM2: 45863 | MN2: 45864 | MO2: 45865 | MP2: 45866 | MQ2: 45867 | MR2: 45868 | MS2: 45869 | MU2: 45839 | MV2: 45840 | MW2: 45841 | MX2: 45842 | MY2: 45843 | MZ2: 45844 | NA2: 45845 | NB2: 45846 | NC2: 45847 | ND2: 45848 | NE2: 45849 | NF2: 45850 | NG2: 45851 | NH2: 45852 | NI2: 45853 | NJ2: 45854 | NK2: 45855 | NL2: 45856 | NM2: 45857 | NN2: 45858 | NO2: 45859 | NP2: 45860 | NQ2: 45861 | NR2: 45862 | NS2: 45863 | NT2: 45864 | NU2: 45865 | NV2: 45866 | NW2: 45867 | NX2: 45868 | NY2: 45869 | OA2: 45901 | OB2: 45902 | OC2: 45903 | OD2: 45904 | OE2: 45905 | OF2: 45906 | OG2: 45907 | OH2: 45908 | OI2: 45909 | OJ2: 45910 | OK2: 45911 | OL2: 45912
A3: =sum(GW3:MR3)*3000 -> 3532950 | B3: حيدر المحاسب | C3: =SUM(LO3:MS3) -> 88.2 | D3: =SUM(MU3:NY3) -> 33.25 | GW3: 10 | GX3: 10 | GY3: 10 | GZ3: 10 | HA3: 6 | HB3: 6 | HC3: 8.5 | HD3: 11 | HE3: 7 | HF3: 10 | HG3: 8 | HH3: 7.5 | HI3: 11 | HJ3: 8.5 | HK3: 7 | HL3: 6 | HM3: 7 | HN3: 13 | HO3: 10 | HP3: 10.5 | HQ3: 8.5 | HR3: 8.5 | HS3: 12 | HT3: 0 | HU3: 3 | HV3: 7 | HW3: 0 | HX3: 11 | HY3: 7 | HZ3: 10 | IA3: 11 | IB3: 11.5 | IC3: 12.5 | ID3: 9 | IE3: 11 | IF3: 13 | IG3: 8 | IH3: 0 | II3: 10 | IJ3: 11 | IK3: 9 | IL3: 13 | IM3: 9 | IN3: 10.5 | IO3: 0 | IP3: 10 | IQ3: 9 | IR3: 9 | IS3: 10 | IT3: 9 | IU3: 9 | IV3: 9.5 | IW3: 9 | IX3: 8 | IY3: 10 | IZ3: 10 | JA3: 13 | JC3: 13 | JD3: 6 | JE3: 10 | JF3: 9 | JG3: 9 | JH3: 8 | JI3: 0 | JJ3: 0 | JK3: 9 | JL3: 12 | JM3: 9 | JN3: 17 | JO3: 10 | JP3: 13 | JQ3: 15 | JR3: 9 | JS3: 14 | JT3: 11 | JU3: 10 | JV3: 9 | JW3: 11 | JX3: 12 | JY3: 10 | JZ3: 11 | KA3: 13 | KB3: 11 | KC3: 6.7 | KD3: 10 | KE3: 11 | KF3: 10 | KG3: 10 | KI3: 10 | KJ3: 10 | KK3: 10 | KL3: 7 | KM3: 10 | KN3: 7 | KO3: 2.5 | KP3: 9 | KQ3: 9.25 | KR3: 5 | KS3: 10 | KT3: 8 | KU3: 8 | KV3: 17 | KW3: 6 | KX3: 7 | KY3: 7.5 | KZ3: 10 | LA3: 10 | LB3: 6.5 | LC3: 14 | LD3: 9 | LE3: 8 | LF3: 12 | LG3: 12 | LH3: 3 | LI3: x | LJ3: 10 | LK3: 10 | LL3: 5 | LM3: 30 | LO3: 9 | LP3: 9 | LQ3: 9 | LU3: 9 | LV3: 9 | LW3: 8 | LX3: 9 | LZ3: 9 | MA3: 9 | MB3: 8.2 | MV3: 5 | MW3: 1.75 | MX3: 10 | NA3: 2 | NB3: 1 | ND3: 0.5 | NE3: 7.5 | NF3: 0.25 | NG3: 5.25
A4: 6458000 | B4: يوسف يعقوب | C4: =SUM(LO4:MS4) -> 67 | D4: =SUM(MU4:NY4) -> 30.5 | P4: 9 | Q4: 11.5 | R4: 11 | S4: 12.5 | T4: 11.5 | U4: 13.5 | V4: 18 | W4: 5 | X4: 11.5 | Y4: 14 | Z4: 13 | AA4: 22 | AB4: 11 | AC4: 5 | AD4: 13.5 | AE4: 20 | AG4: 15 | AH4: 16 | AI4: 2 | AJ4: 20 | AK4: 15 | AL4: 3 | AM4: 10 | AN4: 15 | AO4: 11 | AP4: 12.5 | AQ4: 13 | AR4: 13 | AS4: 11 | AT4: 24 | AU4: 5 | AV4: 11 | AW4: 15 | AX4: 10.3 | AY4: 5 | AZ4: 13 | BA4: 5 | BB4: 12 | BC4: 11.3 | BD4: 13 | BE4: 11 | BF4: 12.3 | BG4: 13 | BH4: 4 | BI4: 12 | BJ4: 13 | BK4: 12 | BL4: 7 | BS4: 13 | BT4: 15.3 | BU4: 16.3 | BV4: 15.3 | BW4: 13 | BX4: 14 | BY4: 10.3 | BZ4: 15 | CA4: 12 | CB4: 14 | CC4: 9 | CD4: 13 | CE4: 12 | CF4: 11.3 | CG4: 14 | CH4: 9 | CI4: 11 | CJ4: 1.3 | CK4: 10 | CL4: 14 | CM4: 12 | CN4: 21 | CO4: 4 | CP4: 15 | CQ4: 0 | CR4: 6 | CS4: 0 | CT4: 9 | CU4: 15 | CV4: 0 | CW4: 10 | CX4: 10 | CY4: 11 | CZ4: 14 | DA4: 10 | DB4: 11 | DC4: 11 | DD4: 11 | DE4: 6 | DF4: 0 | DK4: 6 | DL4: 9 | DM4: 8 | EH4: 6 | EI4: 5.5 | EJ4: 7.5 | EL4: 7 | EO4: 10.5 | EP4: 7 | EQ4: 8 | ER4: 5 | EW4: 10 | EX4: 8 | EY4: 11 | EZ4: 11 | FA4: 13 | FC4: 10.5 | FD4: 11 | FE4: 11 | FF4: 11 | FG4: 8.5 | FH4: 11 | FI4: 15 | FJ4: 8 | FK4: 10 | FL4: 10 | FM4: 10.5 | FN4: 11.5 | FO4: 10.5 | FP4: 9 | FQ4: 8 | FR4: 11 | FS4: 10 | FT4: 9 | FU4: 13 | FX4: 10 | FY4: 11 | FZ4: 7 | GA4: 9 | GB4: 8 | GC4: 12 | GD4: 14 | GE4: 7.5 | GG4: 10 | GH4: 12 | GI4: 9 | GJ4: 8 | GL4: 11 | GM4: 12 | GN4: 7 | GP4: 11.5 | GQ4: 10 | GR4: 16 | GS4: 8 | GT4: 6.5 | GU4: 16 | GV4: 6 | GW4: 7 | GX4: 9 | GY4: 11.5 | GZ4: 10.5 | HA4: 6 | HB4: 11 | HC4: 10 | HD4: 10 | HE4: 9 | HF4: 10 | HG4: 11.5 | HH4: 11 | HI4: 8 | HJ4: 9,5 | HK4: 11 | HL4: 9 | HN4: 10.5 | HO4: 10.5 | HP4: 9 | HQ4: 10.5 | HR4: 6 | HV4: 9 | HX4: 0 | HY4: 10 | HZ4: 13 | IA4: 3 | IB4: 9.5 | IC4: 10.5 | ID4: 11 | IE4: 0 | IF4: 0 | IG4: 0 | IH4: 10 | II4: 9 | IJ4: 11 | IK4: 10.5 | IL4: 7 | IM4: 11 | IN4: 12 | IO4: 4 | IP4: 10 | IQ4: 12 | IR4: 10 | IS4: 10 | IT4: 14 | IU4: 9 | IV4: 4 | IW4: 10 | IX4: 9 | IY4: 12 | IZ4: 9 | JA4: 8 | JC4: 10 | JD4: 10 | JE4: 10 | JF4: 10 | JG4: 10 | JH4: 11 | JI4: 9 | JJ4: 10 | JK4: 10 | JR4: 10 | JS4: 17.25 | JT4: 10 | JU4: 12 | JV4: 8.75 | JW4: 10 | JX4: 9 | JY4: 10 | JZ4: 11.5 | KA4: 10 | KB4: 12.5 | KC4: 12 | KD4: 15 | KE4: 6 | KF4: 7 | KG4: 9 | KI4: 11.5 | KJ4: 9 | KK4: 10 | KL4: 10 | KM4: 10 | KN4: x | KO4: 10 | KP4: 10 | KQ4: 10 | KR4: x | KS4: 10 | KT4: 10 | KU4: 10 | KV4: x | KW4: 10 | KX4: 10 | KY4: 10 | KZ4: x | LA4: 10 | LB4: 10 | LC4: 10 | LD4: 10 | LE4: 10 | LF4: 10 | LG4: 10 | LH4: 10 | LI4: 10 | LJ4: 10 | LK4: 10 | LL4: 10 | LO4: 9 | LP4: 9 | LQ4: 9 | LS4: 9 | LU4: 9 | LV4: 8 | LX4: 5 | LZ4: 9 | MU4: 2 | MV4: 2 | MW4: 2 | MX4: 8 | MY4: 2 | NA4: 2 | NE4: 7.5 | NF4: 5
B5: عبد الرضا عقيل | C5: =SUM(LO5:MS5) -> 72 | D5: =SUM(MU5:NY5) -> 14.85 | AX5: 10 | AY5: 5 | AZ5: 12 | BB5: 9.3 | BC5: 9 | BD5: 11 | BF5: 9 | BJ5: 10 | BK5: 10 | BL5: 9.3 | BM5: 9 | BN5: 12 | BP5: 7.3 | BQ5: 9 | BR5: 10.3 | BS5: 9.3 | BU5: 5 | BV5: 12 | BW5: 10.3 | BX5: 10 | BY5: 10.3 | BZ5: 8 | CA5: 13 | CB5: 9 | CC5: 3 | CD5: 11.3 | CE5: 11 | CF5: 10 | CG5: 13 | CH5: 9 | CI5: 10 | CK5: 8.3 | CL5: 8 | CM5: 9 | CN5: 12 | CO5: 11 | CP5: 0 | CQ5: 0 | CR5: 7 | CS5: 7 | CT5: 0 | CU5: 13 | CY5: 9 | CZ5: 8 | DA5: 11.3 | DB5: 9 | DC5: 12 | DD5: 12 | DE5: 9.15 | DF5: 11 | DG5: 9 | DH5: 10 | DI5: 8 | DJ5: 13 | DK5: 8 | DL5: 13 | DM5: 8 | DN5: 11 | DO5: 12 | DP5: 11 | DQ5: 8 | DR5: 12 | DT5: 11 | DU5: 9.5 | DV5: 11.5 | DW5: 10 | DX5: 9.5 | DY5: 14 | EA5: 11 | EB5: 7.5 | EC5: 8 | ED5: 10 | EE5: 11.5 | EF5: 10 | EH5: 10 | EI5: 8.5 | EJ5: 8 | EK5: 8 | EM5: 13.5 | EN5: 10.5 | EO5: 13.5 | EP5: 9 | EQ5: 12 | ER5: 12 | ES5: 8.3 | ET5: 10 | EV5: 9 | EW5: 9.5 | EX5: 11.5 | EY5: 18 | EZ5: 6.5 | FA5: 11 | FB5: 3.5 | FC5: 9 | FD5: 10 | FE5: 3 | FF5: 12 | FG5: 9 | FH5: 9 | FJ5: 9.5 | FK5: 9 | FL5: 11.75 | FM5: 11 | FN5: 9 | FO5: 8.5 | FQ5: 8 | FR5: 11 | FS5: 9 | FT5: 16 | FU5: 8 | FV5: 10 | FW5: 10 | FX5: 9 | FY5: 10 | FZ5: 15 | GA5: 12 | GB5: 11 | GC5: 9 | GD5: 10 | GE5: 14 | GF5: 13 | GG5: 10 | GI5: 11 | GJ5: 8 | GK5: 11 | GL5: 12 | GM5: 9 | GN5: 12 | GO5: 16 | GP5: 15 | GQ5: 14 | GR5: 20 | GS5: x | GT5: 8 | GU5: 4 | GV5: x | GW5: 5 | GX5: 5.5 | GY5: 8.5 | GZ5: 3.5 | HA5: x | HB5: 8 | HC5: 12 | HD5: 3 | HE5: 11 | HF5: x | HG5: 12 | HH5: 12 | HI5: 5 | HJ5: 2 | HK5: 7.5 | HL5: 7 | HM5: 7 | HN5: 5 | HO5: 12 | HP5: 11 | HQ5: 4.5 | HR5: x | HS5: 4.5 | HT5: 6.5 | HU5: 1.5 | HV5: 5 | HW5: x | HX5: مجاز | HY5: 3 | HZ5: 8 | IA5: 7 | IB5: 6 | IC5: 8.75 | ID5: 10.75 | IE5: 9 | IF5: 9.25 | IG5: 7.75 | IH5: 9.25 | II5: 9.5 | IJ5: 7.25 | IK5: x | IL5: 6.5 | IM5: 9 | IN5: 11.5 | IO5: 12.5 | IP5: 9.5 | IQ5: 9 | IR5: 9.25 | IS5: 12.5 | IT5: 10.75 | IU5: 19 | IV5: 3 | IW5: 11 | IX5: 6.5 | IY5: 10 | IZ5: 0 | JA5: 10 | JC5: 11 | JE5: 10.5 | JF5: 14.5 | JG5: 10 | JH5: 15 | JI5: 10.5 | JJ5: 11 | JL5: 12 | JM5: 14 | JN5: 10 | JO5: 8 | JP5: 2 | JQ5: 3 | JU5: 10 | JW5: 4 | JX5: 11 | JZ5: 11 | KA5: 8.5 | KB5: 8 | KC5: 12 | KD5: 14.75 | KE5: 12.5 | KF5: 11 | KG5: 10 | KI5: 16.5 | KJ5: 9 | KK5: 12.5 | KL5: 16.5 | KM5: 9 | KN5: 16 | KO5: x | KP5: 7 | KQ5: 14.5 | KR5: 4.5 | KS5: 13 | KT5: 3 | KU5: 5 | KV5: 6.5 | KW5: 8 | KX5: x | KY5: 6.5 | KZ5: x | LA5: x | LB5: x | LC5: 8 | LD5: 6.5 | LE5: 9 | LF5: 9 | LG5: x | LH5: 9 | LI5: x | LJ5: 11 | LK5: 9.5 | LL5: 5.5 | LM5: 21 | LP5: 9 | LQ5: 9 | LS5: 9 | LU5: 9 | LV5: 9 | LW5: 9 | LX5: 9 | LZ5: 9 | MV5: 3 | ND5: 1.1 | NE5: 9.25 | NF5: 1.5
B6: محمد رشيد | C6: =SUM(LO6:MS6) -> 0 | D6: =SUM(MU6:NY6) -> 0 | AR6: 10 | AS6: 10 | AT6: 10 | AU6: 12 | AW6: 14 | AX6: 11 | AY6: 10 | AZ6: 11 | BB6: 11 | BC6: 11.3 | BD6: 13 | BE6: 13 | BF6: 12 | BG6: 16 | BH6: 3 | BI6: 10.3 | BJ6: 13 | BK6: 13 | BL6: 16 | BM6: 12 | BN6: 13 | BO6: 9 | BP6: 13 | BQ6: 11 | BR6: 12 | BS6: 10.3 | BT6: 12.3 | BU6: 10.3 | BV6: 9.3 | BW6: 10.3 | BX6: 15 | BY6: 10.3 | BZ6: 12 | CA6: 12 | CB6: 13.3 | CC6: 9 | CD6: 11.3 | CE6: 11 | CF6: 14 | CG6: 14 | CI6: 12.3 | CJ6: 0 | CK6: 10.3 | CL6: 18 | CM6: 6 | CN6: 14 | CO6: 12 | CP6: 13 | CQ6: 6 | CR6: 11 | CS6: 11 | CT6: 13.3 | CU6: 10 | CV6: 7 | CW6: 7 | CX6: 11 | CY6: 10.3 | CZ6: 8.3 | DA6: 12 | DB6: 9 | DC6: 11 | DD6: 12 | DE6: 7 | DF6: 11.45 | DG6: 14.3 | DH6: 16 | DI6: 11 | DK6: 14.5 | DL6: 9.5 | DM6: 8 | DN6: 12 | DO6: 10.5 | DP6: 13 | DQ6: 12 | DR6: 7.5 | DS6: 6 | DT6: 9 | DU6: 9 | DV6: 12 | DW6: 13.5 | DX6: 12 | DY6: 8.5 | EA6: 16.5 | EB6: 12 | EC6: 12 | ED6: 11 | EE6: 12 | EF6: 9.5 | EG6: 11.5 | EH6: 11.5 | EI6: 11 | EJ6: 11 | EK6: 7.5 | EL6: 5 | EM6: 10.75 | EN6: 10 | EO6: 9.5 | EP6: 9 | EQ6: 10.75 | ER6: 12.2 | ES6: 5 | ET6: 12 | EU6: 10 | EV6: 9.5 | EW6: 8.75 | EX6: 10.6 | EY6: 10.25 | EZ6: 13 | FA6: 9.5 | FB6: 9.5 | FC6: 11.2 | FD6: 11.7 | FE6: 10 | FF6: 12.45 | FG6: 16 | FH6: 14 | FI6: 7.6 | FK6: 16 | FL6: 11.2 | FM6: 10 | FN6: 11.2 | FO6: 12 | FP6: 9.5 | FQ6: 11 | FR6: 12 | FS6: 10.5 | FT6: 12 | FU6: 11 | FV6: 12 | FW6: 10 | FX6: 11 | FY6: 9.5 | FZ6: 11 | GA6: 10 | GB6: 10.5 | GC6: 13.5 | GD6: 5 | GE6: 14 | GF6: 11 | GG6: 10.5 | GH6: 10 | GI6: 10.5 | GJ6: 10.5 | GK6: 12 | GM6: 11 | GN6: 10.5 | GO6: 9 | GP6: 12 | GQ6: 116 | GS6: 15 | GT6: 10 | GU6: 12 | GV6: 9 | GW6: 10.5 | GX6: 8 | GY6: 12.5 | GZ6: 10 | HA6: 22 | HB6: 8 | HC6: 10.5 | HD6: 15.5 | HE6: 12 | HF6: 7 | HG6: 11 | HH6: 8 | HI6: 10 | HJ6: 8.5 | HK6: x | HL6: 4.5 | HM6: 7 | HN6: 9.5 | HO6: 15 | HP6: 7.5 | HQ6: 8.5 | HR6: 8 | HS6: 8 | HT6: 8.5 | HU6: 17.5 | HV6: 3 | HW6: 13 | HX6: 13 | HY6: 9 | HZ6: 12 | IA6: 11 | IB6: 17 | IC6: 6 | ID6: 10.5 | IE6: 10 | IF6: 11 | IG6: 5.5 | IH6: 10.5 | II6: 5.5 | IJ6: 10 | IK6: 11.5 | IL6: 11 | IM6: 9.5 | IN6: 10.25 | IO6: 9 | IP6: 12 | IQ6: 12 | IR6: 10 | IS6: 10 | IT6: 3.25 | IU6: 10 | IV6: 7 | IW6: 7.5 | IX6: 12 | IY6: 8.5 | IZ6: 9 | JA6: 14.5 | JC6: 2.5 | JD6: 9 | JE6: 8 | JF6: 11.5 | JG6: 9 | JI6: 11.25 | JJ6: 11 | JK6: 8.5 | JL6: 10.5 | JM6: 9.5 | JN6: 9 | JO6: 8.5 | JP6: 11.25 | JQ6: 8.5 | JR6: 10 | JS6: 7.75 | JT6: 7.5 | JU6: 9 | JV6: 9 | JW6: 8 | JX6: 9.25 | JY6: 7 | JZ6: 5 | KA6: 5 | KB6: 7.25 | KC6: 8.5 | KG6: 7 | KI6: 6 | KJ6: 4.5 | KK6: 5 | KL6: 8 | KM6: 8.5 | KN6: 8 | KO6: x | KP6: 1 | KQ6: 8.75 | KR6: 14 | KS6: 9 | KT6: 13.25 | KU6: 4 | KV6: 12 | KW6: 5 | KX6: 11 | KY6: 7 | KZ6: 6 | LA6: 5 | LB6: x | LC6: 1.5 | LD6: 0 | LE6: 0 | LF6: 0 | LG6: 0 | LH6: 5 | LI6: 8 | LJ6: 4.5 | LK6: 8 | LL6: x
B7: حيدر الصباغ | C7: =SUM(LO7:MS7) -> 24.5 | D7: =SUM(MU7:NY7) -> 10.5 | AC7: 11 | AD7: 11.5 | AE7: 16 | AG7: 21 | AI7: 11 | AJ7: 12 | AK7: 10.5 | AL7: 9.5 | AM7: 9.5 | AN7: 9.5 | AO7: 6.5 | AP7: 10 | AR7: 14 | AS7: 10.3 | AT7: 2.3 | AU7: 13 | AV7: 11 | AW7: 10 | AY7: 5 | AZ7: 12 | BB7: 9.3 | BC7: 14 | BE7: 12.3 | BF7: 9 | BI7: 14 | BK7: 12 | BN7: 12 | BO7: 4 | BP7: 10 | BQ7: 10.3 | BR7: 11 | BS7: 8.3 | BT7: 12 | BU7: 11 | BV7: 14 | BW7: 5.3 | BY7: 11 | BZ7: 12 | CA7: 9 | CB7: 12.3 | CD7: 6,3 | CE7: 13 | CF7: 12 | CH7: 9 | CI7: 9 | CK7: 11 | CL7: 10 | CM7: 11.3 | CN7: 22 | CO7: 10.3 | CP7: 11 | CQ7: 4.3 | CR7: 2 | CS7: 9.3 | CT7: 21 | CX7: 11 | CZ7: 9 | DA7: 10 | DB7: 9 | DC7: 10 | DD7: 11 | DF7: 12 | DG7: 9 | DH7: 9 | DI7: 9 | DJ7: 11 | DK7: 4 | DL7: 12 | DN7: 12 | DO7: 12 | DP7: 12 | DQ7: 12 | DR7: 12 | DT7: 13 | DU7: 7 | DV7: 8.5 | DW7: 8 | DX7: 7.5 | EA7: 8 | EB7: 8 | EC7: 9.2 | ED7: 9 | EE7: 9 | EF7: 8 | EH7: 7 | EI7: 6 | EJ7: 7 | EK7: 5 | EM7: 8 | EN7: 7 | EO7: 9 | EP7: 8.5 | EQ7: 8.5 | ER7: 9 | ES7: 9.25 | ET7: 9 | EU7: 5 | EV7: 8.5 | EX7: 6 | EY7: 16 | FA7: 9 | FC7: 10 | FD7: 10 | FE7: 8.25 | FF7: 9.5 | FG7: 8 | FH7: 8.5 | FJ7: 5.3 | FK7: 7 | FN7: 10 | FO7: 5 | FP7: 7.5 | FQ7: 9 | FR7: 12 | FS7: 9 | FU7: 10 | FV7: 8 | FX7: 10 | FY7: 11 | FZ7: 11 | GA7: 21 | GB7: 6 | GC7: 10 | GD7: 9 | GG7: 16 | GH7: 6 | GI7: 8.5 | GJ7: 5.5 | GK7: 5.5 | GL7: 9 | GM7: 7.5 | GN7: 15 | GO7: 6 | GP7: 8.5 | GQ7: 7 | GR7: 7 | GS7: 4 | GT7: 3.5 | GU7: 6.5 | GV7: 5 | GW7: 8 | GX7: 8.5 | GY7: x | GZ7: 11 | HA7: 6 | HB7: 7.5 | HC7: 5.5 | HD7: 7 | HE7: 6.5 | HF7: 16 | HG7: 5.5 | HH7: 5 | HI7: 5 | HJ7: 7 | HK7: 3.5 | HL7: 5 | HM7: x | HN7: 3.5 | HO7: 13.5 | HP7: 3.5 | HQ7: 6 | HR7: 6 | HS7: x | HT7: 7 | HU7: 5 | HV7: 13 | HW7: x | HX7: 0 | HY7: 6 | HZ7: 10 | IA7: 8 | IB7: 13 | IC7: 13.5 | ID7: 9 | IE7: 9.5 | IF7: 6 | IG7: 0 | IH7: 0 | II7: 8 | IL7: 12 | IM7: 10 | IN7: 8 | IO7: 11 | IP7: 5 | IQ7: 12 | IR7: 10.5 | IS7: 4.5 | IT7: 12 | IU7: 8 | IV7: 5 | IW7: 13 | IX7: 9 | IZ7: 8 | JA7: 3.5 | JC7: 6 | JD7: 10 | JG7: 10 | JH7: 11 | JI7: 10 | JL7: 12 | JM7: 14.5 | JN7: 9 | JO7: 10 | JQ7: 9.5 | JR7: 9.5 | JS7: 16 | JT7: 9 | JU7: 8.25 | JV7: 8.75 | JX7: 11 | JZ7: 10.5 | KA7: 9 | KB7: 10 | KD7: 11 | KI7: 8.5 | KJ7: 11.5 | KK7: 12 | KL7: 10 | KM7: x | KN7: 16 | KO7: x | KP7: x | KQ7: x | KR7: 9.5 | KS7: 6 | KT7: x | KU7: x | KV7: x | KW7: 5.25 | KX7: 6.5 | KY7: 9.5 | KZ7: 6.5 | LA7: x | LB7: 10 | LC7: x | LD7: 7 | LE7: x | LF7: 8.25 | LG7: 6 | LH7: x | LI7: 10 | LJ7: 7 | LK7: x | LL7: x | LM7: 3.4 | LU7: 7 | LW7: 8.5 | LX7: 9 | NE7: 10.5
B8: وليد | C8: =SUM(LO8:MS8) -> 52.75 | D8: =SUM(MU8:NY8) -> 0.6 | DH8: 6 | DI8: 6 | DJ8: 6 | DK8: 6 | DL8: 7 | DM8: 8 | DN8: 10 | DO8: 10 | DP8: 10 | DQ8: 10 | DR8: 10 | DS8: 9 | DT8: 9 | DU8: 9 | DV8: 9 | DW8: 9 | DX8: 9 | DY8: 9 | EA8: 12 | EB8: 12 | EC8: 12 | ED8: 14 | EE8: 8 | EF8: 9 | EG8: 14 | EH8: 13 | EI8: 11 | EJ8: 12 | EK8: 4 | EL8: 9.6 | EM8: 14 | EN8: 15 | EO8: 13 | EP8: 10 | EQ8: 11.2 | ER8: 13 | ES8: 11.5 | ET8: 13.5 | EU8: 4.5 | EV8: 9 | EW8: 10.25 | EX8: 11 | EY8: 9.75 | EZ8: 14.25 | FA8: 13 | FC8: 13 | FD8: 12 | FE8: 12 | FF8: 11.7 | FG8: 15.1 | FH8: 13 | FI8: 8 | FJ8: 10 | FK8: 13 | FL8: 10.2 | FM8: 11 | FN8: 11 | FO8: 10 | FP8: 11 | FQ8: 12 | FR8: 10 | FS8: 11.5 | FT8: 12 | FU8: 10.5 | FV8: 13.5 | FW8: 7 | FX8: 12 | FY8: 12 | FZ8: 13.5 | GA8: 11 | GB8: 10 | GC8: 8.5 | GD8: 6.5 | GE8: 12 | GF8: 11 | GG8: 10 | GH8: 10 | GK8: 9 | GL8: 9.5 | GM8: 6 | GN8: 10.5 | GO8: 13.5 | GP8: 13 | GQ8: 12 | GR8: 12 | GS8: 9.5 | GT8: 9 | GU8: 16 | GV8: 9.5 | GW8: 9.5 | GX8: 6.5 | GY8: 6.5 | GZ8: 9 | HA8: 10 | HB8: 11.5 | HC8: 8.5 | HD8: 6 | HE8: 12 | HF8: 10 | HG8: 7 | HH8: 8 | HI8: 5 | HJ8: 4.5 | HK8: 10 | HL8: 16.5 | HM8: 6.5 | HN8: 10 | HO8: 8.5 | HP8: 7 | HQ8: 5 | HR8: 11 | HS8: 6.5 | HT8: 9.5 | HU8: 9.5 | HV8: 9 | HW8: 4 | HX8: 8.5 | HY8: 8 | HZ8: 10.5 | IA8: 8.5 | IB8: 11 | IC8: 9.5 | ID8: 11.5 | IE8: 3 | IF8: 15.5 | IG8: 16 | IH8: 9 | II8: 9.5 | IJ8: 9.5 | IK8: 12 | IL8: 14 | IM8: 13.5 | IN8: 14 | IO8: 5 | IP8: 8 | IQ8: 9.5 | IR8: 14 | IS8: 12.5 | IT8: 6.5 | IU8: 11 | IV8: 0 | IW8: 10 | IX8: 8 | IY8: 8.5 | IZ8: 11 | JA8: 13 | JC8: 11 | JE8: 8 | JF8: 11.5 | JG8: 6.5 | JH8: 9 | JI8: 6.5 | JJ8: 8.5 | JK8: 5 | JL8: 6 | JM8: 9 | JN8: 11.5 | JO8: 8.5 | JP8: 11 | JQ8: 7 | JR8: 7 | JS8: 7 | JT8: 9.25 | JU8: 7 | JV8: 7 | JW8: 7 | KE8: 9 | KF8: 5 | KI8: 5 | KJ8: 5 | KK8: 7 | KL8: 8 | KM8: 10 | KN8: 9 | KO8: 10 | KP8: 7 | KQ8: 8 | KR8: 5.5 | KS8: 12 | KT8: 3 | KU8: 3 | KV8: 8.5 | KW8: 4 | KX8: 8 | KY8: 10 | KZ8: 5 | LA8: 9 | LB8: 16.5 | LC8: 8 | LD8: 6 | LE8: 9 | LF8: 6 | LG8: 15 | LH8: 8 | LI8: 7 | LJ8: 11 | LK8: 7 | LL8: 6.25 | LM8: 10 | LO8: 7 | LP8: 6.75 | LU8: 9 | LV8: 9 | LW8: 7.5 | LX8: 9 | LZ8: 4.5 | NF8: 0.6
B9: علي الكهربائي | C9: =SUM(LO9:MS9) -> 44 | D9: =SUM(MU9:NY9) -> 6.1 | AA9: 13 | AB9: 10 | AC9: 10 | AD9: 11.5 | AE9: 12 | AF9: 11 | AG9: 11 | AH9: 19 | AI9: 9.5 | AJ9: 10.5 | AK9: 9.5 | AL9: 16 | AM9: 10.5 | AN9: 10 | AQ9: 12.5 | AR9: 13.3 | AS9: 12.3 | AT9: 15 | AU9: 8.3 | AV9: 11.3 | AW9: 14.3 | AX9: 10.3 | AY9: 5 | AZ9: 14 | BB9: 11.3 | BC9: 11.3 | BD9: 10 | BE9: 11 | BF9: 9 | BG9: 12 | BI9: 14 | BK9: 10.3 | BL9: 11.3 | BM9: 9.3 | BN9: 15.3 | BO9: 2 | BP9: 10.3 | BQ9: 10.3 | BR9: 10 | BS9: 12.3 | BT9: 10 | BU9: 12.3 | BV9: 12 | BX9: 10 | BY9: 11.3 | BZ9: 10.3 | CA9: 11.3 | CB9: 12 | CC9: 4 | CD9: 13 | CE9: 11 | CF9: 11 | CG9: 14 | CH9: 7 | CI9: 11 | CK9: 11 | CL9: 10 | CM9: 10 | CN9: 11 | CO9: 11 | CP9: 11 | CQ9: 4.3 | CR9: 10 | CS9: 10.3 | CT9: 11 | CU9: 12 | CX9: 11 | CY9: 9.3 | CZ9: 10 | DA9: 11.3 | DB9: 10 | DC9: 10.3 | DD9: 12 | DE9: 7.3 | DF9: 11 | DG9: 10.3 | DH9: 10 | DI9: 8.3 | DJ9: 12 | DK9: 12 | DL9: 13 | DM9: 10 | DN9: 12 | DO9: 10 | DP9: 12 | DQ9: 13 | DR9: 12 | DS9: 15 | DT9: 8 | DU9: 12 | DW9: 11 | DX9: 12 | DY9: 11 | EA9: 12 | EB9: 12 | EC9: 12 | ED9: 14 | EG9: 9.3 | EH9: 9 | EI9: 8 | EL9: 6.25 | EM9: 8 | EN9: 10 | EO9: 12 | EP9: 9 | EQ9: 9.5 | ER9: 8 | ES9: 9 | ET9: 9.25 | EU9: 3 | EV9: 9.1 | EW9: 10 | EX9: 13 | EY9: 10 | EZ9: 7.5 | FA9: 13 | FC9: 10.5 | FD9: 12 | FE9: 8 | FF9: 10.5 | FG9: 9 | FH9: 10 | FI9: 10.5 | FJ9: 6 | FK9: 7 | FL9: 9 | FM9: 9 | FN9: 10.3 | FO9: 10 | FP9: 9 | FQ9: 9 | FR9: 10 | FS9: 9 | FT9: 8 | FV9: 10 | FW9: 11 | FX9: 12 | FY9: 8 | FZ9: 9 | GA9: 6 | GB9: 12 | GC9: 2 | GD9: 15 | GE9: 12 | GF9: 13 | GG9: 10 | GH9: 10 | GI9: 10 | GJ9: 5.5 | GK9: 11.5 | GL9: 8 | GM9: 7.5 | GN9: 5.5 | GO9: 6 | GP9: 9.25 | GQ9: 8 | GR9: 16 | GS9: 13 | GT9: 9.5 | GU9: 4 | GV9: 4.5 | GW9: 7 | GX9: 11 | GY9: 11 | GZ9: 4.5 | HA9: 5.5 | HB9: 8 | HC9: 14 | HD9: 8 | HE9: 7 | HF9: 8 | HG9: 7 | HH9: 7.5 | HI9: 4.5 | HJ9: 7.5 | HK9: 6 | HL9: X | HM9: 7 | HN9: 6.5 | HO9: 9 | HP9: 12 | HQ9: 7 | HR9: 6.5 | HS9: 6.5 | HT9: 4.5 | HU9: 7.5 | HV9: 4 | HW9: x | HX9: 0 | HY9: 8 | HZ9: 12 | IA9: 9.5 | IB9: 11.5 | IC9: 9.5 | ID9: 18 | IE9: 5 | IF9: 8.5 | IG9: 10.5 | IH9: 11.5 | II9: 10 | IJ9: x | IK9: 10.5 | IL9: 9 | IM9: 10 | IN9: 11.5 | IO9: 9.5 | IP9: 7.5 | IQ9: 10.5 | IR9: 9.5 | IS9: 9.5 | IT9: 15 | IU9: 17 | IV9: x | IW9: 11 | IX9: 12 | IY9: 6.5 | IZ9: 8 | JA9: 8 | JC9: 6.5 | JE9: 8.5 | JF9: 9 | JG9: 16 | JI9: 9 | JJ9: 12.25 | JL9: 15.5 | JM9: 17.5 | JO9: 11 | JP9: 4.5 | JQ9: 8.5 | JR9: 6.5 | JS9: 15.25 | JT9: 9 | JU9: 6.5 | JV9: 11.5 | JW9: 17.5 | JX9: 3 | JZ9: 11 | KA9: 14 | KB9: 5 | KD9: 17 | KF9: 7 | KG9: 7 | KI9: 11 | KJ9: 11 | KK9: 11.75 | KL9: 17 | KM9: 11 | KN9: 16 | KO9: x | KP9: 7 | KQ9: 14 | KR9: 4.5 | KS9: 6.5 | KT9: x | KU9: x | KV9: 18.5 | KW9: 8.75 | KX9: 9.5 | KY9: 10.25 | KZ9: 8 | LA9: x | LB9: 7.5 | LC9: 6.5 | LD9: x | LE9: 6.5 | LF9: x | LG9: 7 | LH9: 8.5 | LI9: 15 | LJ9: 5 | LK9: 5.5 | LL9: x | LM9: 25 | LU9: 9 | LV9: 9 | LW9: 8 | LX9: 9 | LZ9: 9 | NA9: 0.6 | NB9: 0.25 | NE9: 5.25
B10: حيدر يافوز | C10: =SUM(LO10:MS10) -> 60.25 | D10: =SUM(MU10:NY10) -> 7.5 | AN10: 10 | AO10: 14 | AP10: 11 | AQ10: 12 | AR10: 13.3 | AS10: 12.3 | AT10: 15 | AU10: 8.3 | AV10: 11.3 | AW10: 14.3 | AX10: 10.3 | AY10: 5 | BB10: 11.3 | BC10: 11.3 | BD10: 10 | BE10: 11 | BF10: 9 | BG10: 12 | BI10: 14 | BK10: 10.3 | BL10: 11.3 | BM10: 9.3 | BN10: 15.3 | BP10: 10.3 | BQ10: 10.3 | BR10: 10 | BS10: 12.3 | BT10: 10 | BV10: 12 | BX10: 10 | BY10: 11.3 | BZ10: 10.3 | CA10: 11.3 | CB10: 12 | CD10: 13 | CG10: 8 | CH10: 11 | CI10: 11 | CK10: 11 | CL10: 10 | CM10: 11.3 | CN10: 22 | CO10: 10.3 | CP10: 0 | CQ10: 0 | CR10: 10 | CS10: 10.3 | CT10: 11 | CU10: 12 | CX10: 11 | CY10: 6.3 | CZ10: 10.3 | DA10: 13 | DB10: 9 | DC10: 9.5 | DE10: 6 | DF10: 11 | DG10: 10.3 | DH10: 10.3 | DI10: 8.5 | DJ10: 11.45 | DK10: 11 | DL10: 9 | DM10: 9 | DN10: 12 | DO10: 12 | DP10: 12 | DQ10: 12 | DR10: 12 | DV10: 11 | DW10: 10 | DX10: 11 | EA10: 8 | EB10: 7 | ED10: 9.15 | EE10: 6 | EF10: 8 | EH10: 8 | EI10: 9.5 | EJ10: 8 | EK10: 9 | EL10: 5 | EM10: 13.25 | EN10: 12 | EO10: 12 | EP10: 9 | EQ10: 9.5 | ER10: 8 | ES10: 9 | ET10: 9.25 | EV10: 9.2 | EW10: 10 | EX10: 12 | FA10: 12 | FC10: 10.5 | FD10: 10 | FE10: 8.25 | FF10: 10.5 | FG10: 8 | FH10: 10 | FI10: 8 | FJ10: 5.25 | FK10: 7 | FL10: 9 | FM10: 9 | FN10: 9.5 | FO10: 10 | FP10: 8.5 | FR10: 12 | FT10: 10 | FU10: 10 | FV10: 10 | FW10: 8 | FX10: 11 | FY10: 12 | FZ10: 11 | GA10: 11 | GB10: 13 | GC10: 15 | GD10: 8 | GE10: 14 | GF10: 12 | GG10: 12 | GH10: 9 | GI10: 10.5 | GJ10: 6.5 | GK10: 6 | GL10: 11.5 | GM10: 16 | GN10: 13 | GO10: 16 | GP10: 16 | GQ10: 12 | GR10: 18 | GS10: 15 | GT10: 11 | GU10: 6.5 | GV10: 9 | GW10: 10 | GX10: 17 | GY10: X | GZ10: X | HA10: X | HB10: 5 | HC10: X | HD10: X | HE10: 9 | HF10: 4.5 | HG10: 11 | HH10: 9 | HI10: 13 | HJ10: 6 | HK10: 11 | HL10: 10 | HM10: 7 | HN10: 6 | HO10: 12 | HP10: 10.5 | HQ10: 10 | HR10: 10.5 | HS10: 6.5 | HT10: 6.5 | HU10: x | HV10: 5.5 | HW10: x | HX10: 0 | HY10: 10 | IA10: 8 | IB10: 11.5 | IC10: 9.5 | ID10: 8 | IE10: 14 | IF10: 13 | IG10: 11.5 | IH10: 11 | II10: 6.5 | IJ10: 0 | IK10: 13 | IL10: 11.5 | IM10: 12 | IN10: 14 | IO10: 9.5 | IP10: 0 | IQ10: 5.5 | IR10: 4.5 | IS10: 15.5 | IT10: 10 | IU10: 10 | IV10: 17.5 | IW10: 20.5 | IX10: 17.5 | IY10: 17.5 | IZ10: 8 | JA10: 7.5 | JC10: 10 | JF10: 15 | JG10: 17 | JH10: 14.5 | JI10: 11 | JJ10: 8.5 | JK10: 9 | JL10: 16.5 | JM10: 16.5 | JN10: 11 | JO10: 10.5 | JP10: 11 | JQ10: 10.5 | JR10: 11 | JS10: 9.75 | JT10: 10.25 | JU10: 14 | JV10: 14.5 | JW10: 12.75 | JX10: 11 | JY10: 5.5 | JZ10: 13.5 | KA10: 13 | KB10: 11.5 | KC10: 13 | KD10: 12 | KE10: 7 | KF10: 11.5 | KG10: 10 | KI10: 13 | KJ10: 11 | KK10: 11 | KL10: 16.5 | KM10: 7 | KN10: 9 | KO10: 9 | KP10: 4.75 | KQ10: 10 | KR10: x | KS10: 12 | KT10: 4 | KU10: 3.75 | KV10: 13.5 | KW10: x | KX10: 11 | KY10: 12.5 | KZ10: 10.75 | LA10: 14.5 | LB10: 15 | LC10: 5 | LD10: 4.45 | LE10: 11 | LF10: 8 | LG10: 10 | LH10: 8 | LI10: 9 | LJ10: 8 | LK10: 5 | LL10: 2 | LM10: 15 | LO10: 6.25 | LP10: 4 | LQ10: 8 | LU10: 8 | LV10: 8 | LW10: 8 | LX10: 9 | LZ10: 9 | ND10: 1.5 | NE10: 5.5 | NF10: 0.5
B11: عبدالله الصباغ | C11: =SUM(LO11:MS11) -> 52 | D11: =SUM(MU11:NY11) -> 13.75 | HY11: 11 | HZ11: 9.5 | IA11: 6.5 | IB11: 16 | IC11: 10 | ID11: 18 | IE11: 4 | II11: 8.5 | IJ11: 4.5 | IK11: 9 | IL11: 10.5 | IM11: 9.5 | IN11: 11 | IO11: 9.5 | IQ11: 9 | IR11: 10 | IS11: 9.5 | IT11: 10 | IU11: 17 | IV11: 7.5 | IW11: 12.5 | IX11: 8 | IY11: 14.5 | IZ11: 9 | JA11: 8 | JC11: 5 | JD11: 10.5 | JE11: 6.5 | JG11: 14.25 | JH11: 12.5 | JI11: 9.75 | JJ11: 8 | JL11: 10.5 | JM11: 10 | JN11: 8 | JO11: 15.5 | JQ11: 6.5 | JR11: 10 | JS11: 9.25 | JT11: 6 | JU11: 4 | JV11: 9 | JW11: 9 | JX11: 6 | JY11: 6 | JZ11: 7 | KA11: 10 | KB11: 9.5 | KC11: 10 | KD11: 10 | KI11: 10.5 | KJ11: 8.5 | KK11: 10 | KL11: 12 | KM11: 19 | KN11: 7 | KO11: 7 | KP11: 6 | KQ11: 11.5 | KR11: 12 | KS11: 4.5 | KT11: 7 | KU11: 9.5 | KV11: 1.5 | KW11: x | KX11: 11 | KY11: 6 | KZ11: 6 | LA11: x | LB11: 11 | LC11: 6 | LD11: 6 | LE11: 8 | LF11: x | LG11: x | LH11: 11.5 | LI11: 1 | LJ11: 6.5 | LK11: x | LL11: x | LM11: 21 | LO11: 3 | LP11: 5 | LU11: 9 | LV11: 8 | LW11: 9 | LX11: 9 | MB11: 9 | NC11: 2 | NE11: 10.5 | NH11: 1.25
B12: أنوار كريم جواد | C12: =SUM(LO12:MS12) -> 51.4 | D12: =SUM(MU12:NY12) -> 4 | LU12: 7.1 | LV12: 7.1 | LW12: 7.1 | LX12: 7.5 | LZ12: 7.6 | MA12: 7.5 | MB12: 7.5 | NE12: 4
B13: حسين مصطفى | C13: =SUM(LO13:MS13) -> 22.7 | D13: =SUM(MU13:NY13) -> 9.5 | LX13: 6 | LZ13: 9 | MA13: 7.7 | NE13: 7.5 | NF13: 2

Sheet Sheet15
A3: 45658 | B3: يوسف يعقوب | C3: 7 | D3: 1500 | E3: =C3*D3 -> 10500
A4: 45659 | B4: يوسف يعقوب | D4: 1500 | E4: =C4*D4 -> 0
A5: 45660 | B5: يوسف يعقوب | D5: 1500 | E5: =C5*D5 -> 0
A6: 45661 | B6: يوسف يعقوب | C6: 10.5 | D6: 1500 | E6: =C6*D6 -> 15750
A7: 45662 | B7: يوسف يعقوب | C7: 7 | D7: 1500 | E7: =C7*D7 -> 10500
A8: 45663 | B8: يوسف يعقوب | C8: 8 | D8: 1500 | E8: =C8*D8 -> 12000
A9: 45664 | B9: يوسف يعقوب | C9: 5 | D9: 1500 | E9: =C9*D9 -> 7500
A10: 45665 | B10: يوسف يعقوب | D10: 1500 | E10: =C10*D10 -> 0
A11: 45666 | B11: يوسف يعقوب | D11: 1500 | E11: =C11*D11 -> 0
A12: 45667 | B12: يوسف يعقوب | D12: 1500 | E12: =C12*D12 -> 0
A13: 45668 | B13: يوسف يعقوب | D13: 1500 | E13: =C13*D13 -> 0
A14: 45669 | B14: يوسف يعقوب | C14: 10 | D14: 1500 | E14: =C14*D14 -> 15000
A15: 45670 | B15: يوسف يعقوب | C15: 8 | D15: 1500 | E15: =C15*D15 -> 12000
A16: 45671 | B16: يوسف يعقوب | C16: 11 | D16: 1500 | E16: =C16*D16 -> 16500
A17: 45672 | B17: يوسف يعقوب | C17: 11 | D17: 1500 | E17: =C17*D17 -> 16500
A18: 45673 | B18: يوسف يعقوب | C18: 13 | D18: 1500 | E18: =C18*D18 -> 19500
A19: 45674 | B19: يوسف يعقوب | D19: 1500 | E19: =C19*D19 -> 0
A20: 45675 | B20: يوسف يعقوب | C20: 10.5 | D20: 1500 | E20: =C20*D20 -> 15750
A21: 45676 | B21: يوسف يعقوب | C21: 11 | D21: 1500 | E21: =C21*D21 -> 16500
A22: 45677 | B22: يوسف يعقوب | C22: 11 | D22: 1500 | E22: =C22*D22 -> 16500
A23: 45678 | B23: يوسف يعقوب | C23: 11 | D23: 1500 | E23: =C23*D23 -> 16500
A24: 45679 | B24: يوسف يعقوب | C24: 8.5 | D24: 1500 | E24: =C24*D24 -> 12750
A25: 45680 | B25: يوسف يعقوب | C25: 11 | D25: 1500 | E25: =C25*D25 -> 16500
A26: 45681 | B26: يوسف يعقوب | C26: 15 | D26: 1500 | E26: =C26*D26 -> 22500
A27: 45682 | B27: يوسف يعقوب | C27: 8 | D27: 1500 | E27: =C27*D27 -> 12000
A28: 45683 | B28: يوسف يعقوب | C28: 10 | D28: 1500 | E28: =C28*D28 -> 15000
A29: 45684 | B29: يوسف يعقوب | C29: 10 | D29: 1500 | E29: =C29*D29 -> 15000
A30: 45685 | B30: يوسف يعقوب | C30: 10.5 | D30: 1500 | E30: =C30*D30 -> 15750
A31: 45686 | B31: يوسف يعقوب | C31: 11.5 | D31: 1500 | E31: =C31*D31 -> 17250
... A33: 45688 | B33: يوسف يعقوب | C33: 9 | D33: 1500 | E33: =C33*D33 -> 13500
A34: 45658 | B34: عبد الرضا عقيل | D34: 3000 | E34: =C34*D34 -> 0
A35: 45659 | B35: عبد الرضا عقيل | C35: 13.5 | D35: 3000 | E35: =C35*D35 -> 40500
A36: 45660 | B36: عبد الرضا عقيل | C36: 10.5 | D36: 3000 | E36: =C36*D36 -> 31500
A37: 45661 | B37: عبد الرضا عقيل | C37: 13.5 | D37: 3000 | E37: =C37*D37 -> 40500
A38: 45662 | B38: عبد الرضا عقيل | C38: 9 | D38: 3000 | E38: =C38*D38 -> 27000
A39: 45663 | B39: عبد الرضا عقيل | C39: 12 | D39: 3000 | E39: =C39*D39 -> 36000
A40: 45664 | B40: عبد الرضا عقيل | C40: 12 | D40: 3000 | E40: =C40*D40 -> 36000
A41: 45665 | B41: عبد الرضا عقيل | C41: 8.3 | D41: 3000 | E41: =C41*D41 -> 24900
A42: 45666 | B42: عبد الرضا عقيل | C42: 10 | D42: 3000 | E42: =C42*D42 -> 30000
A43: 45667 | B43: عبد الرضا عقيل | D43: 3000 | E43: =C43*D43 -> 0
...

Sheet Sheet16
A2: يوسف يعقوب | B2: =SUMIFS(Sheet15!E:E,Sheet15!B:B,A2) -> 357000
A3: وليد | B3: =SUMIFS(Sheet15!E:E,Sheet15!B:B,A3) -> 858875
A4: علي الكهربائي | B4: =SUMIFS(Sheet15!E:E,Sheet15!B:B,A4) -> 693500
A5: عبد الرضا عقيل | B5: =SUMIFS(Sheet15!E:E,Sheet15!B:B,A5) -> 805650
A6: حيدر يافوز | B6: =SUMIFS(Sheet15!E:E,Sheet15!B:B,A6) -> 507400
A7: وليد | B7: =SUMIFS(Sheet15!E:E,Sheet15!B:B,A7) -> 858875

Sheet رواتب شهر السابع
A4: الموظف | B4: الراتب الأسمي بالساعات | D4: الراتب الأسمي | E4: الحوافز | F4: القطوعات | G4: المستلم | H4: الأجمالي
C5: TIME
A6: حيدر المحاسب
A7: يوسف يعقوب
A8: عبد الرضا عقيل
A9: محمد رشيد | B9: 2750 | C9: =SUM('الحظور'!LO6:MR6) -> 0 | D9: =(B9)*C9 -> 0 | E9: 0 | F9: ='السلف و الغرامات'!C9 -> 50000 | G9: 0 | H9: =(B9)*C9+E9-F9-G9 -> -50000
A10: حيدر الصباغ
A11: وليد
A12: علي الكهربائي
A13: حيدر يافوز
A14: يونس يعقوب
A15: عبدالله الصباغ
A16: أنوار كريم جواد
A17: كرار رمضان | B17: 1750 | C17: =SUM(#REF!) -> #REF! | D17: =(B17)*C17 -> #REF! | E17: 0 | F17: =#REF! -> #REF! | G17: 0 | H17: =(B17)*C17+E17-F17-G17 -> #REF!

Sheet رواتب شهر السادس
A4: الموظف | B4: الراتب الأسمي بالساعات | D4: الراتب الأسمي | E4: الحوافز | F4: القطوعات | G4: المستلم | H4: الأجمالي
C5: TIME
A6: حيدر المحاسب | B6: 3000 | C6: =SUM('الحظور'!KI3:LM3) -> 282.75 | D6: =(B6)*C6 -> 848250 | E6: 9250 | F6: =SUM('السلف و الغرامات'!AI6:BL6) -> 157500 | G6: 700000 | H6: =(B6)*C6+E6-F6-G6 -> 0
A7: يوسف يعقوب | B7: 3000 | C7: =SUM('الحظور'!KI4:LM4) -> 260.5 | D7: =(B7)*C7 -> 781500 | E7: 0 | F7: =SUM('السلف و الغرامات'!AI7:BL7) -> 342000 | G7: 439500 | H7: =(B7)*C7+E7-F7-G7 -> 0
A8: عبد الرضا عقيل | B8: 3000 | C8: =SUM('الحظور'!KI5:LM5) -> 236 | D8: =(B8)*C8 -> 708000 | E8: 3000 | F8: =SUM('السلف و الغرامات'!AI8:BL8) -> 405666 | G8: 305334 | H8: =(B8)*C8+E8-F8-G8 -> 0
A9: محمد رشيد | B9: 2750 | C9: =SUM('الحظور'!KI6:LM6) -> 163 | D9: =(B9)*C9 -> 448250 | E9: 187000 | F9: =SUM('السلف و الغرامات'!AI9:BL9) -> 395416 | G9: 239834 | H9: =(B9)*C9+E9-F9-G9 -> 0
A10: حيدر الصباغ | B10: 2500 | C10: =SUM('الحظور'!KI7:LM7) -> 152.9 | D10: =(B10)*C10 -> 382250 | E10: 100000 | F10: =SUM('السلف و الغرامات'!AI10:BL10) -> 117250 | G10: 365000 | H10: =(B10)*C10+E10-F10-G10 -> 0
A11: وليد | B11: 2500 | C11: =SUM('الحظور'!KI8:LM8) -> 246.75 | D11: =(B11)*C11 -> 616875 | E11: 101000 | F11: =SUM('السلف و الغرامات'!AI11:BL11) -> 681417 | G11: 150542 | H11: =(B11)*C11+E11-F11-G11 -> -114084
A12: علي الكهربائي | B12: 2500 | C12: =SUM('الحظور'!KI9:LM9) -> 251.25 | D12: =(B12)*C12 -> 628125 | E12: 0 | F12: =SUM('السلف و الغرامات'!AI12:BL12) -> 682000 | G12: 0 | H12: =(B12)*C12+E12-F12-G12 -> -53875
A13: حيدر يافوز | B13: 2250 | C13: =SUM('الحظور'!KI10:LM10) -> 273.7 | D13: =(B13)*C13 -> 615825 | E13: 2591 | F13: =SUM('السلف و الغرامات'!AI13:BL13) -> 358416 | G13: 260000 | H13: =(B13)*C13+E13-F13-G13 -> 0
A14: يونس يعقوب | B14: 2000 | C14: =SUM(#REF!) -> #REF! | D14: =(B14)*C14 -> #REF! | E14: 6000 | F14: =SUM(#REF!) -> #REF! | G14: 0 | H14: =(B14)*C14+E14-F14-G14 -> #REF!
A15: عبدالله الصباغ | B15: 2000 | C15: =SUM('الحظور'!KI11:LM11) -> 220 | D15: =(B15)*C15 -> 440000 | E15: 0 | F15: =SUM('السلف و الغرامات'!AI14:BL14) -> 172418 | G15: 267582 | H15: =(B15)*C15+E15-F15-G15 -> 0
A16: أنوار كريم جواد | B16: 2000 | C16: =SUM(#REF!) -> #REF! | D16: =(B16)*C16 -> #REF! | E16: 0 | F16: =SUM('السلف و الغرامات'!AI15:BL15) -> 0 | G16: 346000 | H16: =(B16)*C16+E16-F16-G16 -> #REF!

Sheet السلف و الغرامات
D2: 45778 | E2: 45779 | F2: 45780 | G2: 45781 | H2: 45782 | I2: 45783 | J2: 45784 | K2: 45785 | L2: 45786 | M2: 45787 | N2: 45788 | O2: 45789 | P2: 45790 | Q2: 45791 | R2: 45792 | S2: 45793 | T2: 45794 | U2: 45795 | V2: 45796 | W2: 45797 | X2: 45798 | Y2: 45799 | Z2: 45800 | AA2: 45801 | AB2: 45802 | AC2: 45803 | AD2: 45804 | AE2: 45805 | AF2: 45806 | AG2: 45807 | AH2: 45808 | AI2: 45809 | AJ2: 45810 | AK2: 45811 | AL2: 45812 | AM2: 45813 | AN2: 45814 | AO2: 45815 | AP2: 45816 | AQ2: 45817 | AR2: 45818 | AS2: 45819 | AT2: 45820 | AU2: 45821 | AV2: 45822 | AW2: 45823 | AX2: 45824 | AY2: 45825 | AZ2: 45826 | BA2: 45827 | BB2: 45828 | BC2: 45829 | BD2: 45830 | BE2: 45831 | BF2: 45832 | BG2: 45833 | BH2: 45834 | BI2: 45835 | BJ2: 45836 | BK2: 45837 | BL2: 45838 | BM2: ديون | BN2: 45839 | BO2: 45840 | BP2: 45841 | BQ2: 45842 | BR2: 45843 | BS2: 45844 | BT2: 45845 | BU2: 45846 | BV2: 45847 | BW2: 45848 | BX2: 45849 | BY2: 45850 | BZ2: 45851 | CA2: 45852 | CB2: 45853 | CC2: 45854 | CD2: 45855 | CE2: 45856 | CF2: 45857 | CG2: 45858 | CH2: 45859 | CI2: 45860 | CJ2: 45861 | CK2: 45862 | CL2: 45863 | CM2: 45864 | CN2: 45865 | CO2: 45866 | CP2: 45867 | CQ2: 45868 | CR2: 45869 | CS2: 45870 | CT2: 45871 | CU2: 45872 | CV2: 45873 | CW2: 45874 | CX2: 45875 | CY2: 45876 | CZ2: 45877 | DA2: 45878 | DB2: 45879 | DC2: 45880 | DD2: 45881 | DE2: 45882 | DF2: 45883 | DG2: 45884 | DH2: 45885 | DI2: 45886 | DJ2: 45887 | DK2: 45888 | DL2: 45889 | DM2: 45890 | DN2: 45891 | DO2: 45892 | DP2: 45893 | DQ2: 45894 | DR2: 45895 | DS2: 45896 | DT2: 45897 | DU2: 45898 | DV2: 45899 | DW2: 45900 | DX2: 45901 | DY2: 45902 | DZ2: 45903 | EA2: 45904 | EB2: 45905 | EC2: 45906 | ED2: 45907 | EE2: 45908 | EF2: 45909 | EG2: 45910 | EH2: 45911 | EI2: 45912 | EJ2: 45913 | EK2: 45914 | EL2: 45915 | EM2: 45916 | EN2: 45917 | EO2: 45918 | EP2: 45919 | EQ2: 45920 | ER2: 45921 | ES2: 45922 | ET2: 45923 | EU2: 45924 | EV2: 45925 | EW2: 45926 | EX2: 45927 | EY2: 45928 | EZ2: 45929 | FA2: 45930 | FB2: 45931 | FC2: 45932 | FD2: 45933 | FE2: 45934 | FF2: 45935 | FG2: 45936 | FH2: 45937 | FI2: 45938 | FJ2: 45939 | FK2: 45940 | FL2: 45941 | FM2: 45942 | FN2: 45943 | FO2: 45944 | FP2: 45945 | FQ2: 45946 | FR2: 45947 | FS2: 45948 | FT2: 45949 | FU2: 45950 | FV2: 45951 | FW2: 45952 | FX2: 45953 | FY2: 45954 | FZ2: 45955 | GA2: 45956
BM3: الشهر
D4: =D2 -> 45778 | E4: =E2 -> 45779 | F4: =F2 -> 45780 | G4: =G2 -> 45781 | H4: =H2 -> 45782 | I4: =I2 -> 45783 | J4: =J2 -> 45784 | K4: =K2 -> 45785 | ... BL4: =BL2 -> 45838 | BM4: السابق | BN4: =BN2 -> 45839 | BO4: =BO2 -> 45840 | BP4: =BP2 -> 45841 | BQ4: =BQ2 -> 45842 | BR4: =BR2 -> 45843 | BS4: =BS2 -> 45844 | BT4: =BT2 -> 45845 | BU4: =BU2 -> 45846 | ... GA4: =GA2 -> 45956
C5: المجموع
B6: حيدر المحاسب | C6: =sum(BM6:CQ6) -> 0 | D6: 20000 | F6: 27000 | G6: 36000 | L6: 150000 | M6: 25000 | Q6: 13000 | R6: 33000 | Z6: 35000 | AA6: 100000 | AF6: 26100 | AG6: 35000 | AH6: 287000 | AK6: 5000 | AL6: 20000 | AM6: 5000 | AQ6: 30000 | AR6: 26500 | AT6: 34000 | BF6: 12000 | BK6: 25000
B7: يوسف يعقوب | C7: =sum(BM7:CQ7) -> 0 | G7: 150000 | Q7: 150000 | AK7: 2000 | AQ7: 140000 | AV7: 10000 | AW7: 190000
B8: عبد الرضا عقيل | C8: =sum(BM8:CQ8) -> 150000 | D8: 75000 | H8: 25000 | N8: 35000 | P8: 5000 | Q8: 52000 | R8: 75000 | X8: 25000 | AB8: 2500 | AF8: 10000 | AG8: 25000 | AH8: 34000 | AI8: 140000 | AJ8: 15000 | AK8: 12500 | AQ8: 22000 | AR8: 57000 | AS8: 25000 | AT8: 10000 | AV8: 25000 | AW8: 10000 | AX8: 4166 | BA8: 25000 | BB8: 25000 | BG8: 25000 | BK8: 10000 | BN8: 25000 | BW8: 75000 | BX8: 15000 | BY8: 35000
B9: محمد رشيد | C9: =sum(BM9:CQ9) -> 50000 | Q9: 2000 | U9: 15000 | X9: 25000 | Z9: 25000 | AB9: 100000 | AE9: 250000 | AG9: 25000 | AH9: 25000 | AK9: 10000 | AO9: 5000 | AQ9: 10000 | AT9: 25000 | AX9: 4166 | AY9: 25000 | BA9: 5000 | BB9: 25000 | BC9: 50000 | BE9: 5000 | BF9: 50000 | BG9: 150000 | BJ9: 25000 | BL9: 6250 | BR9: 25000 | BV9: 25000
B10: حيدر الصباغ | C10: =sum(BM10:CQ10) -> 35000 | N10: 100000 | R10: 10000 | AB10: 12500 | AE10: 75000 | AH10: 34000 | AJ10: 20000 | AK10: 2000 | AM10: 10000 | AR10: 25000 | AT10: 25000 | BA10: 25000 | BB10: 2000 | BE10: 2000 | BL10: 6250 | BY10: 35000
B11: وليد | C11: =sum(BM11:CQ11) -> 313000 | O11: 10000 | Q11: 47000 | S11: 15000 | AA11: 100000 | AG11: 5000 | AH11: 39000 | AJ11: 75000 | AM11: 75000 | AQ11: 10000 | AR11: 152000 | AX11: 4167 | BA11: 10000 | BB11: 2000 | BC11: 25000 | BD11: 10000 | BE11: 2000 | BG11: 70000 | BH11: 140000 | BK11: 100000 | BL11: 6250 | BM11: 113000 | BQ11: 50000 | BX11: 150000
B12: علي الكهربائي | C12: =sum(BM12:CQ12) -> 108000 | M12: 5000 | N12: 25000 | V12: 75000 | Y12: 5000 | AD12: 50000 | AG12: 208000 | AH12: 46000 | AO12: 5000 | AT12: 85000 | AV12: 10000 | AY12: 75000 | AZ12: 500000 | BA12: 3000 | BB12: 2000 | BE12: 2000 | BM12: 53000 | BQ12: 50000 | BX12: 5000
B13: حيدر يافوز | C13: =sum(BM13:CQ13) -> 170000 | D13: 10000 | L13: 30000 | Q13: 202000 | T13: 5000 | W13: 2000 | AA13: 5000 | AE13: 20000 | AF13: 263000 | AG13: 10000 | AH13: 46000 | AL13: 5000 | AM13: 10000 | AQ13: 85000 | AU13: 15000 | AV13: 15000 | AX13: 4166 | AY13: 25000 | AZ13: 25000 | BA13: 4000 | BB13: 2000 | BE13: 2000 | BF13: 110000 | BI13: 50000 | BL13: 6250 | BU13: 150000 | BZ13: 5000 | CA13: 15000
B14: عبدالله الصباغ | C14: =sum(BM14:CQ14) -> 35000 | H14: 50000 | O14: 10000 | S14: 20000 | T14: 10000 | V14: 10000 | X14: 25000 | Y14: 25000 | AB14: 25000 | AE14: 75000 | AH14: 47000 | AJ14: 13000 | AK14: 2000 | AL14: 15000 | AR14: 50000 | AX14: 4168 | BB14: 2000 | BC14: 25000 | BE14: 25000 | BJ14: 30000 | BL14: 6250 | BY14: 35000
B15: أنوار كريم جواد | C15: =sum(BM15:CQ15) -> 0
B16: حسين مصطفى | C16: =sum(BM16:CQ16) -> 0
B17: واردات سيف عدنان | C17: =sum(D17:FZ17) -> 11541000 | D17: 4250000 | E17: 3000000 | F17: 250000 | J17: 875000 | M17: 500000 | V17: 255000 | AI17: 50000 | AJ17: 500000 | AM17: 500000 | AO17: 45000 | AW17: 500000 | BB17: 15000 | BI17: 270000 | BK17: 50000 | BN17: 126000 | BP17: 330000 | BR17: 25000
B18: يوسف يعقوب قرض | C18: =sum(D18:FZ18) -> 43356500 | D18: 5000000 | E18: 5000000 | F18: 1090000 | G18: 12675000 | H18: 1000000 | I18: 1000000 | T18: 325000 | U18: 595000 | V18: 485000 | AJ18: 292000 | AK18: 128000 | AY18: 1375000 | BA18: 25000 | BB18: 750000 | BI18: 430000 | BJ18: 355000 | BK18: 2500000 | BL18: 6019000 | BN18: 850000 | BO18: 493500 | BP18: 200000 | BQ18: 100000 | BT18: 1831000 | BU18: 40000 | BV18: 123000 | BW18: 550000 | BX18: 125000

Sheet ٧ السلف و الغرامات
A1: haidermudher28@gmail.com
D2: 45778 | E2: 45779 | F2: 45780 | G2: 45781 | H2: 45782 | I2: 45783 | J2: 45784 | K2: 45785 | L2: 45786 | M2: 45787 | N2: 45788 | O2: 45789 | P2: 45790 | Q2: 45791 | R2: 45792 | S2: 45793 | T2: 45794 | U2: 45795 | V2: 45796 | W2: 45797 | X2: 45798 | Y2: 45799 | Z2: 45800 | AA2: 45801 | AB2: 45802 | AC2: 45803 | AD2: 45804 | AE2: 45805 | AF2: 45806 | AG2: 45807 | AH2: 45808 | AI2: 45809 | AJ2: 45810 | AK2: 45811 | AL2: 45812 | AM2: 45813 | AN2: 45814 | AO2: 45815 | AP2: 45816 | AQ2: 45817 | AR2: 45818 | AS2: 45819 | AT2: 45820 | AU2: 45821 | AV2: 45822 | AW2: 45823 | AX2: 45824 | AY2: 45825 | AZ2: 45826 | BA2: 45827 | BB2: 45828 | BC2: 45829 | BD2: 45830 | BE2: 45831 | BF2: 45832 | BG2: 45833 | BH2: 45834 | BI2: 45835 | BJ2: 45836 | BK2: 45837 | BL2: 45838 | BM2: ديون | BN2: 45839 | BO2: 45840 | BP2: 45841 | BQ2: 45842 | BR2: 45843 | BS2: 45844 | BT2: 45845 | BU2: 45846 | BV2: 45847 | BW2: 45848 | BX2: 45849 | BY2: 45850 | BZ2: 45851 | CA2: 45852 | CB2: 45853 | CC2: 45854 | CD2: 45855 | CE2: 45856 | CF2: 45857 | CG2: 45858 | CH2: 45859 | CI2: 45860 | CJ2: 45861 | CK2: 45862 | CL2: 45863 | CM2: 45864 | CN2: 45865 | CO2: 45866 | CP2: 45867 | CQ2: 45868 | CR2: 45869 | CS2: 45870 | CT2: 45871 | CU2: 45872 | CV2: 45873 | CW2: 45874 | CX2: 45875 | CY2: 45876 | CZ2: 45877 | DA2: 45878 | DB2: 45879 | DC2: 45880 | DD2: 45881 | DE2: 45882 | DF2: 45883 | DG2: 45884 | DH2: 45885 | DI2: 45886 | DJ2: 45887 | DK2: 45888 | DL2: 45889 | DM2: 45890 | DN2: 45891 | DO2: 45892 | DP2: 45893 | DQ2: 45894 | DR2: 45895 | DS2: 45896 | DT2: 45897 | DU2: 45898 | DV2: 45899 | DW2: 45900 | DX2: 45901 | DY2: 45902 | DZ2: 45903 | EA2: 45904 | EB2: 45905 | EC2: 45906 | ED2: 45907 | EE2: 45908 | EF2: 45909 | EG2: 45910 | EH2: 45911 | EI2: 45912 | EJ2: 45913 | EK2: 45914 | EL2: 45915 | EM2: 45916 | EN2: 45917 | EO2: 45918 | EP2: 45919 | EQ2: 45920 | ER2: 45921 | ES2: 45922 | ET2: 45923 | EU2: 45924 | EV2: 45925 | EW2: 45926 | EX2: 45927 | EY2: 45928 | EZ2: 45929 | FA2: 45930 | FB2: 45931 | FC2: 45932 | FD2: 45933 | FE2: 45934 | FF2: 45935 | FG2: 45936 | FH2: 45937 | FI2: 45938 | FJ2: 45939 | FK2: 45940 | FL2: 45941 | FM2: 45942 | FN2: 45943 | FO2: 45944 | FP2: 45945 | FQ2: 45946 | FR2: 45947 | FS2: 45948 | FT2: 45949 | FU2: 45950 | FV2: 45951 | FW2: 45952 | FX2: 45953 | FY2: 45954 | FZ2: 45955 | GA2: 45956
BM3: الشهر
D4: =D2 -> 45778 | E4: =E2 -> 45779 | F4: =F2 -> 45780 | G4: =G2 -> 45781 | H4: =H2 -> 45782 | I4: =I2 -> 45783 | J4: =J2 -> 45784 | K4: =K2 -> 45785 | ... BL4: =BL2 -> 45838 | BM4: السابق | BN4: =BN2 -> 45839 | BO4: =BO2 -> 45840 | BP4: =BP2 -> 45841 | BQ4: =BQ2 -> 45842 | BR4: =BR2 -> 45843 | BS4: =BS2 -> 45844 | BT4: =BT2 -> 45845 | BU4: =BU2 -> 45846 | ... GA4: =GA2 -> 45956
C5: المجموع
B6: حيدر المحاسب | C6: =sum(BM6:CQ6) -> 0 | D6: 20000 | F6: 27000 | G6: 36000 | L6: 150000 | M6: 25000 | Q6: 13000 | R6: 33000 | Z6: 35000 | AA6: 100000 | AF6: 26100 | AG6: 35000 | AH6: 287000 | AK6: 5000 | AL6: 20000 | AM6: 5000 | AQ6: 30000 | AR6: 26500 | AT6: 34000 | BF6: 12000 | BK6: 25000
B7: يوسف يعقوب | C7: =sum(BM7:CQ7) -> 0 | G7: 150000 | Q7: 150000 | AK7: 2000 | AQ7: 140000 | AV7: 10000 | AW7: 190000
B8: عبد الرضا عقيل | C8: =sum(BM8:CQ8) -> 150000 | D8: 75000 | H8: 25000 | N8: 35000 | P8: 5000 | Q8: 52000 | R8: 75000 | X8: 25000 | AB8: 2500 | AF8: 10000 | AG8: 25000 | AH8: 34000 | AI8: 140000 | AJ8: 15000 | AK8: 12500 | AQ8: 22000 | AR8: 57000 | AS8: 25000 | AT8: 10000 | AV8: 25000 | AW8: 10000 | AX8: 4166 | BA8: 25000 | BB8: 25000 | BG8: 25000 | BK8: 10000 | BN8: 25000 | BW8: 75000 | BX8: 15000 | BY8: 35000
B9: محمد رشيد | C9: =sum(BM9:CQ9) -> 50000 | Q9: 2000 | U9: 15000 | X9: 25000 | Z9: 25000 | AB9: 100000 | AE9: 250000 | AG9: 25000 | AH9: 25000 | AK9: 10000 | AO9: 5000 | AQ9: 10000 | AT9: 25000 | AX9: 4166 | AY9: 25000 | BA9: 5000 | BB9: 25000 | BC9: 50000 | BE9: 5000 | BF9: 50000 | BG9: 150000 | BJ9: 25000 | BL9: 6250 | BR9: 25000 | BV9: 25000
B10: حيدر الصباغ | C10: =sum(BM10:CQ10) -> 35000 | N10: 100000 | R10: 10000 | AB10: 12500 | AE10: 75000 | AH10: 34000 | AJ10: 20000 | AK10: 2000 | AM10: 10000 | AR10: 25000 | AT10: 25000 | BA10: 25000 | BB10: 2000 | BE10: 2000 | BL10: 6250 | BY10: 35000
B11: وليد | C11: =sum(BM11:CQ11) -> 313000 | O11: 10000 | Q11: 47000 | S11: 15000 | AA11: 100000 | AG11: 5000 | AH11: 39000 | AJ11: 75000 | AM11: 75000 | AQ11: 10000 | AR11: 152000 | AX11: 4167 | BA11: 10000 | BB11: 2000 | BC11: 25000 | BD11: 10000 | BE11: 2000 | BG11: 70000 | BH11: 140000 | BK11: 100000 | BL11: 6250 | BM11: 113000 | BQ11: 50000 | BX11: 150000
B12: علي الكهربائي | C12: =sum(BM12:CQ12) -> 108000 | M12: 5000 | N12: 25000 | V12: 75000 | Y12: 5000 | AD12: 50000 | AG12: 208000 | AH12: 46000 | AO12: 5000 | AT12: 85000 | AV12: 10000 | AY12: 75000 | AZ12: 500000 | BA12: 3000 | BB12: 2000 | BE12: 2000 | BM12: 53000 | BQ12: 50000 | BX12: 5000
B13: حيدر يافوز | C13: =sum(BM13:CQ13) -> 170000 | D13: 10000 | L13: 30000 | Q13: 202000 | T13: 5000 | W13: 2000 | AA13: 5000 | AE13: 20000 | AF13: 263000 | AG13: 10000 | AH13: 46000 | AL13: 5000 | AM13: 10000 | AQ13: 85000 | AU13: 15000 | AV13: 15000 | AX13: 4166 | AY13: 25000 | AZ13: 25000 | BA13: 4000 | BB13: 2000 | BE13: 2000 | BF13: 110000 | BI13: 50000 | BL13: 6250 | BU13: 150000 | BZ13: 5000 | CA13: 15000
B14: عبدالله الصباغ | C14: =sum(BM14:CQ14) -> 35000 | H14: 50000 | O14: 10000 | S14: 20000 | T14: 10000 | V14: 10000 | X14: 25000 | Y14: 25000 | AB14: 25000 | AE14: 75000 | AH14: 47000 | AJ14: 13000 | AK14: 2000 | AL14: 15000 | AR14: 50000 | AX14: 4168 | BB14: 2000 | BC14: 25000 | BE14: 25000 | BJ14: 30000 | BL14: 6250 | BY14: 35000
B15: أنوار كريم جواد | C15: =sum(BM15:CQ15) -> 0
B16: حسين مصطفى | C16: =sum(BM16:CQ16) -> 0
B17: واردات سيف عدنان | C17: =sum(D17:FZ17) -> 11541000 | D17: 4250000 | E17: 3000000 | F17: 250000 | J17: 875000 | M17: 500000 | V17: 255000 | AI17: 50000 | AJ17: 500000 | AM17: 500000 | AO17: 45000 | AW17: 500000 | BB17: 15000 | BI17: 270000 | BK17: 50000 | BN17: 126000 | BP17: 330000 | BR17: 25000
B18: يوسف يعقوب قرض | C18: =sum(D18:FZ18) -> 43356500 | D18: 5000000 | E18: 5000000 | F18: 1090000 | G18: 12675000 | H18: 1000000 | I18: 1000000 | T18: 325000 | U18: 595000 | V18: 485000 | AJ18: 292000 | AK18: 128000 | AY18: 1375000 | BA18: 25000 | BB18: 750000 | BI18: 430000 | BJ18: 355000 | BK18: 2500000 | BL18: 6019000 | BN18: 850000 | BO18: 493500 | BP18: 200000 | BQ18: 100000 | BT18: 1831000 | BU18: 40000 | BV18: 123000 | BW18: 550000 | BX18: 125000

Sheet الحضور 1
X1: =iferror(concatenate(" Enter ", 'Attendance key'!$B$7, " for ",'Attendance key'!$C$7, ", ", 'Attendance key'!$B$8, " for ", 'Attendance key'!$C$8, ", ", 'Attendance key'!$B$9, " for ", 'Attendance key'!$C$9, ", and ", 'Attendance key'!$B$10, " for ", 'Attendance key'!$C$10, ". Use the 'Attendance key' tab to customize. "),"") | GL1: hhg
E2: 45521 | F2: 45522 | G2: 45523 | H2: 45524 | I2: 45525 | J2: 45526 | K2: 45527 | L2: 45528 | M2: 45529 | N2: 45530 | O2: 45531 | P2: 45532 | Q2: 45533 | R2: 45534 | S2: 45535 | T2: 45536 | U2: 45537 | V2: 45538 | W2: 45539 | X2: 45540 | Y2: 45541 | Z2: 45542 | AA2: 45543 | AB2: 45544 | AC2: 45545 | AD2: 45546 | AE2: 45547 | AF2: 45548 | AG2: 45549 | AH2: 45550 | AI2: 45551 | AJ2: 45552 | AK2: 45553 | AL2: 45554 | AM2: 45555 | AN2: 45556 | AO2: 45557 | AP2: 45558 | AQ2: 45559 | AR2: 45560 | AS2: 45561 | AT2: 45562 | AU2: 45563 | AW2: 45565 | AX2: 45566 | AY2: 45567 | AZ2: 45568 | BA2: 45569 | BB2: 45570 | BC2: 45571 | BD2: 45572 | BE2: 45573 | BF2: 45574 | BG2: 45575 | BH2: 45576 | BI2: 45577 | BJ2: 45578 | BK2: 45579 | BL2: 45580 | BM2: 45581 | BN2: 45582 | BO2: 45583 | BP2: 45584 | BQ2: 45585 | BR2: 45586 | BS2: 45587 | BT2: 45588 | BU2: 45589 | BV2: 45590 | BW2: 45591 | BX2: 45592 | BY2: 45593 | BZ2: 45594 | CA2: 45595 | CB2: 45596 | CC2: 45597 | CD2: 45598 | CE2: 45599 | CF2: 45600 | CG2: 45601 | CH2: 45602 | CI2: 45603 | CJ2: 45604 | CK2: 45605 | CL2: 45606 | CM2: 45607 | CN2: 45608 | CO2: 45609 | CP2: 45610 | CQ2: 45611 | CR2: 45612 | CS2: 45613 | CT2: 45614 | CU2: 45615 | CV2: 45616 | CW2: 45617 | CX2: 45618 | CY2: 45619 | CZ2: 45620 | DA2: 45621 | DB2: 45622 | DC2: 45623 | DD2: 45624 | DE2: 45625 | DF2: 45626 | DG2: 45627 | DH2: 45628 | DI2: 45629 | DJ2: 45630 | DK2: 45631 | DL2: 45632 | DM2: 45633 | DN2: 45634 | DO2: 45635 | DP2: 45636 | DQ2: 45637 | DR2: 45638 | DS2: 45639 | DT2: 45640 | DU2: 45641 | DV2: 45642 | DW2: 45643 | DX2: 45644 | DY2: 45645 | DZ2: 45646 | EA2: 45647 | EB2: 45648 | EC2: 45649 | ED2: 45650 | EE2: 45651 | EF2: 45652 | EG2: 45653 | EH2: 45654 | EI2: 45655 | EJ2: 45656 | EK2: 45657 | EL2: 45658 | EM2: 45659 | EN2: 45660 | EO2: 45661 | EP2: 45662 | EQ2: 45663 | ER2: 45664 | ES2: 45665 | ET2: 45666 | EU2: 45667 | EV2: 45668 | EW2: 45669 | EX2: 45670 | EY2: 45671 | EZ2: 45672 | FA2: 45673 | FB2: 45674 | FC2: 45675 | FD2: 45676 | FE2: 45677 | FF2: 45678 | FG2: 45679 | FH2: 45680 | FI2: 45681 | FJ2: 45682 | FK2: 45683 | FL2: 45684 | FM2: 45685 | FN2: 45686 | FO2: 45687 | FP2: 45688 | FQ2: 45689 | FR2: 45690 | FS2: 45691 | FT2: 45692 | FU2: 45693 | FV2: 45694 | FW2: 45695 | FX2: 45696 | FY2: 45697 | FZ2: 45698 | GA2: 45699 | GB2: 45700 | GC2: 45701 | GD2: 45702 | GE2: 45703 | GF2: 45704 | GG2: 45705 | GH2: 45706 | GI2: 45707 | GJ2: 45708 | GK2: 45709 | GL2: 45710 | GM2: 45711 | GN2: 45712 | GO2: 45713 | GP2: 45714 | GQ2: 45715 | GR2: 45716 | GS2: 45717 | GT2: 45718 | GU2: 45719 | GV2: 45720 | GW2: 45721 | GX2: 45722 | GY2: 45723 | GZ2: 45724 | HA2: 45725 | HB2: 45726 | HC2: 45727 | HD2: 45728 | HE2: 45729 | HF2: 45730 | HG2: 45731 | HH2: 45732 | HI2: 45733 | HJ2: 45734 | HK2: 45735 | HL2: 45736 | HM2: 45737 | HN2: 45738 | HO2: 45739 | HP2: 45740 | HQ2: 45741 | HR2: 45742 | HS2: 45743 | HT2: 45744 | HU2: 45745 | HV2: 45746 | HW2: 45747 | HX2: 45748 | HY2: 45749 | HZ2: 45750 | IA2: 45751 | IB2: 45752 | IC2: 45753 | ID2: 45754 | IE2: 45755 | IF2: 45756 | IG2: 45757 | IH2: 45758 | II2: 45759 | IJ2: 45760 | IK2: 45761 | IL2: 45762 | IM2: 45763 | IN2: 45764 | IO2: 45765 | IP2: 45766 | IQ2: 45767 | IR2: 45768 | IS2: 45769 | IT2: 45770 | IU2: 45771 | IV2: 45772 | IW2: 45773 | IX2: 45774 | IY2: 45775 | IZ2: 45776 | JA2: 45777 | JC2: 45778 | JD2: 45779 | JE2: 45780 | JF2: 45781 | JG2: 45782 | JH2: 45783 | JI2: 45784 | JJ2: 45785 | JK2: 45786 | JL2: 45787 | JM2: 45788 | JN2: 45789 | JO2: 45790 | JP2: 45791 | JQ2: 45792 | JR2: 45793 | JS2: 45794 | JT2: 45795 | JU2: 45796 | JV2: 45797 | JW2: 45798 | JX2: 45799 | JY2: 45800 | JZ2: 45801 | KA2: 45802 | KB2: 45803 | KC2: 45804 | KD2: 45805 | KE2: 45806 | KF2: 45807 | KG2: 45808 | KI2: 45809 | KJ2: 45810 | KK2: 45811 | KL2: 45812 | KM2: 45813 | KN2: 45814 | KO2: 45815 | KP2: 45816 | KQ2: 45817 | KR2: 45818 | KS2: 45819 | KT2: 45820 | KU2: 45821 | KV2: 45822 | KW2: 45823 | KX2: 45824 | KY2: 45825 | KZ2: 45826 | LA2: 45827 | LB2: 45828 | LC2: 45829 | LD2: 45830 | LE2: 45831 | LF2: 45832 | LG2: 45833 | LH2: 45834 | LI2: 45835 | LJ2: 45836 | LK2: 45837 | LL2: 45838 | LM2: الساعات | LO2: 45839 | LP2: 45840 | LQ2: 45841 | LR2: 45842 | LS2: 45843 | LT2: 45844 | LU2: 45845 | LV2: 45846 | LW2: 45847 | LX2: 45848 | LY2: 45849 | LZ2: 45850 | MA2: 45851 | MB2: 45852 | MC2: 45853 | MD2: 45854 | ME2: 45855 | MF2: 45856 | MG2: 45857 | MH2: 45858 | MI2: 45859 | MJ2: 45860 | MK2: 45861 | ML2: 45862 | MM2: 45863 | MN2: 45864 | MO2: 45865 | MP2: 45866 | MQ2: 45867 | MR2: 45868 | MS2: 45869 | MU2: 45839 | MV2: 45840 | MW2: 45841 | MX2: 45842 | MY2: 45843 | MZ2: 45844 | NA2: 45845 | NB2: 45846 | NC2: 45847 | ND2: 45848 | NE2: 45849 | NF2: 45850 | NG2: 45851 | NH2: 45852 | NI2: 45853 | NJ2: 45854 | NK2: 45855 | NL2: 45856 | NM2: 45857 | NN2: 45858 | NO2: 45859 | NP2: 45860 | NQ2: 45861 | NR2: 45862 | NS2: 45863 | NT2: 45864 | NU2: 45865 | NV2: 45866 | NW2: 45867 | NX2: 45868 | NY2: 45869 | OA2: 45901 | OB2: 45902 | OC2: 45903 | OD2: 45904 | OE2: 45905 | OF2: 45906 | OG2: 45907 | OH2: 45908 | OI2: 45909 | OJ2: 45910 | OK2: 45911 | OL2: 45912
C3: الحضور | D3: الاضافي | E3: =E2 -> 45521 | F3: =F2 -> 45522 | G3: =G2 -> 45523 | H3: =H2 -> 45524 | I3: =I2 -> 45525 | J3: =J2 -> 45526 | K3: =K2 -> 45527 | L3: =L2 -> 45528 | ... JA3: =JA2 -> 45777 | JC3: =JC2 -> 45778 | JD3: =JD2 -> 45779 | JE3: =JE2 -> 45780 | JF3: =JF2 -> 45781 | JG3: =JG2 -> 45782 | JH3: =JH2 -> 45783 | JI3: =JI2 -> 45784 | JJ3: =JJ2 -> 45785 | ... KG3: =KG2 -> 45808 | KI3: =KI2 -> 45809 | KJ3: =KJ2 -> 45810 | KK3: =KK2 -> 45811 | KL3: =KL2 -> 45812 | KM3: =KM2 -> 45813 | KN3: =KN2 -> 45814 | KO3: =KO2 -> 45815 | KP3: =KP2 -> 45816 | ... LL3: =LL2 -> 45838 | LM3: الاضافية | LO3: =LO2 -> 45839 | LP3: =LP2 -> 45840 | LQ3: =LQ2 -> 45841 | LR3: =LR2 -> 45842 | LS3: =LS2 -> 45843 | LT3: =LT2 -> 45844 | LU3: =LU2 -> 45845 | LV3: =LV2 -> 45846 | ... MS3: =MS2 -> 45869 | MU3: =MU2 -> 45839 | MV3: =MV2 -> 45840 | MW3: =MW2 -> 45841 | MX3: =MX2 -> 45842 | MY3: =MY2 -> 45843 | MZ3: =MZ2 -> 45844 | NA3: =NA2 -> 45845 | NB3: =NB2 -> 45846 | ... NY3: =NY2 -> 45869 | OA3: =OA2 -> 45901 | OB3: =OB2 -> 45902 | OC3: =OC2 -> 45903 | OD3: =OD2 -> 45904 | OE3: =OE2 -> 45905 | OF3: =OF2 -> 45906 | OG3: =OG2 -> 45907 | OH3: =OH2 -> 45908 | ... OL3: =OL2 -> 45912
B4: الاسم | C4: الحضور | D4: الاضافي
C5: الحضور | D5: الاضافي
A6: =sum(GW6:MR6)*3000 -> 3508350 | B6: حيدر المحاسب | C6: =SUM(LO6:MS6) -> 80 | D6: =SUM(MU6:NY6) -> 33.25 | GW6: 10 | GX6: 10 | GY6: 10 | GZ6: 10 | HA6: 6 | HB6: 6 | HC6: 8.5 | HD6: 11 | HE6: 7 | HF6: 10 | HG6: 8 | HH6: 7.5 | HI6: 11 | HJ6: 8.5 | HK6: 7 | HL6: 6 | HM6: 7 | HN6: 13 | HO6: 10 | HP6: 10.5 | HQ6: 8.5 | HR6: 8.5 | HS6: 12 | HT6: 0 | HU6: 3 | HV6: 7 | HW6: 0 | HX6: 11 | HY6: 7 | HZ6: 10 | IA6: 11 | IB6: 11.5 | IC6: 12.5 | ID6: 9 | IE6: 11 | IF6: 13 | IG6: 8 | IH6: 0 | II6: 10 | IJ6: 11 | IK6: 9 | IL6: 13 | IM6: 9 | IN6: 10.5 | IO6: 0 | IP6: 10 | IQ6: 9 | IR6: 9 | IS6: 10 | IT6: 9 | IU6: 9 | IV6: 9.5 | IW6: 9 | IX6: 8 | IY6: 10 | IZ6: 10 | JA6: 13 | JC6: 13 | JD6: 6 | JE6: 10 | JF6: 9 | JG6: 9 | JH6: 8 | JI6: 0 | JJ6: 0 | JK6: 9 | JL6: 12 | JM6: 9 | JN6: 17 | JO6: 10 | JP6: 13 | JQ6: 15 | JR6: 9 | JS6: 14 | JT6: 11 | JU6: 10 | JV6: 9 | JW6: 11 | JX6: 12 | JY6: 10 | JZ6: 11 | KA6: 13 | KB6: 11 | KC6: 6.7 | KD6: 10 | KE6: 11 | KF6: 10 | KG6: 10 | KI6: 10 | KJ6: 10 | KK6: 10 | KL6: 7 | KM6: 10 | KN6: 7 | KO6: 2.5 | KP6: 9 | KQ6: 9.25 | KR6: 5 | KS6: 10 | KT6: 8 | KU6: 8 | KV6: 17 | KW6: 6 | KX6: 7 | KY6: 7.5 | KZ6: 10 | LA6: 10 | LB6: 6.5 | LC6: 14 | LD6: 9 | LE6: 8 | LF6: 12 | LG6: 12 | LH6: 3 | LI6: x | LJ6: 10 | LK6: 10 | LL6: 5 | LM6: 30 | LO6: 9 | LP6: 9 | LQ6: 9 | LU6: 9 | LV6: 9 | LW6: 8 | LX6: 9 | LZ6: 9 | MA6: 9 | MV6: 5 | MW6: 1.75 | MX6: 10 | NA6: 2 | NB6: 1 | ND6: 0.5 | NE6: 7.5 | NF6: 0.25 | NG6: 5.25
