Workbook
Name S_ITEMS: Form!$B$7:$B$18
Name P_REMAIN: Form!$F$23
Name P_NOTES: Form!$F$24
Name S_NAME: Form!$B$5
Name P_ITEMS: Form!$F$7:$F$18
Name S_NO: Form!$B$3
Name S_DESC: Form!$A$7:$A$18
Name S_DISCOUNT: Form!$F$20
Name p_NAME: Form!$F$5
Name S_DATE: Form!$B$4
Name P_DESC: Form!$E$7:$E$18
Name P_TOTAL: Form!$H$7:$H$18
Name S_REMAIN: Form!$B$23
Name S_AFTER: Form!$B$21
Name P_DISCOUNT: Form!$F$20
Name P_AFTER: Form!$G$22
Name S_TOTAL: Form!$B$19
Name S_RECEIVED: Form!$B$23
Name P_PAID: Form!$F$22
Name P_NO: Form!$F$3
Name S_NOTES: Form!$B$24
Name P_DATE: Form!$F$4

Sheet نسخة من حضور الموضفين
A1: التاريخ | B1: اليوم | C1: اسم الموظف | D1: الراتب الاسمي | E1: وقت الدخول | F1: وقت الخروج | G1: سعر الساعة | H1: ساعات عادية | I1: ساعات إضافية 1.5x | J1: ساعات الجمعة 2x | K1: الراتب اليومي | L1: المكافآت | M1: السلف | N1: الغرامات | O1: الرقم النهائي | P1: الملاحظات
A2: 45901 | B2: =CHOOSE(WEEKDAY(A2,2),"الاثنين","الثلاثاء","الأربعاء","الخميس","الجمعة","السبت","الأحد") -> الاثنين | C2: حيدر مضر | D2: 650000 | E2: 0.44305556 | F2: 0.875 | G2: =D2/235 -> 2765.9574 | H2: =MIN(9,MAX(0,(MIN(F2,TIME(18,0,0))-MAX(E2,TIME(9,0,0)))*24)) -> 7.3666667 | I2: =MAX(0,(MOD(F2-E2,1)*24)-H2) -> 3 | J2: =IF(B2="الجمعة",MOD(F2-E2,1)*24,0) -> 0 | K2: =(H2*G2)+(I2*G2*1.5)+(J2*G2*2) -> 32822.695 | M2: 240000 | N2: =IF(B2="الجمعة",0,IF(E2>TIME(9,0,0),(E2-TIME(9,0,0))*24*60*(G2/60),0)) -> 4517.7305 | O2: =K2+L2-M2-N2 -> -211695.04
A3: 45902 | B3: =CHOOSE(WEEKDAY(A3,2),"الاثنين","الثلاثاء","الأربعاء","الخميس","الجمعة","السبت","الأحد") -> الثلاثاء | C3: حيدر مضر | D3: 650000 | E3: 0.29791667 | F3: 0.875 | G3: =D3/235 -> 2765.9574 | H3: =MIN(9,MAX(0,(MIN(F3,TIME(18,0,0))-MAX(E3,TIME(9,0,0)))*24)) -> 9 | I3: =MAX(0,(MOD(F3-E3,1)*24)-H3) -> 4.85 | J3: =IF(B3="الجمعة",MOD(F3-E3,1)*24,0) -> 0 | K3: =(H3*G3)+(I3*G3*1.5)+(J3*G3*2) -> 45015.957 | N3: =IF(B3="الجمعة",0,IF(E3>TIME(9,0,0),(E3-TIME(9,0,0))*24*60*(G3/60),0)) -> 0 | O3: =K3+L3-M3-N3 -> 45015.957
A4: 45903 | B4: =CHOOSE(WEEKDAY(A4,2),"الاثنين","الثلاثاء","الأربعاء","الخميس","الجمعة","السبت","الأحد") -> الأربعاء | C4: حيدر مضر | D4: 650000 | E4: 0.42638889 | F4: 0.85347222 | G4: =D4/235 -> 2765.9574 | H4: =MIN(9,MAX(0,(MIN(F4,TIME(18,0,0))-MAX(E4,TIME(9,0,0)))*24)) -> 7.7666667 | I4: =MAX(0,(MOD(F4-E4,1)*24)-H4) -> 2.4833333 | J4: =IF(B4="الجمعة",MOD(F4-E4,1)*24,0) -> 0 | K4: =(H4*G4)+(I4*G4*1.5)+(J4*G4*2) -> 31785.461 | N4: =IF(B4="الجمعة",0,IF(E4>TIME(9,0,0),(E4-TIME(9,0,0))*24*60*(G4/60),0)) -> 3411.3475 | O4: =K4+L4-M4-N4 -> 28374.113
A5: 45904 | B5: =CHOOSE(WEEKDAY(A5,2),"الاثنين","الثلاثاء","الأربعاء","الخميس","الجمعة","السبت","الأحد") -> الخميس | C5: حيدر مضر | D5: 650000 | E5: 0.375 | F5: 0.99930556 | G5: =D5/235 -> 2765.9574 | H5: =MIN(9,MAX(0,(MIN(F5,TIME(18,0,0))-MAX(E5,TIME(9,0,0)))*24)) -> 9 | I5: =MAX(0,(MOD(F5-E5,1)*24)-H5) -> 5.9833333 | J5: =IF(B5="الجمعة",MOD(F5-E5,1)*24,0) -> 0 | K5: =(H5*G5)+(I5*G5*1.5)+(J5*G5*2) -> 49718.085 | N5: =IF(B5="الجمعة",0,IF(E5>TIME(9,0,0),(E5-TIME(9,0,0))*24*60*(G5/60),0)) -> 0 | O5: =K5+L5-M5-N5 -> 49718.085
A6: 45905 | B6: =CHOOSE(WEEKDAY(A6,2),"الاثنين","الثلاثاء","الأربعاء","الخميس","الجمعة","السبت","الأحد") -> الجمعة | C6: حيدر مضر | D6: 650000 | E6: 0.41666667 | F6: 0.95833333 | G6: =D6/235 -> 2765.9574 | H6: =MIN(9,MAX(0,(MIN(F6,TIME(18,0,0))-MAX(E6,TIME(9,0,0)))*24)) -> 8 | I6: 0 | J6: =IF(B6="الجمعة",MOD(F6-E6,1)*24,0) -> 13 | K6: =(J6*G6*2) -> 71914.894 | N6: =IF(B6="الجمعة",0,IF(E6>TIME(9,0,0),(E6-TIME(9,0,0))*24*60*(G6/60),0)) -> 0 | O6: =K6+L6-M6-N6 -> 71914.894
A7: 45906 | B7: =CHOOSE(WEEKDAY(A7,2),"الاثنين","الثلاثاء","الأربعاء","الخميس","الجمعة","السبت","الأحد") -> السبت | C7: حيدر مضر | D7: 650000 | E7: 0.40208333 | F7: 0.89791667 | G7: =D7/235 -> 2765.9574 | H7: =MIN(9,MAX(0,(MIN(F7,TIME(18,0,0))-MAX(E7,TIME(9,0,0)))*24)) -> 8.35 | I7: =MAX(0,(MOD(F7-E7,1)*24)-H7) -> 3.55 | J7: =IF(B7="الجمعة",MOD(F7-E7,1)*24,0) -> 0 | K7: =(H7*G7)+(I7*G7*1.5)+(J7*G7*2) -> 37824.468 | N7: =IF(B7="الجمعة",0,IF(E7>TIME(9,0,0),(E7-TIME(9,0,0))*24*60*(G7/60),0)) -> 1797.8723 | O7: =K7+L7-M7-N7 -> 36026.596
A8: 45907 | B8: =CHOOSE(WEEKDAY(A8,2),"الاثنين","الثلاثاء","الأربعاء","الخميس","الجمعة","السبت","الأحد") -> الأحد | C8: حيدر مضر | D8: 650000 | E8: 0.375 | F8: 0.99930556 | G8: =D8/235 -> 2765.9574 | H8: =MIN(9,MAX(0,(MIN(F8,TIME(18,0,0))-MAX(E8,TIME(9,0,0)))*24)) -> 9 | I8: =MAX(0,(MOD(F8-E8,1)*24)-H8) -> 5.9833333 | J8: =IF(B8="الجمعة",MOD(F8-E8,1)*24,0) -> 0 | K8: =(H8*G8)+(I8*G8*1.5)+(J8*G8*2) -> 49718.085 | N8: =IF(B8="الجمعة",0,IF(E8>TIME(9,0,0),(E8-TIME(9,0,0))*24*60*(G8/60),0)) -> 0 | O8: =K8+L8-M8-N8 -> 49718.085
A9: 45908 | B9: =CHOOSE(WEEKDAY(A9,2),"الاثنين","الثلاثاء","الأربعاء","الخميس","الجمعة","السبت","الأحد") -> الاثنين | C9: حيدر مضر | D9: 650000 | E9: 0.375 | F9: 0.99930556 | G9: =D9/235 -> 2765.9574 | H9: =MIN(9,MAX(0,(MIN(F9,TIME(18,0,0))-MAX(E9,TIME(9,0,0)))*24)) -> 9 | I9: =MAX(0,(MOD(F9-E9,1)*24)-H9) -> 5.9833333 | J9: =IF(B9="الجمعة",MOD(F9-E9,1)*24,0) -> 0 | K9: =(H9*G9)+(I9*G9*1.5)+(J9*G9*2) -> 49718.085 | N9: =IF(B9="الجمعة",0,IF(E9>TIME(9,0,0),(E9-TIME(9,0,0))*24*60*(G9/60),0)) -> 0 | O9: =K9+L9-M9-N9 -> 49718.085
A10: 45909 | B10: =CHOOSE(WEEKDAY(A10,2),"الاثنين","الثلاثاء","الأربعاء","الخميس","الجمعة","السبت","الأحد") -> الثلاثاء | C10: حيدر مضر | D10: 650000 | E10: 0.375 | F10: 0.99930556 | G10: =D10/235 -> 2765.9574 | H10: =MIN(9,MAX(0,(MIN(F10,TIME(18,0,0))-MAX(E10,TIME(9,0,0)))*24)) -> 9 | I10: =MAX(0,(MOD(F10-E10,1)*24)-H10) -> 5.9833333 | J10: =IF(B10="الجمعة",MOD(F10-E10,1)*24,0) -> 0 | K10: =(H10*G10)+(I10*G10*1.5)+(J10*G10*2) -> 49718.085 | N10: =IF(B10="الجمعة",0,IF(E10>TIME(9,0,0),(E10-TIME(9,0,0))*24*60*(G10/60),0)) -> 0 | O10: =K10+L10-M10-N10 -> 49718.085
A11: 45910 | B11: =CHOOSE(WEEKDAY(A11,2),"الاثنين","الثلاثاء","الأربعاء","الخميس","الجمعة","السبت","الأحد") -> الأربعاء | C11: حيدر مضر | D11: 650000 | E11: 0.375 | F11: 0.99930556 | G11: =D11/235 -> 2765.9574 | H11: =MIN(9,MAX(0,(MIN(F11,TIME(18,0,0))-MAX(E11,TIME(9,0,0)))*24)) -> 9 | I11: =MAX(0,(MOD(F11-E11,1)*24)-H11) -> 5.9833333 | J11: =IF(B11="الجمعة",MOD(F11-E11,1)*24,0) -> 0 | K11: =(H11*G11)+(I11*G11*1.5)+(J11*G11*2) -> 49718.085 | N11: =IF(B11="الجمعة",0,IF(E11>TIME(9,0,0),(E11-TIME(9,0,0))*24*60*(G11/60),0)) -> 0 | O11: =K11+L11-M11-N11 -> 49718.085
A12: 45911 | B12: =CHOOSE(WEEKDAY(A12,2),"الاثنين","الثلاثاء","الأربعاء","الخميس","الجمعة","السبت","الأحد") -> الخميس | C12: حيدر مضر | D12: 650000 | E12: 0.375 | F12: 0.99930556 | G12: =D12/235 -> 2765.9574 | H12: =MIN(9,MAX(0,(MIN(F12,TIME(18,0,0))-MAX(E12,TIME(9,0,0)))*24)) -> 9 | I12: =MAX(0,(MOD(F12-E12,1)*24)-H12) -> 5.9833333 | J12: =IF(B12="الجمعة",MOD(F12-E12,1)*24,0) -> 0 | K12: =(H12*G12)+(I12*G12*1.5)+(J12*G12*2) -> 49718.085 | N12: =IF(B12="الجمعة",0,IF(E12>TIME(9,0,0),(E12-TIME(9,0,0))*24*60*(G12/60),0)) -> 0 | O12: =K12+L12-M12-N12 -> 49718.085
A13: 45912 | B13: =CHOOSE(WEEKDAY(A13,2),"الاثنين","الثلاثاء","الأربعاء","الخميس","الجمعة","السبت","الأحد") -> الجمعة | C13: حيدر مضر | D13: 650000 | E13: 0 | F13: 0.75 | G13: =D13/235 -> 2765.9574 | H13: =MIN(9,MAX(0,(MIN(F13,TIME(18,0,0))-MAX(E13,TIME(9,0,0)))*24)) -> 9 | I13: 0 | J13: =IF(B13="الجمعة",MOD(F13-E13,1)*24,0) -> 18 | K13: =(J13*G13*2) -> 99574.468 | N13: =IF(B13="الجمعة",0,IF(E13>TIME(9,0,0),(E13-TIME(9,0,0))*24*60*(G13/60),0)) -> 0 | O13: =K13+L13-M13-N13 -> 99574.468
A14: 45913 | B14: =CHOOSE(WEEKDAY(A14,2),"الاثنين","الثلاثاء","الأربعاء","الخميس","الجمعة","السبت","الأحد") -> السبت | C14: حيدر مضر | G14: =D14/235 -> 0 | H14: 0 | I14: =MAX(0,(MOD(F14-E14,1)*24)-H14) -> 0 | J14: =IF(B14="الجمعة",MOD(F14-E14,1)*24,0) -> 0 | K14: =(H14*G14)+(I14*G14*1.5)+(J14*G14*2) -> 0 | N14: =IF(B14="الجمعة",0,IF(E14>TIME(9,0,0),(E14-TIME(9,0,0))*24*60*(G14/60),0)) -> 0 | O14: =K14+L14-M14-N14 -> 0
A15: 45914 | B15: =CHOOSE(WEEKDAY(A15,2),"الاثنين","الثلاثاء","الأربعاء","الخميس","الجمعة","السبت","الأحد") -> الأحد | C15: حيدر مضر | D15: 650000 | E15: 0.39236111 | F15: 0.77430556 | G15: =D15/235 -> 2765.9574 | H15: =MIN(9,MAX(0,(MIN(F15,TIME(18,0,0))-MAX(E15,TIME(9,0,0)))*24)) -> 8.5833333 | I15: =MAX(0,(MOD(F15-E15,1)*24)-H15) -> 0.58333333 | J15: =IF(B15="الجمعة",MOD(F15-E15,1)*24,0) -> 0 | K15: =(H15*G15)+(I15*G15*1.5)+(J15*G15*2) -> 26161.348 | N15: =IF(B15="الجمعة",0,IF(E15>TIME(9,0,0),(E15-TIME(9,0,0))*24*60*(G15/60),0)) -> 1152.4823 | O15: =K15+L15-M15-N15 -> 25008.865
A16: 45915 | B16: =CHOOSE(WEEKDAY(A16,2),"الاثنين","الثلاثاء","الأربعاء","الخميس","الجمعة","السبت","الأحد") -> الاثنين | C16: حيدر مضر | D16: 650000 | E16: 0.46180556 | F16: 0.83125 | G16: =D16/235 -> 2765.9574 | H16: =MIN(9,MAX(0,(MIN(F16,TIME(18,0,0))-MAX(E16,TIME(9,0,0)))*24)) -> 6.9166667 | I16: =MAX(0,(MOD(F16-E16,1)*24)-H16) -> 1.95 | J16: =IF(B16="الجمعة",MOD(F16-E16,1)*24,0) -> 0 | K16: =(H16*G16)+(I16*G16*1.5)+(J16*G16*2) -> 27221.631 | N16: =IF(B16="الجمعة",0,IF(E16>TIME(9,0,0),(E16-TIME(9,0,0))*24*60*(G16/60),0)) -> 5762.4113 | O16: =K16+L16-M16-N16 -> 21459.22
A17: 45916 | B17: =CHOOSE(WEEKDAY(A17,2),"الاثنين","الثلاثاء","الأربعاء","الخميس","الجمعة","السبت","الأحد") -> الثلاثاء | C17: حيدر مضر | D17: 650000 | E17: 0.375 | F17: 0.875 | G17: =D17/235 -> 2765.9574 | H17: =MIN(9,MAX(0,(MIN(F17,TIME(18,0,0))-MAX(E17,TIME(9,0,0)))*24)) -> 9 | I17: =MAX(0,(MOD(F17-E17,1)*24)-H17) -> 3 | J17: =IF(B17="الجمعة",MOD(F17-E17,1)*24,0) -> 0 | K17: =(H17*G17)+(I17*G17*1.5)+(J17*G17*2) -> 37340.426 | N17: =IF(B17="الجمعة",0,IF(E17>TIME(9,0,0),(E17-TIME(9,0,0))*24*60*(G17/60),0)) -> 0 | O17: =K17+L17-M17-N17 -> 37340.426
A18: 45917 | B18: =CHOOSE(WEEKDAY(A18,2),"الاثنين","الثلاثاء","الأربعاء","الخميس","الجمعة","السبت","الأحد") -> الأربعاء | C18: حيدر مضر | D18: 650000 | E18: 0.37222222 | F18: 0.78541667 | G18: =D18/235 -> 2765.9574 | H18: =MIN(9,MAX(0,(MIN(F18,TIME(18,0,0))-MAX(E18,TIME(9,0,0)))*24)) -> 9 | I18: =MAX(0,(MOD(F18-E18,1)*24)-H18) -> 0.91666667 | J18: =IF(B18="الجمعة",MOD(F18-E18,1)*24,0) -> 0 | K18: =(H18*G18)+(I18*G18*1.5)+(J18*G18*2) -> 28696.809 | N18: =IF(B18="الجمعة",0,IF(E18>TIME(9,0,0),(E18-TIME(9,0,0))*24*60*(G18/60),0)) -> 0 | O18: =K18+L18-M18-N18 -> 28696.809
A19: 45918 | B19: =CHOOSE(WEEKDAY(A19,2),"الاثنين","الثلاثاء","الأربعاء","الخميس","الجمعة","السبت","الأحد") -> الخميس | C19: حيدر مضر | D19: 650000 | E19: 0.43541667 | F19: 0.99930556 | G19: =D19/235 -> 2765.9574 | H19: =MIN(9,MAX(0,(MIN(F19,TIME(18,0,0))-MAX(E19,TIME(9,0,0)))*24)) -> 7.55 | I19: =MAX(0,(MOD(F19-E19,1)*24)-H19) -> 5.9833333 | J19: =IF(B19="الجمعة",MOD(F19-E19,1)*24,0) -> 0 | K19: =(H19*G19)+(I19*G19*1.5)+(J19*G19*2) -> 45707.447 | N19: =IF(B19="الجمعة",0,IF(E19>TIME(9,0,0),(E19-TIME(9,0,0))*24*60*(G19/60),0)) -> 4010.6383 | O19: =K19+L19-M19-N19 -> 41696.809
A20: 45919 | B20: =CHOOSE(WEEKDAY(A20,2),"الاثنين","الثلاثاء","الأربعاء","الخميس","الجمعة","السبت","الأحد") -> الجمعة | C20: حيدر مضر | D20: 650000 | E20: 0.375 | F20: 0.5 | G20: =D20/235 -> 2765.9574 | H20: =MIN(9,MAX(0,(MIN(F20,TIME(18,0,0))-MAX(E20,TIME(9,0,0)))*24)) -> 3 | I20: 0 | J20: =IF(B20="الجمعة",MOD(F20-E20,1)*24,0) -> 3 | K20: =(J20*G20*2) -> 16595.745 | N20: =IF(B20="الجمعة",0,IF(E20>TIME(9,0,0),(E20-TIME(9,0,0))*24*60*(G20/60),0)) -> 0 | O20: =K20+L20-M20-N20 -> 16595.745
A21: 45920 | B21: =CHOOSE(WEEKDAY(A21,2),"الاثنين","الثلاثاء","الأربعاء","الخميس","الجمعة","السبت","الأحد") -> السبت | C21: حيدر مضر | D21: 650000 | E21: 0.375 | F21: 0.625 | G21: =D21/235 -> 2765.9574 | H21: =MIN(9,MAX(0,(MIN(F21,TIME(18,0,0))-MAX(E21,TIME(9,0,0)))*24)) -> 6 | I21: =MAX(0,(MOD(F21-E21,1)*24)-H21) -> 0 | J21: =IF(B21="الجمعة",MOD(F21-E21,1)*24,0) -> 0 | K21: =(H21*G21)+(I21*G21*1.5)+(J21*G21*2) -> 16595.745 | N21: =IF(B21="الجمعة",0,IF(E21>TIME(9,0,0),(E21-TIME(9,0,0))*24*60*(G21/60),0)) -> 0 | O21: =K21+L21-M21-N21 -> 16595.745
A22: 45921 | B22: =CHOOSE(WEEKDAY(A22,2),"الاثنين","الثلاثاء","الأربعاء","الخميس","الجمعة","السبت","الأحد") -> الأحد | C22: حيدر مضر | G22: =D22/235 -> 0 | H22: 0 | I22: =MAX(0,(MOD(F22-E22,1)*24)-H22) -> 0 | J22: =IF(B22="الجمعة",MOD(F22-E22,1)*24,0) -> 0 | K22: =(H22*G22)+(I22*G22*1.5)+(J22*G22*2) -> 0 | N22: =IF(B22="الجمعة",0,IF(E22>TIME(9,0,0),(E22-TIME(9,0,0))*24*60*(G22/60),0)) -> 0 | O22: =K22+L22-M22-N22 -> 0
A23: 45922 | B23: =CHOOSE(WEEKDAY(A23,2),"الاثنين","الثلاثاء","الأربعاء","الخميس","الجمعة","السبت","الأحد") -> الاثنين | C23: حيدر مضر | D23: 650000 | E23: 0.53194444 | F23: 0.83333333 | G23: =D23/235 -> 2765.9574 | H23: =MIN(9,MAX(0,(MIN(F23,TIME(18,0,0))-MAX(E23,TIME(9,0,0)))*24)) -> 5.2333333 | I23: =MAX(0,(MOD(F23-E23,1)*24)-H23) -> 2 | J23: =IF(B23="الجمعة",MOD(F23-E23,1)*24,0) -> 0 | K23: =(H23*G23)+(I23*G23*1.5)+(J23*G23*2) -> 22773.05 | N23: =IF(B23="الجمعة",0,IF(E23>TIME(9,0,0),(E23-TIME(9,0,0))*24*60*(G23/60),0)) -> 10418.44 | O23: =K23+L23-M23-N23 -> 12354.61
A24: 45923 | B24: =CHOOSE(WEEKDAY(A24,2),"الاثنين","الثلاثاء","الأربعاء","الخميس","الجمعة","السبت","الأحد") -> الثلاثاء | C24: حيدر مضر | D24: 650000 | E24: 0.375 | F24: 0.75 | G24: =D24/235 -> 2765.9574 | H24: =MIN(9,MAX(0,(MIN(F24,TIME(18,0,0))-MAX(E24,TIME(9,0,0)))*24)) -> 9 | I24: =MAX(0,(MOD(F24-E24,1)*24)-H24) -> 0 | J24: =IF(B24="الجمعة",MOD(F24-E24,1)*24,0) -> 0 | K24: =(H24*G24)+(I24*G24*1.5)+(J24*G24*2) -> 24893.617 | N24: =IF(B24="الجمعة",0,IF(E24>TIME(9,0,0),(E24-TIME(9,0,0))*24*60*(G24/60),0)) -> 0 | O24: =K24+L24-M24-N24 -> 24893.617
A25: 45924 | B25: =CHOOSE(WEEKDAY(A25,2),"الاثنين","الثلاثاء","الأربعاء","الخميس","الجمعة","السبت","الأحد") -> الأربعاء | C25: حيدر مضر | D25: 650000 | E25: 0.375 | F25: 0.75 | G25: =D25/235 -> 2765.9574 | H25: =MIN(9,MAX(0,(MIN(F25,TIME(18,0,0))-MAX(E25,TIME(9,0,0)))*24)) -> 9 | I25: =MAX(0,(MOD(F25-E25,1)*24)-H25) -> 0 | J25: =IF(B25="الجمعة",MOD(F25-E25,1)*24,0) -> 0 | K25: =(H25*G25)+(I25*G25*1.5)+(J25*G25*2) -> 24893.617 | N25: =IF(B25="الجمعة",0,IF(E25>TIME(9,0,0),(E25-TIME(9,0,0))*24*60*(G25/60),0)) -> 0 | O25: =K25+L25-M25-N25 -> 24893.617
A26: 45925 | B26: =CHOOSE(WEEKDAY(A26,2),"الاثنين","الثلاثاء","الأربعاء","الخميس","الجمعة","السبت","الأحد") -> الخميس | C26: حيدر مضر | D26: 650000 | E26: 0.41041667 | F26: 0.75 | G26: =D26/235 -> 2765.9574 | H26: =MIN(9,MAX(0,(MIN(F26,TIME(18,0,0))-MAX(E26,TIME(9,0,0)))*24)) -> 8.15 | I26: =MAX(0,(MOD(F26-E26,1)*24)-H26) -> 0 | J26: =IF(B26="الجمعة",MOD(F26-E26,1)*24,0) -> 0 | K26: =(H26*G26)+(I26*G26*1.5)+(J26*G26*2) -> 22542.553 | N26: =IF(B26="الجمعة",0,IF(E26>TIME(9,0,0),(E26-TIME(9,0,0))*24*60*(G26/60),0)) -> 2351.0638 | O26: =K26+L26-M26-N26 -> 20191.489
A27: 45926 | B27: =CHOOSE(WEEKDAY(A27,2),"الاثنين","الثلاثاء","الأربعاء","الخميس","الجمعة","السبت","الأحد") -> الجمعة | C27: حيدر مضر | G27: =D27/235 -> 0 | H27: 0 | I27: 0 | J27: =IF(B27="الجمعة",MOD(F27-E27,1)*24,0) -> 0 | K27: =(J27*G27*2) -> 0 | N27: =IF(B27="الجمعة",0,IF(E27>TIME(9,0,0),(E27-TIME(9,0,0))*24*60*(G27/60),0)) -> 0 | O27: =K27+L27-M27-N27 -> 0
A28: 45927 | B28: =CHOOSE(WEEKDAY(A28,2),"الاثنين","الثلاثاء","الأربعاء","الخميس","الجمعة","السبت","الأحد") -> السبت | C28: حيدر مضر | D28: 650000 | E28: 0.48333333 | F28: 0.79166667 | G28: =D28/235 -> 2765.9574 | H28: =MIN(9,MAX(0,(MIN(F28,TIME(18,0,0))-MAX(E28,TIME(9,0,0)))*24)) -> 6.4 | I28: 0 | J28: =IF(B28="الجمعة",MOD(F28-E28,1)*24,0) -> 0 | K28: =(H28*G28)+(I28*G28*1.5)+(J28*G28*2) -> 17702.128 | N28: =IF(B28="الجمعة",0,IF(E28>TIME(9,0,0),(E28-TIME(9,0,0))*24*60*(G28/60),0)) -> 7191.4894 | O28: =K28+L28-M28-N28 -> 10510.638
A29: 45928 | B29: =CHOOSE(WEEKDAY(A29,2),"الاثنين","الثلاثاء","الأربعاء","الخميس","الجمعة","السبت","الأحد") -> الأحد | C29: حيدر مضر | D29: 650000 | E29: 0.375 | F29: 0.041666667 | G29: =D29/235 -> 2765.9574 | H29: =MIN(9,MAX(0,(MIN(F29,TIME(18,0,0))-MAX(E29,TIME(9,0,0)))*24)) -> 0 | I29: =MAX(0,(MOD(F29-E29,1)*24)-H29) -> 16 | J29: =IF(B29="الجمعة",MOD(F29-E29,1)*24,0) -> 0 | K29: =(H29*G29)+(I29*G29*1.5)+(J29*G29*2) -> 66382.979 | N29: =IF(B29="الجمعة",0,IF(E29>TIME(9,0,0),(E29-TIME(9,0,0))*24*60*(G29/60),0)) -> 0 | O29: =K29+L29-M29-N29 -> 66382.979
A30: 45929 | B30: =CHOOSE(WEEKDAY(A30,2),"الاثنين","الثلاثاء","الأربعاء","الخميس","الجمعة","السبت","الأحد") -> الاثنين | C30: حيدر مضر | D30: 650000 | E30: 0.54166667 | F30: 0.83333333 | G30: =D30/235 -> 2765.9574 | H30: =MIN(9,MAX(0,(MIN(F30,TIME(18,0,0))-MAX(E30,TIME(9,0,0)))*24)) -> 5 | I30: =MAX(0,(MOD(F30-E30,1)*24)-H30) -> 2 | J30: =IF(B30="الجمعة",MOD(F30-E30,1)*24,0) -> 0 | K30: =(H30*G30)+(I30*G30*1.5)+(J30*G30*2) -> 22127.66 | N30: =IF(B30="الجمعة",0,IF(E30>TIME(9,0,0),(E30-TIME(9,0,0))*24*60*(G30/60),0)) -> 11063.83 | O30: =K30+L30-M30-N30 -> 11063.83
A31: 45930 | B31: =CHOOSE(WEEKDAY(A31,2),"الاثنين","الثلاثاء","الأربعاء","الخميس","الجمعة","السبت","الأحد") -> الثلاثاء | C31: حيدر مضر | D31: 650000 | E31: 0.375 | F31: 0.79166667 | G31: =D31/235 -> 2765.9574 | H31: =MIN(9,MAX(0,(MIN(F31,TIME(18,0,0))-MAX(E31,TIME(9,0,0)))*24)) -> 9 | I31: =MAX(0,(MOD(F31-E31,1)*24)-H31) -> 1 | J31: =IF(B31="الجمعة",MOD(F31-E31,1)*24,0) -> 0 | K31: =(H31*G31)+(I31*G31*1.5)+(J31*G31*2) -> 29042.553 | N31: =IF(B31="الجمعة",0,IF(E31>TIME(9,0,0),(E31-TIME(9,0,0))*24*60*(G31/60),0)) -> 0 | O31: =K31+L31-M31-N31 -> 29042.553
A32: 45901 | B32: =CHOOSE(WEEKDAY(A32,2),"الاثنين","الثلاثاء","الأربعاء","الخميس","الجمعة","السبت","الأحد") -> الاثنين | C32: عبدالرضا عقيل | D32: 700000 | E32: 0.39305556 | F32: 0.75 | G32: =D32/235 -> 2978.7234 | H32: =MIN(9,MAX(0,(MIN(F32,TIME(18,0,0))-MAX(E32,TIME(9,0,0)))*24)) -> 8.5666667 | I32: =MAX(0,(MOD(F32-E32,1)*24)-H32) -> 0 | J32: =IF(B32="الجمعة",MOD(F32-E32,1)*24,0) -> 0 | K32: =(H32*G32)+(I32*G32*1.5)+(J32*G32*2) -> 25517.731 | M32: 50000 | N32: =IF(B32="الجمعة",0,IF(E32>TIME(9,0,0),(E32-TIME(9,0,0))*24*60*(G32/60),0)) -> 1290.7801 | O32: =K32+L32-M32-N32 -> -25773.05 | P32: 285000 دين من الشهر السابق باقي 235000
A33: 45902 | B33: =CHOOSE(WEEKDAY(A33,2),"الاثنين","الثلاثاء","الأربعاء","الخميس","الجمعة","السبت","الأحد") -> الثلاثاء | C33: عبدالرضا عقيل | D33: 700000 | E33: 0.26041667 | F33: 0.57152778 | G33: =D33/235 -> 2978.7234 | H33: =MIN(9,MAX(0,(MIN(F33,TIME(18,0,0))-MAX(E33,TIME(9,0,0)))*24)) -> 4.7166667 | I33: =MAX(0,(MOD(F33-E33,1)*24)-H33) -> 2.75 | J33: =IF(B33="الجمعة",MOD(F33-E33,1)*24,0) -> 0 | K33: =(H33*G33)+(I33*G33*1.5)+(J33*G33*2) -> 26336.879 | N33: =IF(B33="الجمعة",0,IF(E33>TIME(9,0,0),(E33-TIME(9,0,0))*24*60*(G33/60),0)) -> 0 | O33: =K33+L33-M33-N33 -> 26336.879
A34: 45903 | B34: =CHOOSE(WEEKDAY(A34,2),"الاثنين","الثلاثاء","الأربعاء","الخميس","الجمعة","السبت","الأحد") -> الأربعاء | C34: عبدالرضا عقيل | D34: 700000 | E34: 0.36736111 | F34: 0.89861111 | G34: =D34/235 -> 2978.7234 | H34: =MIN(9,MAX(0,(MIN(F34,TIME(18,0,0))-MAX(E34,TIME(9,0,0)))*24)) -> 9 | I34: =MAX(0,(MOD(F34-E34,1)*24)-H34) -> 3.75 | J34: =IF(B34="الجمعة",MOD(F34-E34,1)*24,0) -> 0 | K34: =(H34*G34)+(I34*G34*1.5)+(J34*G34*2) -> 43563.83 | N34: =IF(B34="الجمعة",0,IF(E34>TIME(9,0,0),(E34-TIME(9,0,0))*24*60*(G34/60),0)) -> 0 | O34: =K34+L34-M34-N34 -> 43563.83
A35: 45904 | B35: =CHOOSE(WEEKDAY(A35,2),"الاثنين","الثلاثاء","الأربعاء","الخميس","الجمعة","السبت","الأحد") -> الخميس | C35: عبدالرضا عقيل | D35: 700000 | E35: 0.375 | F35: 0.89583333 | G35: =D35/235 -> 2978.7234 | H35: =MIN(9,MAX(0,(MIN(F35,TIME(18,0,0))-MAX(E35,TIME(9,0,0)))*24)) -> 9 | I35: =MAX(0,(MOD(F35-E35,1)*24)-H35) -> 3.5 | J35: =IF(B35="الجمعة",MOD(F35-E35,1)*24,0) -> 0 | K35: =(H35*G35)+(I35*G35*1.5)+(J35*G35*2) -> 42446.809 | N35: =IF(B35="الجمعة",0,IF(E35>TIME(9,0,0),(E35-TIME(9,0,0))*24*60*(G35/60),0)) -> 0 | O35: =K35+L35-M35-N35 -> 42446.809
A36: 45905 | B36: =CHOOSE(WEEKDAY(A36,2),"الاثنين","الثلاثاء","الأربعاء","الخميس","الجمعة","السبت","الأحد") -> الجمعة | C36: عبدالرضا عقيل | D36: 700000 | E36: 0.46666667 | F36: 0.97916667 | G36: =D36/235 -> 2978.7234 | H36: =MIN(9,MAX(0,(MIN(F36,TIME(18,0,0))-MAX(E36,TIME(9,0,0)))*24)) -> 6.8 | I36: 0 | J36: =IF(B36="الجمعة",MOD(F36-E36,1)*24,0) -> 12.3 | K36: =(J36*G36*2) -> 73276.596 | N36: =IF(B36="الجمعة",0,IF(E36>TIME(9,0,0),(E36-TIME(9,0,0))*24*60*(G36/60),0)) -> 0 | O36: =K36+L36-M36-N36 -> 73276.596
A37: 45906 | B37: =CHOOSE(WEEKDAY(A37,2),"الاثنين","الثلاثاء","الأربعاء","الخميس","الجمعة","السبت","الأحد") -> السبت | C37: عبدالرضا عقيل | D37: 700000 | E37: 0.40486111 | F37: 0.89583333 | G37: =D37/235 -> 2978.7234 | H37: =MIN(9,MAX(0,(MIN(F37,TIME(18,0,0))-MAX(E37,TIME(9,0,0)))*24)) -> 8.2833333 | I37: =MAX(0,(MOD(F37-E37,1)*24)-H37) -> 3.5 | J37: =IF(B37="الجمعة",MOD(F37-E37,1)*24,0) -> 0 | K37: =(H37*G37)+(I37*G37*1.5)+(J37*G37*2) -> 40312.057 | N37: =IF(B37="الجمعة",0,IF(E37>TIME(9,0,0),(E37-TIME(9,0,0))*24*60*(G37/60),0)) -> 2134.7518 | O37: =K37+L37-M37-N37 -> 38177.305
A38: 45907 | B38: =CHOOSE(WEEKDAY(A38,2),"الاثنين","الثلاثاء","الأربعاء","الخميس","الجمعة","السبت","الأحد") -> الأحد | C38: عبدالرضا عقيل | D38: 700000 | E38: 0.40347222 | F38: 0.91666667 | G38: =D38/235 -> 2978.7234 | H38: =MIN(9,MAX(0,(MIN(F38,TIME(18,0,0))-MAX(E38,TIME(9,0,0)))*24)) -> 8.3166667 | I38: =MAX(0,(MOD(F38-E38,1)*24)-H38) -> 4 | J38: =IF(B38="الجمعة",MOD(F38-E38,1)*24,0) -> 0 | K38: =(H38*G38)+(I38*G38*1.5)+(J38*G38*2) -> 42645.39 | N38: =IF(B38="الجمعة",0,IF(E38>TIME(9,0,0),(E38-TIME(9,0,0))*24*60*(G38/60),0)) -> 2035.461 | O38: =K38+L38-M38-N38 -> 40609.929
A39: 45908 | B39: =CHOOSE(WEEKDAY(A39,2),"الاثنين","الثلاثاء","الأربعاء","الخميس","الجمعة","السبت","الأحد") -> الاثنين | C39: عبدالرضا عقيل | D39: 700000 | E39: 0.39097222 | F39: 0.99930556 | G39: =D39/235 -> 2978.7234 | H39: =MIN(9,MAX(0,(MIN(F39,TIME(18,0,0))-MAX(E39,TIME(9,0,0)))*24)) -> 8.6166667 | I39: =MAX(0,(MOD(F39-E39,1)*24)-H39) -> 5.9833333 | J39: =IF(B39="الجمعة",MOD(F39-E39,1)*24,0) -> 0 | K39: =(H39*G39)+(I39*G39*1.5)+(J39*G39*2) -> 52400.709 | N39: =IF(B39="الجمعة",0,IF(E39>TIME(9,0,0),(E39-TIME(9,0,0))*24*60*(G39/60),0)) -> 1141.844 | O39: =K39+L39-M39-N39 -> 51258.865
A40: 45909 | B40: =CHOOSE(WEEKDAY(A40,2),"الاثنين","الثلاثاء","الأربعاء","الخميس","الجمعة","السبت","الأحد") -> الثلاثاء | C40: عبدالرضا عقيل | D40: 700000 | E40: 0.375 | F40: 0.77430556 | G40: =D40/235 -> 2978.7234 | H40: =MIN(9,MAX(0,(MIN(F40,TIME(18,0,0))-MAX(E40,TIME(9,0,0)))*24)) -> 9 | I40: =MAX(0,(MOD(F40-E40,1)*24)-H40) -> 0.58333333 | J40: =IF(B40="الجمعة",MOD(F40-E40,1)*24,0) -> 0 | K40: =(H40*G40)+(I40*G40*1.5)+(J40*G40*2) -> 29414.894 | N40: =IF(B40="الجمعة",0,IF(E40>TIME(9,0,0),(E40-TIME(9,0,0))*24*60*(G40/60),0)) -> 0 | O40: =K40+L40-M40-N40 -> 29414.894
...

Sheet Income
C1: =COUNTIF(C3:C908,"=نقد") -> 833 | E1: =COUNTIF(E3:E908,"=الابرار") -> 0 | G1: =SUM(G3:G908) -> 341716500 | H1: =SUM(H3:H908) -> 1872250 | I1: =G1-H1 -> 339844250 | J1: =SUM(J3:J908) -> 333447500 | K1: =SUM(K3:K908) -> 6396750
A2: رقم الوصل | B2: التاريخ | C2: النوع | D2: الاسم | E2: الوصف / البند | F2: الكمية | G2: المجموع | H2: الخصم | I2: الاجمالي | J2: المستلم | K2: المتبقي | L2: الملاحظات | M2: Column 13
A3: wx1 | B3: 45658 | C3: نقد | D3: حسين | E3: بوكس حلقات | F3: 1 | G3: 120000 | H3: 0 | I3: =G3-H3 -> 120000 | J3: 120000 | K3: =IFERROR(G3-H3-J3,0) -> 0
A4: wx2 | B4: 45658 | C4: نقد | D4: حسين | E4: بورد بصمات | F4: 1 | G4: 35000 | H4: 0 | I4: =G4-H4 -> 35000 | J4: 35000 | K4: =IFERROR(G4-H4-J4,0) -> 0
A5: wx3 | B5: 45658 | C5: نقد | D5: حسين | E5: لوح فوم | F5: 1 | G5: 62000 | H5: 0 | I5: =G5-H5 -> 62000 | J5: 62000 | K5: =IFERROR(G5-H5-J5,0) -> 0
A6: 000/42 | B6: 45658 | C6: نقد | D6: حسين | E6: بوكس فوم عدد2 | F6: 1 | G6: 45000 | H6: 0 | I6: =G6-H6 -> 45000 | J6: 45000 | K6: =IFERROR(G6-H6-J6,0) -> 0 | L6: 19798000
A7: wx4 | B7: 45658 | C7: نقد | D7: حسين | E7: شريط مسكة | F7: 1 | G7: 5000 | H7: 0 | I7: =G7-H7 -> 5000 | J7: 5000 | K7: =IFERROR(G7-H7-J7,0) -> 0 | L7: =L8-L6 -> 2866000
A8: wx6 | B8: 45659 | C8: نقد | D8: الورشة | E8: كتابة اكريلك ذهبي | F8: 1 | G8: 15000 | H8: 0 | I8: =G8-H8 -> 15000 | J8: 15000 | K8: =IFERROR(G8-H8-J8,0) -> 0 | L8: 22664000
A9: wx7 | B9: 45659 | C9: نقد | D9: حسين | E9: كوشة منتظر | F9: 1 | G9: 550000 | H9: 0 | I9: =G9-H9 -> 550000 | J9: 550000 | K9: =IFERROR(G9-H9-J9,0) -> 0
A10: 954716 | B10: 45659 | C10: نقد | D10: حسين | E10: بوكس حلقات مع قاعدة | F10: 1 | G10: 160000 | H10: 0 | I10: =G10-H10 -> 160000 | J10: 160000 | K10: =IFERROR(G10-H10-J10,0) -> 0
A11: 939288 | B11: 45660 | C11: نقد | D11: حسين | E11: تعاليق | F11: 1 | G11: 30000 | H11: 0 | I11: =G11-H11 -> 30000 | J11: 30000 | K11: =IFERROR(G11-H11-J11,0) -> 0
A12: wx8 | B12: 45661 | C12: نقد | D12: الورشة | E12: وائل خطاط | F12: 1 | G12: 7000 | H12: 0 | I12: =G12-H12 -> 7000 | J12: 7000 | K12: =IFERROR(G12-H12-J12,0) -> 0
A13: wx9 | B13: 45661 | C13: نقد | D13: الورشة | E13: استلام دين عن اعلان | F13: 1 | G13: 1535000 | H13: 0 | I13: =G13-H13 -> 1535000 | J13: 1535000 | K13: =IFERROR(G13-H13-J13,0) -> 0
A14: 984645 | B14: 45662 | C14: نقد | D14: حسين | E14: بوكس ذهب | F14: 1 | G14: 145000 | H14: 0 | I14: =G14-H14 -> 145000 | J14: 145000 | K14: =IFERROR(G14-H14-J14,0) -> 0
A15: 000/63 | B15: 45662 | C15: نقد | D15: حسين | E15: مبخرة | F15: 1 | G15: 35000 | H15: 0 | I15: =G15-H15 -> 35000 | J15: 35000 | K15: =IFERROR(G15-H15-J15,0) -> 0
A16: 000/84 | B16: 45662 | C16: نقد | D16: الورشة | E16: لوحة مكتبية | F16: 1 | G16: 25000 | H16: 0 | I16: =G16-H16 -> 25000 | J16: 25000 | K16: =IFERROR(G16-H16-J16,0) -> 0
A17: wx10 | B17: 45663 | C17: نقد | D17: المالك | E17: 23 قطعة اكرلك | F17: 1 | G17: 380000 | H17: 0 | I17: =G17-H17 -> 380000 | J17: 380000 | K17: =IFERROR(G17-H17-J17,0) -> 0
A18: 000/63 | B18: 45663 | C18: نقد | D18: حسين | E18: مبخرة | F18: 1 | G18: 60000 | H18: 0 | I18: =G18-H18 -> 60000 | J18: 60000 | K18: =IFERROR(G18-H18-J18,0) -> 0
A19: 000/75 | B19: 45663 | C19: نقد | D19: حسين | E19: بورد بصمات | F19: 1 | G19: 30000 | H19: 0 | I19: =G19-H19 -> 30000 | J19: 30000 | K19: =IFERROR(G19-H19-J19,0) -> 0
A20: 000/64 | B20: 45663 | C20: نقد | D20: حسين | E20: مكتبيه | F20: 1 | G20: 75000 | H20: 0 | I20: =G20-H20 -> 75000 | J20: 75000 | K20: =IFERROR(G20-H20-J20,0) -> 0
A21: 000/82 | B21: 45663 | C21: نقد | D21: الورشة | E21: علامات دلالة | F21: 1 | G21: 200000 | H21: 0 | I21: =G21-H21 -> 200000 | J21: 200000 | K21: =IFERROR(G21-H21-J21,0) -> 0
A22: 000/83 | B22: 45663 | C22: نقد | D22: حسين | E22: لوغو كوزمتك | F22: 1 | G22: 60000 | H22: 0 | I22: =G22-H22 -> 60000 | J22: 60000 | K22: =IFERROR(G22-H22-J22,0) -> 0
A23: wx11 | B23: 45664 | C23: ديون | D23: حسين | E23: شريط ورد | F23: 1 | G23: 5000 | H23: 0 | I23: =G23-H23 -> 5000 | J23: 0 | K23: =IFERROR(G23-H23-J23,0) -> 5000
A24: 784646 | B24: 45664 | C24: نقد | D24: حسين | E24: بوكس ذهب | F24: 1 | G24: 70000 | H24: 0 | I24: =G24-H24 -> 70000 | J24: 70000 | K24: =IFERROR(G24-H24-J24,0) -> 0
A25: 784644 | B25: 45664 | C25: نقد | D25: حسين | E25: بوكس حلقات | F25: 1 | G25: 60000 | H25: 0 | I25: =G25-H25 -> 60000 | J25: 60000 | K25: =IFERROR(G25-H25-J25,0) -> 0
A26: 784644 | B26: 45664 | C26: نقد | D26: حسين | E26: بورد بصمات | F26: 1 | G26: 30000 | H26: 0 | I26: =G26-H26 -> 30000 | J26: 30000 | K26: =IFERROR(G26-H26-J26,0) -> 0
A27: wx12 | B27: 45664 | C27: نقد | D27: حسين | E27: حلقات اكريليك ذهبي | F27: 1 | G27: 7000 | H27: 0 | I27: =G27-H27 -> 7000 | J27: 7000 | K27: =IFERROR(G27-H27-J27,0) -> 0
A28: 000/66 | B28: 45664 | C28: نقد | D28: حسين | E28: مبخرة مع علبة بخور | F28: 1 | G28: 75000 | H28: 0 | I28: =G28-H28 -> 75000 | J28: 75000 | K28: =IFERROR(G28-H28-J28,0) -> 0
A29: 000/65 | B29: 45664 | C29: نقد | D29: حسين | E29: فوم جداري | F29: 1 | G29: 50000 | H29: 0 | I29: =G29-H29 -> 50000 | J29: 50000 | K29: =IFERROR(G29-H29-J29,0) -> 0
A30: 000/69 | B30: 45664 | C30: نقد | D30: حسين | E30: بوكس مهر | F30: 1 | G30: 300000 | H30: 0 | I30: =G30-H30 -> 300000 | J30: 300000 | K30: =IFERROR(G30-H30-J30,0) -> 0
A31: wx13 | B31: 45664 | C31: نقد | D31: الورشة | E31: اعلان | F31: 1 | G31: 550000 | H31: 0 | I31: =G31-H31 -> 550000 | J31: 550000 | K31: =IFERROR(G31-H31-J31,0) -> 0
A32: 784642 | B32: 45664 | C32: نقد | D32: حسين | E32: بوكس حلقات | F32: 1 | G32: 50000 | H32: 0 | I32: =G32-H32 -> 50000 | J32: 50000 | K32: =IFERROR(G32-H32-J32,0) -> 0
A33: 784644 | B33: 45664 | C33: نقد | D33: حسين | E33: بورد بصمات | F33: 1 | G33: 35000 | H33: 0 | I33: =G33-H33 -> 35000 | J33: 35000 | K33: =IFERROR(G33-H33-J33,0) -> 0
A34: 000/68 | B34: 45665 | C34: جزئي | D34: حسين | E34: احرف علب بخور | F34: 1 | G34: 25000 | H34: 0 | I34: =G34-H34 -> 25000 | J34: 15000 | K34: =IFERROR(G34-H34-J34,0) -> 10000
A35: 000/76 | B35: 45665 | C35: نقد | D35: حسين | E35: بوكس فلوس | F35: 1 | G35: 65000 | H35: 0 | I35: =G35-H35 -> 65000 | J35: 65000 | K35: =IFERROR(G35-H35-J35,0) -> 0
A36: 000/68 | B36: 45665 | C36: نقد | D36: حسين | E36: اسماء كوشه | F36: 1 | G36: 25000 | H36: 0 | I36: =G36-H36 -> 25000 | J36: 25000 | K36: =IFERROR(G36-H36-J36,0) -> 0
A37: 000/72 | B37: 45665 | C37: نقد | D37: الورشة | E37: 4 بوكسات | F37: 1 | G37: 60000 | H37: 0 | I37: =G37-H37 -> 60000 | J37: 60000 | K37: =IFERROR(G37-H37-J37,0) -> 0
A38: 000/71 | B38: 45665 | C38: نقد | D38: حسين | E38: بوكس فارغ | F38: 1 | G38: 20000 | H38: 0 | I38: =G38-H38 -> 20000 | J38: 20000 | K38: =IFERROR(G38-H38-J38,0) -> 0
A39: 000/59 | B39: 45665 | C39: نقد | D39: الورشة | E39: اعلان cnc | F39: 1 | G39: 1425000 | H39: 0 | I39: =G39-H39 -> 1425000 | J39: 1425000 | K39: =IFERROR(G39-H39-J39,0) -> 0
A40: 000/60 | B40: 45665 | C40: نقد | D40: الورشة | E40: كوبون cnc | F40: 1 | G40: 10000 | H40: 0 | I40: =G40-H40 -> 10000 | J40: 10000 | K40: =IFERROR(G40-H40-J40,0) -> 0
...

Sheet Archive
A1: رقم الوصل | B1: التاريخ | C1: النوع | D1: الاسم | E1: الوصف / البند | F1: الكمية | G1: المجموع | H1: الخصم | I1: الاجمالي | J1: المستلم / المدفوع | K1: المتبقي | L1: الملاحظات
A2: 5001 | B2: 45973 | C2: شراء | D2: محل جينكو | E2: جينكو | F2: 7 || 1 | G2: 176000 | H2: 1000 | I2: 175000 | J2: 175000 | K2: 0
A3: 5002 | B3: 45973 | C3: شراء | D3: حسين سعد | E3: جرخ كوسرة | F3: 6 || 2 | G3: 14000 | H3: 0 | I3: 14000 | J3: 14000 | K3: 0
A4: 37349 | B4: 45966 | C4: شراء | D4: الخوره | E4: كلوروفوم | F4: 1 || 3 || 1 | G4: 50000 | H4: 0 | I4: 50000 | J4: 50000 | K4: 0
A5: 5003 | B5: 45973 | C5: شراء | D5: سيف عدنان | E5: لفة دبل | F5: 1 || 1 | G5: 3000 | H5: 0 | I5: 3500 | J5: 3500 | K5: 0
A6: 5004 | B6: 45973 | C6: شراء | D6: سرالج | E6: سلكون صوصج | F6: 1 | G6: 50000 | H6: 0 | I6: 50000 | J6: 50000 | K6: 0
A7: 1001 | B7: 45970 | C7: بيع | D7: يوسف يعقوب | E7: احرف لدائن | F7: 36 | G7: 36000 | H7: 0 | I7: 36000 | J7: 0 | K7: 0
A8: 1002 | B8: 45976 | C8: بيع | D8: سراج | E8: عارضة عطور فوم علاى شكل مدرج | F8: 6 | G8: 100500 | H8: 0 | I8: 90000 | J8: 0 | K8: 0
A9: 2933 | B9: 45965 | C9: شراء | D9: معرض الابرار | E9: بلاستك برتقالي بلاستك بنفسجي لد شمسي | F9: 1 || 1 || 8 | G9: 178000 | H9: 0 | I9: 178000 | J9: 0 | K9: 178000
A10: 2938 | B10: 45965 | C10: شراء | D10: معرض الابرار | E10: لد شريط 8 ملم ابيض | F10: 8 | G10: 88000 | H10: 0 | I10: 88000 | J10: 0 | K10: 88000
A11: 2866 | B11: 45966 | C11: شراء | D11: معرض الابرار | E11: بلاستك + اجر ة | F11: 1 || 1 || 1 | G11: 120000 | H11: 0 | I11: 120000 | J11: 0 | K11: 120000
C12: شراء

Sheet Form
A1: البيع | E1: الشراء
I2: العمل الاسطوري الذي اممامك هو خارج قدرات العقل البشري فلا تحاول صنع شئ مشابه لانك و بكل بساطة لاتستطيع
A3: رقم الوصل | C3: الورشة للطباعة و لكافة انواع الاعلانات الضوئية و اعمال الديكور الداخلي و الخارجي | E3: رقم الوصل | G3: الورشة للطباعة و لكافة انواع الاعلانات الضوئية و اعمال الديكور الداخلي و الخارجي
A4: التأريخ | E4: التأريخ
A5: الاسم | E5: الاسم
I6: بيع | J6: شراء
C7: 10000 | D7: =B7*C7 -> 0 | G7: 23000 | I7: =B7*D7 -> 0 | J7: =F7*G7 -> 0
D8: =B8*C8 -> 0 | G8: 14000 | I8: =B8*D8 -> 0 | J8: =F8*G8 -> 0
D9: =B9*C9 -> 0 | I9: =B9*D9 -> 0 | J9: =F9*G9 -> 0
D10: =B10*C10 -> 0 | I10: =B10*D10 -> 0 | J10: =F10*G10 -> 0
D11: =B11*C11 -> 0 | I11: =B11*D11 -> 0 | J11: =F11*G11 -> 0
D12: =B12*C12 -> 0 | I12: =B12*D12 -> 0 | J12: =F12*G12 -> 0
D13: =B13*C13 -> 0 | I13: =B13*D13 -> 0 | J13: =F13*G13 -> 0
D14: =B14*C14 -> 0 | I14: =B14*D14 -> 0 | J14: =F14*G14 -> 0
D15: =B15*C15 -> 0 | I15: =B15*D15 -> 0 | J15: =F15*G15 -> 0
D16: =B16*C16 -> 0 | I16: =B16*D16 -> 0 | J16: =F16*G16 -> 0
D17: =B17*C17 -> 0 | I17: =B17*D17 -> 0 | J17: =F17*G17 -> 0
D18: =B18*C18 -> 0 | I18: =B18*D18 -> 0 | J18: =F18*G18 -> 0
A19: المجموع | C19: =sum(D7:D18) -> 0 | E19: المجموع | F19: 175000 | G19: =sum(J7:J18) -> 0 | I19: بعد كتابة تفاصيل الوصل تأخذ المجاميع من الخانات المقابلة لها يتم نسخها ووضعها في مكانها
A20: الخصم | B20: 500 | E20: الخصم | G20: 0
A21: الاجمالي | C21: =C19-B20 -> -500 | E21: الاجمالي | F21: =G19-F20 -> 0 | G21: =F19-F20 -> 175000 | I21: بعد اضغط على الدالة البرمجية للبيع او للشراء تذهب المعلومات تلقائيا الى الارشيف والايرادات اذا كان بيع و المصروفات اذا كان شراء
A22: المستلم | B22: 17000 | E22: المدفوع
A23: المتبقي | C23: =C21-B22 -> -17500 | E23: المتبقي | G23: =G21-F22 -> 175000 | I23: تحتاج الدالة الموافقة من داخل الحساب المربوط بالجدول لكي تعمل بشكل صحيح
A24: الملاحظات | E24: الملاحظات

Sheet Expense
E1: =#REF! -> #REF! | G1: =SUM(جدول_6[المجموع]) -> 206850085 | H1: =sum(H4:H1430) -> 0 | I1: =SUM(I4:I1430) -> 206849085 | J1: =SUM(J4:J1430) -> 204777085 | K1: =sum(K4:K1430) -> 2073000
A2: رقم الوصل | B2: التاريخ | C2: النوع | D2: الاسم | E2: الوصف / البند | F2: الكية | G2: المجموع | H2: الخصم | I2: الاجمالي | J2: المدفوع | K2: المتبقي | L2: الملاحظات | M2: Column 13 | N2: Column 14
A4: 644 | B4: 45659 | C4: تكاليف تطوير | D4: المكتب | E4: صحيات | G4: 84000 | H4: 0 | I4: 84000 | J4: 84000 | K4: =IFERROR(G4-H4-J4,0) -> 0
B5: 45659 | C5: استهلاكيات ورشة | D5: الورشة | E5: شراء كفوف وكمامات | G5: 20000 | H5: 0 | I5: 20000 | J5: 20000 | K5: =IFERROR(G5-H5-J5,0) -> 0
B6: 45659 | C6: استهلاكيات ورشة | D6: الورشة | E6: كهربائيات | G6: 20000 | H6: 0 | I6: 20000 | J6: 20000 | K6: =IFERROR(G6-H6-J6,0) -> 0
B7: 45659 | C7: رصيد | D7: الورشة | E7: طرقات ورصيد | G7: 15000 | H7: 0 | I7: 15000 | J7: 15000 | K7: =IFERROR(G7-H7-J7,0) -> 0
B8: 45661 | C8: المواد الخام | D8: الورشة | E8: شراء اقمشة | G8: 50000 | H8: 0 | I8: 50000 | J8: 50000 | K8: =IFERROR(G8-H8-J8,0) -> 0
A9: 12٬224 | B9: 45661 | C9: عدة يدوية | D9: الورشة | E9: مكص قماش ومستلزمات تعليب | G9: 26000 | H9: 0 | I9: 26000 | J9: 26000 | K9: =IFERROR(G9-H9-J9,0) -> 0
B10: 45662 | C10: استهلاكيات ورشة | D10: الورشة | E10: شراء كهربائيات | G10: 30000 | H10: 0 | I10: 30000 | J10: 30000 | K10: =IFERROR(G10-H10-J10,0) -> 0
A11: 32327 وصل قبض الورشة | B11: 45663 | C11: خشب MDF | D11: الورشة | E11: تسديد حساب قديم ( صفاء ) | G11: 765000 | H11: 0 | I11: 765000 | J11: 765000 | K11: =IFERROR(G11-H11-J11,0) -> 0
B12: 45663 | C12: خدمات | D12: الورشة | E12: شراء معدات ولواصق | G12: 45000 | H12: 0 | I12: 45000 | J12: 45000 | K12: =IFERROR(G12-H12-J12,0) -> 0
B13: 45663 | C13: المواد الخام | D13: الورشة | E13: شراء عدد يدوية + مواد للصحيات | G13: 40000 | H13: 0 | I13: 40000 | J13: 40000 | K13: =IFERROR(G13-H13-J13,0) -> 0
B14: 45663 | C14: عدة يدوية | D14: الورشة | E14: عدة حدادة يوسف | G14: 40000 | H14: 0 | I14: 40000 | J14: 40000 | K14: =IFERROR(G14-H14-J14,0) -> 0
B15: 45663 | C15: خدمات | D15: الورشة | E15: نقليات (تكسي توصيل طلبيات) | G15: 11000 | H15: 0 | I15: 11000 | J15: 11000 | K15: =IFERROR(G15-H15-J15,0) -> 0
A16: 3٬562 | B16: 45664 | C16: المواد الخام | D16: الورشة | E16: الابرار | G16: 192000 | H16: 0 | I16: 192000 | J16: 192000 | K16: =IFERROR(G16-H16-J16,0) -> 0
B17: 45664 | C17: استهلاكيات ورشة | D17: الورشة | E17: صرفيات يوسف نثرية ( مواد تنظيف - عدة - بخاخات -....) | G17: 40000 | H17: 0 | I17: 40000 | J17: 40000 | K17: =IFERROR(G17-H17-J17,0) -> 0
A18: 31٬089 | B18: 45666 | C18: المواد الخام | D18: الورشة | E18: عمود تل | G18: 180000 | H18: 0 | I18: 180000 | J18: 180000 | K18: =IFERROR(G18-H18-J18,0) -> 0
A19: 943 | B19: 45666 | C19: لواصق | D19: الورشة | E19: علي عبد الواحد حمود | G19: 77500 | H19: 0 | I19: 77500 | J19: 77500 | K19: =IFERROR(G19-H19-J19,0) -> 0
A20: 30٬053 | B20: 45666 | C20: المواد الخام | D20: الورشة | E20: شركة الضيف | G20: 55000 | I20: 55000 | J20: 55000 | K20: =IFERROR(G20-H20-J20,0) -> 0
A21: 1٬474 | B21: 45666 | C21: استهلاكيات ورشة | D21: الورشة | E21: درة الخليج | G21: 43750 | H21: 0 | I21: 43750 | J21: 43750 | K21: =IFERROR(G21-H21-J21,0) -> 0
A22: 244 | B22: 45666 | C22: استهلاكيات ورشة | D22: محل الاخوين | E22: انشائيات | G22: 43000 | H22: 0 | I22: 43000 | J22: 43000 | K22: =IFERROR(G22-H22-J22,0) -> 0
A23: 121 | B23: 45666 | C23: نثرية | D23: وليد | E23: نثرية | G23: 25000 | H23: 0 | I23: 25000 | J23: 25000 | K23: =IFERROR(G23-H23-J23,0) -> 0
B24: 45666 | C24: خدمات | D24: نقليات | E24: نقليات | G24: 20000 | H24: 0 | I24: 20000 | J24: 20000 | K24: =IFERROR(G24-H24-J24,0) -> 0
B25: 45666 | C25: استهلاكيات ورشة | D25: الورشة | E25: شراء كفوف وكمامات | G25: 10000 | H25: 0 | I25: 10000 | J25: 10000 | K25: =IFERROR(G25-H25-J25,0) -> 0
B26: 45666 | C26: تكاليف تطوير | D26: الورشة | E26: شراء كاكات | G26: 10000 | I26: 10000 | J26: 10000 | K26: =IFERROR(G26-H26-J26,0) -> 0
B27: 45666 | C27: رصيد | D27: الورشة | E27: شراء رصيد | G27: 10000 | H27: 0 | I27: 10000 | J27: 10000 | K27: =IFERROR(G27-H27-J27,0) -> 0
A28: 121 | B28: 45666 | C28: لواصق | D28: الورشة | E28: علي عبد الواحد حمود | G28: 8000 | H28: 0 | I28: 8000 | J28: 8000 | K28: =IFERROR(G28-H28-J28,0) -> 0
B29: 45666 | C29: استهلاكيات ورشة | D29: الورشة | E29: نفاضة | G29: 5000 | H29: 0 | I29: 5000 | J29: 5000 | K29: =IFERROR(G29-H29-J29,0) -> 0
B30: 45667 | C30: خدمات | D30: الورشة | E30: وليد طرقات | G30: 26000 | H30: 0 | I30: 26000 | J30: 26000 | K30: =IFERROR(G30-H30-J30,0) -> 0
B31: 45667 | C31: خدمات | D31: الورشة | E31: طرقات اشرف | G31: 15000 | H31: 0 | I31: 15000 | J31: 15000 | K31: =IFERROR(G31-H31-J31,0) -> 0
B32: 45667 | C32: رصيد | D32: الورشة | E32: رصيد | G32: 10000 | H32: 0 | I32: 10000 | J32: 10000 | K32: =IFERROR(G32-H32-J32,0) -> 0
B33: 45667 | C33: خدمات | D33: الورشة | E33: نقليات | G33: 5000 | H33: 0 | I33: 5000 | J33: 5000 | K33: =IFERROR(G33-H33-J33,0) -> 0
A34: 3٬615 | B34: 45668 | C34: المواد الخام | D34: الابرار | E34: الابرار | G34: 1097000 | H34: 0 | I34: 1097000 | J34: 1097000 | K34: =IFERROR(G34-H34-J34,0) -> 0
A35: 31٬771 | B35: 45668 | C35: المواد الخام | D35: الخورة | E35: الخورة | G35: 260000 | H35: 0 | I35: 260000 | J35: 260000 | K35: =IFERROR(G35-H35-J35,0) -> 0
B36: 45669 | C36: خدمات | D36: الورشة | E36: نقليات عبدالرضا | G36: 25000 | H36: 0 | I36: 25000 | J36: 25000 | K36: =IFERROR(G36-H36-J36,0) -> 0
B37: 45670 | C37: استهلاكيات ورشة | D37: الورشة | E37: مشتريات( مسامير + كهربائيات + نثرية) | G37: 250000 | H37: 0 | I37: 250000 | J37: 250000 | K37: =IFERROR(G37-H37-J37,0) -> 0
A38: 3٬662 | B38: 45670 | C38: المواد الخام | D38: الورشة | E38: الابرار | G38: 85000 | H38: 0 | I38: 85000 | J38: 85000 | K38: =IFERROR(G38-H38-J38,0) -> 0
B39: 45670 | C39: المواد الخام | D39: الورشة | E39: شراء اقمشة ومواد خام | G39: 75000 | H39: 0 | I39: 75000 | J39: 75000 | K39: =IFERROR(G39-H39-J39,0) -> 0
B40: 45670 | C40: خدمات | D40: الورشة | E40: نقل حسين للمدينة | G40: 40000 | H40: 0 | I40: 40000 | J40: 40000 | K40: =IFERROR(G40-H40-J40,0) -> 0
A41: 60٬186 | B41: 45670 | C41: المواد الخام | D41: الورشة | E41: الضيف | G41: 31500 | H41: 0 | I41: 31500 | J41: 31500 | K41: =IFERROR(G41-H41-J41,0) -> 0
...

Sheet الرواتب
A1: الاسم | B1: الحضور | C1: جمعة | D1: *1 | E1: *1.5 | F1: *2 | G1: الساعات | H1: نقل + طعام | I1: الراتب الكلي | J1: المكافآت | K1: السلف | L1: الغرامات | M1: الإجمالي النهائي | N1: المستلم | O1: العمود 15 | P1: الملاحظات
H2: =100000*B2/26 -> 0 | I2: 0 | O2: 45658 | P2: يناير
A3: معتصم | H3: =100000*B3/26 -> 0 | I3: 857000 | M3: =I3+J3-K3-L3-N3 -> 0 | N3: 857000 | O3: 45658
A4: حيدر الصباغ | H4: =100000*B4/26 -> 0 | I4: 595000 | M4: =I4+J4-K4-L4-N4 -> 0 | N4: 595000 | O4: 45658
A5: صديق يونس | H5: =100000*B5/26 -> 0 | I5: 266000 | M5: =I5+J5-K5-L5-N5 -> 0 | N5: 266000 | O5: 45658
A6: فرقان | H6: =100000*B6/26 -> 0 | I6: 285000 | M6: =I6+J6-K6-L6-N6 -> 0 | N6: 285000 | O6: 45658
A7: عامل يوسف | H7: =100000*B7/26 -> 0 | I7: 20000 | M7: =I7+J7-K7-L7-N7 -> 0 | N7: 20000 | O7: 45658
A8: علي الكهربائي | H8: =100000*B8/26 -> 0 | I8: 785000 | M8: =I8+J8-K8-L8-N8 -> 0 | N8: 785000 | O8: 45658
A9: اشرف | H9: =100000*B9/26 -> 0 | I9: 705000 | M9: =I9+J9-K9-L9-N9 -> 0 | N9: 705000 | O9: 45658
A10: وليد | H10: =100000*B10/26 -> 0 | I10: 893000 | M10: =I10+J10-K10-L10-N10 -> 0 | N10: 893000 | O10: 45658
A11: حيدر يافوز | H11: =100000*B11/26 -> 0 | I11: 779000 | M11: =I11+J11-K11-L11-N11 -> 0 | N11: 779000 | O11: 45658
A12: عبدالرضا عقيل | H12: =100000*B12/26 -> 0 | I12: 1122000 | M12: =I12+J12-K12-L12-N12 -> 0 | N12: 1122000 | O12: 45658
A13: عبدالله الصباغ | H13: =100000*B13/26 -> 0 | I13: 411000 | M13: =I13+J13-K13-L13-N13 -> 0 | N13: 411000 | O13: 45658
A14: علي عمار | H14: =100000*B14/26 -> 0 | I14: 640000 | M14: =I14+J14-K14-L14-N14 -> 0 | N14: 640000 | O14: 45658
... A86: حيدر يافوز | H86: =100000*B86/26 -> 0 | I86: 600000 | M86: =I86+J86-K86-L86-N86 -> 0 | N86: 600000 | O86: 45818
A87: يوسف يعقوب | H87: =100000*B87/26 -> 0 | I87: 287000 | J87: 0 | M87: =I87+J87-K87-L87-N87 -> 0 | N87: 287000 | O87: 45819
A88: عبدالرضا عقيل | H88: =100000*B88/26 -> 0 | I88: 400000 | M88: =I88+J88-K88-L88-N88 -> 0 | N88: 400000 | O88: 45820
A89: عبدالله الصباغ | H89: =100000*B89/26 -> 0 | I89: 302000 | M89: =I89+J89-K89-L89-N89 -> 0 | N89: 302000 | O89: 45821
A90: علي الكهربائي | H90: =100000*B90/26 -> 0 | I90: 675000 | M90: =I90+J90-K90-L90-N90 -> 0 | N90: 675000 | O90: 45822
A91: كرار رمضان | H91: =100000*B91/26 -> 0 | I91: 226000 | M91: =I91+J91-K91-L91-N91 -> 0 | N91: 226000 | O91: 45823
A92: محمد السوري | H92: =100000*B92/26 -> 0 | I92: 679000 | M92: =I92+J92-K92-L92-N92 -> 0 | N92: 679000 | O92: 45824
A94: حيدر الصباغ | H94: =100000*B94/26 -> 0 | I94: 590000 | M94: =I94+J94-K94-L94-N94 -> 0 | N94: 590000 | O94: 45839
A95: ابو علي | H95: =100000*B95/26 -> 0 | I95: 278000 | M95: =I95+J95-K95-L95-N95 -> 0 | N95: 278000 | O95: 45840
A96: منتظر فلاح | H96: =100000*B96/26 -> 0 | I96: 220000 | M96: =I96+J96-K96-L96-N96 -> 0 | N96: 220000 | O96: 45841
A97: حيدر الصباغ | H97: =100000*B97/26 -> 0 | I97: 451000 | M97: =I97+J97-K97-L97-N97 -> 0 | N97: 451000 | O97: 45842
A98: انوار كريم | H98: =100000*B98/26 -> 0 | I98: 360000 | M98: =I98+J98-K98-L98-N98 -> 0 | N98: 360000 | O98: 45843
A99: اخو عبد الرضا | H99: =100000*B99/26 -> 0 | I99: 16000 | M99: =I99+J99-K99-L99-N99 -> 0 | N99: 16000 | O99: 45844
A100: حسين معماري | H100: =100000*B100/26 -> 0 | I100: 550000 | M100: =I100+J100-K100-L100-N100 -> 0 | N100: 550000 | O100: 45845
... A117: عبدالرضا عقيل | H117: =100000*B117/26 -> 0 | I117: 225000 | M117: =I117+J117-K117-L117-N117 -> 0 | N117: 225000 | O117: 45870
A118: يوسف يعقوب
A120: حيدر مضر | B120: =IF(A120="",",",COUNTIFS('الحضور'!B2:B238,A120,'الحضور'!E2:E238,"<>",'الحضور'!F2:F238,"<>")) -> 27 | C120: =IF(A120="",",",SUMPRODUCT(( 'الحضور'!B2:B238=A120)*(WEEKDAY('الحضور'!A2:A238,2)=5)*('الحضور'!D2:D238<>"")*('الحضور'!E2:E238<>""))) -> 3 | D120: =IF(A120="",",",SUMIFS('الحضور'!H2:H238,'الحضور'!B2:B238,A120)) -> 187.23333 | E120: =IF(A120="",",",SUMIFS('الحضور'!I2:I238,'الحضور'!B2:B238,A120)) -> 82.3 | F120: =IF(A120="",",",SUMIFS('الحضور'!J2:J238,'الحضور'!B2:B238,A120)) -> 34 | G120: =IF(A120="",",", SUMPRODUCT(('الحضور'!B2:B238=A120)*('الحضور'!H2:H238+'الحضور'!J2:J238+'الحضور'!I2:I238))) -> 303.53333 | H120: =100000*B120/26 -> 103846.15 | I120: =IF(A120="",",",SUMIFS('الحضور'!K2:K238,'الحضور'!B2:B238,A120))+H120 -> 1151268.1 | J120: =IF(A120="",",",SUMIFS('الحضور'!L2:L1994,'الحضور'!B2:B1994,A120)) -> 0 | K120: =IF(A120="",",",SUMIFS('الحضور'!M2:M238,'الحضور'!B2:B238,A120)) -> 240000 | L120: =IF(A120="",",",SUMIFS('الحضور'!N2:N238,'الحضور'!B2:B238, A120)) -> 70677.305 | M120: =I120+J120-K120-L120-N120 -> -2.3283064e-10 | N120: 840590.83 | O120: 45901
A121: عبدالرضا عقيل | B121: =IF(A121="",",",COUNTIFS('الحضور'!B3:B239,A121,'الحضور'!E3:E239,"<>",'الحضور'!F3:F239,"<>")) -> 25 | C121: =IF(A121="",",",SUMPRODUCT(( 'الحضور'!B3:B239=A121)*(WEEKDAY('الحضور'!A3:A239,2)=5)*('الحضور'!D3:D239<>"")*('الحضور'!E3:E239<>""))) -> 3 | D121: =IF(A121="",",",SUMIFS('الحضور'!H3:H239,'الحضور'!B3:B239,A121)) -> 183.3 | E121: =IF(A121="",",",SUMIFS('الحضور'!I3:I239,'الحضور'!B3:B239,A121)) -> 45.933333 | F121: =IF(A121="",",",SUMIFS('الحضور'!J3:J239,'الحضور'!B3:B239,A121)) -> 30.283333 | G121: =IF(A121="",",", SUMPRODUCT(('الحضور'!B3:B239=A121)*('الحضور'!H3:H239+'الحضور'!J3:J239+'الحضور'!I3:I239))) -> 259.51667 | H121: =100000*B121/26 -> 96153.846 | I121: =IF(A121="",",",SUMIFS('الحضور'!K3:K239,'الحضور'!B3:B239,A121))+H121 -> 961253.14 | J121: =IF(A121="",",",SUMIFS('الحضور'!L3:L1995,'الحضور'!B3:B1995,A121)) -> 47000 | K121: =IF(A121="",",",SUMIFS('الحضور'!M3:M239,'الحضور'!B3:B239,A121)) -> 280000 | L121: =IF(A121="",",",SUMIFS('الحضور'!N3:N239,'الحضور'!B3:B239, A121)) -> 28253.177 | M121: =I121+J121-K121-L121-N121 -> 0 | N121: 699999.96 | O121: 45901
A122: حيدر يافوز | B122: =IF(A122="",",",COUNTIFS('الحضور'!B4:B100,A122,'الحضور'!E4:E100,"<>",'الحضور'!F4:F100,"<>")) -> 28 | C122: =IF(A122="",",",SUMPRODUCT(( 'الحضور'!B4:B240=A122)*(WEEKDAY('الحضور'!A4:A240,2)=5)*('الحضور'!D4:D240<>"")*('الحضور'!E4:E240<>""))) -> 3 | D122: =IF(A122="",",",SUMIFS('الحضور'!H4:H240,'الحضور'!B4:B240,A122)) -> 208.95 | E122: =IF(A122="",",",SUMIFS('الحضور'!I4:I240,'الحضور'!B4:B240,A122)) -> 30.733333 | F122: =IF(A122="",",",SUMIFS('الحضور'!J4:J240,'الحضور'!B4:B240,A122)) -> 28.866667 | G122: =IF(A122="",",", SUMPRODUCT(('الحضور'!B4:B240=A122)*('الحضور'!H4:H240+'الحضور'!J4:J240+'الحضور'!I4:I240))) -> 268.55 | H122: =100000*B122/26 -> 107692.31 | I122: =IF(A122="",",",SUMIFS('الحضور'!K4:K240,'الحضور'!B4:B240,A122))+H122 -> 640089.47 | J122: =IF(A122="",",",SUMIFS('الحضور'!L4:L1996,'الحضور'!B4:B1996,A122)) -> 35000 | K122: =IF(A122="",",",SUMIFS('الحضور'!M4:M240,'الحضور'!B4:B240,A122)) -> 410000 | L122: =IF(A122="",",",SUMIFS('الحضور'!N4:N240,'الحضور'!B4:B240, A122)) -> 37283.688 | M122: =I122+J122-K122-L122-N122 -> 0 | N122: 227805.78 | O122: 45901 | P122: 1136000
A123: سراج نزار | B123: =IF(A123="",",",COUNTIFS('الحضور'!B5:B241,A123,'الحضور'!E5:E241,"<>",'الحضور'!F5:F241,"<>")) -> 28 | C123: =IF(A123="",",",SUMPRODUCT(( 'الحضور'!B5:B241=A123)*(WEEKDAY('الحضور'!A5:A241,2)=5)*('الحضور'!D5:D241<>"")*('الحضور'!E5:E241<>""))) -> 3 | D123: =IF(A123="",",",SUMIFS('الحضور'!H5:H241,'الحضور'!B5:B241,A123)) -> 213.13333 | E123: =IF(A123="",",",SUMIFS('الحضور'!I5:I241,'الحضور'!B5:B241,A123)) -> 17.083333 | F123: =IF(A123="",",",SUMIFS('الحضور'!J5:J241,'الحضور'!B5:B241,A123)) -> 33.1 | G123: =IF(A123="",",", SUMPRODUCT(('الحضور'!B5:B241=A123)*('الحضور'!H5:H241+'الحضور'!J5:J241+'الحضور'!I5:I241))) -> 263.31667 | H123: =100000*B123/26 -> 107692.31 | I123: =IF(A123="",",",SUMIFS('الحضور'!K5:K241,'الحضور'!B5:B241,A123))+H123 -> 886309.33 | J123: =IF(A123="",",",SUMIFS('الحضور'!L5:L1997,'الحضور'!B5:B1997,A123)) -> 331500 | K123: =IF(A123="",",",SUMIFS('الحضور'!M5:M241,'الحضور'!B5:B241,A123)) -> 18800 | L123: =IF(A123="",",",SUMIFS('الحضور'!N5:N241,'الحضور'!B5:B241, A123)) -> 31308.83 | M123: =I123+J123-K123-L123-N123 -> 0 | N123: 1167700.5 | O123: 45901
A124: زكي صادق | B124: =IF(A124="",",",COUNTIFS('الحضور'!B6:B242,A124,'الحضور'!E6:E242,"<>",'الحضور'!F6:F242,"<>")) -> 12 | C124: =IF(A124="",",",SUMPRODUCT(( 'الحضور'!B6:B242=A124)*(WEEKDAY('الحضور'!A6:A242,2)=5)*('الحضور'!D6:D242<>"")*('الحضور'!E6:E242<>""))) -> 0 | D124: =IF(A124="",",",SUMIFS('الحضور'!H6:H242,'الحضور'!B6:B242,A124)) -> 101.53333 | E124: =IF(A124="",",",SUMIFS('الحضور'!I6:I242,'الحضور'!B6:B242,A124)) -> 0 | F124: =IF(A124="",",",SUMIFS('الحضور'!J6:J242,'الحضور'!B6:B242,A124)) -> 0 | G124: =IF(A124="",",", SUMPRODUCT(('الحضور'!B6:B242=A124)*('الحضور'!H6:H242+'الحضور'!J6:J242+'الحضور'!I6:I242))) -> 101.53333 | H124: =100000*B124/26 -> 46153.846 | I124: =IF(A124="",",",SUMIFS('الحضور'!K6:K242,'الحضور'!B6:B242,A124))+H124 -> 218976.54 | J124: =IF(A124="",",",SUMIFS('الحضور'!L6:L1998,'الحضور'!B6:B1998,A124)) -> 52000 | K124: =IF(A124="",",",SUMIFS('الحضور'!M6:M242,'الحضور'!B6:B242,A124)) -> 210000 | L124: =IF(A124="",",",SUMIFS('الحضور'!N6:N242,'الحضور'!B6:B242, A124)) -> 3290.7801 | M124: =I124+J124-K124-L124-N124 -> 0 | N124: 57685.761 | O124: 45901
A125: محمد حسن | B125: =IF(A125="",",",COUNTIFS('الحضور'!B7:B243,A125,'الحضور'!E7:E243,"<>",'الحضور'!F7:F243,"<>")) -> 9 | C125: =IF(A125="",",",SUMPRODUCT(( 'الحضور'!B7:B243=A125)*(WEEKDAY('الحضور'!A7:A243,2)=5)*('الحضور'!D7:D243<>"")*('الحضور'!E7:E243<>""))) -> 0 | D125: =IF(A125="",",",SUMIFS('الحضور'!H7:H243,'الحضور'!B7:B243,A125)) -> 46.483333 | E125: =IF(A125="",",",SUMIFS('الحضور'!I7:I243,'الحضور'!B7:B243,A125)) -> 19.666667 | F125: =IF(A125="",",",SUMIFS('الحضور'!J7:J243,'الحضور'!B7:B243,A125)) -> 0 | G125: =IF(A125="",",", SUMPRODUCT(('الحضور'!B7:B243=A125)*('الحضور'!H7:H243+'الحضور'!J7:J243+'الحضور'!I7:I243))) -> 66.15 | H125: =100000*B125/26 -> 34615.385 | I125: =IF(A125="",",",SUMIFS('الحضور'!K7:K243,'الحضور'!B7:B243,A125))+H125 -> 131615.38 | J125: =IF(A125="",",",SUMIFS('الحضور'!L7:L1999,'الحضور'!B7:B1999,A125)) -> 0 | K125: =IF(A125="",",",SUMIFS('الحضور'!M7:M243,'الحضور'!B7:B243,A125)) -> 0 | L125: =IF(A125="",",",SUMIFS('الحضور'!N7:N243,'الحضور'!B7:B243, A125)) -> 0 | M125: =I125+J125-K125-L125-N125 -> 0 | N125: 131615.38 | O125: 45901
A126: انوار كريم | B126: =IF(A126="",",",COUNTIFS('الحضور'!B8:B214,A126,'الحضور'!E8:E214,"<>",'الحضور'!F8:F214,"<>")) -> 23 | C126: =IF(A126="",",",SUMPRODUCT(( 'الحضور'!B8:B244=A126)*(WEEKDAY('الحضور'!A8:A244,2)=5)*('الحضور'!D8:D244<>"")*('الحضور'!E8:E244<>""))) -> 1 | D126: =IF(A126="",",",SUMIFS('الحضور'!H8:H244,'الحضور'!B8:B244,A126)) -> 197.93333 | E126: =IF(A126="",",",SUMIFS('الحضور'!I8:I244,'الحضور'!B8:B244,A126)) -> 4.0333333 | F126: =IF(A126="",",",SUMIFS('الحضور'!J8:J244,'الحضور'!B8:B244,A126)) -> 6.6833333 | G126: =IF(A126="",",", SUMPRODUCT(('الحضور'!B8:B244=A126)*('الحضور'!H8:H244+'الحضور'!J8:J244+'الحضور'!I8:I244))) -> 208.65 | H126: =100000*B126/26 -> 88461.538 | I126: =IF(A126="",",",SUMIFS('الحضور'!K8:K244,'الحضور'!B8:B244,A126))+H126 -> 446730.77 | J126: =IF(A126="",",",SUMIFS('الحضور'!L8:L2000,'الحضور'!B8:B2000,A126)) -> 0 | K126: =IF(A126="",",",SUMIFS('الحضور'!M8:M244,'الحضور'!B8:B244,A126)) -> 0 | L126: =IF(A126="",",",SUMIFS('الحضور'!N8:N244,'الحضور'!B8:B244, A126)) -> 8340.6593 | M126: =I126+J126-K126-L126-N126 -> 0.10989011 | N126: 438390 | O126: 45901
A127: حسين سعد | B127: =IF(A127="",",",COUNTIFS('الحضور'!B9:B215,A127,'الحضور'!E9:E215,"<>",'الحضور'!F9:F215,"<>")) -> 24 | C127: =IF(A127="",",",SUMPRODUCT(( 'الحضور'!B9:B245=A127)*(WEEKDAY('الحضور'!A9:A245,2)=5)*('الحضور'!D9:D245<>"")*('الحضور'!E9:E245<>""))) -> 3 | D127: =IF(A127="",",",SUMIFS('الحضور'!H9:H245,'الحضور'!B9:B245,A127)) -> 188.93333 | E127: =IF(A127="",",",SUMIFS('الحضور'!I9:I245,'الحضور'!B9:B245,A127)) -> 12.9 | F127: =IF(A127="",",",SUMIFS('الحضور'!J9:J245,'الحضور'!B9:B245,A127)) -> 38.4 | G127: =IF(A127="",",", SUMPRODUCT(('الحضور'!B9:B245=A127)*('الحضور'!H9:H245+'الحضور'!J9:J245+'الحضور'!I9:I245))) -> 240.23333 | H127: =100000*B127/26 -> 92307.692 | I127: =IF(A127="",",",SUMIFS('الحضور'!K9:K245,'الحضور'!B9:B245,A127))+H127 -> 456243.86 | J127: 0 | K127: =IF(A127="",",",SUMIFS('الحضور'!M9:M245,'الحضور'!B9:B245,A127)) -> 180000 | L127: =IF(A127="",",",SUMIFS('الحضور'!N9:N245,'الحضور'!B9:B245, A127)) -> 2191.4894 | M127: =I127+J127-K127-L127-N127 -> 0 | N127: 274052.37 | O127: 45901
A128: باقر | B128: =IF(A128="",",",COUNTIFS('الحضور'!B10:B216,A128,'الحضور'!E10:E216,"<>",'الحضور'!F10:F216,"<>")) -> 0 | C128: =IF(A128="",",",SUMPRODUCT(( 'الحضور'!B10:B246=A128)*(WEEKDAY('الحضور'!A10:A246,2)=5)*('الحضور'!D10:D246<>"")*('الحضور'!E10:E246<>""))) -> 0 | D128: =IF(A128="",",",SUMIFS('الحضور'!H10:H246,'الحضور'!B10:B246,A128)) -> 0 | E128: =IF(A128="",",",SUMIFS('الحضور'!I10:I246,'الحضور'!B10:B246,A128)) -> 0 | F128: =IF(A128="",",",SUMIFS('الحضور'!J10:J246,'الحضور'!B10:B246,A128)) -> 0 | G128: =IF(A128="",",", SUMPRODUCT(('الحضور'!B10:B246=A128)*('الحضور'!H10:H246+'الحضور'!J10:J246+'الحضور'!I10:I246))) -> 0 | H128: =100000*B128/26 -> 0 | I128: =IF(A128="",",",SUMIFS('الحضور'!K10:K246,'الحضور'!B10:B246,A128))+H128 -> 0 | J128: 0 | K128: =IF(A128="",",",SUMIFS('الحضور'!M10:M246,'الحضور'!B10:B246,A128)) -> 0 | L128: =IF(A128="",",",SUMIFS('الحضور'!N10:N246,'الحضور'!B10:B246, A128)) -> 0 | M128: =I128+J128-K128-L128-N128 -> -16263 | N128: 16263 | O128: 45901
A129: يوسف يعقوب | B129: =IF(A129="",",",COUNTIFS('الحضور'!B11:B227,A129,'الحضور'!E11:E227,"<>",'الحضور'!F11:F227,"<>")) -> 21 | C129: =IF(A129="",",",SUMPRODUCT(( 'الحضور'!B11:B227=A129)*(WEEKDAY('الحضور'!A11:A227,2)=5)*('الحضور'!D11:D227<>"")*('الحضور'!E11:E227<>""))) -> 2 | D129: =IF(A129="",",",SUMIFS('الحضور'!H11:H227,'الحضور'!B11:B227,A129)) -> 151.31667 | E129: =IF(A129="",",",SUMIFS('الحضور'!I11:I227,'الحضور'!B11:B227,A129)) -> 2.2833333 | F129: =IF(A129="",",",SUMIFS('الحضور'!J11:J227,'الحضور'!B11:B227,A129)) -> 15.433333 | G129: =IF(A129="",",", SUMPRODUCT(('الحضور'!B11:B227=A129)*('الحضور'!H11:H227+'الحضور'!J11:J227+'الحضور'!I11:I227))) -> 169.03333 | H129: =100000*B129/26 -> 80769.231 | I129: =IF(A129="",",",SUMIFS('الحضور'!K11:K227,'الحضور'!B11:B227,A129))+H129 -> 633645.12 | J129: =IF(A129="",",",SUMIFS('الحضور'!L11:L227,'الحضور'!B11:B227,A129)) -> 0 | K129: =IF(A129="",",",SUMIFS('الحضور'!M11:M247,'الحضور'!B11:B247,A129)) -> 0 | L129: =IF(A129="",",",SUMIFS('الحضور'!N11:N247,'الحضور'!B11:B247, A129)) -> 37829.787 | M129: =I129+J129-K129-L129-N129 -> 0.33006001 | N129: 595815 | O129: 45901
...

Sheet الحضور
A1: العمود 1 | B1: اسم الموظف | C1: اليوم | D1: وقت الدخول | E1: وقت الخروج | F1: الراتب الاسمي | G1: سعر الساعة | H1: ساعات عادية | I1: ساعات إضافية 1.5x | J1: ساعات الجمعة 2x | K1: الراتب اليومي | L1: المكافآت | M1: السلف | N1: الغرامات التاخيرية | O1: الرقم النهائي | P1: الملاحظات
A2: 45901 | B2: حيدر مضر | C2: =CHOOSE(WEEKDAY(A2,2),"الاثنين","الثلاثاء","الأربعاء","الخميس","الجمعة","السبت","الأحد") -> الاثنين | D2: 0.44305556 | E2: 0.875 | F2: 650000 | G2: =F2/235 -> 2765.9574 | H2: =IF(ISNUMBER(SEARCH("جمعة",C2)),0, IF(OR(D2="", E2=""),0, MIN(12,MAX(0,(MIN(E2,TIME(18,0,0))-MAX(D2,TIME(6,0,0)))*24)))) -> 7.3666667 | I2: =IF(ISNUMBER(SEARCH("جمعة",C2)), 0, MAX(0,(MOD(E2-D2,1)*24)-H2)) -> 3 | J2: =IF(C2="الجمعة",MOD(E2-D2,1)*24,0) -> 0 | K2: =sum(H2*G2)+(I2*1.5*G2)+(J2*2*G2) -> 32822.695 | M2: 240000 | N2: =(9-H2)*G2 -> 4517.7305 | O2: =K2+L2-M2-N2 -> -211695.04
A3: 45902 | B3: حيدر مضر | C3: =CHOOSE(WEEKDAY(A3,2),"الاثنين","الثلاثاء","الأربعاء","الخميس","الجمعة","السبت","الأحد") -> الثلاثاء | D3: 0.29791667 | E3: 0.875 | F3: 650000 | G3: =F3/235 -> 2765.9574 | H3: =IF(ISNUMBER(SEARCH("جمعة",C3)), 0, IF(OR(D3="", E3=""), 0, MIN(12,MAX(0,(MIN(E3,TIME(18,0,0))-MAX(D3,TIME(6,0,0)))*24)))) -> 10.85 | I3: =IF(ISNUMBER(SEARCH("جمعة",C3)), 0, MAX(0,(MOD(E3-D3,1)*24)-H3)) -> 3 | J3: =IF(C3="الجمعة",MOD(E3-D3,1)*24,0) -> 0 | K3: =sum(H3*G3)+(I3*1.5*G3)+(J3*2*G3) -> 42457.447 | N3: 15000 | O3: =K3+L3-M3-N3 -> 27457.447 | P3: 1 قوطية صبغ اساس طبليات مصطفى
A4: 45903 | B4: حيدر مضر | C4: =CHOOSE(WEEKDAY(A4,2),"الاثنين","الثلاثاء","الأربعاء","الخميس","الجمعة","السبت","الأحد") -> الأربعاء | D4: 0.42638889 | E4: 0.85347222 | F4: 650000 | G4: =F4/235 -> 2765.9574 | H4: =IF(ISNUMBER(SEARCH("جمعة",C4)), 0, IF(OR(D4="", E4=""), 0, MIN(12,MAX(0,(MIN(E4,TIME(18,0,0))-MAX(D4,TIME(6,0,0)))*24)))) -> 7.7666667 | I4: =IF(ISNUMBER(SEARCH("جمعة",C4)), 0, MAX(0,(MOD(E4-D4,1)*24)-H4)) -> 2.4833333 | J4: =IF(C4="الجمعة",MOD(E4-D4,1)*24,0) -> 0 | K4: =sum(H4*G4)+(I4*1.5*G4)+(J4*2*G4) -> 31785.461 | N4: =IF(C4="الجمعة",0,IF(D4>TIME(9,0,0),(D4-TIME(9,0,0))*24*60*(G4/60),0)) -> 3411.3475 | O4: =K4+L4-M4-N4 -> 28374.113
A5: 45904 | B5: حيدر مضر | C5: =CHOOSE(WEEKDAY(A5,2),"الاثنين","الثلاثاء","الأربعاء","الخميس","الجمعة","السبت","الأحد") -> الخميس | D5: 0.375 | E5: 0.99930556 | F5: 650000 | G5: =F5/235 -> 2765.9574 | H5: =IF(ISNUMBER(SEARCH("جمعة",C5)), 0, IF(OR(D5="", E5=""), 0, MIN(12,MAX(0,(MIN(E5,TIME(18,0,0))-MAX(D5,TIME(6,0,0)))*24)))) -> 9 | I5: =IF(ISNUMBER(SEARCH("جمعة",C5)), 0, MAX(0,(MOD(E5-D5,1)*24)-H5)) -> 5.9833333 | J5: =IF(C5="الجمعة",MOD(E5-D5,1)*24,0) -> 0 | K5: =sum(H5*G5)+(I5*1.5*G5)+(J5*2*G5) -> 49718.085 | N5: 4000 | O5: =K5+L5-M5-N5 -> 45718.085 | P5: مكتبية
A6: 45905 | B6: حيدر مضر | C6: =CHOOSE(WEEKDAY(A6,2),"الاثنين","الثلاثاء","الأربعاء","الخميس","الجمعة","السبت","الأحد") -> الجمعة | D6: 0.41666667 | E6: 0.95833333 | F6: 650000 | G6: =F6/235 -> 2765.9574 | H6: =IF(ISNUMBER(SEARCH("جمعة",C6)), 0, IF(OR(D6="", E6=""), 0, MIN(12,MAX(0,(MIN(E6,TIME(18,0,0))-MAX(D6,TIME(6,0,0)))*24)))) -> 0 | I6: =IF(ISNUMBER(SEARCH("جمعة",C6)), 0, MAX(0,(MOD(E6-D6,1)*24)-H6)) -> 0 | J6: =IF(C6="الجمعة",MOD(E6-D6,1)*24,0) -> 13 | K6: =sum(H6*G6)+(I6*1.5*G6)+(J6*2*G6) -> 71914.894 | N6: =IF(C6="الجمعة",0,IF(D6>TIME(9,0,0),(D6-TIME(9,0,0))*24*60*(G6/60),0)) -> 0 | O6: =K6+L6-M6-N6 -> 71914.894
A7: 45906 | B7: حيدر مضر | C7: =CHOOSE(WEEKDAY(A7,2),"الاثنين","الثلاثاء","الأربعاء","الخميس","الجمعة","السبت","الأحد") -> السبت | D7: 0.40208333 | E7: 0.89791667 | F7: 650000 | G7: =F7/235 -> 2765.9574 | H7: =IF(ISNUMBER(SEARCH("جمعة",C7)), 0, IF(OR(D7="", E7=""), 0, MIN(12,MAX(0,(MIN(E7,TIME(18,0,0))-MAX(D7,TIME(6,0,0)))*24)))) -> 8.35 | I7: =IF(ISNUMBER(SEARCH("جمعة",C7)), 0, MAX(0,(MOD(E7-D7,1)*24)-H7)) -> 3.55 | J7: =IF(C7="الجمعة",MOD(E7-D7,1)*24,0) -> 0 | K7: =sum(H7*G7)+(I7*1.5*G7)+(J7*2*G7) -> 37824.468 | N7: =IF(C7="الجمعة",0,IF(D7>TIME(9,0,0),(D7-TIME(9,0,0))*24*60*(G7/60),0)) -> 1797.8723 | O7: =K7+L7-M7-N7 -> 36026.596
A8: 45907 | B8: حيدر مضر | C8: =CHOOSE(WEEKDAY(A8,2),"الاثنين","الثلاثاء","الأربعاء","الخميس","الجمعة","السبت","الأحد") -> الأحد | D8: 0.375 | E8: 0.99930556 | F8: 650000 | G8: =F8/235 -> 2765.9574 | H8: =IF(ISNUMBER(SEARCH("جمعة",C8)), 0, IF(OR(D8="", E8=""), 0, MIN(12,MAX(0,(MIN(E8,TIME(18,0,0))-MAX(D8,TIME(6,0,0)))*24)))) -> 9 | I8: =IF(ISNUMBER(SEARCH("جمعة",C8)), 0, MAX(0,(MOD(E8-D8,1)*24)-H8)) -> 5.9833333 | J8: =IF(C8="الجمعة",MOD(E8-D8,1)*24,0) -> 0 | K8: =sum(H8*G8)+(I8*1.5*G8)+(J8*2*G8) -> 49718.085 | N8: =IF(C8="الجمعة",0,IF(D8>TIME(9,0,0),(D8-TIME(9,0,0))*24*60*(G8/60),0)) -> 0 | O8: =K8+L8-M8-N8 -> 49718.085
A9: 45908 | B9: حيدر مضر | C9: =CHOOSE(WEEKDAY(A9,2),"الاثنين","الثلاثاء","الأربعاء","الخميس","الجمعة","السبت","الأحد") -> الاثنين | D9: 0.375 | E9: 0.99930556 | F9: 650000 | G9: =F9/235 -> 2765.9574 | H9: =IF(ISNUMBER(SEARCH("جمعة",C9)), 0, IF(OR(D9="", E9=""), 0, MIN(12,MAX(0,(MIN(E9,TIME(18,0,0))-MAX(D9,TIME(6,0,0)))*24)))) -> 9 | I9: =IF(ISNUMBER(SEARCH("جمعة",C9)), 0, MAX(0,(MOD(E9-D9,1)*24)-H9)) -> 5.9833333 | J9: =IF(C9="الجمعة",MOD(E9-D9,1)*24,0) -> 0 | K9: =sum(H9*G9)+(I9*1.5*G9)+(J9*2*G9) -> 49718.085 | N9: =IF(C9="الجمعة",0,IF(D9>TIME(9,0,0),(D9-TIME(9,0,0))*24*60*(G9/60),0)) -> 0 | O9: =K9+L9-M9-N9 -> 49718.085
A10: 45909 | B10: حيدر مضر | C10: =CHOOSE(WEEKDAY(A10,2),"الاثنين","الثلاثاء","الأربعاء","الخميس","الجمعة","السبت","الأحد") -> الثلاثاء | D10: 0.375 | E10: 0.99930556 | F10: 650000 | G10: =F10/235 -> 2765.9574 | H10: =IF(ISNUMBER(SEARCH("جمعة",C10)), 0, IF(OR(D10="", E10=""), 0, MIN(12,MAX(0,(MIN(E10,TIME(18,0,0))-MAX(D10,TIME(6,0,0)))*24)))) -> 9 | I10: =IF(ISNUMBER(SEARCH("جمعة",C10)), 0, MAX(0,(MOD(E10-D10,1)*24)-H10)) -> 5.9833333 | J10: =IF(C10="الجمعة",MOD(E10-D10,1)*24,0) -> 0 | K10: =sum(H10*G10)+(I10*1.5*G10)+(J10*2*G10) -> 49718.085 | N10: =IF(C10="الجمعة",0,IF(D10>TIME(9,0,0),(D10-TIME(9,0,0))*24*60*(G10/60),0)) -> 0 | O10: =K10+L10-M10-N10 -> 49718.085
A11: 45910 | B11: حيدر مضر | C11: =CHOOSE(WEEKDAY(A11,2),"الاثنين","الثلاثاء","الأربعاء","الخميس","الجمعة","السبت","الأحد") -> الأربعاء | D11: 0.375 | E11: 0.99930556 | F11: 650000 | G11: =F11/235 -> 2765.9574 | H11: =IF(ISNUMBER(SEARCH("جمعة",C11)), 0, IF(OR(D11="", E11=""), 0, MIN(12,MAX(0,(MIN(E11,TIME(18,0,0))-MAX(D11,TIME(6,0,0)))*24)))) -> 9 | I11: =IF(ISNUMBER(SEARCH("جمعة",C11)), 0, MAX(0,(MOD(E11-D11,1)*24)-H11)) -> 5.9833333 | J11: =IF(C11="الجمعة",MOD(E11-D11,1)*24,0) -> 0 | K11: =sum(H11*G11)+(I11*1.5*G11)+(J11*2*G11) -> 49718.085 | N11: =IF(C11="الجمعة",0,IF(D11>TIME(9,0,0),(D11-TIME(9,0,0))*24*60*(G11/60),0)) -> 0 | O11: =K11+L11-M11-N11 -> 49718.085
