Workbook

Sheet الواجه الرئيسية
C1: WORKSHOP AUTO SERVICE CENTERACCOUNTING DASHBOARD
C6: تسديد خارجي | D6: الرواتب | E6: قبض | F6: صرف | G6: دفع الى الورشه | H6: ديون علينا | I6: دفع سيف اجمالي
C7: =I7-G7 -> 20812000 | D7: =SUMIFS('رواتب'!J:J,'رواتب'!A:A,"اجمالي") -> 13397242 | E7: =SUMIFS('الحركات'!D:D,'الحركات'!B:B,"سند قبض") -> 22343000 | F7: =SUMIFS('الحركات'!D:D,'الحركات'!B:B,"سند صرف") -> -4613991 | G7: =SUMIFS('الحركات'!D:D,'الحركات'!B:B,"سند دفع")+E7 -> 17798000 | H7: ='الديون'!F2 -> 19012000 | I7: =SUMIFS('الحركات'!H:H,'الحركات'!G:G,"sife") -> 38610000
D9: السلفة | E9: =SUM('الحركات'!D4:D32) -> 785000 | H9: ديون لنا
D10: =SUMIFS('رواتب'!G:G,'رواتب'!A:A,"اجمالي") -> 7306503.5 | H10: ='الديون'!G2 -> 10098250
B12: الاسم | C12: الاجر | D12: إجمالي السلف | E12: الغرامات | F12: الراتب الكلي | G12: صافي الراتب | H12: المستلم | I12: التاريخ
B13: =IFERROR(__xludf.DUMMYFUNCTION("QUERY('رواتب'!A24:M31,""select A,F,G,H,J,K,L,M order by A desc limit 12"",1)"),"حسين سالم") -> حسين سالم | C13: =IFERROR(__xludf.DUMMYFUNCTION("""COMPUTED_VALUE""")," IQD 692٬593") -> IQD 692٬593 | D13: =IFERROR(__xludf.DUMMYFUNCTION("""COMPUTED_VALUE""")," IQD 206٬750") -> IQD 206٬750 | E13: =IFERROR(__xludf.DUMMYFUNCTION("""COMPUTED_VALUE""")," IQD 50٬000") -> IQD 50٬000 | F13: =IFERROR(__xludf.DUMMYFUNCTION("""COMPUTED_VALUE""")," IQD 727٬689") -> IQD 727٬689 | G13: =IFERROR(__xludf.DUMMYFUNCTION("""COMPUTED_VALUE""")," IQD 470٬939") -> IQD 470٬939 | H13: =IFERROR(__xludf.DUMMYFUNCTION("""COMPUTED_VALUE"""),"") | I13: =IFERROR(__xludf.DUMMYFUNCTION("""COMPUTED_VALUE""")," مارس") -> مارس
B14: =IFERROR(__xludf.DUMMYFUNCTION("""COMPUTED_VALUE"""),"يوسف احمد") -> يوسف احمد | C14: =IFERROR(__xludf.DUMMYFUNCTION("""COMPUTED_VALUE"""),55555.555555555555) -> 55555.556 | D14: =IFERROR(__xludf.DUMMYFUNCTION("""COMPUTED_VALUE"""),0.0) -> 0 | E14: =IFERROR(__xludf.DUMMYFUNCTION("""COMPUTED_VALUE"""),0.0) -> 0 | F14: =IFERROR(__xludf.DUMMYFUNCTION("""COMPUTED_VALUE"""),47839.50617283951) -> 47839.506 | G14: =IFERROR(__xludf.DUMMYFUNCTION("""COMPUTED_VALUE"""),-0.49382716049149167) -> -0.49382716 | H14: =IFERROR(__xludf.DUMMYFUNCTION("""COMPUTED_VALUE"""),50000.0) -> 50000 | I14: =IFERROR(__xludf.DUMMYFUNCTION("""COMPUTED_VALUE"""),46099.0) -> 46099
B15: =IFERROR(__xludf.DUMMYFUNCTION("""COMPUTED_VALUE"""),"محمد فؤاد سالم") -> محمد فؤاد سالم | C15: =IFERROR(__xludf.DUMMYFUNCTION("""COMPUTED_VALUE"""),48148.148148148146) -> 48148.148 | D15: =IFERROR(__xludf.DUMMYFUNCTION("""COMPUTED_VALUE"""),0.0) -> 0 | E15: =IFERROR(__xludf.DUMMYFUNCTION("""COMPUTED_VALUE"""),0.0) -> 0 | F15: =IFERROR(__xludf.DUMMYFUNCTION("""COMPUTED_VALUE"""),45473.25102880658) -> 45473.251 | G15: =IFERROR(__xludf.DUMMYFUNCTION("""COMPUTED_VALUE"""),0.25102880658232607) -> 0.25102881 | H15: =IFERROR(__xludf.DUMMYFUNCTION("""COMPUTED_VALUE"""),50000.0) -> 50000 | I15: =IFERROR(__xludf.DUMMYFUNCTION("""COMPUTED_VALUE"""),46098.0) -> 46098
B16: =IFERROR(__xludf.DUMMYFUNCTION("""COMPUTED_VALUE"""),"علي الباكستاني") -> علي الباكستاني | C16: =IFERROR(__xludf.DUMMYFUNCTION("""COMPUTED_VALUE"""),0.0) -> 0 | D16: =IFERROR(__xludf.DUMMYFUNCTION("""COMPUTED_VALUE"""),15000.0) -> 15000 | E16: =IFERROR(__xludf.DUMMYFUNCTION("""COMPUTED_VALUE"""),50000.0) -> 50000 | F16: =IFERROR(__xludf.DUMMYFUNCTION("""COMPUTED_VALUE"""),550000.0) -> 550000 | G16: =IFERROR(__xludf.DUMMYFUNCTION("""COMPUTED_VALUE"""),485000.0) -> 485000 | I16: =IFERROR(__xludf.DUMMYFUNCTION("""COMPUTED_VALUE"""),46097.0) -> 46097
B17: =IFERROR(__xludf.DUMMYFUNCTION("""COMPUTED_VALUE"""),"خضر عبد الخالق") -> خضر عبد الخالق | C17: =IFERROR(__xludf.DUMMYFUNCTION("""COMPUTED_VALUE"""),222222.2222222222) -> 222222.22 | D17: =IFERROR(__xludf.DUMMYFUNCTION("""COMPUTED_VALUE"""),88500.0) -> 88500 | E17: =IFERROR(__xludf.DUMMYFUNCTION("""COMPUTED_VALUE"""),50000.0) -> 50000 | F17: =IFERROR(__xludf.DUMMYFUNCTION("""COMPUTED_VALUE"""),299691.35802469135) -> 299691.36 | G17: =IFERROR(__xludf.DUMMYFUNCTION("""COMPUTED_VALUE"""),161191.35802469135) -> 161191.36 | I17: =IFERROR(__xludf.DUMMYFUNCTION("""COMPUTED_VALUE"""),46095.0) -> 46095
B18: =IFERROR(__xludf.DUMMYFUNCTION("""COMPUTED_VALUE"""),"حيدر يافوز") -> حيدر يافوز | C18: =IFERROR(__xludf.DUMMYFUNCTION("""COMPUTED_VALUE"""),550000.0000000001) -> 550000 | D18: =IFERROR(__xludf.DUMMYFUNCTION("""COMPUTED_VALUE"""),353500.0) -> 353500 | E18: =IFERROR(__xludf.DUMMYFUNCTION("""COMPUTED_VALUE"""),0.0) -> 0 | F18: =IFERROR(__xludf.DUMMYFUNCTION("""COMPUTED_VALUE"""),722506.8587105622) -> 722506.86 | G18: =IFERROR(__xludf.DUMMYFUNCTION("""COMPUTED_VALUE"""),369006.8587105622) -> 369006.86 | I18: =IFERROR(__xludf.DUMMYFUNCTION("""COMPUTED_VALUE"""),46094.0) -> 46094
B19: =IFERROR(__xludf.DUMMYFUNCTION("""COMPUTED_VALUE"""),"حيدر المحاسب") -> حيدر المحاسب | C19: =IFERROR(__xludf.DUMMYFUNCTION("""COMPUTED_VALUE"""),0.0) -> 0 | D19: =IFERROR(__xludf.DUMMYFUNCTION("""COMPUTED_VALUE"""),182000.0) -> 182000 | E19: =IFERROR(__xludf.DUMMYFUNCTION("""COMPUTED_VALUE"""),25000.0) -> 25000 | F19: =IFERROR(__xludf.DUMMYFUNCTION("""COMPUTED_VALUE"""),350000.0) -> 350000 | G19: =IFERROR(__xludf.DUMMYFUNCTION("""COMPUTED_VALUE"""),143000.0) -> 143000 | I19: =IFERROR(__xludf.DUMMYFUNCTION("""COMPUTED_VALUE"""),46096.0) -> 46096

Sheet الديون
A1: الاسم | B1: نوع الدين | C1: المبلغ | D1: المسدد | E1: المتبقي | F1: علينا | G1: لنا
F2: =SUMIFS(E:E,B:B,"علينا") -> 19012000 | G2: =SUMIFS(E:E,B:B,"لنا") -> 10098250
A3: يوسف يعقوب | B3: علينا | C3: =SUMIFS('السجل'!C:C,'السجل'!B:B,A3) -> 45370000 | D3: =SUMIFS('السجل'!D:D,'السجل'!B:B,A3) -> 26455000 | E3: =IF(C3="","",C3-IF(D3="",0,D3)) -> 18915000
A4: نعيم حديد | B4: علينا | C4: =SUMIFS('السجل'!C:C,'السجل'!B:B,A4) -> 6181000 | D4: =SUMIFS('السجل'!D:D,'السجل'!B:B,A4) -> 6180000 | E4: =IF(C4="","",C4-IF(D4="",0,D4)) -> 1000
A5: الابرار | B5: علينا | C5: =SUMIFS('السجل'!C:C,'السجل'!B:B,A5) -> 9201000 | D5: =SUMIFS('السجل'!D:D,'السجل'!B:B,A5) -> 9200000 | E5: =IF(C5="","",C5-IF(D5="",0,D5)) -> 1000
A6: حسين سالم | B6: لنا | C6: =SUMIFS('السجل'!C:C,'السجل'!B:B,A6) -> 2724750 | D6: =SUMIFS('السجل'!D:D,'السجل'!B:B,A6) -> 542000 | E6: =IF(C6="","",C6-IF(D6="",0,D6)) -> 2182750
A7: حيدر يافوز | B7: لنا | C7: =SUMIFS('السجل'!C:C,'السجل'!B:B,A7) -> 954000 | D7: =SUMIFS('السجل'!D:D,'السجل'!B:B,A7) -> 367000 | E7: =IF(C7="","",C7-IF(D7="",0,D7)) -> 587000
A8: خضر عبد الخالق | B8: لنا | C8: =SUMIFS('السجل'!C:C,'السجل'!B:B,A8) -> 998500 | D8: =SUMIFS('السجل'!D:D,'السجل'!B:B,A8) -> 345000 | E8: =IF(C8="","",C8-IF(D8="",0,D8)) -> 653500
A9: حنان | B9: لنا | C9: =SUMIFS('السجل'!C:C,'السجل'!B:B,A9) -> 1500000 | D9: =SUMIFS('السجل'!D:D,'السجل'!B:B,A9) -> 350000 | E9: =IF(C9="","",C9-IF(D9="",0,D9)) -> 1150000
A10: اشرف | B10: لنا | C10: =SUMIFS('السجل'!C:C,'السجل'!B:B,A10) -> 6000000 | D10: =SUMIFS('السجل'!D:D,'السجل'!B:B,A10) -> 750000 | E10: =IF(C10="","",C10-IF(D10="",0,D10)) -> 5250000
A11: الماجد لتجارة الاخشاب | B11: علينا | C11: =SUMIFS('السجل'!C:C,'السجل'!B:B,A11) -> 435000 | D11: =SUMIFS('السجل'!D:D,'السجل'!B:B,A11) -> 435000 | E11: =IF(C11="","",C11-IF(D11="",0,D11)) -> 0
A12: الفردان التجارية | B12: علينا | C12: =SUMIFS('السجل'!C:C,'السجل'!B:B,A12) -> 53000 | D12: =SUMIFS('السجل'!D:D,'السجل'!B:B,A12) -> 53000 | E12: =IF(C12="","",C12-IF(D12="",0,D12)) -> 0
A13: نعيم السراي للاضائة الحديثة | B13: علينا | C13: =SUMIFS('السجل'!C:C,'السجل'!B:B,A13) -> 45000 | D13: =SUMIFS('السجل'!D:D,'السجل'!B:B,A13) -> 0 | E13: =IF(C13="","",C13-IF(D13="",0,D13)) -> 45000
A14: الخورة | B14: علينا | C14: =SUMIFS('السجل'!C:C,'السجل'!B:B,A14) -> 50000 | D14: =SUMIFS('السجل'!D:D,'السجل'!B:B,A14) -> 0 | E14: =IF(C14="","",C14-IF(D14="",0,D14)) -> 50000
... A16: عبود | B16: لنا | C16: =SUMIFS('السجل'!C:C,'السجل'!B:B,A16) -> 10000 | D16: =SUMIFS('السجل'!D:D,'السجل'!B:B,A16) -> 0 | E16: =IF(C16="","",C16-IF(D16="",0,D16)) -> 10000
C17: =SUMIFS('السجل'!C:C,'السجل'!B:B,A17) -> 0 | D17: =SUMIFS('السجل'!D:D,'السجل'!B:B,A17) -> 0 | E17: =IF(C17="","",C17-IF(D17="",0,D17)) -> 0
C18: =SUMIFS('السجل'!C:C,'السجل'!B:B,A18) -> 0 | D18: =SUMIFS('السجل'!D:D,'السجل'!B:B,A18) -> 0 | E18: =IF(C18="","",C18-IF(D18="",0,D18)) -> 0
C19: =SUMIFS('السجل'!C:C,'السجل'!B:B,A19) -> 0 | D19: =SUMIFS('السجل'!D:D,'السجل'!B:B,A19) -> 0 | E19: =IF(C19="","",C19-IF(D19="",0,D19)) -> 0
C20: =SUMIFS('السجل'!C:C,'السجل'!B:B,A20) -> 0 | D20: =SUMIFS('السجل'!D:D,'السجل'!B:B,A20) -> 0 | E20: =IF(C20="","",C20-IF(D20="",0,D20)) -> 0
C21: =SUMIFS('السجل'!C:C,'السجل'!B:B,A21) -> 0 | D21: =SUMIFS('السجل'!D:D,'السجل'!B:B,A21) -> 0 | E21: =IF(C21="","",C21-IF(D21="",0,D21)) -> 0
C22: =SUMIFS('السجل'!C:C,'السجل'!B:B,A22) -> 0 | D22: =SUMIFS('السجل'!D:D,'السجل'!B:B,A22) -> 0 | E22: =IF(C22="","",C22-IF(D22="",0,D22)) -> 0
C23: =SUMIFS('السجل'!C:C,'السجل'!B:B,A23) -> 0 | D23: =SUMIFS('السجل'!D:D,'السجل'!B:B,A23) -> 0 | E23: =IF(C23="","",C23-IF(D23="",0,D23)) -> 0
C24: =SUMIFS('السجل'!C:C,'السجل'!B:B,A24) -> 0 | D24: =SUMIFS('السجل'!D:D,'السجل'!B:B,A24) -> 0 | E24: =IF(C24="","",C24-IF(D24="",0,D24)) -> 0
C25: =SUMIFS('السجل'!C:C,'السجل'!B:B,A25) -> 0 | D25: =SUMIFS('السجل'!D:D,'السجل'!B:B,A25) -> 0 | E25: =IF(C25="","",C25-IF(D25="",0,D25)) -> 0
C26: =SUMIFS('السجل'!C:C,'السجل'!B:B,A26) -> 0 | D26: =SUMIFS('السجل'!D:D,'السجل'!B:B,A26) -> 0 | E26: =IF(C26="","",C26-IF(D26="",0,D26)) -> 0
C27: =SUMIFS('السجل'!C:C,'السجل'!B:B,A27) -> 0 | D27: =SUMIFS('السجل'!D:D,'السجل'!B:B,A27) -> 0 | E27: =IF(C27="","",C27-IF(D27="",0,D27)) -> 0
C28: =SUMIFS('السجل'!C:C,'السجل'!B:B,A28) -> 0 | D28: =SUMIFS('السجل'!D:D,'السجل'!B:B,A28) -> 0 | E28: =IF(C28="","",C28-IF(D28="",0,D28)) -> 0
... C32: =SUMIFS('السجل'!C:C,'السجل'!B:B,A32) -> 0 | D32: =SUMIFS('السجل'!D:D,'السجل'!B:B,A32) -> 0 | E32: =IF(C32="","",C32-IF(D32="",0,D32)) -> 0

Sheet كشف حساب
A1: كشف حساب الابرار لشهر فبراير
C4: =SUM(C6:C18) -> 8095000 | D4: =SUM(D6:D16) -> 7000000 | E4: =E16 -> 1065000
A5: التاريخ | B5: رقم الوصل | C5: قيمة الوصولات خلال شهر فبراير | D5: المدفوع | E5: المتبقي | F5: قيمة الطلب السابق
A6: 46054 | B6: متبقي 2025 | C6: 2139000 | D6: 2000000 | E6: =C6-D6 -> 139000 | F6: =C6 -> 2139000
A7: 46055 | B7: 2087 | C7: 666000 | D7: 0 | E7: =E6+C7-D7 -> 805000 | F7: =F6+C7 -> 2805000
A8: 46056 | B8: 2114 | C8: 1557000 | D8: 0 | E8: =E7+C8-D8 -> 2362000 | F8: =F7+C8 -> 4362000
A9: 46058 | B9: 2180 | C9: 967000 | D9: 2000000 | E9: =E8+C9-D9 -> 1329000 | F9: =F8+C9 -> 5329000
A10: 46060 | B10: 2190 | C10: 260000 | D10: 0 | E10: =E9+C10-D10 -> 1589000 | F10: =F9+C10 -> 5589000
A11: 46069 | B11: 2500 | C11: 287000 | D11: 1000000 | E11: =E10+C11-D11 -> 876000 | F11: =F10+C11 -> 5876000
A12: 46072 | B12: 2597 | C12: 814000 | D12: 0 | E12: =E11+C12-D12 -> 1690000 | F12: =F11+C12 -> 6690000
A13: 46075 | B13: 2644 | C13: 170000 | D13: 0 | E13: =E12+C13-D13 -> 1860000 | F13: =F12+C13 -> 6860000
A14: 46079 | B14: 2768 | C14: 485000 | D14: 2000000 | E14: =E13+C14-D14 -> 345000 | F14: =F13+C14 -> 7345000
A15: 46086 | B15: 2902 | C15: 232000 | D15: 0 | E15: =E14+C15-D15 -> 577000 | F15: =F14+C15 -> 7577000
A16: 46089 | B16: 2945 | C16: 488000 | D16: 0 | E16: =E15+C16-D16 -> 1065000 | F16: =F15+C16 -> 8065000
A17: 46090 | B17: 2958 | C17: 30000 | D17: 0 | E17: =E16+C17-D17 -> 1095000 | F17: =F16+C17 -> 8095000

Sheet السجل
A1: التأريخ | B1: العمود 1 | C1: العمود 2 | D1: العمود 3 | E1: العمود 4 | F1: العمود 5
B2: نعيم حديد | C2: 3756000 | D2: 2835000 | E2: =IF(C2="","",C2-IF(D2="",0,D2)) -> 921000
A3: 46054 | B3: الابرار | C3: 2139000 | D3: 2000000 | E3: =IF(C3="","",C3-IF(D3="",0,D3)) -> 139000
A4: 46055 | B4: الابرار | C4: 666000 | E4: =IF(C4="","",C4-IF(D4="",0,D4)) -> 666000
A5: 46056 | B5: الابرار | C5: 1557000 | E5: =IF(C5="","",C5-IF(D5="",0,D5)) -> 1557000
A6: 46058 | B6: الابرار | C6: 967000 | E6: =IF(C6="","",C6-IF(D6="",0,D6)) -> 967000
A7: 46060 | B7: الابرار | C7: 260000 | E7: =IF(C7="","",C7-IF(D7="",0,D7)) -> 260000
A8: 46069 | B8: الابرار | C8: 287000 | D8: 2000000 | E8: =IF(C8="","",C8-IF(D8="",0,D8)) -> -1713000
A9: 46072 | B9: الابرار | C9: 814000 | E9: =IF(C9="","",C9-IF(D9="",0,D9)) -> 814000
A10: 46075 | B10: الابرار | C10: 170000 | D10: 1000000 | E10: =IF(C10="","",C10-IF(D10="",0,D10)) -> -830000
A11: 46079 | B11: الابرار | C11: 485000 | E11: =IF(C11="","",C11-IF(D11="",0,D11)) -> 485000
A12: 46086 | B12: الابرار | C12: 232000 | D12: 2000000 | E12: =IF(C12="","",C12-IF(D12="",0,D12)) -> -1768000
A13: 46089 | B13: الابرار | C13: 488000 | E13: =IF(C13="","",C13-IF(D13="",0,D13)) -> 488000
A14: 46084 | B14: حسين سالم | C14: 2518000 | D14: 542000 | E14: =IF(C14="","",C14-IF(D14="",0,D14)) -> 1976000
A15: 46082 | B15: حيدر يافوز | C15: 601000 | D15: 367000 | E15: =IF(C15="","",C15-IF(D15="",0,D15)) -> 234000
A16: 46082 | B16: خضر عبد الخالق | C16: 910000 | D16: 345000 | E16: =IF(C16="","",C16-IF(D16="",0,D16)) -> 565000
B17: حنان | C17: 500000 | D17: 350000 | E17: =IF(C17="","",C17-IF(D17="",0,D17)) -> 150000
B18: حنان | C18: 170000 | E18: =IF(C18="","",C18-IF(D18="",0,D18)) -> 170000
B19: حنان | C19: 250000 | E19: =IF(C19="","",C19-IF(D19="",0,D19)) -> 250000
B20: حنان | C20: 580000 | E20: =IF(C20="","",C20-IF(D20="",0,D20)) -> 580000
B21: يوسف يعقوب | C21: 6019000 | D21: 1375000 | E21: =IF(C21="","",C21-IF(D21="",0,D21)) -> 4644000
B22: يوسف يعقوب | C22: 5000000 | D22: 7305000 | E22: =IF(C22="","",C22-IF(D22="",0,D22)) -> -2305000
B23: يوسف يعقوب | C23: 5000000 | D23: 2000000 | E23: =IF(C23="","",C23-IF(D23="",0,D23)) -> 3000000
B24: يوسف يعقوب | C24: 1000000 | D24: 5000000 | E24: =IF(C24="","",C24-IF(D24="",0,D24)) -> -4000000
B25: يوسف يعقوب | C25: 1000000 | D25: 10000000 | E25: =IF(C25="","",C25-IF(D25="",0,D25)) -> -9000000
B26: يوسف يعقوب | C26: 12675000 | D26: 775000 | E26: =IF(C26="","",C26-IF(D26="",0,D26)) -> 11900000
B27: يوسف يعقوب | C27: 1090000 | E27: =IF(C27="","",C27-IF(D27="",0,D27)) -> 1090000
B28: يوسف يعقوب | C28: 325000 | E28: =IF(C28="","",C28-IF(D28="",0,D28)) -> 325000
B29: يوسف يعقوب | C29: 595000 | E29: =IF(C29="","",C29-IF(D29="",0,D29)) -> 595000
B30: يوسف يعقوب | C30: 485000 | E30: =IF(C30="","",C30-IF(D30="",0,D30)) -> 485000
B31: يوسف يعقوب | C31: 293000 | E31: =IF(C31="","",C31-IF(D31="",0,D31)) -> 293000
B32: يوسف يعقوب | C32: 148000 | E32: =IF(C32="","",C32-IF(D32="",0,D32)) -> 148000
B33: يوسف يعقوب | C33: 80000 | E33: =IF(C33="","",C33-IF(D33="",0,D33)) -> 80000
B34: يوسف يعقوب | C34: 45000 | E34: =IF(C34="","",C34-IF(D34="",0,D34)) -> 45000
B35: يوسف يعقوب | C35: 17000 | E35: =IF(C35="","",C35-IF(D35="",0,D35)) -> 17000
B36: يوسف يعقوب | C36: 85000 | E36: =IF(C36="","",C36-IF(D36="",0,D36)) -> 85000
B37: يوسف يعقوب | C37: 1375000 | E37: =IF(C37="","",C37-IF(D37="",0,D37)) -> 1375000
B38: يوسف يعقوب | C38: 50000 | E38: =IF(C38="","",C38-IF(D38="",0,D38)) -> 50000
... B62: يوسف يعقوب | C62: 87000 | E62: =IF(C62="","",C62-IF(D62="",0,D62)) -> 87000
B63: اشرف | C63: 2280750 | D63: 750000 | E63: =IF(C63="","",C63-IF(D63="",0,D63)) -> 1530750
...

Sheet الحركات
E1: =SUM(E4:E1007) -> 22343000 | F1: =SUM(F4:F1007) -> 21558000
A2: التاريخ | B2: نوع العملية | C2: =E1-F1 -> 785000 | D2: المبلغ بالدينار | E2: داخل | F2: خارج | G2: الصارف | H2: دفع | I2: الحركة اليومية للقاصة | J2: FALSE | K2: رقم المستند
A3: 46037 | B3: سند دفع | C3: سمنت مقاوم 100 . حصو + رمل 110 . جاي 5 | D3: 0 | E3: 0 | F3: 0 | G3: JOZYF | H3: 212000 | I3: 0 | K3: 1
A4: 46037 | B4: سلفة | C4: علي الباكستاني | D4: 0 | E4: 0 | F4: 0 | G4: JOZYF | H4: 10000 | I4: =I3+D4 -> 0
A5: 46038 | B5: سند دفع | C5: مبلغ تسديد الابرار | D5: 0 | E5: 0 | F5: 0 | G5: SIFE | H5: 2000000 | I5: =I4+D5 -> 0 | K5: 2
A6: 46039 | B6: سند دفع | C6: تسديد حساب فاتورة | D6: 0 | E6: 0 | F6: 0 | G6: SIFE | H6: 176000 | I6: =I5+D6 -> 0 | K6: 3
A7: 46039 | B7: سند دفع | C7: سلفف الى حسين من يوسف راتب حسين شهر 12 | D7: 0 | E7: 0 | F7: 0 | G7: JOZYF | H7: 1300000 | I7: =I6+D7 -> 0
A8: 46040 | B8: سند دفع | C8: تسديد نعيم | D8: 0 | E8: 0 | F8: 0 | G8: SIFE | H8: 1000000 | I8: =I7+D8 -> 0 | K8: 4
A9: 46041 | B9: سند دفع | C9: تسديد يوسف | D9: 0 | E9: 0 | F9: 0 | G9: SIFE | H9: 776000 | I9: =I8+D9 -> 0 | K9: 5
A10: 46041 | B10: سند قبض | C10: من سيف | D10: 2893000 | E10: 2893000 | F10: 0 | G10: SIFE | H10: 2893000 | I10: =I9+D10 -> 2893000
A11: 46041 | B11: سند صرف | C11: تصليح ماييكرو | D11: -30000 | E11: 0 | F11: 30000 | G11: HUSSEN | H11: 0 | I11: =I10+D11 -> 2863000 | K11: 22
A12: 46041 | B12: سند صرف | D12: -2000 | E12: 0 | F12: 2000 | G12: HUSSEN | H12: 0 | I12: =I11+D12 -> 2861000 | K12: 23
A13: 46041 | B13: سند صرف | C13: بانزين | D13: -10000 | E13: 0 | F13: 10000 | G13: HUSSEN | H13: 0 | I13: =I12+D13 -> 2851000 | K13: 24
A14: 46041 | B14: سند صرف | C14: تصليح مواد | D14: -60000 | E14: 0 | F14: 60000 | G14: HUSSEN | H14: 0 | I14: =I13+D14 -> 2791000 | K14: 25
A15: 46041 | B15: سند صرف | C15: اجرة | D15: -15000 | E15: 0 | F15: 15000 | G15: HUSSEN | H15: 0 | I15: =I14+D15 -> 2776000 | K15: 26
A16: 46041 | B16: سند صرف | C16: اجرة | D16: -7000 | E16: 0 | F16: 7000 | G16: HUSSEN | H16: 0 | I16: =I15+D16 -> 2769000 | K16: 27
A17: 46041 | B17: سلفة | C17: يافوز | D17: -5000 | E17: 0 | F17: 5000 | G17: HUSSEN | H17: 0 | I17: =I16+D17 -> 2764000 | K17: 30
A18: 46041 | B18: سند صرف | C18: براغي | D18: -5000 | E18: 0 | F18: 5000 | G18: HUSSEN | H18: 0 | I18: =I17+D18 -> 2759000 | K18: 31
A19: 46041 | B19: سند صرف | C19: تصليح مواد | D19: -60000 | E19: 0 | F19: 60000 | G19: HUSSEN | H19: 0 | I19: =I18+D19 -> 2699000 | K19: 52
A20: 46041 | B20: سلفة | C20: يافوز | D20: -5000 | E20: 0 | F20: 5000 | G20: HUSSEN | H20: 0 | I20: =I19+D20 -> 2694000 | K20: 56
A21: 46041 | B21: سلفة | C21: حسين سالم | D21: -5000 | E21: 0 | F21: 5000 | G21: HUSSEN | H21: 0 | I21: =I20+D21 -> 2689000 | K21: 51
A22: 46041 | B22: سلفة | C22: حسين سالم | D22: -25000 | E22: 0 | F22: 25000 | G22: HUSSEN | H22: 0 | I22: =I21+D22 -> 2664000 | K22: 53
A23: 46041 | B23: سلفة | C23: حيدر محمد | D23: -10000 | E23: 0 | F23: 10000 | G23: HUSSEN | H23: 0 | I23: =I22+D23 -> 2654000 | K23: 55
A24: 46041 | B24: سلفة | C24: حيدر محمد | D24: -10000 | E24: 0 | F24: 10000 | G24: HUSSEN | H24: 0 | I24: =I23+D24 -> 2644000 | K24: 29
... A74: 46054 | B74: سند دفع | C74: تسديد الابرار | D74: 0 | E74: 0 | F74: 0 | G74: SIFE | H74: 1000000 | I74: =I73+D74 -> 471500 | K74: 15
A75: 46054 | B75: سند دفع | C75: تسديد الابرار | D75: 0 | E75: 0 | F75: 0 | G75: SIFE | H75: 1000000 | I75: =I74+D75 -> 471500
A76: 46055 | B76: سلفة | C76: حيدر محمد | D76: -5000 | E76: 0 | F76: 5000 | G76: HUSSEN | H76: 0 | I76: =I75+D76 -> 466500 | K76: 87
A77: 46055 | B77: سند قبض | C77: صرف ورشه | D77: 1000000 | E77: 1000000 | F77: 0 | G77: SIFE | H77: 1000000 | I77: =I76+D77 -> 1466500 | K77: 48
A78: 46055 | B78: راتب | C78: حسين سالم | D78: -750000 | E78: 0 | F78: 750000 | G78: HUSSEN | H78: 0 | I78: =I77+D78 -> 716500 | K78: 80
A79: 46055 | B79: سلفة | C79: حسين سالم | D79: -5000 | E79: 0 | F79: 5000 | G79: HUSSEN | H79: 0 | I79: =I78+D79 -> 711500 | K79: 89
A80: 46055 | B80: سلفة | C80: حسين سالم | D80: -10000 | E80: 0 | F80: 10000 | G80: HUSSEN | H80: 0 | I80: =I79+D80 -> 701500 | K80: 92
A81: 46055 | B81: سند صرف | C81: اجرة الابرار | D81: -10000 | E81: 0 | F81: 10000 | G81: HUSSEN | H81: 0 | I81: =I80+D81 -> 691500 | K81: 16
A82: 46055 | B82: سند صرف | C82: اجرة | D82: -10000 | E82: 0 | F82: 10000 | G82: HUSSEN | H82: 0 | I82: =I81+D82 -> 681500 | K82: 76
A83: 46055 | B83: سند صرف | C83: اجرة | D83: -7000 | E83: 0 | F83: 7000 | G83: HUSSEN | H83: 0 | I83: =I82+D83 -> 674500 | K83: 77
A84: 46055 | B84: سند صرف | C84: جاي و شكر | D84: -5000 | E84: 0 | F84: 5000 | G84: HUSSEN | H84: 0 | I84: =I83+D84 -> 669500 | K84: 78
A85: 46055 | B85: سند صرف | C85: معجون | D85: -6000 | E85: 0 | F85: 6000 | G85: HUSSEN | H85: 0 | I85: =I84+D85 -> 663500 | K85: 79
A86: 46055 | B86: سند صرف | C86: اجرة حروف | D86: -40000 | E86: 0 | F86: 40000 | G86: HUSSEN | H86: 0 | I86: =I85+D86 -> 623500 | K86: 83
A87: 46055 | B87: سند صرف | C87: شركة | D87: -10000 | E87: 0 | F87: 10000 | G87: HUSSEN | H87: 0 | I87: =I86+D87 -> 613500 | K87: 90
... A166: 46063 | B166: سلفة | C166: غداء | D166: -10000 | E166: 0 | F166: 10000 | G166: HUSSEN | H166: 0 | I166: =I165+D166 -> -54500 | K166: 175
A167: 46063 | B167: سند دفع | C167: تسديد الابرار | D167: 0 | E167: 0 | F167: 0 | G167: SIFE | H167: 2000000 | I167: =I166+D167 -> -54500
...

Sheet واردات
A1: المجموع | B1: المدفوع | C1: المتبقي
A2: =sum(B4:B14) -> 57450000 | B2: =SUMIFS('الحركات'!H:H,'الحركات'!G:G,"SIFE") -> 38610000 | C2: =SUM(B4:B14)-B2 -> 18840000
A3: التاريخ | B3: واردات مشاريع | C3: المصدر
A4: 46053 | B4: 30000000 | C4: بلدية البصرة
A5: 46054 | B5: 500000 | C5: متبقي الميز الرصاصي
A6: 46081 | B6: 20000000 | C6: بلدية البصرة
A7: 46106 | B7: 5225000 | C7: اكاديمية ياس التعليميه
A8: 46109 | B8: 1725000 | C8: متبقي فايبر اكس

Sheet حضور 
A1: الاسم | B1: التأريخ | C1: اليوم | D1: الراتب الاسمي | E1: دخول | F1: خروج | G1: ساعات حضور | H1: ايام حضور | I1: سعر الساعة | J1: غرامات | K1: السلفة | L1: مكافئات | M1: الراتب اليومي
A2: خضر عبد الخالق | B2: 46011 | C2: 46011 | D2: 650000 | E2: 0.33333333 | F2: 0.83333333 | G2: =IF(AND(E2<>"",F2<>""),(F2-E2)*24,"") -> 12 | H2: =IF(A2<>"",1,"") -> 1 | I2: =D2/30/9 -> 2407.4074 | M2: =G2*I2 -> 28888.889
A3: خضر عبد الخالق | B3: 46012 | C3: 46012 | D3: 650000 | E3: 0.33333333 | F3: 0.70833333 | G3: =IF(AND(E3<>"",F3<>""),(F3-E3)*24,"") -> 9 | H3: =IF(A3<>"",1,"") -> 1 | I3: =D3/30/9 -> 2407.4074 | M3: =G3*I3 -> 21666.667
A4: خضر عبد الخالق | B4: 46013 | C4: 46013 | D4: 650000 | E4: 0.33333333 | F4: 0.70833333 | G4: =IF(AND(E4<>"",F4<>""),(F4-E4)*24,"") -> 9 | H4: =IF(A4<>"",1,"") -> 1 | I4: =D4/30/9 -> 2407.4074 | M4: =G4*I4 -> 21666.667
A5: خضر عبد الخالق | B5: 46014 | C5: 46014 | D5: 650000 | E5: 0.33333333 | F5: 0.70833333 | G5: =IF(AND(E5<>"",F5<>""),(F5-E5)*24,"") -> 9 | H5: =IF(A5<>"",1,"") -> 1 | I5: =D5/30/9 -> 2407.4074 | M5: =G5*I5 -> 21666.667
A6: خضر عبد الخالق | B6: 46015 | C6: 46015 | D6: 650000 | E6: 0.33333333 | F6: 0.70833333 | G6: =IF(AND(E6<>"",F6<>""),(F6-E6)*24,"") -> 9 | H6: =IF(A6<>"",1,"") -> 1 | I6: =D6/30/9 -> 2407.4074 | M6: =G6*I6 -> 21666.667
A7: خضر عبد الخالق | B7: 46016 | C7: 46016 | D7: 650000 | E7: 0.33333333 | F7: 0.70833333 | G7: =IF(AND(E7<>"",F7<>""),(F7-E7)*24,"") -> 9 | H7: =IF(A7<>"",1,"") -> 1 | I7: =D7/30/9 -> 2407.4074 | M7: =G7*I7 -> 21666.667
A8: خضر عبد الخالق | B8: 46018 | C8: 46018 | D8: 650000 | E8: 0.33333333 | F8: 0.70833333 | G8: =IF(AND(E8<>"",F8<>""),(F8-E8)*24,"") -> 9 | H8: =IF(A8<>"",1,"") -> 1 | I8: =D8/30/9 -> 2407.4074 | M8: =G8*I8 -> 21666.667
A9: خضر عبد الخالق | B9: 46019 | C9: 46019 | D9: 650000 | E9: 0.33333333 | F9: 0.70833333 | G9: =IF(AND(E9<>"",F9<>""),(F9-E9)*24,"") -> 9 | H9: =IF(A9<>"",1,"") -> 1 | I9: =D9/30/9 -> 2407.4074 | M9: =G9*I9 -> 21666.667
A10: خضر عبد الخالق | B10: 46020 | C10: 46020 | D10: 650000 | E10: 0.33333333 | F10: 0.83333333 | G10: =IF(AND(E10<>"",F10<>""),(F10-E10)*24,"") -> 12 | H10: =IF(A10<>"",1,"") -> 1 | I10: =D10/30/9 -> 2407.4074 | M10: =G10*I10 -> 28888.889
A11: خضر عبد الخالق | B11: 46021 | C11: 46021 | D11: 650000 | E11: 0.33333333 | F11: 0.70833333 | G11: =IF(AND(E11<>"",F11<>""),(F11-E11)*24,"") -> 9 | H11: =IF(A11<>"",1,"") -> 1 | I11: =D11/30/9 -> 2407.4074 | M11: =G11*I11 -> 21666.667
A12: خضر عبد الخالق | B12: 46022 | C12: 46022 | D12: 650000 | E12: 0.375 | F12: 0.70833333 | G12: =IF(AND(E12<>"",F12<>""),(F12-E12)*24,"") -> 8 | H12: =IF(A12<>"",1,"") -> 1 | I12: =D12/30/9 -> 2407.4074 | M12: =G12*I12 -> 19259.259
A13: حيدر المحاسب | B13: 46023 | C13: 46023 | D13: 350000 | E13: 0.33333333 | F13: 0.70833333 | G13: =IF(AND(E13<>"",F13<>""),(F13-E13)*24,"") -> 9 | H13: =IF(A13<>"",1,"") -> 1 | I13: =D13/30/9 -> 1296.2963 | M13: =G13*I13 -> 11666.667
A14: علي الباكستاني | B14: 46023 | C14: 46023 | D14: 500000 | E14: 0.33333333 | F14: 0.70833333 | G14: =IF(AND(E14<>"",F14<>""),(F14-E14)*24,"") -> 9 | H14: =IF(A14<>"",1,"") -> 1 | I14: =D14/26/9 -> 2136.7521 | M14: =G14*I14 -> 19230.769
A15: خضر عبد الخالق | B15: 46024 | C15: 46024 | D15: 650000 | E15: 0.75 | F15: 0.83333333 | G15: =IF(AND(E15<>"",F15<>""),(F15-E15)*24,"") -> 2 | H15: =IF(A15<>"",1,"") -> 1 | I15: =D15/30/9 -> 2407.4074 | M15: =G15*I15 -> 4814.8148
A16: علي الباكستاني | B16: 46024 | C16: 46024 | D16: 500000 | E16: 0.33333333 | F16: 0.70833333 | G16: =IF(AND(E16<>"",F16<>""),(F16-E16)*24,"") -> 9 | H16: =IF(A16<>"",1,"") -> 1 | I16: =D16/26/9 -> 2136.7521 | M16: =G16*I16 -> 19230.769
A17: حسين سالم | B17: 46025 | C17: 46025 | D17: 850000 | E17: 0.55694444 | F17: 0.87291667 | G17: =IF(AND(E17<>"",F17<>""),(F17-E17)*24,"") -> 7.5833333 | H17: =IF(A17<>"",1,"") -> 1 | I17: =D17/30/9 -> 3148.1481 | M17: =G17*I17 -> 23873.457
A18: حيدر يافوز | B18: 46025 | C18: 46025 | D18: 550000 | E18: 0.36805556 | F18: 0.92222222 | G18: =IF(AND(E18<>"",F18<>""),(F18-E18)*24,"") -> 13.3 | H18: =IF(A18<>"",1,"") -> 1 | I18: =D18/30/9 -> 2037.037 | K18: 43000 | M18: =G18*I18 -> 27092.593
A19: خضر عبد الخالق | B19: 46025 | C19: 46025 | D19: 650000 | E19: 0.33333333 | F19: 0.70833333 | G19: =IF(AND(E19<>"",F19<>""),(F19-E19)*24,"") -> 9 | H19: =IF(A19<>"",1,"") -> 1 | I19: =D19/30/9 -> 2407.4074 | M19: =G19*I19 -> 21666.667
A20: حيدر المحاسب | B20: 46025 | C20: 46025 | D20: 350000 | E20: 0.33333333 | F20: 0.70833333 | G20: =IF(AND(E20<>"",F20<>""),(F20-E20)*24,"") -> 9 | H20: =IF(A20<>"",1,"") -> 1 | I20: =D20/30/9 -> 1296.2963 | M20: =G20*I20 -> 11666.667
A21: علي الباكستاني | B21: 46025 | C21: 46025 | D21: 500000 | E21: 0.33333333 | F21: 0.70833333 | G21: =IF(AND(E21<>"",F21<>""),(F21-E21)*24,"") -> 9 | H21: =IF(A21<>"",1,"") -> 1 | I21: =D21/26/9 -> 2136.7521 | M21: =G21*I21 -> 19230.769
A22: حسين سالم | B22: 46026 | C22: 46026 | D22: 850000 | E22: 0.47152778 | F22: 0.92986111 | G22: =IF(AND(E22<>"",F22<>""),(F22-E22)*24,"") -> 11 | H22: =IF(A22<>"",1,"") -> 1 | I22: =D22/30/9 -> 3148.1481 | M22: =G22*I22 -> 34629.63
A23: حيدر يافوز | B23: 46026 | C23: 46026 | D23: 550000 | E23: 0.40972222 | F23: 0.92222222 | G23: =IF(AND(E23<>"",F23<>""),(F23-E23)*24,"") -> 12.3 | H23: =IF(A23<>"",1,"") -> 1 | I23: =D23/30/9 -> 2037.037 | K23: 80000 | M23: =G23*I23 -> 25055.556
A24: خضر عبد الخالق | B24: 46026 | C24: 46026 | D24: 650000 | E24: 0.33333333 | F24: 0.70833333 | G24: =IF(AND(E24<>"",F24<>""),(F24-E24)*24,"") -> 9 | H24: =IF(A24<>"",1,"") -> 1 | I24: =D24/30/9 -> 2407.4074 | M24: =G24*I24 -> 21666.667
A25: حيدر المحاسب | B25: 46026 | C25: 46026 | D25: 350000 | E25: 0.33333333 | F25: 0.70833333 | G25: =IF(AND(E25<>"",F25<>""),(F25-E25)*24,"") -> 9 | H25: =IF(A25<>"",1,"") -> 1 | I25: =D25/30/9 -> 1296.2963 | M25: =G25*I25 -> 11666.667
A26: علي الباكستاني | B26: 46026 | C26: 46026 | D26: 500000 | E26: 0.33333333 | F26: 0.70833333 | G26: =IF(AND(E26<>"",F26<>""),(F26-E26)*24,"") -> 9 | H26: =IF(A26<>"",1,"") -> 1 | I26: =D26/26/9 -> 2136.7521 | M26: =G26*I26 -> 19230.769
A27: حسين سالم | B27: 46027 | C27: 46027 | D27: 850000 | E27: 0.33333333 | F27: 0.8 | G27: =IF(AND(E27<>"",F27<>""),(F27-E27)*24,"") -> 11.2 | H27: =IF(A27<>"",1,"") -> 1 | I27: =D27/30/9 -> 3148.1481 | M27: =G27*I27 -> 35259.259
A28: حيدر يافوز | B28: 46027 | C28: 46027 | D28: 550000 | E28: 0.33333333 | F28: 0.70833333 | G28: =IF(AND(E28<>"",F28<>""),(F28-E28)*24,"") -> 9 | H28: =IF(A28<>"",1,"") -> 1 | I28: =D28/30/9 -> 2037.037 | K28: 10000 | M28: =G28*I28 -> 18333.333
A29: خضر عبد الخالق | B29: 46027 | C29: 46027 | D29: 650000 | E29: 0.33333333 | F29: 0.8125 | G29: =IF(AND(E29<>"",F29<>""),(F29-E29)*24,"") -> 11.5 | H29: =IF(A29<>"",1,"") -> 1 | I29: =D29/30/9 -> 2407.4074 | M29: =G29*I29 -> 27685.185
A30: حيدر المحاسب | B30: 46027 | C30: 46027 | D30: 350000 | E30: 0.33333333 | F30: 0.70833333 | G30: =IF(AND(E30<>"",F30<>""),(F30-E30)*24,"") -> 9 | H30: =IF(A30<>"",1,"") -> 1 | I30: =D30/30/9 -> 1296.2963 | M30: =G30*I30 -> 11666.667
A31: علي الباكستاني | B31: 46027 | C31: 46027 | D31: 500000 | E31: 0.33333333 | F31: 0.70833333 | G31: =IF(AND(E31<>"",F31<>""),(F31-E31)*24,"") -> 9 | H31: =IF(A31<>"",1,"") -> 1 | I31: =D31/26/9 -> 2136.7521 | M31: =G31*I31 -> 19230.769
A32: حسين سالم | B32: 46028 | C32: 46028 | D32: 850000 | E32: 0.44583333 | F32: 0.92222222 | G32: =IF(AND(E32<>"",F32<>""),(F32-E32)*24,"") -> 11.433333 | H32: =IF(A32<>"",1,"") -> 1 | I32: =D32/30/9 -> 3148.1481 | M32: =G32*I32 -> 35993.827
A33: حيدر يافوز | B33: 46028 | C33: 46028 | D33: 550000 | E33: 0.33333333 | F33: 0.70833333 | G33: =IF(AND(E33<>"",F33<>""),(F33-E33)*24,"") -> 9 | H33: =IF(A33<>"",1,"") -> 1 | I33: =D33/30/9 -> 2037.037 | K33: 85000 | M33: =G33*I33 -> 18333.333
A34: حيدر المحاسب | B34: 46028 | C34: 46028 | D34: 350000 | E34: 0.33333333 | F34: 0.70833333 | G34: =IF(AND(E34<>"",F34<>""),(F34-E34)*24,"") -> 9 | H34: =IF(A34<>"",1,"") -> 1 | I34: =D34/30/9 -> 1296.2963 | M34: =G34*I34 -> 11666.667
A35: علي الباكستاني | B35: 46028 | C35: 46028 | D35: 500000 | E35: 0.33333333 | F35: 0.70833333 | G35: =IF(AND(E35<>"",F35<>""),(F35-E35)*24,"") -> 9 | H35: =IF(A35<>"",1,"") -> 1 | I35: =D35/26/9 -> 2136.7521 | M35: =G35*I35 -> 19230.769
A36: حسين سالم | B36: 46029 | C36: 46029 | D36: 850000 | E36: 0.34583333 | F36: 0.92222222 | G36: =IF(AND(E36<>"",F36<>""),(F36-E36)*24,"") -> 13.833333 | H36: =IF(A36<>"",1,"") -> 1 | I36: =D36/30/9 -> 3148.1481 | M36: =G36*I36 -> 43549.383
A37: حيدر يافوز | B37: 46029 | C37: 46029 | D37: 550000 | E37: 0.33333333 | F37: 0.70833333 | G37: =IF(AND(E37<>"",F37<>""),(F37-E37)*24,"") -> 9 | H37: =IF(A37<>"",1,"") -> 1 | I37: =D37/30/9 -> 2037.037 | K37: 105000 | M37: =G37*I37 -> 18333.333
A38: خضر عبد الخالق | B38: 46029 | C38: 46029 | D38: 650000 | E38: 0.33333333 | F38: 0.70833333 | G38: =IF(AND(E38<>"",F38<>""),(F38-E38)*24,"") -> 9 | H38: =IF(A38<>"",1,"") -> 1 | I38: =D38/30/9 -> 2407.4074 | M38: =G38*I38 -> 21666.667
A39: حيدر المحاسب | B39: 46029 | C39: 46029 | D39: 350000 | E39: 0.33333333 | F39: 0.70833333 | G39: =IF(AND(E39<>"",F39<>""),(F39-E39)*24,"") -> 9 | H39: =IF(A39<>"",1,"") -> 1 | I39: =D39/30/9 -> 1296.2963 | M39: =G39*I39 -> 11666.667
A40: علي الباكستاني | B40: 46029 | C40: 46029 | D40: 500000 | E40: 0.33333333 | F40: 0.70833333 | G40: =IF(AND(E40<>"",F40<>""),(F40-E40)*24,"") -> 9 | H40: =IF(A40<>"",1,"") -> 1 | I40: =D40/26/9 -> 2136.7521 | M40: =G40*I40 -> 19230.769
...

Sheet رواتب
A1: 1 | B1: عدد الأيام | C1: عدد الساعات | D1: العمل الخارجي | E1: الاضافي | F1: الاجر | G1: إجمالي السلف | H1: الغرامات | I1: المكافئات | J1: الراتب الكلي | K1: صافي الراتب | L1: المستلم | M1: التاريخ | O1: =IFERROR(__xludf.DUMMYFUNCTION("IFERROR(AVERAGE(FILTER('حضور '!I:I,'حضور '!A:A=A1,MONTH('حضور '!B:B)=N1)),"""")"),"")
A2: حسين سالم | B2: =IFERROR(__xludf.DUMMYFUNCTION("COUNTA(UNIQUE(FILTER('حضور '!B:B,'حضور '!A:A=A2,'حضور '!B:B>=EOMONTH(M2,-1)+1,'حضور '!B:B<=EOMONTH(M2,0))))"),29.0) -> 29 | C2: =SUMIFS('حضور '!G:G,'حضور '!A:A,A2,'حضور '!B:B,">="&EOMONTH(M2,-1)+1,'حضور '!B:B,"<="&EOMONTH(M2,0)) -> 273.73333 | E2: =J2-F2 -> 40086.42 | F2: =B2*9*O2 -> 821666.67 | G2: =SUMIFS('حضور '!K:K,'حضور '!A:A,A2,'حضور '!B:B,">="&EOMONTH(M2,-1)+1,'حضور '!B:B,"<="&EOMONTH(M2,0)) -> 111000 | H2: =SUMIFS('حضور '!J:J,'حضور '!A:A,A2,'حضور '!B:B,">="&EOMONTH(M2,-1)+1,'حضور '!B:B,"<="&EOMONTH(M2,0)) -> 0 | I2: =SUMIFS('حضور '!L:L,'حضور '!A:A,A2,'حضور '!B:B,">="&EOMONTH(M2,-1)+1,'حضور '!B:B,"<="&EOMONTH(M2,0)) -> 0 | J2: =SUMIFS('حضور '!M:M,'حضور '!A:A,A2,'حضور '!B:B,">="&EOMONTH(M2,-1)+1,'حضور '!B:B,"<="&EOMONTH(M2,0)) -> 861753.09 | K2: =J2-G2-L2 -> 0.086420523 | L2: 750753 | M2: 46024 | N2: 1 | O2: =IFERROR(__xludf.DUMMYFUNCTION("IFERROR(AVERAGE(FILTER('حضور '!I:I,'حضور '!A:A=A2,MONTH('حضور '!B:B)=N2)),"""")"),3148.1481481481464) -> 3148.1481
A3: حيدر يافوز | B3: =IFERROR(__xludf.DUMMYFUNCTION("COUNTA(UNIQUE(FILTER('حضور '!B:B,'حضور '!A:A=A3,'حضور '!B:B>=EOMONTH(M3,-1)+1,'حضور '!B:B<=EOMONTH(M3,0))))"),25.0) -> 25 | C3: =SUMIFS('حضور '!G:G,'حضور '!A:A,A3,'حضور '!B:B,">="&EOMONTH(M3,-1)+1,'حضور '!B:B,"<="&EOMONTH(M3,0)) -> 232.23333 | E3: =J3-F3 -> 14734.568 | F3: =B3*9*O3 -> 458333.33 | G3: =SUMIFS('حضور '!K:K,'حضور '!A:A,A3,'حضور '!B:B,">="&EOMONTH(M3,-1)+1,'حضور '!B:B,"<="&EOMONTH(M3,0)) -> 353000 | H3: =SUMIFS('حضور '!J:J,'حضور '!A:A,A3,'حضور '!B:B,">="&EOMONTH(M3,-1)+1,'حضور '!B:B,"<="&EOMONTH(M3,0)) -> 0 | I3: =SUMIFS('حضور '!L:L,'حضور '!A:A,A3,'حضور '!B:B,">="&EOMONTH(M3,-1)+1,'حضور '!B:B,"<="&EOMONTH(M3,0)) -> 0 | J3: =SUMIFS('حضور '!M:M,'حضور '!A:A,A3,'حضور '!B:B,">="&EOMONTH(M3,-1)+1,'حضور '!B:B,"<="&EOMONTH(M3,0)) -> 473067.9 | K3: =J3-G3-L3 -> -179932.1 | L3: 300000 | M3: 46025 | N3: 1 | O3: =IFERROR(__xludf.DUMMYFUNCTION("IFERROR(AVERAGE(FILTER('حضور '!I:I,'حضور '!A:A=A3,MONTH('حضور '!B:B)=N3)),"""")"),2037.0370370370367) -> 2037.037
A4: خضر عبد الخالق | B4: =IFERROR(__xludf.DUMMYFUNCTION("COUNTA(UNIQUE(FILTER('حضور '!B:B,'حضور '!A:A=A4,'حضور '!B:B>=EOMONTH(M4,-1)+1,'حضور '!B:B<=EOMONTH(M4,0))))"),16.0) -> 16 | C4: =SUMIFS('حضور '!G:G,'حضور '!A:A,A4,'حضور '!B:B,">="&EOMONTH(M4,-1)+1,'حضور '!B:B,"<="&EOMONTH(M4,0)) -> 141.68333 | E4: =J4-F4 -> -5577.1605 | F4: =B4*9*O4 -> 346666.67 | G4: =SUMIFS('حضور '!K:K,'حضور '!A:A,A4,'حضور '!B:B,">="&EOMONTH(M4,-1)+1,'حضور '!B:B,"<="&EOMONTH(M4,0)) -> 0 | H4: =SUMIFS('حضور '!J:J,'حضور '!A:A,A4,'حضور '!B:B,">="&EOMONTH(M4,-1)+1,'حضور '!B:B,"<="&EOMONTH(M4,0)) -> 0 | I4: =SUMIFS('حضور '!L:L,'حضور '!A:A,A4,'حضور '!B:B,">="&EOMONTH(M4,-1)+1,'حضور '!B:B,"<="&EOMONTH(M4,0)) -> 0 | J4: =SUMIFS('حضور '!M:M,'حضور '!A:A,A4,'حضور '!B:B,">="&EOMONTH(M4,-1)+1,'حضور '!B:B,"<="&EOMONTH(M4,0)) -> 341089.51 | K4: 143000 | L4: 250000 | M4: 46027 | N4: 1 | O4: =IFERROR(__xludf.DUMMYFUNCTION("IFERROR(AVERAGE(FILTER('حضور '!I:I,'حضور '!A:A=A4,MONTH('حضور '!B:B)=N4)),"""")"),2407.407407407408) -> 2407.4074
A5: سجاد رعد | B5: =IFERROR(__xludf.DUMMYFUNCTION("COUNTA(UNIQUE(FILTER('حضور '!B:B,'حضور '!A:A=A5,'حضور '!B:B>=EOMONTH(M5,-1)+1,'حضور '!B:B<=EOMONTH(M5,0))))"),5.0) -> 5 | C5: =SUMIFS('حضور '!G:G,'حضور '!A:A,A5,'حضور '!B:B,">="&EOMONTH(M5,-1)+1,'حضور '!B:B,"<="&EOMONTH(M5,0)) -> 49.666667 | E5: =J5-F5 -> 10370.37 | F5: =B5*9*O5 -> 100000 | G5: =SUMIFS('حضور '!K:K,'حضور '!A:A,A5,'حضور '!B:B,">="&EOMONTH(M5,-1)+1,'حضور '!B:B,"<="&EOMONTH(M5,0)) -> 0 | H5: =SUMIFS('حضور '!J:J,'حضور '!A:A,A5,'حضور '!B:B,">="&EOMONTH(M5,-1)+1,'حضور '!B:B,"<="&EOMONTH(M5,0)) -> 0 | I5: =SUMIFS('حضور '!L:L,'حضور '!A:A,A5,'حضور '!B:B,">="&EOMONTH(M5,-1)+1,'حضور '!B:B,"<="&EOMONTH(M5,0)) -> 0 | J5: =SUMIFS('حضور '!M:M,'حضور '!A:A,A5,'حضور '!B:B,">="&EOMONTH(M5,-1)+1,'حضور '!B:B,"<="&EOMONTH(M5,0)) -> 110370.37 | K5: =J5-G5-L5 -> 0.37037037 | L5: 110370 | M5: 46028 | N5: 1 | O5: =IFERROR(__xludf.DUMMYFUNCTION("IFERROR(AVERAGE(FILTER('حضور '!I:I,'حضور '!A:A=A5,MONTH('حضور '!B:B)=N5)),"""")"),2222.222222222222) -> 2222.2222
A6: حيدر المحاسب | B6: =IFERROR(__xludf.DUMMYFUNCTION("COUNTA(UNIQUE(FILTER('حضور '!B:B,'حضور '!A:A=A6,'حضور '!B:B>=EOMONTH(M6,-1)+1,'حضور '!B:B<=EOMONTH(M6,0))))"),30.0) -> 30 | C6: =SUMIFS('حضور '!G:G,'حضور '!A:A,A6,'حضور '!B:B,">="&EOMONTH(M6,-1)+1,'حضور '!B:B,"<="&EOMONTH(M6,0)) -> 270 | E6: =J6-F6 -> 4.5269844e-06 | F6: =B6*9*O6 -> 350000 | G6: =SUMIFS('حضور '!K:K,'حضور '!A:A,A6,'حضور '!B:B,">="&EOMONTH(M6,-1)+1,'حضور '!B:B,"<="&EOMONTH(M6,0)) -> 183000 | H6: =SUMIFS('حضور '!J:J,'حضور '!A:A,A6,'حضور '!B:B,">="&EOMONTH(M6,-1)+1,'حضور '!B:B,"<="&EOMONTH(M6,0)) -> 0 | I6: =SUMIFS('حضور '!L:L,'حضور '!A:A,A6,'حضور '!B:B,">="&EOMONTH(M6,-1)+1,'حضور '!B:B,"<="&EOMONTH(M6,0)) -> 0 | J6: =SUMIFS('حضور '!M:M,'حضور '!A:A,A6,'حضور '!B:B,">="&EOMONTH(M6,-1)+1,'حضور '!B:B,"<="&EOMONTH(M6,0)) -> 350000 | K6: =J6-G6-L6 -> 4.5269844e-06 | L6: 167000 | M6: 46029 | N6: 1 | O6: =IFERROR(__xludf.DUMMYFUNCTION("IFERROR(AVERAGE(FILTER('حضور '!I:I,'حضور '!A:A=A6,MONTH('حضور '!B:B)=N6)),"""")"),1296.2962962962963) -> 1296.2963
A7: علي الباكستاني | B7: =IFERROR(__xludf.DUMMYFUNCTION("COUNTA(UNIQUE(FILTER('حضور '!B:B,'حضور '!A:A=A7,'حضور '!B:B>=EOMONTH(M7,-1)+1,'حضور '!B:B<=EOMONTH(M7,0))))"),30.0) -> 30 | C7: =SUMIFS('حضور '!G:G,'حضور '!A:A,A7,'حضور '!B:B,">="&EOMONTH(M7,-1)+1,'حضور '!B:B,"<="&EOMONTH(M7,0)) -> 270 | E7: =J7-F7 -> -3.4924597e-10 | F7: =B7*9*O7 -> 576923.08 | G7: =SUMIFS('حضور '!K:K,'حضور '!A:A,A7,'حضور '!B:B,">="&EOMONTH(M7,-1)+1,'حضور '!B:B,"<="&EOMONTH(M7,0)) -> 96923.077 | H7: =SUMIFS('حضور '!J:J,'حضور '!A:A,A7,'حضور '!B:B,">="&EOMONTH(M7,-1)+1,'حضور '!B:B,"<="&EOMONTH(M7,0)) -> 0 | I7: =SUMIFS('حضور '!L:L,'حضور '!A:A,A7,'حضور '!B:B,">="&EOMONTH(M7,-1)+1,'حضور '!B:B,"<="&EOMONTH(M7,0)) -> 0 | J7: =SUMIFS('حضور '!M:M,'حضور '!A:A,A7,'حضور '!B:B,">="&EOMONTH(M7,-1)+1,'حضور '!B:B,"<="&EOMONTH(M7,0)) -> 576923.08 | K7: =J7-G7-L7 -> 0 | L7: 480000 | M7: 46030 | N7: 1 | O7: =IFERROR(__xludf.DUMMYFUNCTION("IFERROR(AVERAGE(FILTER('حضور '!I:I,'حضور '!A:A=A7,MONTH('حضور '!B:B)=N7)),"""")"),2136.7521367521385) -> 2136.7521
A8: اجمالي | G8: =SUM(G2:G7) -> 743923.08 | H8: =SUM(H2:H7) -> 0 | I8: =SUM(I2:I7) -> 0 | J8: =SUM(J2:J7) -> 2713203.9 | K8: =SUM(K2:K7) -> -36931.642 | L8: =SUM(L2:L7) -> 2058123 | M8: يناير
A9: حسين سالم | B9: =IFERROR(__xludf.DUMMYFUNCTION("COUNTA(UNIQUE(FILTER('حضور '!B:B,'حضور '!A:A=A9,'حضور '!B:B>=EOMONTH(M9,-1)+1,'حضور '!B:B<=EOMONTH(M9,0))))"),28.0) -> 28 | C9: =SUMIFS('حضور '!G:G,'حضور '!A:A,A9,'حضور '!B:B,">="&EOMONTH(M9,-1)+1,'حضور '!B:B,"<="&EOMONTH(M9,0)) -> 333.15 | D9: =SUMIFS('حضور عمل خارجي'!I:I,'حضور عمل خارجي'!A:A,A9,'حضور عمل خارجي'!C:C,">="&EOMONTH(M9,-1)+1,'حضور عمل خارجي'!C:C,"<="&EOMONTH(M9,0)) -> 97705.04 | E9: =J9-F9 -> 492853.84 | F9: =B9*9*O9 -> 850000.12 | G9: =SUMIFS('حضور '!K:K,'حضور '!A:A,A9,'حضور '!B:B,">="&EOMONTH(M9,-1)+1,'حضور '!B:B,"<="&EOMONTH(M9,0)) -> 2518854 | H9: =SUMIFS('حضور '!J:J,'حضور '!A:A,A9,'حضور '!B:B,">="&EOMONTH(M9,-1)+1,'حضور '!B:B,"<="&EOMONTH(M9,0)) -> 0 | I9: =SUMIFS('حضور '!L:L,'حضور '!A:A,A9,'حضور '!B:B,">="&EOMONTH(M9,-1)+1,'حضور '!B:B,"<="&EOMONTH(M9,0)) -> 0 | J9: =SUMIFS('حضور '!M:M,'حضور '!A:A,A9,'حضور '!B:B,">="&EOMONTH(M9,-1)+1,'حضور '!B:B,"<="&EOMONTH(M9,0))+(O9*36)+D9 -> 1342854 | K9: =J9-G9-L9 -> -1976000 | L9: 800000 | M9: 46054 | N9: 2 | O9: =IFERROR(__xludf.DUMMYFUNCTION("IFERROR(AVERAGE(FILTER('حضور '!I:I,'حضور '!A:A=A9,MONTH('حضور '!B:B)=N9)),"""")"),3373.016354016354) -> 3373.0164
A10: حيدر يافوز | B10: =IFERROR(__xludf.DUMMYFUNCTION("COUNTA(UNIQUE(FILTER('حضور '!B:B,'حضور '!A:A=A10,'حضور '!B:B>=EOMONTH(M10,-1)+1,'حضور '!B:B<=EOMONTH(M10,0))))"),26.0) -> 26 | C10: =SUMIFS('حضور '!G:G,'حضور '!A:A,A10,'حضور '!B:B,">="&EOMONTH(M10,-1)+1,'حضور '!B:B,"<="&EOMONTH(M10,0)) -> 266.78333 | D10: =SUMIFS('حضور عمل خارجي'!I:I,'حضور عمل خارجي'!A:A,A10,'حضور عمل خارجي'!C:C,">="&EOMONTH(M10,-1)+1,'حضور عمل خارجي'!C:C,"<="&EOMONTH(M10,0)) -> 0 | E10: =J10-F10 -> 150122.35 | F10: =B10*9*O10 -> 510714.29 | G10: =SUMIFS('حضور '!K:K,'حضور '!A:A,A10,'حضور '!B:B,">="&EOMONTH(M10,-1)+1,'حضور '!B:B,"<="&EOMONTH(M10,0)) -> 594837 | H10: =SUMIFS('حضور '!J:J,'حضور '!A:A,A10,'حضور '!B:B,">="&EOMONTH(M10,-1)+1,'حضور '!B:B,"<="&EOMONTH(M10,0)) -> 0 | I10: =SUMIFS('حضور '!L:L,'حضور '!A:A,A10,'حضور '!B:B,">="&EOMONTH(M10,-1)+1,'حضور '!B:B,"<="&EOMONTH(M10,0)) -> 0 | J10: =SUMIFS('حضور '!M:M,'حضور '!A:A,A10,'حضور '!B:B,">="&EOMONTH(M10,-1)+1,'حضور '!B:B,"<="&EOMONTH(M10,0))+(O10*36)+D10 -> 660836.64 | K10: =J10-G10-L10 -> -234000.36 | L10: 300000 | M10: 46054 | N10: 2 | O10: =IFERROR(__xludf.DUMMYFUNCTION("IFERROR(AVERAGE(FILTER('حضور '!I:I,'حضور '!A:A=A10,MONTH('حضور '!B:B)=N10)),"""")"),2182.5396825396824) -> 2182.5397
A11: خضر عبد الخالق | B11: =IFERROR(__xludf.DUMMYFUNCTION("COUNTA(UNIQUE(FILTER('حضور '!B:B,'حضور '!A:A=A11,'حضور '!B:B>=EOMONTH(M11,-1)+1,'حضور '!B:B<=EOMONTH(M11,0))))"),22.0) -> 22 | C11: =SUMIFS('حضور '!G:G,'حضور '!A:A,A11,'حضور '!B:B,">="&EOMONTH(M11,-1)+1,'حضور '!B:B,"<="&EOMONTH(M11,0)) -> 217.03333 | D11: =SUMIFS('حضور عمل خارجي'!I:I,'حضور عمل خارجي'!A:A,A11,'حضور عمل خارجي'!C:C,">="&EOMONTH(M11,-1)+1,'حضور عمل خارجي'!C:C,"<="&EOMONTH(M11,0)) -> 42516.534 | E11: =J11-F11 -> 327467.59 | F11: =B11*9*O11 -> 510714.29 | G11: =SUMIFS('حضور '!K:K,'حضور '!A:A,A11,'حضور '!B:B,">="&EOMONTH(M11,-1)+1,'حضور '!B:B,"<="&EOMONTH(M11,0)) -> 903182 | H11: =SUMIFS('حضور '!J:J,'حضور '!A:A,A11,'حضور '!B:B,">="&EOMONTH(M11,-1)+1,'حضور '!B:B,"<="&EOMONTH(M11,0)) -> 0 | I11: =SUMIFS('حضور '!L:L,'حضور '!A:A,A11,'حضور '!B:B,">="&EOMONTH(M11,-1)+1,'حضور '!B:B,"<="&EOMONTH(M11,0)) -> 0 | J11: =SUMIFS('حضور '!M:M,'حضور '!A:A,A11,'حضور '!B:B,">="&EOMONTH(M11,-1)+1,'حضور '!B:B,"<="&EOMONTH(M11,0))+(O11*36)+D11+143000 -> 838181.88 | K11: =J11-G11-L11 -> -565000.12 | L11: 500000 | M11: 46054 | N11: 2 | O11: =IFERROR(__xludf.DUMMYFUNCTION("IFERROR(AVERAGE(FILTER('حضور '!I:I,'حضور '!A:A=A11,MONTH('حضور '!B:B)=N11)),"""")"),2579.365079365081) -> 2579.3651
A12: سجاد رعد | B12: =IFERROR(__xludf.DUMMYFUNCTION("COUNTA(UNIQUE(FILTER('حضور '!B:B,'حضور '!A:A=A12,'حضور '!B:B>=EOMONTH(M12,-1)+1,'حضور '!B:B<=EOMONTH(M12,0))))"),18.0) -> 18 | C12: =SUMIFS('حضور '!G:G,'حضور '!A:A,A12,'حضور '!B:B,">="&EOMONTH(M12,-1)+1,'حضور '!B:B,"<="&EOMONTH(M12,0)) -> 169.38333 | D12: =SUMIFS('حضور عمل خارجي'!I:I,'حضور عمل خارجي'!A:A,A12,'حضور عمل خارجي'!C:C,">="&EOMONTH(M12,-1)+1,'حضور عمل خارجي'!C:C,"<="&EOMONTH(M12,0)) -> 0 | E12: =J12-F12 -> 103293.65 | F12: =B12*9*O12 -> 385714.29 | G12: =SUMIFS('حضور '!K:K,'حضور '!A:A,A12,'حضور '!B:B,">="&EOMONTH(M12,-1)+1,'حضور '!B:B,"<="&EOMONTH(M12,0)) -> 86000 | H12: =SUMIFS('حضور '!J:J,'حضور '!A:A,A12,'حضور '!B:B,">="&EOMONTH(M12,-1)+1,'حضور '!B:B,"<="&EOMONTH(M12,0)) -> 0 | I12: =SUMIFS('حضور '!L:L,'حضور '!A:A,A12,'حضور '!B:B,">="&EOMONTH(M12,-1)+1,'حضور '!B:B,"<="&EOMONTH(M12,0)) -> 0 | J12: =SUMIFS('حضور '!M:M,'حضور '!A:A,A12,'حضور '!B:B,">="&EOMONTH(M12,-1)+1,'حضور '!B:B,"<="&EOMONTH(M12,0))+(O12*36)+D12 -> 489007.94 | K12: =J12-G12-L12 -> -0.063492063 | L12: 403008 | M12: 46054 | N12: 2 | O12: =IFERROR(__xludf.DUMMYFUNCTION("IFERROR(AVERAGE(FILTER('حضور '!I:I,'حضور '!A:A=A12,MONTH('حضور '!B:B)=N12)),"""")"),2380.952380952381) -> 2380.9524
A13: حيدر المحاسب | B13: =IFERROR(__xludf.DUMMYFUNCTION("COUNTA(UNIQUE(FILTER('حضور '!B:B,'حضور '!A:A=A13,'حضور '!B:B>=EOMONTH(M13,-1)+1,'حضور '!B:B<=EOMONTH(M13,0))))"),28.0) -> 28 | C13: =SUMIFS('حضور '!G:G,'حضور '!A:A,A13,'حضور '!B:B,">="&EOMONTH(M13,-1)+1,'حضور '!B:B,"<="&EOMONTH(M13,0)) -> 252 | D13: =SUMIFS('حضور عمل خارجي'!I:I,'حضور عمل خارجي'!A:A,A13,'حضور عمل خارجي'!C:C,">="&EOMONTH(M13,-1)+1,'حضور عمل خارجي'!C:C,"<="&EOMONTH(M13,0)) -> 0 | E13: =J13-F13 -> -2.3283064e-10 | F13: =B13*9*O13 -> 350000 | G13: =SUMIFS('حضور '!K:K,'حضور '!A:A,A13,'حضور '!B:B,">="&EOMONTH(M13,-1)+1,'حضور '!B:B,"<="&EOMONTH(M13,0)) -> 133000 | H13: =SUMIFS('حضور '!J:J,'حضور '!A:A,A13,'حضور '!B:B,">="&EOMONTH(M13,-1)+1,'حضور '!B:B,"<="&EOMONTH(M13,0)) -> 0 | I13: =SUMIFS('حضور '!L:L,'حضور '!A:A,A13,'حضور '!B:B,">="&EOMONTH(M13,-1)+1,'حضور '!B:B,"<="&EOMONTH(M13,0)) -> 0 | J13: =SUMIFS('حضور '!M:M,'حضور '!A:A,A13,'حضور '!B:B,">="&EOMONTH(M13,-1)+1,'حضور '!B:B,"<="&EOMONTH(M13,0)) -> 350000 | K13: =J13-G13-L13 -> 25000 | L13: 192000 | M13: 46054 | N13: 2 | O13: =IFERROR(__xludf.DUMMYFUNCTION("IFERROR(AVERAGE(FILTER('حضور '!I:I,'حضور '!A:A=A13,MONTH('حضور '!B:B)=N13)),"""")"),1388.8888888888898) -> 1388.8889
A14: علي الباكستاني | B14: =IFERROR(__xludf.DUMMYFUNCTION("COUNTA(UNIQUE(FILTER('حضور '!B:B,'حضور '!A:A=A14,'حضور '!B:B>=EOMONTH(M14,-1)+1,'حضور '!B:B<=EOMONTH(M14,0))))"),28.0) -> 28 | C14: =SUMIFS('حضور '!G:G,'حضور '!A:A,A14,'حضور '!B:B,">="&EOMONTH(M14,-1)+1,'حضور '!B:B,"<="&EOMONTH(M14,0)) -> 252 | D14: =SUMIFS('حضور عمل خارجي'!I:I,'حضور عمل خارجي'!A:A,A14,'حضور عمل خارجي'!C:C,">="&EOMONTH(M14,-1)+1,'حضور عمل خارجي'!C:C,"<="&EOMONTH(M14,0)) -> 0 | E14: =J14-F14 -> 50000 | F14: =B14*9*O14 -> 500000 | G14: =SUMIFS('حضور '!K:K,'حضور '!A:A,A14,'حضور '!B:B,">="&EOMONTH(M14,-1)+1,'حضور '!B:B,"<="&EOMONTH(M14,0)) -> 0 | H14: =SUMIFS('حضور '!J:J,'حضور '!A:A,A14,'حضور '!B:B,">="&EOMONTH(M14,-1)+1,'حضور '!B:B,"<="&EOMONTH(M14,0)) -> 0 | I14: =SUMIFS('حضور '!L:L,'حضور '!A:A,A14,'حضور '!B:B,">="&EOMONTH(M14,-1)+1,'حضور '!B:B,"<="&EOMONTH(M14,0)) -> 0 | J14: =SUMIFS('حضور '!M:M,'حضور '!A:A,A14,'حضور '!B:B,">="&EOMONTH(M14,-1)+1,'حضور '!B:B,"<="&EOMONTH(M14,0)) -> 550000 | K14: =J14-G14-L14 -> -1.1641532e-10 | L14: 550000 | M14: 46054 | N14: 2 | O14: =IFERROR(__xludf.DUMMYFUNCTION("IFERROR(AVERAGE(FILTER('حضور '!I:I,'حضور '!A:A=A14,MONTH('حضور '!B:B)=N14)),"""")"),1984.1269841269839) -> 1984.127
A15: احمد امين | B15: =IFERROR(__xludf.DUMMYFUNCTION("COUNTA(UNIQUE(FILTER('حضور '!B:B,'حضور '!A:A=A15,'حضور '!B:B>=EOMONTH(M15,-1)+1,'حضور '!B:B<=EOMONTH(M15,0))))"),7.0) -> 7 | C15: =SUMIFS('حضور '!G:G,'حضور '!A:A,A15,'حضور '!B:B,">="&EOMONTH(M15,-1)+1,'حضور '!B:B,"<="&EOMONTH(M15,0)) -> 64.016667 | D15: =SUMIFS('حضور عمل خارجي'!I:I,'حضور عمل خارجي'!A:A,A15,'حضور عمل خارجي'!C:C,">="&EOMONTH(M15,-1)+1,'حضور عمل خارجي'!C:C,"<="&EOMONTH(M15,0)) -> 0 | E15: =J15-F15 -> 3025.7937 | F15: =B15*9*O15 -> 187500 | G15: =SUMIFS('حضور '!K:K,'حضور '!A:A,A15,'حضور '!B:B,">="&EOMONTH(M15,-1)+1,'حضور '!B:B,"<="&EOMONTH(M15,0)) -> 91525.794 | H15: =SUMIFS('حضور '!J:J,'حضور '!A:A,A15,'حضور '!B:B,">="&EOMONTH(M15,-1)+1,'حضور '!B:B,"<="&EOMONTH(M15,0)) -> 0 | I15: =SUMIFS('حضور '!L:L,'حضور '!A:A,A15,'حضور '!B:B,">="&EOMONTH(M15,-1)+1,'حضور '!B:B,"<="&EOMONTH(M15,0)) -> 0 | J15: =SUMIFS('حضور '!M:M,'حضور '!A:A,A15,'حضور '!B:B,">="&EOMONTH(M15,-1)+1,'حضور '!B:B,"<="&EOMONTH(M15,0)) -> 190525.79 | K15: =J15-G15-L15 -> 0 | L15: 99000 | M15: 46054 | N15: 2 | O15: =IFERROR(__xludf.DUMMYFUNCTION("IFERROR(AVERAGE(FILTER('حضور '!I:I,'حضور '!A:A=A15,MONTH('حضور '!B:B)=N15)),"""")"),2976.1904761904766) -> 2976.1905
A16: عبدالله هاشم | B16: =IFERROR(__xludf.DUMMYFUNCTION("COUNTA(UNIQUE(FILTER('حضور '!B:B,'حضور '!A:A=A16,'حضور '!B:B>=EOMONTH(M16,-1)+1,'حضور '!B:B<=EOMONTH(M16,0))))"),20.0) -> 20 | C16: =SUMIFS('حضور '!G:G,'حضور '!A:A,A16,'حضور '!B:B,">="&EOMONTH(M16,-1)+1,'حضور '!B:B,"<="&EOMONTH(M16,0)) -> 169.33333 | D16: =SUMIFS('حضور عمل خارجي'!I:I,'حضور عمل خارجي'!A:A,A16,'حضور عمل خارجي'!C:C,">="&EOMONTH(M16,-1)+1,'حضور عمل خارجي'!C:C,"<="&EOMONTH(M16,0)) -> 0 | E16: =J16-F16 -> -31746.032 | F16: =B16*9*O16 -> 535714.29 | G16: =SUMIFS('حضور '!K:K,'حضور '!A:A,A16,'حضور '!B:B,">="&EOMONTH(M16,-1)+1,'حضور '!B:B,"<="&EOMONTH(M16,0)) -> 253968.25 | H16: =SUMIFS('حضور '!J:J,'حضور '!A:A,A16,'حضور '!B:B,">="&EOMONTH(M16,-1)+1,'حضور '!B:B,"<="&EOMONTH(M16,0)) -> 0 | I16: =SUMIFS('حضور '!L:L,'حضور '!A:A,A16,'حضور '!B:B,">="&EOMONTH(M16,-1)+1,'حضور '!B:B,"<="&EOMONTH(M16,0)) -> 0 | J16: =SUMIFS('حضور '!M:M,'حضور '!A:A,A16,'حضور '!B:B,">="&EOMONTH(M16,-1)+1,'حضور '!B:B,"<="&EOMONTH(M16,0)) -> 503968.25 | K16: =J16-G16-L16 -> 0 | L16: 250000 | M16: 46054 | N16: 2 | O16: =IFERROR(__xludf.DUMMYFUNCTION("IFERROR(AVERAGE(FILTER('حضور '!I:I,'حضور '!A:A=A16,MONTH('حضور '!B:B)=N16)),"""")"),2976.1904761904752) -> 2976.1905
A17: حيدر محمد | B17: =IFERROR(__xludf.DUMMYFUNCTION("COUNTA(UNIQUE(FILTER('حضور '!B:B,'حضور '!A:A=A17,'حضور '!B:B>=EOMONTH(M17,-1)+1,'حضور '!B:B<=EOMONTH(M17,0))))"),23.0) -> 23 | C17: =SUMIFS('حضور '!G:G,'حضور '!A:A,A17,'حضور '!B:B,">="&EOMONTH(M17,-1)+1,'حضور '!B:B,"<="&EOMONTH(M17,0)) -> 204.61667 | D17: =SUMIFS('حضور عمل خارجي'!I:I,'حضور عمل خارجي'!A:A,A17,'حضور عمل خارجي'!C:C,">="&EOMONTH(M17,-1)+1,'حضور عمل خارجي'!C:C,"<="&EOMONTH(M17,0)) -> 0 | E17: =J17-F17 -> -9575.8929 | F17: =B17*9*O17 -> 831696.43 | G17: =SUMIFS('حضور '!K:K,'حضور '!A:A,A17,'حضور '!B:B,">="&EOMONTH(M17,-1)+1,'حضور '!B:B,"<="&EOMONTH(M17,0)) -> 472120.54 | H17: =SUMIFS('حضور '!J:J,'حضور '!A:A,A17,'حضور '!B:B,">="&EOMONTH(M17,-1)+1,'حضور '!B:B,"<="&EOMONTH(M17,0)) -> 0 | I17: =SUMIFS('حضور '!L:L,'حضور '!A:A,A17,'حضور '!B:B,">="&EOMONTH(M17,-1)+1,'حضور '!B:B,"<="&EOMONTH(M17,0)) -> 0 | J17: =SUMIFS('حضور '!M:M,'حضور '!A:A,A17,'حضور '!B:B,">="&EOMONTH(M17,-1)+1,'حضور '!B:B,"<="&EOMONTH(M17,0)) -> 822120.54 | K17: =J17-G17-L17 -> 0 | L17: 350000 | M17: 46054 | N17: 2 | O17: =IFERROR(__xludf.DUMMYFUNCTION("IFERROR(AVERAGE(FILTER('حضور '!I:I,'حضور '!A:A=A17,MONTH('حضور '!B:B)=N17)),"""")"),4017.8571428571436) -> 4017.8571
A18: محمد فؤاد سالم | B18: =IFERROR(__xludf.DUMMYFUNCTION("COUNTA(UNIQUE(FILTER('حضور '!B:B,'حضور '!A:A=A18,'حضور '!B:B>=EOMONTH(M18,-1)+1,'حضور '!B:B<=EOMONTH(M18,0))))"),20.0) -> 20 | C18: =SUMIFS('حضور '!G:G,'حضور '!A:A,A18,'حضور '!B:B,">="&EOMONTH(M18,-1)+1,'حضور '!B:B,"<="&EOMONTH(M18,0)) -> 198.51667 | D18: =SUMIFS('حضور عمل خارجي'!I:I,'حضور عمل خارجي'!A:A,A18,'حضور عمل خارجي'!C:C,">="&EOMONTH(M18,-1)+1,'حضور عمل خارجي'!C:C,"<="&EOMONTH(M18,0)) -> 0 | E18: =J18-F18 -> 55109.101 | F18: =B18*9*O18 -> 535714.32 | G18: =SUMIFS('حضور '!K:K,'حضور '!A:A,A18,'حضور '!B:B,">="&EOMONTH(M18,-1)+1,'حضور '!B:B,"<="&EOMONTH(M18,0)) -> 67823.421 | H18: =SUMIFS('حضور '!J:J,'حضور '!A:A,A18,'حضور '!B:B,">="&EOMONTH(M18,-1)+1,'حضور '!B:B,"<="&EOMONTH(M18,0)) -> 0 | I18: =SUMIFS('حضور '!L:L,'حضور '!A:A,A18,'حضور '!B:B,">="&EOMONTH(M18,-1)+1,'حضور '!B:B,"<="&EOMONTH(M18,0)) -> 0 | J18: =SUMIFS('حضور '!M:M,'حضور '!A:A,A18,'حضور '!B:B,">="&EOMONTH(M18,-1)+1,'حضور '!B:B,"<="&EOMONTH(M18,0)) -> 590823.42 | K18: =J18-G18-L18 -> 0 | L18: 523000 | M18: 46054 | N18: 2 | O18: =IFERROR(__xludf.DUMMYFUNCTION("IFERROR(AVERAGE(FILTER('حضور '!I:I,'حضور '!A:A=A18,MONTH('حضور '!B:B)=N18)),"""")"),2976.19066515495) -> 2976.1907
A19: مصطفى عبد الخالق | B19: =IFERROR(__xludf.DUMMYFUNCTION("COUNTA(UNIQUE(FILTER('حضور '!B:B,'حضور '!A:A=A19,'حضور '!B:B>=EOMONTH(M19,-1)+1,'حضور '!B:B<=EOMONTH(M19,0))))"),8.0) -> 8 | C19: =SUMIFS('حضور '!G:G,'حضور '!A:A,A19,'حضور '!B:B,">="&EOMONTH(M19,-1)+1,'حضور '!B:B,"<="&EOMONTH(M19,0)) -> 85.716667 | D19: =SUMIFS('حضور عمل خارجي'!I:I,'حضور عمل خارجي'!A:A,A19,'حضور عمل خارجي'!C:C,">="&EOMONTH(M19,-1)+1,'حضور عمل خارجي'!C:C,"<="&EOMONTH(M19,0)) -> 0 | E19: =J19-F19 -> 40823.413 | F19: =B19*9*O19 -> 214285.71 | G19: =SUMIFS('حضور '!K:K,'حضور '!A:A,A19,'حضور '!B:B,">="&EOMONTH(M19,-1)+1,'حضور '!B:B,"<="&EOMONTH(M19,0)) -> 160109.13 | H19: =SUMIFS('حضور '!J:J,'حضور '!A:A,A19,'حضور '!B:B,">="&EOMONTH(M19,-1)+1,'حضور '!B:B,"<="&EOMONTH(M19,0)) -> 0 | I19: =SUMIFS('حضور '!L:L,'حضور '!A:A,A19,'حضور '!B:B,">="&EOMONTH(M19,-1)+1,'حضور '!B:B,"<="&EOMONTH(M19,0)) -> 0 | J19: =SUMIFS('حضور '!M:M,'حضور '!A:A,A19,'حضور '!B:B,">="&EOMONTH(M19,-1)+1,'حضور '!B:B,"<="&EOMONTH(M19,0)) -> 255109.13 | K19: =J19-G19-L19 -> 0 | L19: 95000 | M19: 46054 | N19: 2 | O19: =IFERROR(__xludf.DUMMYFUNCTION("IFERROR(AVERAGE(FILTER('حضور '!I:I,'حضور '!A:A=A19,MONTH('حضور '!B:B)=N19)),"""")"),2976.1904761904766) -> 2976.1905
A20: يوسف احمد | B20: =IFERROR(__xludf.DUMMYFUNCTION("COUNTA(UNIQUE(FILTER('حضور '!B:B,'حضور '!A:A=A20,'حضور '!B:B>=EOMONTH(M20,-1)+1,'حضور '!B:B<=EOMONTH(M20,0))))"),20.0) -> 20 | C20: =SUMIFS('حضور '!G:G,'حضور '!A:A,A20,'حضور '!B:B,">="&EOMONTH(M20,-1)+1,'حضور '!B:B,"<="&EOMONTH(M20,0)) -> 214.2 | D20: =SUMIFS('حضور عمل خارجي'!I:I,'حضور عمل خارجي'!A:A,A20,'حضور عمل خارجي'!C:C,">="&EOMONTH(M20,-1)+1,'حضور عمل خارجي'!C:C,"<="&EOMONTH(M20,0)) -> 0 | E20: =J20-F20 -> 93726.708 | F20: =B20*9*O20 -> 489130.43 | G20: =SUMIFS('حضور '!K:K,'حضور '!A:A,A20,'حضور '!B:B,">="&EOMONTH(M20,-1)+1,'حضور '!B:B,"<="&EOMONTH(M20,0)) -> 322857 | H20: =SUMIFS('حضور '!J:J,'حضور '!A:A,A20,'حضور '!B:B,">="&EOMONTH(M20,-1)+1,'حضور '!B:B,"<="&EOMONTH(M20,0)) -> 0 | I20: =SUMIFS('حضور '!L:L,'حضور '!A:A,A20,'حضور '!B:B,">="&EOMONTH(M20,-1)+1,'حضور '!B:B,"<="&EOMONTH(M20,0)) -> 0 | J20: =SUMIFS('حضور '!M:M,'حضور '!A:A,A20,'حضور '!B:B,">="&EOMONTH(M20,-1)+1,'حضور '!B:B,"<="&EOMONTH(M20,0)) -> 582857.14 | K20: =J20-G20-L20 -> 0.14285703 | L20: 260000 | M20: 46054 | N20: 2 | O20: =IFERROR(__xludf.DUMMYFUNCTION("IFERROR(AVERAGE(FILTER('حضور '!I:I,'حضور '!A:A=A20,MONTH('حضور '!B:B)=N20)),"""")"),2717.3913043478265) -> 2717.3913
A21: مصطفى حسين | B21: =IFERROR(__xludf.DUMMYFUNCTION("COUNTA(UNIQUE(FILTER('حضور '!B:B,'حضور '!A:A=A21,'حضور '!B:B>=EOMONTH(M21,-1)+1,'حضور '!B:B<=EOMONTH(M21,0))))"),1.0) -> 1 | C21: =SUMIFS('حضور '!G:G,'حضور '!A:A,A21,'حضور '!B:B,">="&EOMONTH(M21,-1)+1,'حضور '!B:B,"<="&EOMONTH(M21,0)) -> 12 | D21: =SUMIFS('حضور عمل خارجي'!I:I,'حضور عمل خارجي'!A:A,A21,'حضور عمل خارجي'!C:C,">="&EOMONTH(M21,-1)+1,'حضور عمل خارجي'!C:C,"<="&EOMONTH(M21,0)) -> 0 | E21: =J21-F21 -> 8928.5714 | F21: =B21*9*O21 -> 26785.714 | G21: =SUMIFS('حضور '!K:K,'حضور '!A:A,A21,'حضور '!B:B,">="&EOMONTH(M21,-1)+1,'حضور '!B:B,"<="&EOMONTH(M21,0)) -> 1714.2857 | H21: =SUMIFS('حضور '!J:J,'حضور '!A:A,A21,'حضور '!B:B,">="&EOMONTH(M21,-1)+1,'حضور '!B:B,"<="&EOMONTH(M21,0)) -> 0 | I21: =SUMIFS('حضور '!L:L,'حضور '!A:A,A21,'حضور '!B:B,">="&EOMONTH(M21,-1)+1,'حضور '!B:B,"<="&EOMONTH(M21,0)) -> 0 | J21: =SUMIFS('حضور '!M:M,'حضور '!A:A,A21,'حضور '!B:B,">="&EOMONTH(M21,-1)+1,'حضور '!B:B,"<="&EOMONTH(M21,0)) -> 35714.286 | K21: =J21-G21-L21 -> 0 | L21: 34000 | M21: 46054 | N21: 2 | O21: =IFERROR(__xludf.DUMMYFUNCTION("IFERROR(AVERAGE(FILTER('حضور '!I:I,'حضور '!A:A=A21,MONTH('حضور '!B:B)=N21)),"""")"),2976.190476190476) -> 2976.1905
A22: محمد حسين الحداد | B22: =IFERROR(__xludf.DUMMYFUNCTION("COUNTA(UNIQUE(FILTER('حضور '!B:B,'حضور '!A:A=A22,'حضور '!B:B>=EOMONTH(M22,-1)+1,'حضور '!B:B<=EOMONTH(M22,0))))"),14.0) -> 14 | C22: =SUMIFS('حضور '!G:G,'حضور '!A:A,A22,'حضور '!B:B,">="&EOMONTH(M22,-1)+1,'حضور '!B:B,"<="&EOMONTH(M22,0)) -> 145.4 | D22: =SUMIFS('حضور عمل خارجي'!I:I,'حضور عمل خارجي'!A:A,A22,'حضور عمل خارجي'!C:C,">="&EOMONTH(M22,-1)+1,'حضور عمل خارجي'!C:C,"<="&EOMONTH(M22,0)) -> 0 | E22: =J22-F22 -> 222589.3 | F22: =B22*9*O22 -> 506250.03 | G22: =SUMIFS('حضور '!K:K,'حضور '!A:A,A22,'حضور '!B:B,">="&EOMONTH(M22,-1)+1,'حضور '!B:B,"<="&EOMONTH(M22,0)) -> 110839 | H22: =SUMIFS('حضور '!J:J,'حضور '!A:A,A22,'حضور '!B:B,">="&EOMONTH(M22,-1)+1,'حضور '!B:B,"<="&EOMONTH(M22,0)) -> 0 | I22: =SUMIFS('حضور '!L:L,'حضور '!A:A,A22,'حضور '!B:B,">="&EOMONTH(M22,-1)+1,'حضور '!B:B,"<="&EOMONTH(M22,0)) -> 0 | J22: =SUMIFS('حضور '!M:M,'حضور '!A:A,A22,'حضور '!B:B,">="&EOMONTH(M22,-1)+1,'حضور '!B:B,"<="&EOMONTH(M22,0))+(O22*36)+D22 -> 728839.33 | K22: =J22-G22-L22 -> 0.32586368 | L22: 618000 | M22: 46054 | N22: 2 | O22: =IFERROR(__xludf.DUMMYFUNCTION("IFERROR(AVERAGE(FILTER('حضور '!I:I,'حضور '!A:A=A22,MONTH('حضور '!B:B)=N22)),"""")"),4017.8573762838478) -> 4017.8574
A23: اجمالي | G23: =SUM(G9:G22) -> 5716830.4 | H23: =SUM(H9:H22) -> 0 | I23: =SUM(I9:I22) -> 0 | J23: =SUM(J9:J22) -> 7940838.3 | K23: =SUM(K9:K22) -> -2750000.1 | L23: =SUM(L9:L22) -> 4974008 | M23: فبراير
A24: حسين سالم | B24: =SUMIFS('حضور '!H:H,'حضور '!A:A,A24,'حضور '!B:B,">="&EOMONTH(M24,-1)+1,'حضور '!B:B,"<="&EOMONTH(M24,0)) -> 22 | C24: =SUMIFS('حضور '!G:G,'حضور '!A:A,A24,'حضور '!B:B,">="&EOMONTH(M24,-1)+1,'حضور '!B:B,"<="&EOMONTH(M24,0)) -> 172.03333 | D24: =SUMIFS('حضور عمل خارجي'!I:I,'حضور عمل خارجي'!A:A,A24,'حضور عمل خارجي'!C:C,">="&EOMONTH(M24,-1)+1,'حضور عمل خارجي'!C:C,"<="&EOMONTH(M24,0)) -> 0 | E24: =J24-F24 -> 35096.022 | F24: =B24*9*O24 -> 692592.59 | G24: =SUMIFS('حضور '!K:K,'حضور '!A:A,A24,'حضور '!B:B,">="&EOMONTH(M24,-1)+1,'حضور '!B:B,"<="&EOMONTH(M24,0)) -> 206750 | H24: =SUMIFS('حضور '!J:J,'حضور '!A:A,A24,'حضور '!B:B,">="&EOMONTH(M24,-1)+1,'حضور '!B:B,"<="&EOMONTH(M24,0)) -> 50000 | I24: =SUMIFS('حضور '!L:L,'حضور '!A:A,A24,'حضور '!B:B,">="&EOMONTH(M24,-1)+1,'حضور '!B:B,"<="&EOMONTH(M24,0)) -> 0 | J24: =SUMIFS('حضور '!M:M,'حضور '!A:A,A24,'حضور '!B:B,">="&EOMONTH(M24,-1)+1,'حضور '!B:B,"<="&EOMONTH(M24,0))+(O24*36)+D24 -> 727688.61 | K24: =J24-G24-L24-H24+I24 -> 470938.61 | M24: 46093 | N24: 3 | O24: =IFERROR(__xludf.DUMMYFUNCTION("IFERROR(AVERAGE(FILTER('حضور '!I:I,'حضور '!A:A=A24,MONTH('حضور '!B:B)=N24)),"""")"),3497.9423868312747) -> 3497.9424
A25: حيدر يافوز | B25: =SUMIFS('حضور '!H:H,'حضور '!A:A,A25,'حضور '!B:B,">="&EOMONTH(M25,-1)+1,'حضور '!B:B,"<="&EOMONTH(M25,0)) -> 27 | C25: =SUMIFS('حضور '!G:G,'حضور '!A:A,A25,'حضور '!B:B,">="&EOMONTH(M25,-1)+1,'حضور '!B:B,"<="&EOMONTH(M25,0)) -> 253.21667 | D25: =SUMIFS('حضور عمل خارجي'!I:I,'حضور عمل خارجي'!A:A,A25,'حضور عمل خارجي'!C:C,">="&EOMONTH(M25,-1)+1,'حضور عمل خارجي'!C:C,"<="&EOMONTH(M25,0)) -> 67901.235 | E25: =J25-F25 -> 172506.86 | F25: =B25*9*O25 -> 550000 | G25: =SUMIFS('حضور '!K:K,'حضور '!A:A,A25,'حضور '!B:B,">="&EOMONTH(M25,-1)+1,'حضور '!B:B,"<="&EOMONTH(M25,0)) -> 353500 | H25: =SUMIFS('حضور '!J:J,'حضور '!A:A,A25,'حضور '!B:B,">="&EOMONTH(M25,-1)+1,'حضور '!B:B,"<="&EOMONTH(M25,0)) -> 0 | I25: =SUMIFS('حضور '!L:L,'حضور '!A:A,A25,'حضور '!B:B,">="&EOMONTH(M25,-1)+1,'حضور '!B:B,"<="&EOMONTH(M25,0)) -> 0 | J25: =SUMIFS('حضور '!M:M,'حضور '!A:A,A25,'حضور '!B:B,">="&EOMONTH(M25,-1)+1,'حضور '!B:B,"<="&EOMONTH(M25,0))+(O25*36)+D25 -> 722506.86 | K25: =J25-G25-L25-H25+I25 -> 369006.86 | M25: 46094 | N25: 3 | O25: =IFERROR(__xludf.DUMMYFUNCTION("IFERROR(AVERAGE(FILTER('حضور '!I:I,'حضور '!A:A=A25,MONTH('حضور '!B:B)=N25)),"""")"),2263.3744855967084) -> 2263.3745
A26: خضر عبد الخالق | B26: =SUMIFS('حضور '!H:H,'حضور '!A:A,A26,'حضور '!B:B,">="&EOMONTH(M26,-1)+1,'حضور '!B:B,"<="&EOMONTH(M26,0)) -> 8 | C26: =SUMIFS('حضور '!G:G,'حضور '!A:A,A26,'حضور '!B:B,">="&EOMONTH(M26,-1)+1,'حضور '!B:B,"<="&EOMONTH(M26,0)) -> 61.1 | E26: =J26-F26 -> 77469.136 | F26: =B26*9*O26 -> 222222.22 | G26: =SUMIFS('حضور '!K:K,'حضور '!A:A,A26,'حضور '!B:B,">="&EOMONTH(M26,-1)+1,'حضور '!B:B,"<="&EOMONTH(M26,0)) -> 88500 | H26: =SUMIFS('حضور '!J:J,'حضور '!A:A,A26,'حضور '!B:B,">="&EOMONTH(M26,-1)+1,'حضور '!B:B,"<="&EOMONTH(M26,0)) -> 50000 | I26: =SUMIFS('حضور '!L:L,'حضور '!A:A,A26,'حضور '!B:B,">="&EOMONTH(M26,-1)+1,'حضور '!B:B,"<="&EOMONTH(M26,0)) -> 0 | J26: =SUMIFS('حضور '!M:M,'حضور '!A:A,A26,'حضور '!B:B,">="&EOMONTH(M26,-1)+1,'حضور '!B:B,"<="&EOMONTH(M26,0))+(O26*36)+D26 -> 299691.36 | K26: =J26-G26-L26-H26+I26 -> 161191.36 | M26: 46095 | N26: 3 | O26: =IFERROR(__xludf.DUMMYFUNCTION("IFERROR(AVERAGE(FILTER('حضور '!I:I,'حضور '!A:A=A26,MONTH('حضور '!B:B)=N26)),"""")"),3086.4197530864194) -> 3086.4198
A27: محمد فؤاد سالم | B27: =SUMIFS('حضور '!H:H,'حضور '!A:A,A27,'حضور '!B:B,">="&EOMONTH(M27,-1)+1,'حضور '!B:B,"<="&EOMONTH(M27,0)) -> 2 | C27: =SUMIFS('حضور '!G:G,'حضور '!A:A,A27,'حضور '!B:B,">="&EOMONTH(M27,-1)+1,'حضور '!B:B,"<="&EOMONTH(M27,0)) -> 17 | E27: =J27-F27 -> -2674.8971 | F27: =B27*9*O27 -> 48148.148 | G27: =SUMIFS('حضور '!K:K,'حضور '!A:A,A27,'حضور '!B:B,">="&EOMONTH(M27,-1)+1,'حضور '!B:B,"<="&EOMONTH(M27,0)) -> 0 | H27: =SUMIFS('حضور '!J:J,'حضور '!A:A,A27,'حضور '!B:B,">="&EOMONTH(M27,-1)+1,'حضور '!B:B,"<="&EOMONTH(M27,0)) -> 0 | I27: =SUMIFS('حضور '!L:L,'حضور '!A:A,A27,'حضور '!B:B,">="&EOMONTH(M27,-1)+1,'حضور '!B:B,"<="&EOMONTH(M27,0)) -> 4527 | J27: =SUMIFS('حضور '!M:M,'حضور '!A:A,A27,'حضور '!B:B,">="&EOMONTH(M27,-1)+1,'حضور '!B:B,"<="&EOMONTH(M27,0)) -> 45473.251 | K27: =J27-G27-L27-H27+I27 -> 0.25102881 | L27: 50000 | M27: 46098 | N27: 3 | O27: =IFERROR(__xludf.DUMMYFUNCTION("IFERROR(AVERAGE(FILTER('حضور '!I:I,'حضور '!A:A=A27,MONTH('حضور '!B:B)=N27)),"""")"),2674.8971193415637) -> 2674.8971
A28: يوسف احمد | B28: =SUMIFS('حضور '!H:H,'حضور '!A:A,A28,'حضور '!B:B,">="&EOMONTH(M28,-1)+1,'حضور '!B:B,"<="&EOMONTH(M28,0)) -> 2 | C28: =SUMIFS('حضور '!G:G,'حضور '!A:A,A28,'حضور '!B:B,">="&EOMONTH(M28,-1)+1,'حضور '!B:B,"<="&EOMONTH(M28,0)) -> 15.5 | E28: =J28-F28 -> -7716.0494 | F28: =B28*9*O28 -> 55555.556 | G28: =SUMIFS('حضور '!K:K,'حضور '!A:A,A28,'حضور '!B:B,">="&EOMONTH(M28,-1)+1,'حضور '!B:B,"<="&EOMONTH(M28,0)) -> 0 | H28: =SUMIFS('حضور '!J:J,'حضور '!A:A,A28,'حضور '!B:B,">="&EOMONTH(M28,-1)+1,'حضور '!B:B,"<="&EOMONTH(M28,0)) -> 0 | I28: =SUMIFS('حضور '!L:L,'حضور '!A:A,A28,'حضور '!B:B,">="&EOMONTH(M28,-1)+1,'حضور '!B:B,"<="&EOMONTH(M28,0)) -> 2160 | J28: =SUMIFS('حضور '!M:M,'حضور '!A:A,A28,'حضور '!B:B,">="&EOMONTH(M28,-1)+1,'حضور '!B:B,"<="&EOMONTH(M28,0)) -> 47839.506 | K28: =J28-G28-L28-H28+I28 -> -0.49382716 | L28: 50000 | M28: 46099 | N28: 3 | O28: =IFERROR(__xludf.DUMMYFUNCTION("IFERROR(AVERAGE(FILTER('حضور '!I:I,'حضور '!A:A=A28,MONTH('حضور '!B:B)=N28)),"""")"),3086.41975308642) -> 3086.4198
