Workbook
Name exp_name: 'نسخة من المصروفات'!$H:$H
Name EXP_CAT: 'نسخة من المصروفات'!$M:$M
Name زبائن: #REF!
Name employee: DATABASE!$D$2:$D$50
Name exp_name: 'المصروفات'!$K:$K
Name EXP_CAT: 'المصروفات'!$D:$D

Sheet الورقة9
A1: 127 | B1: مبخرة مع علبة بخور | C1: 75000 | D1: 45664 | E1: زبون سوشيال | F1: 000/66 | G1: حسين | H1: 75000 | I1: 10000 | J1: =IF(OR(ISBLANK(C1),ISBLANK(I1)),"",C1-I1) -> 65000 | K1: ارباح | L1: 0 | M1: =IF(K1="مبيعات", L1%*C1, IF(K1="ارباح", L1%*J1, "")) -> 0 | N1: =IF(OR(ISBLANK(J1),ISBLANK(M1),M1=0),"",J1-M1) | O1: مبعوث لم استلمه اشرف
A2: 152 | B2: طبع قماش | C2: 25000 | D2: 45668 | E2: زهراء | G2: حسين | H2: 25000 | I2: 10000 | J2: =IF(OR(ISBLANK(C2),ISBLANK(I2)),"",C2-I2) -> 15000 | K2: ارباح | L2: 0 | M2: =IF(K2="مبيعات", L2%*C2, IF(K2="ارباح", L2%*J2, "")) -> 0 | N2: =IF(OR(ISBLANK(J2),ISBLANK(M2),M2=0),"",J2-M2) | O2: واصل ورشة لم يستلمه اشرف
A3: 159 | B3: بورد بصمات + تعلاقات كلاصات | C3: 15000 | D3: 45675 | E3: محمد فيروزة | F3: 000/83 | G3: حسين | H3: 15000 | I3: 5000 | J3: =IF(OR(ISBLANK(C3),ISBLANK(I3)),"",C3-I3) -> 10000 | K3: ارباح | L3: 0 | M3: =IF(K3="مبيعات", L3%*C3, IF(K3="ارباح", L3%*J3, "")) -> 0 | N3: =IF(OR(ISBLANK(J3),ISBLANK(M3),M3=0),"",J3-M3) | O3: مبعوث لم استلمه اشرف
A4: 163 | B4: بورد ايباد | C4: 100000 | D4: 45675 | E4: زبون سوشيال | G4: حسين | I4: 15000 | J4: =IF(OR(ISBLANK(C4),ISBLANK(I4)),"",C4-I4) -> 85000 | K4: ارباح | L4: 0 | M4: =IF(K4="مبيعات", L4%*C4, IF(K4="ارباح", L4%*J4, "")) -> 0 | N4: =IF(OR(ISBLANK(J4),ISBLANK(M4),M4=0),"",J4-M4) | O4: مبعوث لم استلمه اشرف
A5: 164 | B5: بوكس مهر | C5: 100000 | D5: 45675 | E5: نرجس ورد | G5: حسين | H5: 100000 | I5: 25000 | J5: =IF(OR(ISBLANK(C5),ISBLANK(I5)),"",C5-I5) -> 75000 | K5: ارباح | L5: 0 | M5: =IF(K5="مبيعات", L5%*C5, IF(K5="ارباح", L5%*J5, "")) -> 0 | N5: =IF(OR(ISBLANK(J5),ISBLANK(M5),M5=0),"",J5-M5) | O5: مستلم نقوده لم يستلمه اشرف
A6: 183 | B6: تعلاقة | C6: 10000 | D6: 45676 | E6: زبون سوشيال | G6: حسين | H6: 10000 | I6: 5000 | J6: =IF(OR(ISBLANK(C6),ISBLANK(I6)),"",C6-I6) -> 5000 | K6: ارباح | L6: 0 | M6: =IF(K6="مبيعات", L6%*C6, IF(K6="ارباح", L6%*J6, "")) -> 0 | N6: =IF(OR(ISBLANK(J6),ISBLANK(M6),M6=0),"",J6-M6) | O6: واصل لم استلمه اشرف
A7: 184 | B7: تعلاقة مسكات | C7: 10000 | D7: 45676 | E7: زبون سوشيال | G7: حسين | H7: 10000 | I7: 3000 | J7: =IF(OR(ISBLANK(C7),ISBLANK(I7)),"",C7-I7) -> 7000 | K7: ارباح | L7: 0 | M7: =IF(K7="مبيعات", L7%*C7, IF(K7="ارباح", L7%*J7, "")) -> 0 | N7: =IF(OR(ISBLANK(J7),ISBLANK(M7),M7=0),"",J7-M7) | O7: واصل لم استلمه اشرف
A8: 225 | B8: قاعدة بورد | C8: 80000 | D8: 45685 | E8: زبون سوشيال | G8: حسين | H8: 80000 | I8: 20000 | J8: =IF(OR(ISBLANK(C8),ISBLANK(I8)),"",C8-I8) -> 60000 | K8: ارباح | L8: 0 | M8: =IF(K8="مبيعات", L8%*C8, IF(K8="ارباح", L8%*J8, "")) -> 0 | N8: =IF(OR(ISBLANK(J8),ISBLANK(M8),M8=0),"",J8-M8) | O8: مبعوث لم استلمه اشرف

Sheet الرواتب
A1: الرواتب
A10: الرقم التعريفي | B10: اسم الموظف | C10: الراتب الاسمي بالساعات | D10: عدد ساعات العمل داخل الورشة | E10: عدد ساعات العمل خارج الورشة | F10: الحوافز | G10: الخصومات | H10: السلف | I10: الاجمالي
A11: 10001 | B11: يوسف يعقوب | C11: =SUMIFS('المصروفات'!F:F, exp_name, B11, EXP_CAT, "راتب") -> 0 | F11: =SUMIFS('المصروفات'!F:F, exp_name, B11, EXP_CAT, "الحوافز") -> 0 | G11: =IFERROR(__xludf.DUMMYFUNCTION("IMPORTRANGE( ""https://docs.google.com/spreadsheets/d/1DwfNhxfCYJYwBjeiPqn3xZyjMmzDkpS9634bVMHLYJQ/edit?usp=sharing"" , ""CUTS!C6"")"),"#REF!") -> #REF! | H11: =SUMIFS('المصروفات'!F:F, exp_name, B11, EXP_CAT, "سلفة") -> 0 | I11: 700000
A12: 10002 | B12: يونس يعقوب | C12: =SUMIFS('المصروفات'!F:F, exp_name, B12, EXP_CAT, "راتب") -> 0 | F12: =SUMIFS('المصروفات'!F:F, exp_name, B12, EXP_CAT, "الحوافز") -> 0 | G12: =IFERROR(__xludf.DUMMYFUNCTION("IMPORTRANGE( ""https://docs.google.com/spreadsheets/d/1DwfNhxfCYJYwBjeiPqn3xZyjMmzDkpS9634bVMHLYJQ/edit?usp=sharing"" , ""CUTS!C7"")"),"#REF!") -> #REF! | H12: =SUMIFS('المصروفات'!F:F, exp_name, B12, EXP_CAT, "سلفة") -> 0 | I12: =C12+F12-G12-H12 -> #REF!
A13: 10003 | B13: منتظر عبد الكريم | C13: =SUMIFS('المصروفات'!F:F, exp_name, B13, EXP_CAT, "راتب") -> 0 | F13: =SUMIFS('المصروفات'!F:F, exp_name, B13, EXP_CAT, "الحوافز") -> 0 | G13: =IFERROR(__xludf.DUMMYFUNCTION("IMPORTRANGE( ""https://docs.google.com/spreadsheets/d/1DwfNhxfCYJYwBjeiPqn3xZyjMmzDkpS9634bVMHLYJQ/edit?usp=sharing"" , ""CUTS!C8"")"),"#REF!") -> #REF! | H13: =SUMIFS('المصروفات'!F:F, exp_name, B13, EXP_CAT, "سلفة") -> 0 | I13: =C13+F13-G13-H13 -> #REF!
A14: 10004 | B14: حيدر الصباغ | C14: =SUMIFS('المصروفات'!F:F, exp_name, B14, EXP_CAT, "راتب") -> 0 | F14: =SUMIFS('المصروفات'!F:F, exp_name, B14, EXP_CAT, "الحوافز") -> 0 | G14: =IFERROR(__xludf.DUMMYFUNCTION("IMPORTRANGE( ""https://docs.google.com/spreadsheets/d/1DwfNhxfCYJYwBjeiPqn3xZyjMmzDkpS9634bVMHLYJQ/edit?usp=sharing"" , ""CUTS!C9"")"),"#REF!") -> #REF! | H14: =SUMIFS('المصروفات'!F:F, exp_name, B14, EXP_CAT, "سلفة") -> 0 | I14: =C14+F14-G14-H14 -> #REF!
A15: 10005 | B15: حيدر الكهربائي | C15: =SUMIFS('المصروفات'!F:F, exp_name, B15, EXP_CAT, "راتب") -> 0 | F15: =SUMIFS('المصروفات'!F:F, exp_name, B15, EXP_CAT, "الحوافز") -> 0 | G15: =IFERROR(__xludf.DUMMYFUNCTION("IMPORTRANGE( ""https://docs.google.com/spreadsheets/d/1DwfNhxfCYJYwBjeiPqn3xZyjMmzDkpS9634bVMHLYJQ/edit?usp=sharing"" , ""CUTS!C10"")"),"#REF!") -> #REF! | H15: =SUMIFS('المصروفات'!F:F, exp_name, B15, EXP_CAT, "سلفة") -> 0 | I15: =C15+F15-G15-H15 -> #REF!
A16: 10006 | B16: علي الكهربائي | C16: =SUMIFS('المصروفات'!F:F, exp_name, B16, EXP_CAT, "راتب") -> 0 | F16: =SUMIFS('المصروفات'!F:F, exp_name, B16, EXP_CAT, "الحوافز") -> 0 | G16: =IFERROR(__xludf.DUMMYFUNCTION("IMPORTRANGE( ""https://docs.google.com/spreadsheets/d/1DwfNhxfCYJYwBjeiPqn3xZyjMmzDkpS9634bVMHLYJQ/edit?usp=sharing"" , ""CUTS!C11"")"),"#REF!") -> #REF! | H16: =SUMIFS('المصروفات'!F:F, exp_name, B16, EXP_CAT, "سلفة") -> 0 | I16: =C16+F16-G16-H16 -> #REF!
A17: 10007 | B17: اسماعيل | C17: =SUMIFS('المصروفات'!F:F, exp_name, B17, EXP_CAT, "راتب") -> 0 | F17: =SUMIFS('المصروفات'!F:F, exp_name, B17, EXP_CAT, "الحوافز") -> 0 | G17: =IFERROR(__xludf.DUMMYFUNCTION("IMPORTRANGE( ""https://docs.google.com/spreadsheets/d/1DwfNhxfCYJYwBjeiPqn3xZyjMmzDkpS9634bVMHLYJQ/edit?usp=sharing"" , ""CUTS!C12"")"),"#REF!") -> #REF! | H17: =SUMIFS('المصروفات'!F:F, exp_name, B17, EXP_CAT, "سلفة") -> 0 | I17: =C17+F17-G17-H17 -> #REF!
A18: 10008 | B18: علي هادي | C18: =SUMIFS('المصروفات'!F:F, exp_name, B18, EXP_CAT, "راتب") -> 0 | F18: =SUMIFS('المصروفات'!F:F, exp_name, B18, EXP_CAT, "الحوافز") -> 0 | G18: =IFERROR(__xludf.DUMMYFUNCTION("IMPORTRANGE( ""https://docs.google.com/spreadsheets/d/1DwfNhxfCYJYwBjeiPqn3xZyjMmzDkpS9634bVMHLYJQ/edit?usp=sharing"" , ""CUTS!C13"")"),"#REF!") -> #REF! | H18: =SUMIFS('المصروفات'!F:F, exp_name, B18, EXP_CAT, "سلفة") -> 0 | I18: =C18+F18-G18-H18 -> #REF!
A19: 10009 | B19: نبيل | C19: =SUMIFS('المصروفات'!F:F, exp_name, B19, EXP_CAT, "راتب") -> 0 | F19: =SUMIFS('المصروفات'!F:F, exp_name, B19, EXP_CAT, "الحوافز") -> 0 | G19: =IFERROR(__xludf.DUMMYFUNCTION("IMPORTRANGE( ""https://docs.google.com/spreadsheets/d/1DwfNhxfCYJYwBjeiPqn3xZyjMmzDkpS9634bVMHLYJQ/edit?usp=sharing"" , ""CUTS!C14"")"),"#REF!") -> #REF! | H19: =SUMIFS('المصروفات'!F:F, exp_name, B19, EXP_CAT, "سلفة") -> 0 | I19: =C19+F19-G19-H19 -> #REF!
A20: 10010 | B20: حسين | C20: =SUMIFS('المصروفات'!F:F, exp_name, B20, EXP_CAT, "راتب") -> 0 | F20: =SUMIFS('المصروفات'!F:F, exp_name, B20, EXP_CAT, "الحوافز") -> 0 | G20: =IFERROR(__xludf.DUMMYFUNCTION("IMPORTRANGE( ""https://docs.google.com/spreadsheets/d/1DwfNhxfCYJYwBjeiPqn3xZyjMmzDkpS9634bVMHLYJQ/edit?usp=sharing"" , ""CUTS!C15"")"),"#REF!") -> #REF! | H20: =SUMIFS('المصروفات'!F:F, exp_name, B20, EXP_CAT, "سلفة") -> 0 | I20: =C20+F20-G20-H20 -> #REF!
A21: 10011 | B21: محمد | C21: =SUMIFS('المصروفات'!F:F, exp_name, B21, EXP_CAT, "راتب") -> 0 | F21: =SUMIFS('المصروفات'!F:F, exp_name, B21, EXP_CAT, "الحوافز") -> 0 | G21: =IFERROR(__xludf.DUMMYFUNCTION("IMPORTRANGE( ""https://docs.google.com/spreadsheets/d/1DwfNhxfCYJYwBjeiPqn3xZyjMmzDkpS9634bVMHLYJQ/edit?usp=sharing"" , ""CUTS!C16"")"),"#REF!") -> #REF! | H21: =SUMIFS('المصروفات'!F:F, exp_name, B21, EXP_CAT, "سلفة") -> 0 | I21: =C21+F21-G21-H21 -> #REF!
A22: 10012 | B22: محمد السوري | C22: =SUMIFS('المصروفات'!F:F, exp_name, B22, EXP_CAT, "راتب") -> 0 | F22: =SUMIFS('المصروفات'!F:F, exp_name, B22, EXP_CAT, "الحوافز") -> 0 | G22: =IFERROR(__xludf.DUMMYFUNCTION("IMPORTRANGE( ""https://docs.google.com/spreadsheets/d/1DwfNhxfCYJYwBjeiPqn3xZyjMmzDkpS9634bVMHLYJQ/edit?usp=sharing"" , ""CUTS!C17"")"),"#REF!") -> #REF! | H22: =SUMIFS('المصروفات'!F:F, exp_name, B22, EXP_CAT, "سلفة") -> 0 | I22: =C22+F22-G22-H22 -> #REF!
A23: 10013 | B23: عبد الرضا عقيل | C23: =SUMIFS('المصروفات'!F:F, exp_name, B23, EXP_CAT, "راتب") -> 0 | F23: =SUMIFS('المصروفات'!F:F, exp_name, B23, EXP_CAT, "الحوافز") -> 0 | G23: =IFERROR(__xludf.DUMMYFUNCTION("IMPORTRANGE( ""https://docs.google.com/spreadsheets/d/1DwfNhxfCYJYwBjeiPqn3xZyjMmzDkpS9634bVMHLYJQ/edit?usp=sharing"" , ""CUTS!C18"")"),"#REF!") -> #REF! | H23: =SUMIFS('المصروفات'!F:F, exp_name, B23, EXP_CAT, "سلفة") -> 0 | I23: =C23+F23-G23-H23 -> #REF!
A24: 10014 | B24: سجاد | C24: =SUMIFS('المصروفات'!F:F, exp_name, B24, EXP_CAT, "راتب") -> 0 | F24: =SUMIFS('المصروفات'!F:F, exp_name, B24, EXP_CAT, "الحوافز") -> 0 | G24: =IFERROR(__xludf.DUMMYFUNCTION("IMPORTRANGE( ""https://docs.google.com/spreadsheets/d/1DwfNhxfCYJYwBjeiPqn3xZyjMmzDkpS9634bVMHLYJQ/edit?usp=sharing"" , ""CUTS!C19"")"),"#REF!") -> #REF! | H24: =SUMIFS('المصروفات'!F:F, exp_name, B24, EXP_CAT, "سلفة") -> 0 | I24: =C24+F24-G24-H24 -> #REF!
A25: 10015 | B25: معتصم | C25: =SUMIFS('المصروفات'!F:F, exp_name, B25, EXP_CAT, "راتب") -> 0 | F25: =SUMIFS('المصروفات'!F:F, exp_name, B25, EXP_CAT, "الحوافز") -> 0 | G25: =IFERROR(__xludf.DUMMYFUNCTION("IMPORTRANGE( ""https://docs.google.com/spreadsheets/d/1DwfNhxfCYJYwBjeiPqn3xZyjMmzDkpS9634bVMHLYJQ/edit?usp=sharing"" , ""CUTS!C20"")"),"#REF!") -> #REF! | H25: =SUMIFS('المصروفات'!F:F, exp_name, B25, EXP_CAT, "سلفة") -> 0 | I25: =C25+F25-G25-H25 -> #REF!
A26: 10016 | B26: عبدالله الصباغ | C26: =SUMIFS('المصروفات'!F:F, exp_name, B26, EXP_CAT, "راتب") -> 0 | F26: =SUMIFS('المصروفات'!F:F, exp_name, B26, EXP_CAT, "الحوافز") -> 0 | G26: =IFERROR(__xludf.DUMMYFUNCTION("IMPORTRANGE( ""https://docs.google.com/spreadsheets/d/1DwfNhxfCYJYwBjeiPqn3xZyjMmzDkpS9634bVMHLYJQ/edit?usp=sharing"" , ""CUTS!C21"")"),"#REF!") -> #REF! | H26: =SUMIFS('المصروفات'!F:F, exp_name, B26, EXP_CAT, "سلفة") -> 0 | I26: =C26+F26-G26-H26 -> #REF!
A27: 10017 | B27: علي لافوف | C27: =SUMIFS('المصروفات'!F:F, exp_name, B27, EXP_CAT, "راتب") -> 0 | F27: =SUMIFS('المصروفات'!F:F, exp_name, B27, EXP_CAT, "الحوافز") -> 0 | G27: =IFERROR(__xludf.DUMMYFUNCTION("IMPORTRANGE( ""https://docs.google.com/spreadsheets/d/1DwfNhxfCYJYwBjeiPqn3xZyjMmzDkpS9634bVMHLYJQ/edit?usp=sharing"" , ""CUTS!C22"")"),"#REF!") -> #REF! | H27: =SUMIFS('المصروفات'!F:F, exp_name, B27, EXP_CAT, "سلفة") -> 0 | I27: =C27+F27-G27-H27 -> #REF!
A28: 10018 | B28: اشرف الادقاني | C28: =SUMIFS('المصروفات'!F:F, exp_name, B28, EXP_CAT, "راتب") -> 0 | F28: =SUMIFS('المصروفات'!F:F, exp_name, B28, EXP_CAT, "الحوافز") -> 0 | G28: =IFERROR(__xludf.DUMMYFUNCTION("IMPORTRANGE( ""https://docs.google.com/spreadsheets/d/1DwfNhxfCYJYwBjeiPqn3xZyjMmzDkpS9634bVMHLYJQ/edit?usp=sharing"" , ""CUTS!C23"")"),"#REF!") -> #REF! | H28: =SUMIFS('المصروفات'!F:F, exp_name, B28, EXP_CAT, "سلفة") -> 0 | I28: =C28+F28-G28-H28 -> #REF!
A29: 10019 | B29: رضا تنظيف | C29: =SUMIFS('المصروفات'!F:F, exp_name, B29, EXP_CAT, "راتب") -> 0 | F29: =SUMIFS('المصروفات'!F:F, exp_name, B29, EXP_CAT, "الحوافز") -> 0 | G29: =IFERROR(__xludf.DUMMYFUNCTION("IMPORTRANGE( ""https://docs.google.com/spreadsheets/d/1DwfNhxfCYJYwBjeiPqn3xZyjMmzDkpS9634bVMHLYJQ/edit?usp=sharing"" , ""CUTS!C24"")"),"#REF!") -> #REF! | H29: =SUMIFS('المصروفات'!F:F, exp_name, B29, EXP_CAT, "سلفة") -> 0 | I29: =C29+F29-G29-H29 -> #REF!
A30: 10020 | B30: وليد | C30: =SUMIFS('المصروفات'!F:F, exp_name, B30, EXP_CAT, "راتب") -> 0 | F30: =SUMIFS('المصروفات'!F:F, exp_name, B30, EXP_CAT, "الحوافز") -> 0 | G30: =IFERROR(__xludf.DUMMYFUNCTION("IMPORTRANGE( ""https://docs.google.com/spreadsheets/d/1DwfNhxfCYJYwBjeiPqn3xZyjMmzDkpS9634bVMHLYJQ/edit?usp=sharing"" , ""CUTS!C25"")"),"#REF!") -> #REF! | H30: =SUMIFS('المصروفات'!F:F, exp_name, B30, EXP_CAT, "سلفة") -> 0 | I30: =C30+F30-G30-H30 -> #REF!
B31: فاطمة محسن | C31: =SUMIFS('المصروفات'!F:F, exp_name, B31, EXP_CAT, "راتب") -> 0 | F31: =SUMIFS('المصروفات'!F:F, exp_name, B31, EXP_CAT, "الحوافز") -> 0 | H31: =SUMIFS('المصروفات'!F:F, exp_name, B31, EXP_CAT, "سلفة") -> 0 | I31: =C31+F31-G31-H31 -> 0
B32: زهراء صالح | C32: =SUMIFS('المصروفات'!F:F, exp_name, B32, EXP_CAT, "راتب") -> 0 | F32: =SUMIFS('المصروفات'!F:F, exp_name, B32, EXP_CAT, "الحوافز") -> 0 | H32: =SUMIFS('المصروفات'!F:F, exp_name, B32, EXP_CAT, "سلفة") -> 0 | I32: =C32+F32-G32-H32 -> 0
B33: علي اعلانات | C33: =SUMIFS('المصروفات'!F:F, exp_name, B33, EXP_CAT, "راتب") -> 0 | F33: =SUMIFS('المصروفات'!F:F, exp_name, B33, EXP_CAT, "الحوافز") -> 0 | H33: =SUMIFS('المصروفات'!F:F, exp_name, B33, EXP_CAT, "سلفة") -> 0 | I33: =C33+F33-G33-H33 -> 0
C34: =SUMIFS('المصروفات'!F:F, exp_name, B34, EXP_CAT, "راتب") -> 0 | F34: =SUMIFS('المصروفات'!F:F, exp_name, B34, EXP_CAT, "الحوافز") -> 0 | H34: =SUMIFS('المصروفات'!F:F, exp_name, B34, EXP_CAT, "سلفة") -> 0 | I34: =C34+F34-G34-H34 -> 0
C35: =SUMIFS('المصروفات'!F:F, exp_name, B35, EXP_CAT, "راتب") -> 0 | F35: =SUMIFS('المصروفات'!F:F, exp_name, B35, EXP_CAT, "الحوافز") -> 0 | H35: =SUMIFS('المصروفات'!F:F, exp_name, B35, EXP_CAT, "سلفة") -> 0 | I35: =C35+F35-G35-H35 -> 0
C36: =SUMIFS('المصروفات'!F:F, exp_name, B36, EXP_CAT, "راتب") -> 0 | F36: =SUMIFS('المصروفات'!F:F, exp_name, B36, EXP_CAT, "الحوافز") -> 0 | H36: =SUMIFS('المصروفات'!F:F, exp_name, B36, EXP_CAT, "سلفة") -> 0 | I36: =C36+F36-G36-H36 -> 0
C37: =SUMIFS('المصروفات'!F:F, exp_name, B37, EXP_CAT, "راتب") -> 0 | F37: =SUMIFS('المصروفات'!F:F, exp_name, B37, EXP_CAT, "الحوافز") -> 0 | H37: =SUMIFS('المصروفات'!F:F, exp_name, B37, EXP_CAT, "سلفة") -> 0 | I37: =C37+F37-G37-H37 -> 0
C38: =SUMIFS('المصروفات'!F:F, exp_name, B38, EXP_CAT, "راتب") -> 0 | F38: =SUMIFS('المصروفات'!F:F, exp_name, B38, EXP_CAT, "الحوافز") -> 0 | H38: =SUMIFS('المصروفات'!F:F, exp_name, B38, EXP_CAT, "سلفة") -> 0 | I38: =C38+F38-G38-H38 -> 0
C39: =SUMIFS('المصروفات'!F:F, exp_name, B39, EXP_CAT, "راتب") -> 0 | F39: =SUMIFS('المصروفات'!F:F, exp_name, B39, EXP_CAT, "الحوافز") -> 0 | H39: =SUMIFS('المصروفات'!F:F, exp_name, B39, EXP_CAT, "سلفة") -> 0 | I39: =C39+F39-G39-H39 -> 0
C40: =SUMIFS('المصروفات'!F:F, exp_name, B40, EXP_CAT, "راتب") -> 0 | F40: =SUMIFS('المصروفات'!F:F, exp_name, B40, EXP_CAT, "الحوافز") -> 0 | H40: =SUMIFS('المصروفات'!F:F, exp_name, B40, EXP_CAT, "سلفة") -> 0 | I40: =C40+F40-G40-H40 -> 0
C41: =SUMIFS('المصروفات'!F:F, exp_name, B41, EXP_CAT, "راتب") -> 0 | F41: =SUMIFS('المصروفات'!F:F, exp_name, B41, EXP_CAT, "الحوافز") -> 0 | H41: =SUMIFS('المصروفات'!F:F, exp_name, B41, EXP_CAT, "سلفة") -> 0 | I41: =C41+F41-G41-H41 -> 0
C42: =SUMIFS('المصروفات'!F:F, exp_name, B42, EXP_CAT, "راتب") -> 0 | F42: =SUMIFS('المصروفات'!F:F, exp_name, B42, EXP_CAT, "الحوافز") -> 0 | H42: =SUMIFS('المصروفات'!F:F, exp_name, B42, EXP_CAT, "سلفة") -> 0 | I42: =C42+F42-G42-H42 -> 0
C43: =SUMIFS('المصروفات'!F:F, exp_name, B43, EXP_CAT, "راتب") -> 0 | F43: =SUMIFS('المصروفات'!F:F, exp_name, B43, EXP_CAT, "الحوافز") -> 0 | H43: =SUMIFS('المصروفات'!F:F, exp_name, B43, EXP_CAT, "سلفة") -> 0 | I43: =C43+F43-G43-H43 -> 0
C44: =SUMIFS('المصروفات'!F:F, exp_name, B44, EXP_CAT, "راتب") -> 0 | F44: =SUMIFS('المصروفات'!F:F, exp_name, B44, EXP_CAT, "الحوافز") -> 0 | H44: =SUMIFS('المصروفات'!F:F, exp_name, B44, EXP_CAT, "سلفة") -> 0 | I44: =C44+F44-G44-H44 -> 0
C45: =SUMIFS('المصروفات'!F:F, exp_name, B45, EXP_CAT, "راتب") -> 0 | F45: =SUMIFS('المصروفات'!F:F, exp_name, B45, EXP_CAT, "الحوافز") -> 0 | H45: =SUMIFS('المصروفات'!F:F, exp_name, B45, EXP_CAT, "سلفة") -> 0 | I45: =C45+F45-G45-H45 -> 0
... C47: =SUMIFS('المصروفات'!F:F, exp_name, B47, EXP_CAT, "راتب") -> 0 | F47: =SUMIFS('المصروفات'!F:F, exp_name, B47, EXP_CAT, "الحوافز") -> 0 | H47: =SUMIFS('المصروفات'!F:F, exp_name, B47, EXP_CAT, "سلفة") -> 0 | I47: =C47+F47-G47-H47 -> 0

Sheet ادخال الواردات
A1: العمود 1 | B1: NO. | C1: البند | D1: تاريخ استلام الطلب | E1: الحالة | F1: اسم الزبون | G1: رقم الوصل | H1: اسم البائع | I1: سعر البيع | J1: تاريخ الدفع | K1: المدفوع | L1: الباقي | M1: كلفة المنتج | N1: Column 16 | O1: Column 18 | P1: Column 17 | Q1: Column 15 | R1: Column 14 | S1: الملاحظات | T1: طريقة الدفع | U1: العمود 1 2 | V1: العمود 2 | W1: العمود 3 | X1: العمود 4 | Y1: العمود 5 | Z1: العمود 6 | AA1: العمود 7 | AB1: العمود 8 | AC1: العمود 9 | AD1: العمود 10 | AE1: العمود 11 | AF1: العمود 12 | AG1: العمود 13 | AH1: العمود 14 | AI1: العمود 15 | AJ1: العمود 16 | AK1: العمود 17 | AL1: العمود 18
A2: 45696.814 | B2: NO. | C2: البند | D2: تاريخ استلام الطلب | F2: الحالة | G2: اسم الزبون | H2: رقم الوصل | I2: اسم البائع | J2: القيمة | L2: تاريخ الدفع | M2: المدفوع | N2: الباقي | O2: كلفة المنتج | P2: الربح | Q2: نوع العمولة | R2: قيمة النسبة % | S2: العمولة | T2: الربح بعد اقتطاع العمولة | U2: الملاحظات | V2: طريقة الدفع | W2: 747000 | X2: القاصة =
A3: 45696.815 | B3: 11 | C3: 24ث12 | D3: 45707 | F3: شسيي | G3: 2132 | H3: الورشة | I3: شسيشس | J3: 45691 | L3: شسي | M3: سشي | S3: شسي | T3: شيس
A4: 45696.872 | B4: 112 | C4: مبخرة | D4: 45693 | F4: بيج تاليا | G4: 00223 | H4: حسين | I4: 35000 | J4: 45696 | L4: 35000 | M4: 15000 | S4: لاتحتوي رقم طلب | T4: اجل
A5: 45698.821 | B5: 1212 | C5: TEST | D5: 45694 | F5: SAIF | G5: 515514 | H5: حسين | I5: 50000 | J5: 45700 | L5: 15000 | M5: 50000 | S5: DASDAS, | T5: ZAIN

Sheet واردات شهر فبراير 2025
A1: دققت | B1: NO. | C1: البند | D1: تاريخ | E1: الحالة | F1: اسم الزبون | G1: رقم الوصل | H1: البائع | I1: القيمة | J1: تاريخ الاستلام | K1: الباقي | L1: كلفة المنتج | M1: الربح | N1: نوع العمولة | O1: قيمة النسبة % | P1: العمولة | Q1: الربح بعد اقتطاع العمولة | R1: الملاحظات | S1: طريقة الدفع | T1: 0 | U1: القاصة =
A2: TRU | B2: 242a | C2: اكرليك ذهبي | D2: 45689 | E2: مستلم | F2: زهور لمسة | G2: 201 | H2: الورشة | I2: 20000 | L2: 3000 | M2: =IF(OR(ISBLANK(I2),ISBLANK(L2)),"",I2-L2) -> 17000 | N2: ارباح | O2: 0 | P2: =IF(N2="مبيعات", O2%*I2, IF(N2="ارباح", O2%*M2, "")) -> 0 | Q2: =IF(OR(ISBLANK(M2),ISBLANK(P2),P2=0),"",M2-P2) | R2: مراجعة
A3: TRUE | B3: 243a | C3: خلفية جبسين عربي | D3: 45689 | E3: مكرر | F3: زبون سوشيال | G3: 000/66 | H3: حسين | L3: 200000 | M3: =IF(OR(ISBLANK(I3),ISBLANK(L3)),"",I3-L3) | N3: ارباح | P3: =IF(N3="مبيعات", O3%*I3, IF(N3="ارباح", O3%*M3, "")) -> 0 | Q3: =IF(OR(ISBLANK(M3),ISBLANK(P3),P3=0),"",M3-P3) | R3: مكرر | S3: 650000
A4: TRUE | B4: 248 | C4: بوكس مهر | D4: 45690 | E4: دين | F4: ادو | G4: 204 | H4: حسين | I4: 80000 | K4: 80000 | L4: 25000 | M4: =IF(OR(ISBLANK(I4),ISBLANK(L4)),"",I4-L4) -> 55000 | P4: =IF(N4="مبيعات", O4%*I4, IF(N4="ارباح", O4%*M4, "")) | Q4: =IF(OR(ISBLANK(M4),ISBLANK(P4),P4=0),"",M4-P4) -> 55000 | R4: دين
A5: TRUE | B5: a22b | C5: عالم الامريكي | D5: 45690 | E5: مستلم | F5: عالم الامريكي | G5: 170 | H5: الورشة | I5: 500000 | K5: 0 | L5: 200000 | M5: =IF(OR(ISBLANK(I5),ISBLANK(L5)),"",I5-L5) -> 300000 | P5: =IF(N5="مبيعات", O5%*I5, IF(N5="ارباح", O5%*M5, "")) | Q5: =IF(OR(ISBLANK(M5),ISBLANK(P5),P5=0),"",M5-P5) -> 300000
A6: TRUE | B6: 246 | C6: مبخرو بورد | D6: 45690 | E6: مستلم | F6: زبون سوشيال | G6: 939253 | H6: حسين | I6: 95000 | J6: 45710 | K6: 0 | L6: 20000 | M6: =IF(OR(ISBLANK(I6),ISBLANK(L6)),"",I6-L6) -> 75000 | P6: =IF(N6="مبيعات", O6%*I6, IF(N6="ارباح", O6%*M6, "")) | Q6: =IF(OR(ISBLANK(M6),ISBLANK(P6),P6=0),"",M6-P6) -> 75000 | R6: معلق
A7: TRUE | B7: 245a | C7: بوكس حلقات | D7: 45690 | E7: مستلم | F7: زبون سوشيال | G7: 939253 | H7: حسين | I7: 60000 | J7: 45710 | K7: 0 | L7: 20000 | M7: =IF(OR(ISBLANK(I7),ISBLANK(L7)),"",I7-L7) -> 40000 | P7: =IF(N7="مبيعات", O7%*I7, IF(N7="ارباح", O7%*M7, "")) | Q7: =IF(OR(ISBLANK(M7),ISBLANK(P7),P7=0),"",M7-P7) -> 40000 | R7: معلق
A8: TRUE | B8: 247 | C8: شريط2 | D8: 45690 | E8: مستلم | F8: زبون سوشيال | G8: 939253 | H8: حسين | I8: 15000 | J8: 45710 | K8: 0 | L8: 3000 | M8: =IF(OR(ISBLANK(I8),ISBLANK(L8)),"",I8-L8) -> 12000 | P8: =IF(N8="مبيعات", O8%*I8, IF(N8="ارباح", O8%*M8, "")) | Q8: =IF(OR(ISBLANK(M8),ISBLANK(P8),P8=0),"",M8-P8) -> 12000 | R8: معلق
A9: TRUE | B9: 255 | C9: خلفيات 2 مع كوشة تغليف قماش رصاصي مع صواني | D9: 45690 | E9: مستلم | F9: كورتادو | G9: 209 | H9: حسين | I9: 1725000 | L9: 800000 | M9: =IF(OR(ISBLANK(I9),ISBLANK(L9)),"",I9-L9) -> 925000 | N9: مبيعات | O9: 5 | P9: =IF(N9="مبيعات", O9%*I9, IF(N9="ارباح", O9%*M9, "")) -> 86250 | Q9: =IF(OR(ISBLANK(M9),ISBLANK(P9),P9=0),"",M9-P9) -> 838750
A10: TRUE | B10: 243 | C10: بوكس حلقات + بورد | D10: 45690 | E10: راجع | F10: زبون سوشيال | G10: 939252 | H10: حسين | L10: 15000 | M10: =IF(OR(ISBLANK(S10),ISBLANK(L10)),"",S10-L10) -> 20000 | P10: =IF(N10="مبيعات", O10%*S10, IF(N10="ارباح", O10%*M10, "")) | Q10: =IF(OR(ISBLANK(M10),ISBLANK(P10),P10=0),"",M10-P10) -> 20000 | S10: 35000
A11: TRUE | B11: 244 | C11: بورد بصمات | D11: 45690 | E11: راجع | F11: زبون سوشيال | G11: 939252 | H11: حسين | L11: 15000 | M11: =IF(OR(ISBLANK(S11),ISBLANK(L11)),"",S11-L11) -> 45000 | N11: ارباح | P11: =IF(N11="مبيعات", O11%*S11, IF(N11="ارباح", O11%*M11, "")) -> 0 | Q11: =IF(OR(ISBLANK(M11),ISBLANK(P11),P11=0),"",M11-P11) | S11: 60000
A12: TRUE | B12: مك | C12: بوكس حلقات | D12: 45690 | E12: مكرر | F12: زبون سوشيال | H12: حسين | L12: 20000 | M12: =IF(OR(ISBLANK(I13),ISBLANK(L12)),"",I13-L12) -> 20000 | P12: =IF(N12="مبيعات", O12%*I13, IF(N12="ارباح", O12%*M12, "")) | Q12: =IF(OR(ISBLANK(M12),ISBLANK(P12),P12=0),"",M12-P12) -> 20000 | R12: مكرر | S12: 60000
A13: TRUE | B13: 249 | C13: بوكس حلقات | D13: 45691 | E13: دين | F13: ادو | G13: 204 | H13: حسين | I13: 40000 | K13: 40000 | L13: 15000 | M13: =IF(OR(ISBLANK(I13),ISBLANK(L13)),"",I13-L13) -> 25000 | P13: =IF(N13="مبيعات", O13%*I13, IF(N13="ارباح", O13%*M13, "")) | Q13: =IF(OR(ISBLANK(M13),ISBLANK(P13),P13=0),"",M13-P13) -> 25000 | R13: دين
A14: TRUE | B14: 250 | C14: بوكس ساعات | D14: 45691 | E14: دين | F14: ادو | G14: 204 | H14: حسين | I14: 40000 | K14: 40000 | L14: 15000 | M14: =IF(OR(ISBLANK(I14),ISBLANK(L14)),"",I14-L14) -> 25000 | P14: =IF(N14="مبيعات", O14%*I14, IF(N14="ارباح", O14%*M14, "")) | Q14: =IF(OR(ISBLANK(M14),ISBLANK(P14),P14=0),"",M14-P14) -> 25000 | R14: دين
A15: TRUE | B15: ***** | C15: شمس البصرة 2024 | D15: 45691 | E15: مستلم | F15: زبون سوشيال | G15: كشوفات حساب شمس البصرة | H15: حسين | I15: 1955000 | M15: =IF(OR(ISBLANK(I15),ISBLANK(L15)),"",I15-L15) | P15: =IF(N15="مبيعات", O15%*I15, IF(N15="ارباح", O15%*M15, "")) | Q15: =IF(OR(ISBLANK(M15),ISBLANK(P15),P15=0),"",M15-P15) -> 0 | R15: تم استلامهم في سنة 2025 حسب كشوفات الحساب
A16: TRUE | B16: 252 | C16: طبق ورق | D16: 45691 | E16: مستلم | F16: زهراء | G16: 205 | H16: حسين | I16: 75000 | L16: 25000 | M16: =IF(OR(ISBLANK(I16),ISBLANK(L16)),"",I16-L16) -> 50000 | P16: =IF(N16="مبيعات", O16%*I16, IF(N16="ارباح", O16%*M16, "")) | Q16: =IF(OR(ISBLANK(M16),ISBLANK(P16),P16=0),"",M16-P16) -> 50000
A17: TRUE | B17: 251 | C17: مبخرة اكرلك جلد جوزي | D17: 45691 | E17: مستلم | F17: زبون سوشيال | G17: 203 | H17: حسين | I17: 30000 | J17: 45697 | L17: 15000 | M17: =IF(OR(ISBLANK(I17),ISBLANK(L17)),"",I17-L17) -> 15000 | P17: =IF(N17="مبيعات", O17%*I17, IF(N17="ارباح", O17%*M17, "")) | Q17: =IF(OR(ISBLANK(M17),ISBLANK(P17),P17=0),"",M17-P17) -> 15000
A18: TRUE | B18: 231 | C18: مبخرة | D18: 45691 | E18: مستلم | F18: زهراء | G18: 232 | H18: حسين | I18: 30000 | J18: 45698 | L18: 15000 | M18: =IF(OR(ISBLANK(I18),ISBLANK(L18)),"",I18-L18) -> 15000 | P18: =IF(N18="مبيعات", O18%*I18, IF(N18="ارباح", O18%*M18, "")) | Q18: =IF(OR(ISBLANK(M18),ISBLANK(P18),P18=0),"",M18-P18) -> 15000 | R18: دين
A19: TRUE | B19: A26 | C19: شركة نقل | D19: 45691 | E19: مستلم | F19: زبون سوشيال | G19: 000/159 | H19: الورشة | I19: 180000 | L19: 80000 | M19: =IF(OR(ISBLANK(I19),ISBLANK(L19)),"",I19-L19) -> 100000 | P19: =IF(N19="مبيعات", O19%*I19, IF(N19="ارباح", O19%*M19, "")) | Q19: =IF(OR(ISBLANK(M19),ISBLANK(P19),P19=0),"",M19-P19) -> 100000
A20: TRUE | B20: A25 | C20: اتقان للبناء | D20: 45691 | E20: مستلم | F20: زبون سوشيال | G20: 000/156 | H20: الورشة | I20: 40000 | L20: 15000 | M20: =IF(OR(ISBLANK(I20),ISBLANK(L20)),"",I20-L20) -> 25000 | P20: =IF(N20="مبيعات", O20%*I20, IF(N20="ارباح", O20%*M20, "")) | Q20: =IF(OR(ISBLANK(M20),ISBLANK(P20),P20=0),"",M20-P20) -> 25000
A21: TRUE | B21: 256 | C21: بورد بصمات | D21: 45692 | F21: زبون سوشيال | G21: 211 | H21: حسين | I21: 25000 | K21: 25000 | L21: 15000 | M21: =IF(OR(ISBLANK(I21),ISBLANK(L21)),"",I21-L21) -> 10000 | P21: =IF(N21="مبيعات", O21%*I21, IF(N21="ارباح", O21%*M21, "")) | Q21: =IF(OR(ISBLANK(M21),ISBLANK(P21),P21=0),"",M21-P21) -> 10000
A22: TRUE | C22: تصفية حسابات اسماء | D22: 45692 | E22: مستلم | F22: اسماء | H22: حسين | I22: 1000000 | L22: 0 | M22: 0 | P22: =IF(N22="مبيعات", O22%*I22, IF(N22="ارباح", O22%*M22, "")) | Q22: =IF(OR(ISBLANK(M22),ISBLANK(P22),P22=0),"",M22-P22) -> 0
A23: TRUE | C23: حنان دين قديم | D23: 45692 | E23: مستلم | F23: حنان | H23: حسين | I23: 460000 | M23: =IF(OR(ISBLANK(I23),ISBLANK(L23)),"",I23-L23) | P23: =IF(N23="مبيعات", O23%*I23, IF(N23="ارباح", O23%*M23, "")) | Q23: =IF(OR(ISBLANK(M23),ISBLANK(P23),P23=0),"",M23-P23) -> 0
A24: FALSE | C24: سيف عدنان | D24: 45692 | E24: مستلم | F24: سيف عدنان | I24: 450000 | M24: =IF(OR(ISBLANK(I24),ISBLANK(L24)),"",I24-L24) | P24: =IF(N24="مبيعات", O24%*I24, IF(N24="ارباح", O24%*M24, "")) | Q24: =IF(OR(ISBLANK(M24),ISBLANK(P24),P24=0),"",M24-P24) -> 0
A25: TRUE | B25: 255 | C25: بوكس بدلة | D25: 45692 | E25: مستلم | F25: لجين بيوتي | G25: 214 | H25: حسين | I25: 140000 | L25: 25000 | M25: =IF(OR(ISBLANK(I25),ISBLANK(L25)),"",I25-L25) -> 115000 | P25: =IF(N25="مبيعات", O25%*I25, IF(N25="ارباح", O25%*M25, "")) | Q25: =IF(OR(ISBLANK(M25),ISBLANK(P25),P25=0),"",M25-P25) -> 115000
A26: FALSE | B26: 253 | C26: صينية ع2 | D26: 45692 | E26: مستلم | F26: حنان | G26: 208 | H26: حسين | I26: 70000 | L26: 35000 | M26: =IF(OR(ISBLANK(I26),ISBLANK(L26)),"",I26-L26) -> 35000 | P26: =IF(N26="مبيعات", O26%*I26, IF(N26="ارباح", O26%*M26, "")) | Q26: =IF(OR(ISBLANK(M26),ISBLANK(P26),P26=0),"",M26-P26) -> 35000 | R26: دين + اختلاف بتسجيل المبلغ بين الوصل والشيت
A27: FALSE | B27: 254 | C27: ستاند اكرلك | D27: 45692 | E27: مستلم | F27: حنان | G27: 208 | H27: حسين | I27: 40000 | L27: 15000 | M27: =IF(OR(ISBLANK(I27),ISBLANK(L27)),"",I27-L27) -> 25000 | P27: =IF(N27="مبيعات", O27%*I27, IF(N27="ارباح", O27%*M27, "")) | Q27: =IF(OR(ISBLANK(M27),ISBLANK(P27),P27=0),"",M27-P27) -> 25000 | R27: دين + اختلاف بتسجيل المبلغ بين الوصل والشيت
A28: TRUE | B28: 259 | C28: صنية فوم تغليف | D28: 45692 | E28: مكرر | F28: زبون سوشيال | H28: حسين | L28: 25000 | M28: =IF(OR(ISBLANK(I28),ISBLANK(L28)),"",I28-L28) | P28: =IF(N28="مبيعات", O28%*I28, IF(N28="ارباح", O28%*M28, "")) | Q28: =IF(OR(ISBLANK(M28),ISBLANK(P28),P28=0),"",M28-P28) -> 0 | R28: مكرر طلب 253 | S28: 70000
A29: TRUE | B29: 266 | C29: مبخرة و علبية بخور | D29: 45693 | E29: مستلم | F29: زبون سوشيال | G29: 939256 | H29: حسين | I29: 100000 | J29: 45724 | K29: 0 | L29: 30000 | M29: =IF(OR(ISBLANK(I29),ISBLANK(L29)),"",I29-L29) -> 70000 | P29: =IF(N29="مبيعات", O29%*I29, IF(N29="ارباح", O29%*M29, "")) | Q29: =IF(OR(ISBLANK(M29),ISBLANK(P29),P29=0),"",M29-P29) -> 70000
A30: TRUE | B30: 264 | C30: يوكس مهر | D30: 45693 | F30: زهراء | G30: 241 | H30: حسين | I30: 125000 | K30: 125000 | L30: 25000 | M30: =IF(OR(ISBLANK(I30),ISBLANK(L30)),"",I30-L30) -> 100000 | P30: =IF(N30="مبيعات", O30%*I30, IF(N30="ارباح", O30%*M30, "")) | Q30: =IF(OR(ISBLANK(M30),ISBLANK(P30),P30=0),"",M30-P30) -> 100000
A31: FALSE | B31: 265 | C31: بورد بصمات | D31: 45693 | F31: زبون سوشيال | H31: حسين | I31: 45000 | K31: 45000 | L31: 15000 | M31: =IF(OR(ISBLANK(I31),ISBLANK(L31)),"",I31-L31) -> 30000 | P31: =IF(N31="مبيعات", O31%*I31, IF(N31="ارباح", O31%*M31, "")) | Q31: =IF(OR(ISBLANK(M31),ISBLANK(P31),P31=0),"",M31-P31) -> 30000
A32: TRUE | B32: 263 | C32: بوكس حلقات | D32: 45693 | F32: زهراء | G32: 241 | H32: حسين | I32: 40000 | K32: 40000 | L32: 15000 | M32: =IF(OR(ISBLANK(I32),ISBLANK(L32)),"",I32-L32) -> 25000 | P32: =IF(N32="مبيعات", O32%*I32, IF(N32="ارباح", O32%*M32, "")) | Q32: =IF(OR(ISBLANK(M32),ISBLANK(P32),P32=0),"",M32-P32) -> 25000
A33: TRUE | B33: 261 | C33: صينية قوم تغليف | D33: 45693 | F33: ياسر اوكسجين | G33: 216 | H33: حسين | I33: 35000 | K33: 35000 | L33: 20000 | M33: =IF(OR(ISBLANK(I33),ISBLANK(L33)),"",I33-L33) -> 15000 | P33: =IF(N33="مبيعات", O33%*I33, IF(N33="ارباح", O33%*M33, "")) | Q33: =IF(OR(ISBLANK(M33),ISBLANK(P33),P33=0),"",M33-P33) -> 15000 | R33: مراجعة الوصل
A34: TRUE | B34: 262 | C34: بورد تغليف | D34: 45693 | F34: زهراء | G34: 241 | H34: حسين | I34: 35000 | K34: 35000 | L34: 15000 | M34: =IF(OR(ISBLANK(I34),ISBLANK(L34)),"",I34-L34) -> 20000 | P34: =IF(N34="مبيعات", O34%*I34, IF(N34="ارباح", O34%*M34, "")) | Q34: =IF(OR(ISBLANK(M34),ISBLANK(P34),P34=0),"",M34-P34) -> 20000
A35: TRUE | B35: A23B | C35: بوتيك هافان | D35: 45693 | E35: مستلم | F35: زبون سوشيال | G35: 000/158 | H35: الورشة | I35: 600000 | J35: 45723 | K35: 0 | L35: 250000 | M35: =IF(OR(ISBLANK(I35),ISBLANK(L35)),"",I35-L35) -> 350000 | P35: =IF(N35="مبيعات", O35%*I35, IF(N35="ارباح", O35%*M35, "")) | Q35: =IF(OR(ISBLANK(M35),ISBLANK(P35),P35=0),"",M35-P35) -> 350000
A36: TRUE | B36: 257 | C36: بوكس بدلة | D36: 45693 | E36: مستلم | F36: زبون سوشيال | G36: 217 | H36: حسين | I36: 150000 | J36: 45697 | M36: =IF(OR(ISBLANK(I36),ISBLANK(L36)),"",I36-L36) | P36: =IF(N36="مبيعات", O36%*I36, IF(N36="ارباح", O36%*M36, "")) | Q36: =IF(OR(ISBLANK(M36),ISBLANK(P36),P36=0),"",M36-P36) -> 0
A37: TRUE | B37: 267 | C37: شريط مع كروت معايدة | D37: 45693 | E37: مستلم | F37: نرجس | G37: 213 | H37: حسين | I37: 8000 | J37: 45696 | L37: 10000 | M37: =IF(OR(ISBLANK(I37),ISBLANK(L37)),"",I37-L37) -> -2000 | P37: =IF(N37="مبيعات", O37%*I37, IF(N37="ارباح", O37%*M37, "")) | Q37: =IF(OR(ISBLANK(M37),ISBLANK(P37),P37=0),"",M37-P37) -> -2000
A38: TRUE | B38: 268 | C38: شريط طبع | D38: 45693 | E38: مستلم | F38: زبون سوشيال | G38: 212 | H38: حسين | I38: 5000 | J38: 45696 | L38: 1000 | M38: =IF(OR(ISBLANK(I38),ISBLANK(L38)),"",I38-L38) -> 4000 | P38: =IF(N38="مبيعات", O38%*I38, IF(N38="ارباح", O38%*M38, "")) | Q38: =IF(OR(ISBLANK(M38),ISBLANK(P38),P38=0),"",M38-P38) -> 4000
A39: FALSE | B39: A31 | C39: محمد سلام | D39: 45693 | E39: مستلم | F39: زبون سوشيال | G39: 000/155 | H39: الورشة | I39: 405000 | L39: 75000 | M39: =IF(OR(ISBLANK(I39),ISBLANK(L39)),"",I39-L39) -> 330000 | P39: =IF(N39="مبيعات", O39%*I39, IF(N39="ارباح", O39%*M39, "")) | Q39: =IF(OR(ISBLANK(M39),ISBLANK(P39),P39=0),"",M39-P39) -> 330000
A40: TRUE | B40: A24B | C40: مكتب خدمات المهندس | D40: 45693 | E40: مستلم | F40: زبون سوشيال | G40: 000/157 | H40: الورشة | I40: 100000 | L40: 80000 | M40: =IF(OR(ISBLANK(I40),ISBLANK(L40)),"",I40-L40) -> 20000 | P40: =IF(N40="مبيعات", O40%*I40, IF(N40="ارباح", O40%*M40, "")) | Q40: =IF(OR(ISBLANK(M40),ISBLANK(P40),P40=0),"",M40-P40) -> 20000
...

Sheet واردات شهر يناير 2025
A1: TRUE | B1: 114 | C1: بوكس فوم عدد2 | D1: 45658 | E1: دين | F1: حراير | G1: 000/42 | H1: حسين | I1: 45000 | K1: 0 | L1: 45000 | M1: 15000 | N1: =IF(OR(ISBLANK(I1),ISBLANK(M1)),"",I1-M1) -> 30000 | O1: ارباح | P1: 0 | Q1: =IF(O1="مبيعات", P1%*I1, IF(O1="ارباح", P1%*N1, "")) -> 0 | R1: =IF(OR(ISBLANK(N1),ISBLANK(Q1),Q1=0),"",N1-Q1) | S1: دين + المبلغ الواصل في الوصل غير مطابق مع المسجل في الشيت
A2: FALSE | B2: 115 | C2: شريط مسكة | D2: 45658 | E2: دين | F2: ادو | H2: حسين | I2: 5000 | K2: =I2-L2 -> 0 | L2: 5000 | M2: 1000 | N2: =IF(OR(ISBLANK(I2),ISBLANK(M2)),"",I2-M2) -> 4000 | O2: ارباح | P2: 0 | Q2: =IF(O2="مبيعات", P2%*I2, IF(O2="ارباح", P2%*N2, "")) -> 0 | R2: =IF(OR(ISBLANK(N2),ISBLANK(Q2),Q2=0),"",N2-Q2) | S2: دين
A3: TRUE | C3: رصيد ابتدائي | D3: 45658 | E3: مستلم | H3: سيف | I3: 1864500 | K3: 1864500 | N3: =IF(OR(ISBLANK(I3),ISBLANK(M3)),"",I3-M3) | Q3: =IF(O3="مبيعات", P3%*I3, IF(O3="ارباح", P3%*N3, "")) | R3: =IF(OR(ISBLANK(N3),ISBLANK(Q3),Q3=0),"",N3-Q3) -> 0
A4: FALSE | B4: 113 | C4: بوكس حلقات | D4: 45658 | E4: مستلم | F4: شمس البصرة | H4: حسين | I4: 120000 | K4: 120000 | M4: 25000 | N4: =IF(OR(ISBLANK(I4),ISBLANK(M4)),"",I4-M4) -> 95000 | O4: ارباح | P4: 0 | Q4: =IF(O4="مبيعات", P4%*I4, IF(O4="ارباح", P4%*N4, "")) -> 0 | R4: =IF(OR(ISBLANK(N4),ISBLANK(Q4),Q4=0),"",N4-Q4) | S4: مراجعة
A5: FALSE | B5: 206a | C5: لوح فوم | D5: 45658 | E5: مستلم | F5: حنان | H5: حسين | I5: 62000 | K5: 62000 | M5: 30000 | N5: =IF(OR(ISBLANK(I5),ISBLANK(M5)),"",I5-M5) -> 32000 | Q5: =IF(O5="مبيعات", P5%*I5, IF(O5="ارباح", P5%*N5, "")) | R5: =IF(OR(ISBLANK(N5),ISBLANK(Q5),Q5=0),"",N5-Q5) -> 32000 | S5: مراجعة
A6: FALSE | B6: 111 | C6: بورد بصمات | D6: 45658 | E6: مستلم | F6: زبون سوشيال | H6: حسين | I6: 35000 | K6: 35000 | M6: 10000 | N6: =IF(OR(ISBLANK(I6),ISBLANK(M6)),"",I6-M6) -> 25000 | O6: ارباح | P6: 0 | Q6: =IF(O6="مبيعات", P6%*I6, IF(O6="ارباح", P6%*N6, "")) -> 0 | R6: =IF(OR(ISBLANK(N6),ISBLANK(Q6),Q6=0),"",N6-Q6) | S6: مراجعة
A7: TRUE | B7: 112 | C7: بطاقات زفاف | D7: 45658 | E7: راجع | F7: زبون سوشيال | H7: حسين | M7: 10000 | N7: =IF(OR(ISBLANK(T7),ISBLANK(M7)),"",T7-M7) -> 0 | O7: ارباح | P7: 0 | Q7: =IF(O7="مبيعات", P7%*T7, IF(O7="ارباح", P7%*N7, "")) -> 0 | R7: =IF(OR(ISBLANK(N7),ISBLANK(Q7),Q7=0),"",N7-Q7) | T7: 10000
A8: TRUE | B8: 1* | C8: كوشة منتظر | D8: 45659 | E8: مستلم | F8: زبون سوشيال | H8: حسين | I8: 550000 | K8: 550000 | M8: 350000 | N8: =IF(OR(ISBLANK(I8),ISBLANK(M8)),"",I8-M8) -> 200000 | O8: مبيعات | P8: 5 | Q8: =IF(O8="مبيعات", P8%*I8, IF(O8="ارباح", P8%*N8, "")) -> 27500 | R8: =IF(OR(ISBLANK(N8),ISBLANK(Q8),Q8=0),"",N8-Q8) -> 172500 | S8: واصل كاش
A9: TRUE | B9: 116 | C9: بوكس حلقات مع قاعدة | D9: 45659 | E9: مستلم | F9: زبون سوشيال | G9: 954716 | H9: حسين | I9: 160000 | K9: 160000 | M9: 30000 | N9: =IF(OR(ISBLANK(I9),ISBLANK(M9)),"",I9-M9) -> 130000 | O9: ارباح | P9: 25 | Q9: =IF(O9="مبيعات", P9%*I9, IF(O9="ارباح", P9%*N9, "")) -> 32500 | R9: =IF(OR(ISBLANK(N9),ISBLANK(Q9),Q9=0),"",N9-Q9) -> 97500 | S9: واصل كاش | T9: شمس البصرة
A10: FALSE | B10: 115a | C10: كتابة اكريلك ذهبي | D10: 45659 | E10: مستلم | F10: لمسه | H10: الورشة | I10: 15000 | K10: 15000 | M10: 5000 | N10: =IF(OR(ISBLANK(I10),ISBLANK(M10)),"",I10-M10) -> 10000 | O10: ارباح | P10: 0 | Q10: =IF(O10="مبيعات", P10%*I10, IF(O10="ارباح", P10%*N10, "")) -> 0 | R10: =IF(OR(ISBLANK(N10),ISBLANK(Q10),Q10=0),"",N10-Q10) | S10: واصل كاش
A11: TRUE | B11: 415 | C11: تعاليق | D11: 45660 | E11: مستلم | F11: زبون سوشيال | G11: 939288 | H11: حسين | I11: 30000 | J11: 45724 | K11: 30000 | L11: 0 | M11: 15000 | N11: =IF(OR(ISBLANK(I11),ISBLANK(M11)),"",I11-M11) -> 15000 | Q11: =IF(O11="مبيعات", P11%*I11, IF(O11="ارباح", P11%*N11, "")) | R11: =IF(OR(ISBLANK(N11),ISBLANK(Q11),Q11=0),"",N11-Q11) -> 15000
A12: TRUE | C12: استلام دين عن اعلان | D12: 45661 | E12: مستلم | F12: الدوغجي | H12: الورشة | I12: 1535000 | K12: 1535000 | N12: =IF(OR(ISBLANK(I12),ISBLANK(M12)),"",I12-M12) | Q12: =IF(O12="مبيعات", P12%*I12, IF(O12="ارباح", P12%*N12, "")) | R12: =IF(OR(ISBLANK(N12),ISBLANK(Q12),Q12=0),"",N12-Q12) -> 0
A13: TRUE | B13: a14 | C13: وائل خطاط | D13: 45661 | E13: مستلم | F13: زبون سوشيال | H13: الورشة | I13: 7000 | K13: 7000 | M13: 7000 | N13: =IF(OR(ISBLANK(I13),ISBLANK(M13)),"",I13-M13) -> 0 | Q13: =IF(O13="مبيعات", P13%*I13, IF(O13="ارباح", P13%*N13, "")) | R13: =IF(OR(ISBLANK(N13),ISBLANK(Q13),Q13=0),"",N13-Q13) -> 0
A14: TRUE | B14: 117 | C14: بوكس ذهب | D14: 45662 | E14: مستلم | F14: زبون سوشيال | G14: 984645 | H14: حسين | I14: 145000 | K14: 145000 | M14: 30000 | N14: =IF(OR(ISBLANK(I14),ISBLANK(M14)),"",I14-M14) -> 115000 | O14: ارباح | P14: 0 | Q14: =IF(O14="مبيعات", P14%*I14, IF(O14="ارباح", P14%*N14, "")) -> 0 | R14: =IF(OR(ISBLANK(N14),ISBLANK(Q14),Q14=0),"",N14-Q14) | S14: واصل كاش
A15: TRUE | B15: 118 | C15: مبخرة | D15: 45662 | E15: مستلم | F15: بيج تاليا | G15: 000/63 | H15: حسين | I15: 35000 | K15: 35000 | M15: 10000 | N15: =IF(OR(ISBLANK(I15),ISBLANK(M15)),"",I15-M15) -> 25000 | O15: ارباح | P15: 0 | Q15: =IF(O15="مبيعات", P15%*I15, IF(O15="ارباح", P15%*N15, "")) -> 0 | R15: =IF(OR(ISBLANK(N15),ISBLANK(Q15),Q15=0),"",N15-Q15) | S15: واصل كاش | T15: كاش
A16: TRUE | B16: A20 | C16: لوحة مكتبية | D16: 45662 | E16: مستلم | F16: مستطرق | G16: 000/84 | H16: الورشة | I16: 25000 | K16: 25000 | M16: 5000 | N16: =IF(OR(ISBLANK(I16),ISBLANK(M16)),"",I16-M16) -> 20000 | O16: ارباح | P16: 0 | Q16: =IF(O16="مبيعات", P16%*I16, IF(O16="ارباح", P16%*N16, "")) -> 0 | R16: =IF(OR(ISBLANK(N16),ISBLANK(Q16),Q16=0),"",N16-Q16) | S16: واصل كاش
A17: TRUE | B17: 121 | C17: مكتبيه | D17: 45663 | E17: دين | F17: حسين | G17: 000/64 | H17: حسين | I17: 75000 | K17: =I17-L17 -> 0 | L17: 75000 | M17: 25000 | N17: =IF(OR(ISBLANK(I17),ISBLANK(M17)),"",I17-M17) -> 50000 | O17: ارباح | P17: 25 | Q17: =IF(O17="مبيعات", P17%*I17, IF(O17="ارباح", P17%*N17, "")) -> 12500 | R17: =IF(OR(ISBLANK(N17),ISBLANK(Q17),Q17=0),"",N17-Q17) -> 37500 | S17: دين
A18: TRUE | B18: 119 | C18: مبخرة | D18: 45663 | E18: مستلم | F18: بيج تاليا | G18: 000/63 | H18: حسين | I18: 60000 | K18: 60000 | M18: 30000 | N18: =IF(OR(ISBLANK(I18),ISBLANK(M18)),"",I18-M18) -> 30000 | O18: ارباح | P18: 0 | Q18: =IF(O18="مبيعات", P18%*I18, IF(O18="ارباح", P18%*N18, "")) -> 0 | R18: =IF(OR(ISBLANK(N18),ISBLANK(Q18),Q18=0),"",N18-Q18) | S18: واصل كاش
A19: TRUE | B19: 120 | C19: بورد بصمات | D19: 45663 | E19: مستلم | F19: ادو | G19: 000/75 | H19: حسين | I19: 30000 | K19: 30000 | M19: 15000 | N19: =IF(OR(ISBLANK(I19),ISBLANK(M19)),"",I19-M19) -> 15000 | O19: ارباح | P19: 0 | Q19: =IF(O19="مبيعات", P19%*I19, IF(O19="ارباح", P19%*N19, "")) -> 0 | R19: =IF(OR(ISBLANK(N19),ISBLANK(Q19),Q19=0),"",N19-Q19) | S19: واصل كاش | T19: كاش
A20: TRUE | B20: A17 | C20: علامات دلالة | D20: 45663 | E20: مستلم | F20: وائل الخطاط | G20: 000/82 | H20: الورشة | I20: 200000 | K20: 200000 | M20: 50000 | N20: =IF(OR(ISBLANK(I20),ISBLANK(M20)),"",I20-M20) -> 150000 | O20: ارباح | P20: 0 | Q20: =IF(O20="مبيعات", P20%*I20, IF(O20="ارباح", P20%*N20, "")) -> 0 | R20: =IF(OR(ISBLANK(N20),ISBLANK(Q20),Q20=0),"",N20-Q20) | S20: واصل كاش
A21: TRUE | B21: A18 | C21: لوغو كوزمتك | D21: 45663 | E21: مستلم | F21: حسين | G21: 000/83 | H21: الورشة | I21: 60000 | K21: 60000 | M21: 20000 | N21: =IF(OR(ISBLANK(I21),ISBLANK(M21)),"",I21-M21) -> 40000 | O21: ارباح | P21: 0 | Q21: =IF(O21="مبيعات", P21%*I21, IF(O21="ارباح", P21%*N21, "")) -> 0 | R21: =IF(OR(ISBLANK(N21),ISBLANK(Q21),Q21=0),"",N21-Q21) | S21: واصل كاش
A22: TRUE | B22: 127 | C22: مبخرة مع علبة بخور | D22: 45664 | E22: دين | F22: حسين | G22: 000/66 | H22: حسين | I22: 75000 | K22: =I22-L22 -> 0 | L22: 75000 | M22: 10000 | N22: =IF(OR(ISBLANK(I22),ISBLANK(M22)),"",I22-M22) -> 65000 | O22: ارباح | P22: 0 | Q22: =IF(O22="مبيعات", P22%*I22, IF(O22="ارباح", P22%*N22, "")) -> 0 | R22: =IF(OR(ISBLANK(N22),ISBLANK(Q22),Q22=0),"",N22-Q22) | S22: مبعوث لم استلمه اشرف
A23: TRUE | B23: 123 | C23: بوكس حلقات | D23: 45664 | E23: معلق شمس البصرة | F23: زبون سوشيال | G23: 784642 | H23: حسين | I23: 50000 | L23: 50000 | M23: 15000 | N23: =IF(OR(ISBLANK(I23),ISBLANK(M23)),"",I23-M23) -> 35000 | O23: ارباح | P23: 0 | Q23: =IF(O23="مبيعات", P23%*I23, IF(O23="ارباح", P23%*N23, "")) -> 0 | R23: =IF(OR(ISBLANK(N23),ISBLANK(Q23),Q23=0),"",N23-Q23) | S23: معلق | T23: شمس البصرة
A24: FALSE | B24: 130 | C24: شريط ورد | D24: 45664 | E24: دين | F24: نرجس | H24: حسين | I24: 5000 | K24: =I24-L24 -> 0 | L24: 5000 | M24: 1000 | N24: =IF(OR(ISBLANK(I24),ISBLANK(M24)),"",I24-M24) -> 4000 | O24: ارباح | P24: 0 | Q24: =IF(O24="مبيعات", P24%*I24, IF(O24="ارباح", P24%*N24, "")) -> 0 | R24: =IF(OR(ISBLANK(N24),ISBLANK(Q24),Q24=0),"",N24-Q24) | S24: دين
A25: TRUE | C25: اعلان | D25: 45664 | E25: مستلم | F25: بنت الشيخة | H25: الورشة | I25: 550000 | K25: 550000 | N25: =IF(OR(ISBLANK(I25),ISBLANK(M25)),"",I25-M25) | Q25: =IF(O25="مبيعات", P25%*I25, IF(O25="ارباح", P25%*N25, "")) | R25: =IF(OR(ISBLANK(N25),ISBLANK(Q25),Q25=0),"",N25-Q25) -> 0
A26: TRUE | B26: 129 | C26: بوكس مهر | D26: 45664 | E26: مستلم | F26: زبون سوشيال | G26: 000/69 | H26: حسين | I26: 300000 | K26: 300000 | M26: 100000 | N26: =IF(OR(ISBLANK(I26),ISBLANK(M26)),"",I26-M26) -> 200000 | O26: ارباح | P26: 0 | Q26: =IF(O26="مبيعات", P26%*I26, IF(O26="ارباح", P26%*N26, "")) -> 0 | R26: =IF(OR(ISBLANK(N26),ISBLANK(Q26),Q26=0),"",N26-Q26) | S26: واصل كاش | T26: كاش
A27: TRUE | B27: 122 | C27: بوكس ذهب | D27: 45664 | E27: مستلم | F27: زبون سوشيال | G27: 784646 | H27: حسين | I27: 70000 | K27: 70000 | M27: 30000 | N27: =IF(OR(ISBLANK(I27),ISBLANK(M27)),"",I27-M27) -> 40000 | O27: ارباح | P27: 0 | Q27: =IF(O27="مبيعات", P27%*I27, IF(O27="ارباح", P27%*N27, "")) -> 0 | R27: =IF(OR(ISBLANK(N27),ISBLANK(Q27),Q27=0),"",N27-Q27) | S27: واصل كاش | T27: شمس البصرة
A28: TRUE | B28: 125 | C28: بوكس حلقات | D28: 45664 | E28: مستلم | F28: زبون سوشيال | G28: 984644 | H28: حسين | I28: 60000 | K28: 60000 | M28: 15000 | N28: =IF(OR(ISBLANK(I28),ISBLANK(M28)),"",I28-M28) -> 45000 | O28: ارباح | P28: 0 | Q28: =IF(O28="مبيعات", P28%*I28, IF(O28="ارباح", P28%*N28, "")) -> 0 | R28: =IF(OR(ISBLANK(N28),ISBLANK(Q28),Q28=0),"",N28-Q28) | S28: واصل كاش
A29: TRUE | B29: 128 | C29: فوم جداري | D29: 45664 | E29: مستلم | F29: زبون سوشيال | G29: 000/65 | H29: حسين | I29: 50000 | K29: 50000 | M29: 10000 | N29: =IF(OR(ISBLANK(I29),ISBLANK(M29)),"",I29-M29) -> 40000 | O29: ارباح | P29: 0 | Q29: =IF(O29="مبيعات", P29%*I29, IF(O29="ارباح", P29%*N29, "")) -> 0 | R29: =IF(OR(ISBLANK(N29),ISBLANK(Q29),Q29=0),"",N29-Q29) | S29: واصل كاش | T29: كاش
A30: TRUE | B30: 124 | C30: بورد بصمات | D30: 45664 | E30: مستلم | F30: زبون سوشيال | G30: 984644 | H30: حسين | I30: 35000 | K30: 35000 | M30: 15000 | N30: =IF(OR(ISBLANK(I30),ISBLANK(M30)),"",I30-M30) -> 20000 | O30: ارباح | P30: 0 | Q30: =IF(O30="مبيعات", P30%*I30, IF(O30="ارباح", P30%*N30, "")) -> 0 | R30: =IF(OR(ISBLANK(N30),ISBLANK(Q30),Q30=0),"",N30-Q30) | S30: واصل كاش | T30: شمس البصرة
A31: TRUE | B31: 126 | C31: بورد بصمات | D31: 45664 | E31: مستلم | F31: زبون سوشيال | G31: 984644 | H31: حسين | I31: 35000 | K31: 35000 | M31: 15000 | N31: =IF(OR(ISBLANK(I31),ISBLANK(M31)),"",I31-M31) -> 20000 | O31: ارباح | P31: 0 | Q31: =IF(O31="مبيعات", P31%*I31, IF(O31="ارباح", P31%*N31, "")) -> 0 | R31: =IF(OR(ISBLANK(N31),ISBLANK(Q31),Q31=0),"",N31-Q31) | S31: واصل كاش
A32: FALSE | B32: 126a | C32: حلقات اكريليك ذهبي | D32: 45664 | E32: مستلم | F32: زبون سوشيال | H32: حسين | I32: 7000 | K32: 7000 | M32: 2000 | N32: =IF(OR(ISBLANK(I32),ISBLANK(M32)),"",I32-M32) -> 5000 | O32: ارباح | Q32: =IF(O32="مبيعات", P32%*I32, IF(O32="ارباح", P32%*N32, "")) -> 0 | R32: =IF(OR(ISBLANK(N32),ISBLANK(Q32),Q32=0),"",N32-Q32) | S32: واصل كاش
A33: TRUE | B33: 133 | C33: احرف علب بخور | D33: 45665 | E33: مستلم | F33: محمد رشيد | G33: 000/68 | H33: حسين | I33: 25000 | K33: 15000 | L33: 10000 | M33: 3000 | N33: =IF(OR(ISBLANK(#REF!),ISBLANK(M33)),"",#REF!-M33) -> #REF! | O33: ارباح | P33: 0 | Q33: =IF(O33="مبيعات", P33%*#REF!, IF(O33="ارباح", P33%*N33, "")) -> #REF! | R33: =IF(OR(ISBLANK(N33),ISBLANK(Q33),Q33=0),"",N33-Q33) -> #REF! | S33: دين
A34: TRUE | B34: A21 | C34: كوبون cnc | D34: 45665 | E34: دين | F34: وائل الخطاط | G34: 000/60 | H34: الورشة | I34: 10000 | K34: 3000 | L34: 7000 | M34: 5000 | N34: =IF(OR(ISBLANK(I34),ISBLANK(M34)),"",I34-M34) -> 5000 | O34: ارباح | Q34: =IF(O34="مبيعات", P34%*I34, IF(O34="ارباح", P34%*N34, "")) -> 0 | R34: =IF(OR(ISBLANK(N34),ISBLANK(Q34),Q34=0),"",N34-Q34) | S34: واصل كاش
A35: TRUE | B35: 132 | C35: اسماء كوشه | D35: 45665 | E35: مستلم | F35: محمد رشيد | G35: 000/68 | H35: حسين | I35: 25000 | K35: 25000 | L35: 0 | M35: 10000 | N35: =IF(OR(ISBLANK(I36),ISBLANK(M35)),"",I36-M35) -> 55000 | O35: ارباح | P35: 0 | Q35: =IF(O35="مبيعات", P35%*I36, IF(O35="ارباح", P35%*N35, "")) -> 0 | R35: =IF(OR(ISBLANK(N35),ISBLANK(Q35),Q35=0),"",N35-Q35) | S35: دين
A36: TRUE | B36: 131 | C36: بوكس فلوس | D36: 45665 | E36: مستلم | F36: زهور امل | G36: 000/76 | H36: حسين | I36: 65000 | K36: 65000 | M36: 20000 | N36: =IF(OR(ISBLANK(I36),ISBLANK(M36)),"",I36-M36) -> 45000 | O36: ارباح | P36: 0 | Q36: =IF(O36="مبيعات", P36%*I36, IF(O36="ارباح", P36%*N36, "")) -> 0 | R36: =IF(OR(ISBLANK(N36),ISBLANK(Q36),Q36=0),"",N36-Q36) | S36: الوصل غير موقع من قبل اشرف
A37: TRUE | B37: 134 | C37: 4 بوكسات | D37: 45665 | E37: مستلم | F37: لمسه | G37: 000/72 | H37: الورشة | I37: 60000 | K37: 60000 | M37: 20000 | N37: =IF(OR(ISBLANK(I37),ISBLANK(M37)),"",I37-M37) -> 40000 | O37: ارباح | P37: 0 | Q37: =IF(O37="مبيعات", P37%*I37, IF(O37="ارباح", P37%*N37, "")) -> 0 | R37: =IF(OR(ISBLANK(N37),ISBLANK(Q37),Q37=0),"",N37-Q37) | S37: واصل كاش | T37: كاش
A38: TRUE | B38: 135 | C38: بوكس فارغ | D38: 45665 | E38: مستلم | F38: لمسه | G38: 000/71 | H38: حسين | I38: 20000 | K38: 20000 | M38: 5000 | N38: =IF(OR(ISBLANK(I38),ISBLANK(M38)),"",I38-M38) -> 15000 | O38: ارباح | P38: 0 | Q38: =IF(O38="مبيعات", P38%*I38, IF(O38="ارباح", P38%*N38, "")) -> 0 | R38: =IF(OR(ISBLANK(N38),ISBLANK(Q38),Q38=0),"",N38-Q38) | S38: واصل كاش | T38: كاش
A39: TRUE | B39: 135a | C39: بوكس ورد | D39: 45665 | E39: مكرر | F39: زبون سوشيال | H39: الورشة | M39: 100000 | N39: =IF(OR(ISBLANK(I39),ISBLANK(M39)),"",I39-M39) | O39: ارباح | Q39: =IF(O39="مبيعات", P39%*I39, IF(O39="ارباح", P39%*N39, "")) -> 0 | R39: =IF(OR(ISBLANK(N39),ISBLANK(Q39),Q39=0),"",N39-Q39) | S39: مكرر التسجيل | T39: 300000
A40: TRUE | B40: A11 | C40: اعلان cnc | D40: 45665 | E40: مستلم | F40: الفيحاء | G40: 000/59 | H40: الورشة | I40: 1425000 | K40: 1425000 | M40: 400000 | N40: =IF(OR(ISBLANK(I40),ISBLANK(M40)),"",I40-M40) -> 1025000 | Q40: =IF(O40="مبيعات", P40%*I40, IF(O40="ارباح", P40%*N40, "")) | R40: =IF(OR(ISBLANK(N40),ISBLANK(Q40),Q40=0),"",N40-Q40) -> 1025000 | S40: واصل كاش
...

Sheet مصروفات شهر فبراير 2025
A1: TRUE | D1: 45689 | E1: 500000 | F1: حسين مارس | H1: سلفة | L1: 500000
D2: 45689 | E2: 250000 | F2: اشرف الادقاني | H2: سلفة | L2: 250000
A3: TRUE | C3: قماش مع توصيل0 | D3: 45689 | E3: 70000 | F3: الورشة | H3: المواد الخام | L3: 70000
A4: TRUE | C4: اصباغ سيغما | D4: 45689 | E4: 38000 | F4: الورشة | G4: 106263 | H4: الوان ودهانات | L4: 38000
A5: TRUE | C5: الوان | D5: 45689 | E5: 35000 | F5: الورشة | G5: 2456 | H5: الوان ودهانات | L5: 35000
A6: TRUE | C6: كوفي شوب | D6: 45689 | E6: 8000 | F6: الورشة | H6: نثرية | L6: 8000
A7: TRUE | C7: طرقات | D7: 45689 | E7: 6000 | F7: الورشة | L7: 6000
A8: TRUE | D8: 45690 | E8: 175000 | F8: محمد السوري | H8: سلفة | L8: 175000
A9: TRUE | C9: باسكت | D9: 45690 | E9: 75000 | F9: الورشة | H9: خدمات | L9: 75000
A10: TRUE | C10: قماش | D10: 45690 | E10: 38000 | F10: الورشة | L10: 38000
A11: TRUE | D11: 45690 | E11: 25000 | F11: علي عمار | H11: راتب | L11: 25000
A12: TRUE | D12: 45690 | E12: 25000 | F12: وليد | H12: راتب | L12: 25000
A13: TRUE | C13: ورقيات | D13: 45690 | E13: 25000 | F13: الورشة | H13: المواد الخام | L13: 25000
A14: TRUE | C14: الابرار | D14: 45690 | E14: 20000 | F14: الورشة | G14: 3482 | H14: خشب MDF | L14: 20000
A15: TRUE | C15: انشائيية | D15: 45690 | E15: 14000 | F15: الورشة | G15: 120 | L15: 14000
A16: TRUE | C16: فلوس كروة حيدر يافوز | D16: 45690 | E16: 10000 | F16: الورشة | H16: خدمات | L16: 10000
A17: TRUE | D17: 45690 | E17: 8000 | F17: يونس يعقوب | H17: راتب | L17: 8000
A18: TRUE | D18: 45690 | E18: 5000 | F18: محمد السوري | H18: سلفة | L18: 5000
A19: TRUE | C19: صب رش | D19: 45690 | E19: 2000 | F19: الورشة | H19: الوان ودهانات | L19: 2000
A20: TRUE | C20: الابرار | D20: 45691 | E20: 532000 | F20: الورشة | G20: 4058 | H20: المواد الخام, لواصق | L20: 532000
A21: TRUE | C21: الابرار | D21: 45691 | E21: 373000 | F21: الورشة | G21: 4062 | H21: المواد الخام, لواصق | L21: 373000
A22: FALSE | C22: سحب سلفة | D22: 45691 | E22: 300000 | F22: سيف عدنان | H22: سلفة | L22: 300000
A23: FALSE | C23: داينة | D23: 45691 | E23: 175000 | F23: الورشة | H23: استهلاكيات الورشة | L23: 175000
A24: FALSE | C24: تم سحيى راتب | D24: 45691 | E24: 135000 | F24: ليث محاسب | H24: راتب | L24: 135000
A25: TRUE | D25: 45691 | E25: 90000 | F25: حيدر الصباغ | H25: راتب | L25: 90000
A26: TRUE | D26: 45691 | E26: 85000 | F26: عبدالله الصباغ | H26: راتب | L26: 85000
A27: TRUE | C27: الابرار | D27: 45691 | E27: 80000 | F27: الورشة | G27: 4064 | H27: المواد الخام | L27: 80000
A28: TRUE | C28: الابرار | D28: 45691 | E28: 75000 | F28: الورشة | G28: 4063 | H28: المواد الخام | L28: 75000
A29: TRUE | C29: اوسكار | D29: 45691 | E29: 58000 | F29: الورشة | G29: 1634/1642 | H29: المواد الخام | L29: 58000
A30: TRUE | C30: شراء مواد خام | D30: 45691 | E30: 35000 | F30: الورشة | H30: المواد الخام | L30: 35000
A31: TRUE | C31: طلبية | D31: 45691 | E31: 30000 | F31: سيف عدنان | H31: سلفة | L31: 30000
A32: FALSE | C32: تم سحب سلفة | D32: 45691 | E32: 30000 | F32: حيدر الصباغ | H32: سلفة | L32: 30000
A33: TRUE | D33: 45691 | E33: 25000 | F33: عبد الرضا عقيل | H33: راتب | L33: 25000
A34: TRUE | D34: 45691 | E34: 25000 | F34: حيدر الصباغ | H34: راتب | L34: 25000
A35: TRUE | D35: 45691 | E35: 25000 | F35: حسين مارس | H35: سلفة | L35: 25000
A36: FALSE | C36: تم سحب سلفة | D36: 45691 | E36: 25000 | F36: علي الكهربائي | H36: سلفة | L36: 25000
A37: TRUE | C37: الابرار | D37: 45691 | E37: 19000 | F37: الورشة | G37: 3533 | H37: المواد الخام | L37: 19000
A38: TRUE | C38: طرقات | D38: 45691 | E38: 19000 | F38: الورشة | H38: خدمات | L38: 19000
A39: FALSE | C39: تم سحب سلفة | D39: 45691 | E39: 5000 | F39: حيدر الكهربائي | H39: سلفة | L39: 5000
A40: TRUE | C40: برينة | D40: 45691 | E40: 3000 | H40: عدة يدوية | L40: 3000
...

Sheet الورقة26
A1: الاسم | B1: التاريخ | C1: الوقت | D1: الوقت | G1: الغرامة
A2: انوار كريم | B2: 45932 | C2: 0.36388889 | D2: 0.38680556 | E2: =((MIN(10,MAX(0,(MIN(D2,TIME(10,0,0))-MAX(C2,TIME(8,0,0)))*24)))) -> 0.55 | F2: =300000/235 -> 1276.5957 | G2: =F2*E2 -> 702.12766
A3: انوار كريم | B3: 45934 | C3: 0.33333333 | D3: 0.36805556 | E3: =((MIN(10,MAX(0,(MIN(D3,TIME(10,0,0))-MAX(C3,TIME(8,0,0)))*24)))) -> 0.83333333 | F3: =300000/235 -> 1276.5957 | G3: =F3*E3 -> 1063.8298
A4: انوار كريم | B4: 45935 | C4: 0.34722222 | D4: 0.38194444 | E4: =((MIN(10,MAX(0,(MIN(D4,TIME(10,0,0))-MAX(C4,TIME(8,0,0)))*24)))) -> 0.83333333 | F4: =300000/235 -> 1276.5957 | G4: =F4*E4 -> 1063.8298
A5: حيدر يافوز | B5: 45932 | C5: 0.36388889 | D5: 0.38680556 | E5: =((MIN(10,MAX(0,(MIN(D5,TIME(10,0,0))-MAX(C5,TIME(8,0,0)))*24)))) -> 0.55 | F5: =300000/235 -> 1276.5957 | G5: =F5*E5 -> 702.12766
A6: انوار كريم | B6: 45936 | C6: 0.35486111 | D6: 0.36319444 | E6: =((MIN(10,MAX(0,(MIN(D6,TIME(10,0,0))-MAX(C6,TIME(8,0,0)))*24)))) -> 0.2 | F6: =300000/235 -> 1276.5957 | G6: =F6*E6 -> 255.31915
A7: انوار كريم | B7: 45938 | C7: 0.33472222 | D7: 0.37361111 | E7: =((MIN(10,MAX(0,(MIN(D7,TIME(10,0,0))-MAX(C7,TIME(8,0,0)))*24)))) -> 0.93333333 | F7: =300000/235 -> 1276.5957 | G7: =F7*E7 -> 1191.4894
A8: انوار كريم | B8: 45939 | C8: 0.33333333 | D8: 0.36041667 | E8: =((MIN(10,MAX(0,(MIN(D8,TIME(10,0,0))-MAX(C8,TIME(8,0,0)))*24)))) -> 0.65 | F8: =300000/235 -> 1276.5957 | G8: =F8*E8 -> 829.78723
A9: محمد | B9: 45935 | C9: 0.36111111 | D9: 0.38194444 | E9: =((MIN(10,MAX(0,(MIN(D9,TIME(10,0,0))-MAX(C9,TIME(8,0,0)))*24)))) -> 0.5 | F9: =300000/235 -> 1276.5957 | G9: =F9*E9 -> 638.29787
A10: محمد | B10: 45938 | C10: 0.33958333 | D10: 0.37361111 | E10: =((MIN(10,MAX(0,(MIN(D10,TIME(10,0,0))-MAX(C10,TIME(8,0,0)))*24)))) -> 0.81666667 | F10: =300000/235 -> 1276.5957 | G10: =F10*E10 -> 1042.5532
A11: محمد | B11: 45939 | C11: 0.33333333 | D11: 0.36041667 | E11: =((MIN(10,MAX(0,(MIN(D11,TIME(10,0,0))-MAX(C11,TIME(8,0,0)))*24)))) -> 0.65 | F11: =300000/235 -> 1276.5957 | G11: =F11*E11 -> 829.78723
A12: يافوز | B12: 45935 | C12: 0.35416667 | D12: 0.38194444 | E12: =((MIN(10,MAX(0,(MIN(D12,TIME(10,0,0))-MAX(C12,TIME(8,0,0)))*24)))) -> 0.66666667 | F12: =375000/235 -> 1595.7447 | G12: =F12*E12 -> 1063.8298
A13: يافوز | B13: 45936 | C13: 0.35486111 | D13: 0.36319444 | E13: =((MIN(10,MAX(0,(MIN(D13,TIME(10,0,0))-MAX(C13,TIME(8,0,0)))*24)))) -> 0.2 | F13: =375000/235 -> 1595.7447 | G13: =F13*E13 -> 319.14894
A14: يافوز | B14: 45937 | C14: 0.33680556 | D14: 0.35416667 | E14: =((MIN(10,MAX(0,(MIN(D14,TIME(10,0,0))-MAX(C14,TIME(8,0,0)))*24)))) -> 0.41666667 | F14: =375000/235 -> 1595.7447 | G14: =F14*E14 -> 664.89362
A15: يافوز | B15: 45938 | C15: 0.33680556 | D15: 0.37361111 | E15: =((MIN(10,MAX(0,(MIN(D15,TIME(10,0,0))-MAX(C15,TIME(8,0,0)))*24)))) -> 0.88333333 | F15: =375000/235 -> 1595.7447 | G15: =F15*E15 -> 1409.5745
A16: يافوز | B16: 45939 | C16: 0.33333333 | D16: 0.36041667 | E16: =((MIN(10,MAX(0,(MIN(D16,TIME(10,0,0))-MAX(C16,TIME(8,0,0)))*24)))) -> 0.65 | F16: =375000/235 -> 1595.7447 | G16: =F16*E16 -> 1037.234

Sheet عرض 
A3: 2025/01/
A5: المصروفات | C5: الورادات
A6: الرواتب والسلف | B6: =IFERROR(__xludf.DUMMYFUNCTION("AI(""make this cell to calculate query for A3 month date and bring it from "")"),"=AI(""make this cell to calculate query for A3 month date and bring it from "")") -> =AI("make this cell to calculate query for A3 month date and bring it from ")
A7: المشتريات

Sheet مصروفات شهر يناير 2025
A1: TRUE | D1: 45659 | E1: 100000 | F1: علي الكهربائي | H1: راتب | L1: 100000
A2: TRUE | C2: صحيات | D2: 45659 | E2: 84000 | F2: المكتب | G2: 644 | H2: تكاليف تطوير | L2: 84000
A3: TRUE | D3: 45659 | E3: 82000 | F3: حسين مارس | H3: سلفة | L3: 82000
A4: TRUE | D4: 45659 | E4: 25000 | F4: علي عمار | H4: راتب | L4: 25000
A5: TRUE | D5: 45659 | E5: 25000 | F5: عبد الرضا عقيل | H5: راتب | L5: 25000
A6: TRUE | D6: 45659 | E6: 25000 | F6: حيدر الكهربائي | H6: راتب | L6: 25000
A7: TRUE | C7: طرقات ورصيد | D7: 45659 | E7: 15000 | F7: الورشة | H7: خدمات, رصيد | L7: 15000
A8: TRUE | C8: كهربائيات | D8: 45659 | E8: 15000 | F8: الورشة | H8: استهلاكيات الورشة | L8: 15000
A9: TRUE | C9: شراء كفوف وكمامات | D9: 45659 | E9: 10000 | F9: الورشة | H9: استهلاكيات الورشة | L9: 10000
A10: TRUE | D10: 45661 | E10: 630000 | F10: عبد الرضا عقيل | H10: راتب | L10: 630000
A11: TRUE | D11: 45661 | E11: 348000 | F11: حيدر الكهربائي | H11: راتب | L11: 348000
A12: TRUE | D12: 45661 | E12: 260000 | F12: يونس يعقوب | H12: الحوافز, راتب | L12: 260000
A13: TRUE | D13: 45661 | E13: 150000 | F13: اشرف الادقاني | H13: سلفة | L13: 150000 | M13: مراجعة
A14: TRUE | C14: شراء اقمشة | D14: 45661 | E14: 50000 | F14: الورشة | H14: المواد الخام | L14: 50000
A15: TRUE | C15: مكص قماش ومستلزمات تعليب | D15: 45661 | E15: 26000 | F15: الورشة | G15: 12224 | H15: عدة يدوية, المواد الخام | L15: 26000
A16: TRUE | D16: 45662 | E16: 477500 | F16: حيدر الصباغ | H16: راتب | L16: 477500
A17: TRUE | D17: 45662 | E17: 411000 | F17: عبدالله الصباغ | H17: راتب | L17: 411000
A18: TRUE | D18: 45662 | E18: 335000 | F18: علي الكهربائي | H18: راتب | L18: 335000
A19: TRUE | C19: شراء كهربائيات | D19: 45662 | E19: 30000 | F19: الورشة | H19: استهلاكيات الورشة | L19: 30000
A20: TRUE | C20: تسديد حساب قديم ( صفاء ) | D20: 45663 | E20: 745000 | F20: الورشة | G20: 32327 وصل قبض الورشة | H20: خشب MDF | L20: 745000
A21: TRUE | D21: 45663 | E21: 200000 | F21: يوسف يعقوب | H21: راتب | L21: 200000
A22: TRUE | C22: شراء معدات ولواصق | D22: 45663 | E22: 45000 | F22: الورشة | H22: لواصق, عدة يدوية | L22: 45000
A23: TRUE | C23: عدة حدادة يوسف | D23: 45663 | E23: 40000 | F23: الورشة | H23: عدة يدوية | L23: 40000
A24: FALSE | C24: شراء عدد يدوية + مواد للصحيات | D24: 45663 | E24: 40000 | F24: الورشة | H24: المواد الخام | L24: 40000
A25: TRUE | C25: نقليات (تكسي توصيل طلبيات) | D25: 45663 | E25: 11000 | F25: الورشة | H25: خدمات | L25: 11000
A26: TRUE | D26: 45663 | E26: 10000 | F26: عبد الرضا عقيل | H26: راتب | L26: 10000
A27: TRUE | D27: 45664 | E27: 857000 | F27: معتصم | H27: راتب | L27: 857000
A28: TRUE | C28: الابرار | D28: 45664 | E28: 192000 | F28: الورشة | G28: 3562 | H28: المواد الخام | L28: 192000
A29: TRUE | C29: صرفيات يوسف نثرية ( مواد تنظيف - عدة - بخاخات -....) | D29: 45664 | E29: 40000 | F29: الورشة | H29: استهلاكيات الورشة | L29: 40000
A30: TRUE | D30: 45664 | E30: 25000 | F30: علي عمار | H30: راتب | L30: 25000
A31: TRUE | D31: 45665 | E31: 200000 | F31: محمد السوري | H31: سلفة | L31: 200000
A32: TRUE | C32: عمود تل | D32: 45666 | E32: 180000 | F32: الورشة | G32: 31089 | H32: المواد الخام | L32: 180000
A33: TRUE | D33: 45666 | E33: 100000 | F33: وليد | H33: راتب | L33: 100000
A34: TRUE | D34: 45666 | E34: 100000 | F34: اشرف الادقاني | H34: سلفة | L34: 100000
A35: TRUE | C35: علي عبد الواحد حمود | D35: 45666 | E35: 77500 | F35: الورشة | G35: 943 | H35: لواصق | L35: 77500
A36: TRUE | C36: شركة الضيف | D36: 45666 | E36: 55000 | F36: الورشة | G36: 30053 | H36: المواد الخام | L36: 55000
A37: TRUE | C37: درة الخليج | D37: 45666 | E37: 43750 | F37: الورشة | G37: 1474 | H37: استهلاكيات الورشة | L37: 43750
A38: TRUE | C38: انشائيات | D38: 45666 | E38: 43000 | F38: محل الاخوين | G38: 244 | H38: استهلاكيات الورشة | L38: 43000
A39: TRUE | D39: 45666 | E39: 25000 | F39: وليد | G39: 121 | H39: نثرية | L39: 25000
A40: TRUE | D40: 45666 | E40: 20000 | F40: نقليات | H40: خدمات | L40: 20000
...

Sheet نسخة من الواردات
F1: =sum(F3:F2879) -> 241736000 | L1: =sum(L3:L2879) -> 234527000 | M1: =SUM(M3:M968) -> 842000 | N1: =sum(N3:N2879) -> 6367000 | O1: =F1-N1-L1-M1 -> 0 | P1: =SUM(P3:P863) -> 17671500 | X1: =L1-sum( 'المصروفات'!D1)-X2 -> -72960750 | Y1: النقص | Z1: ='المصروفات'!J1 -> 732000 | AA1: الديون
A2: تدقيق شمس البصرة | B2: دققت | C2: NO. | D2: تاريخ البند | E2: الحالة | F2: القيمة | G2: البند | H2: المندوب | I2: رقم الوصل | J2: اسم الزبون | K2: Column 22 | L2: المستلم | M2: الخصم | N2: الباقي | O2: تاريخ الاستلام | P2: كلفة المنتج | Q2: الربح | R2: نوع العمولة | S2: قيمة النسبة % | T2: العمولة | U2: الربح بعد اقتطاع العمولة | V2: الملاحظات | W2: طريقة الدفع | X2: 3584500 | Y2: القاصة الحالية | Z2: ='المصروفات'!D1 -> 303903250 | AA2: مجموع المصروفات
A3: FALSE | B3: TRUE | C3: 267 | D3: 45693 | E3: مستلم | F3: 8000 | G3: شريط مع كروت معايدة | H3: حسين | I3: 213 | J3: نرجس | L3: 8000 | M3: 0 | N3: 0 | O3: 45696 | P3: 10000 | Q3: =IF(OR(ISBLANK(F3),ISBLANK(P3)),"",F3-P3) -> -2000 | T3: =IF(R3="مبيعات", S3%*F3, IF(R3="ارباح", S3%*Q3, "")) | U3: =IF(OR(ISBLANK(Q3),ISBLANK(T3),T3=0),"",Q3-T3) -> -2000
A4: FALSE | B4: TRUE | C4: 268 | D4: 45693 | E4: مستلم | F4: 5000 | G4: شريط طبع | H4: حسين | I4: 212 | J4: زبون سوشيال | L4: 5000 | M4: 0 | N4: 0 | O4: 45696 | P4: 1000 | Q4: =IF(OR(ISBLANK(F4),ISBLANK(P4)),"",F4-P4) -> 4000 | T4: =IF(R4="مبيعات", S4%*F4, IF(R4="ارباح", S4%*Q4, "")) | U4: =IF(OR(ISBLANK(Q4),ISBLANK(T4),T4=0),"",Q4-T4) -> 4000
A5: FALSE | B5: TRUE | D5: 45695 | E5: مستلم | F5: 360000 | G5: قص سي ان سي شركة السراج | H5: الورشة | I5: 162 | J5: محمد مصمم | L5: 360000 | M5: 0 | N5: 0 | O5: 45696 | P5: 150000 | Q5: =IF(OR(ISBLANK(F5),ISBLANK(P5)),"",F5-P5) -> 210000 | T5: =IF(R5="مبيعات", S5%*F5, IF(R5="ارباح", S5%*Q5, "")) | U5: =IF(OR(ISBLANK(Q5),ISBLANK(T5),T5=0),"",Q5-T5) -> 210000
A6: FALSE | B6: TRUE | C6: AA32 | D6: 45696 | E6: مستلم | F6: 490000 | G6: مهدي الموسوي | H6: الورشة | I6: 163 | J6: زبون سوشيال | L6: 490000 | M6: 0 | N6: 0 | O6: 45696 | P6: 200000 | R6: مبيعات
A7: FALSE | B7: TRUE | C7: 251 | D7: 45691 | E7: مستلم | F7: 30000 | G7: مبخرة اكرلك جلد جوزي | H7: حسين | I7: 203 | J7: زبون سوشيال | L7: 30000 | M7: 0 | N7: 0 | O7: 45697 | P7: 15000 | Q7: =IF(OR(ISBLANK(F7),ISBLANK(P7)),"",F7-P7) -> 15000 | T7: =IF(R7="مبيعات", S7%*F7, IF(R7="ارباح", S7%*Q7, "")) | U7: =IF(OR(ISBLANK(Q7),ISBLANK(T7),T7=0),"",Q7-T7) -> 15000 | AA7: قيد الانشاء | AB7: ابيض
A8: FALSE | B8: TRUE | C8: 257 | D8: 45693 | E8: مستلم | F8: 150000 | G8: بوكس بدلة | H8: حسين | I8: 217 | J8: زبون سوشيال | L8: 150000 | M8: 0 | N8: 0 | O8: 45697 | Q8: =IF(OR(ISBLANK(F8),ISBLANK(P8)),"",F8-P8) | T8: =IF(R8="مبيعات", S8%*F8, IF(R8="ارباح", S8%*Q8, "")) | U8: =IF(OR(ISBLANK(Q8),ISBLANK(T8),T8=0),"",Q8-T8) -> 0
A9: FALSE | B9: TRUE | C9: 258 | D9: 45694 | E9: مستلم | F9: 25000 | G9: بورد فوم | H9: حسين | I9: 218 | J9: زبون سوشيال | L9: 25000 | M9: 0 | N9: 0 | O9: 45697 | Q9: =IF(OR(ISBLANK(F9),ISBLANK(P9)),"",F9-P9) | T9: =IF(R9="مبيعات", S9%*F9, IF(R9="ارباح", S9%*Q9, "")) | U9: =IF(OR(ISBLANK(Q9),ISBLANK(T9),T9=0),"",Q9-T9) -> 0 | AA9: ذ
