Workbook
Name MY_FUNCTION1: LAMBDA(SUMIFS(Calculations!$B:$B, Attendance!$B:$B, Dashboard!$T$3, Attendance!$A:$A, ">="&Dashboard!$W$8, Attendance!$A:$A, "<="&EOMONTH(Dashboard!$W$8,0)))

Sheet Dashboard
T2: الاسم
T3: حسين سالم | AO3: FALSE
K5: سعر الساعة | N5: الراتب الاسمي | Q5: الراتب الصافي
B6: FALSE | K6: =(VLOOKUP(T3, Employees!A:B, 2, 0) / DAY(EOMONTH(W8, 0))) /9 -> 2777.7778 | N6: =VLOOKUP(T3, Employees!A:B, 2, 0) -> 750000 | Q6: =(T8) - (B14 + K14+N14+Q14+E14) -> -1234509.3 | T6: الراتب الإجمالي
B8: مبلغ ايام الجمعة | E8: مجموع مبلغ الإضافي | H8: مجموع النقل والطعام | T8: =((W17-W21)*K6)+((W13*9)*(K6))+H10+E10+B10-H14 -> 1286990.7 | W8: 46113 | X8: الشهر الحالي
B10: =(W14*K6)*2 -> 190648.15 | E10: =SUMIFS(Calculations!D:D, Attendance!B:B, T3, Attendance!A:A, ">="&W8, Attendance!A:A, "<="&EOMONTH(W8,0)) -> 58611.111 | H10: =(100000 / W10) * W16 -> 100000 | W10: =_xlfn.NETWORKDAYS.INTL(W8, EOMONTH(W8,0), 16) -> 26 | X10: عدد ايام الشهر عدا الجمعة
W12: =DAY(EOMONTH(W8,0))-W10 -> 4 | X12: عدد ايام الجمعة لهذا الشهر
B13: الغرامات | E13: الديون | H13: مجموع مبلغ التأخير | K13: مجموع السلف | N13: الطلب السابق | Q13: المستلم | W13: =SUMIFS('الجمعة + الغياب'!$F$2:$F44, 'الجمعة + الغياب'!$A$2:$A44, T3, 'الجمعة + الغياب'!$B$2:$B44, MONTH(W8)) -> 4 | X13: عدد الجمع التي حققت 6 ايام
B14: =SUMIFS(Attendance!H:H, Attendance!B:B, T3, Attendance!A:A, ">="&W8, Attendance!A:A, "<="&EOMONTH(W8,0)) -> 0 | E14: {=XLOOKUP(T3, 'الديون'!A:A, 'الديون'!E:E, 0)} -> 2261000 | H14: =SUMIFS(Calculations!C:C, Attendance!B:B, T3, Attendance!A:A, ">="&W8, Attendance!A:A, "<="&EOMONTH(W8,0)) -> 2037.037 | K14: =SUMPRODUCT(('السلفة'!$E$3:$E$22=TRIM(T3))*(TEXT('السلفة'!$F2:$I2,"yyyy-mm")=TEXT(W8,"yyyy-mm"))*('السلفة'!$F$3:$I$22)) -> 260500 | N14: 0 | Q14: 0 | W14: =SUMIFS(Attendance!$G$29:$G44, Attendance!$B$29:$B44, $T$3, Attendance!$F$29:$F44, MONTH($W$8), Attendance!$E$29:$E44, "الجمعة") -> 34.316667 | X14: عدد ساعات الجمعة
W16: =IFERROR(__xludf.DUMMYFUNCTION("COUNTUNIQUEIFS(Attendance!$A$29:$A44, Attendance!$B$29:$B44, $T$3, Attendance!$F$29:$F44, MONTH($W$8))-W18"),26.0) -> 26 | X16: عدد أيام الدوام
B17: ساعات اضافي سنوي | E17: مجموع ايام سنوي | H17: مجموع ساعات السنوي | K17: مجموع جمعة سنوي | W17: =SUMIFS(Attendance!$G$29:$G44, Attendance!$B$29:$B44, $T$3, Attendance!$F$29:$F44, MONTH($W$8), Attendance!$E$29:$E44, "<>الجمعة") -> 327.73333 | X17: عدد ساعات ايام الدوام
B18: =SUMIF(Attendance!$B$29:$B44, $T$3, Attendance!$M$29:$M44) -> 135.41667 | E18: =COUNTIF(Attendance!$B$29:$B44, $T$3) -> 30 | H18: =SUMIF(Attendance!$B$29:$B44, $T$3, Attendance!$G$29:$G44) -> 362.05 | K18: =COUNTIFS(Attendance!$B$29:$B44, $T$3, Attendance!$K$29:$K44, "جمعة") -> 3 | W18: =IFERROR(__xludf.DUMMYFUNCTION("COUNTUNIQUEIFS(Attendance!$A$29:$A44, Attendance!$B$29:$B44, $T$3, Attendance!$F$29:$F44, MONTH($W$8), Attendance!$E$29:$E44, ""الجمعة"")"),3.0) -> 3 | X18: عدد ايام حضور الجمعة
B20: سلفة سنوي | E20: اضافي سنوي | H20: راتب اجمالي سنوي | K20: راتب صافي سنوي | N20: نقل و طعام سنوي | Q20: تأخير سنوي | W20: =IFERROR(__xludf.DUMMYFUNCTION("NETWORKDAYS.INTL(W8, MIN(TODAY(), EOMONTH(W8, 0)), ""0000100"") - COUNTUNIQUEIFS(Attendance!$A$29:$A44, Attendance!$B$29:$B44, $T$3, Attendance!$A$29:$A44, "">=""&$W$8, Attendance!$A$29:$A44, ""<=""&MIN(TODAY(), EOMONTH(W8, 0)), Attendance!$E$29:$E44, ""<"&">الجمعة"")"),0.0) -> 0 | X20: ايام الغياب
B21: {=SUM(XLOOKUP(TRIM(T3), 'السلفة'!$E$2:$E$22, 'السلفة'!$F$2:$I$22))} -> 3370250 | E21: =SUMPRODUCT((TRIM(Data!$A$2:$A$)=TRIM($T$3))*(Data!$F$2:$F$)) + $E$10 -> #ERROR! | H21: =SUMPRODUCT((TRIM(Data!$A$3:$A$491)=TRIM($T$3))*(Data!$K$3:$K$491)) + $T$8 -> #VALUE! | K21: =H21+E21+N21-B21-Q21-Q14-N14 -> #VALUE! | N21: =SUMPRODUCT((TRIM(Data!$A$3:$A$491)=TRIM($T$3))*(Data!$H$3:$H$491)) + $H$10 -> #VALUE! | Q21: =SUMPRODUCT((TRIM(Data!$A$3:$A$491)=TRIM($T$3))*(Data!$J$3:$J$491)) + $H$14 -> #VALUE! | W21: {=SUM(IF((Attendance!$B$29:$B44=$T$3)*(Attendance!$F$29:$F44=MONTH($W$8)), IF(Attendance!$D$29:$D44>TIME(18,0,0), (Attendance!$D$29:$D44-TIME(18,0,0))*24, 0), 0))} -> 25.416667 | X21: عدد ساعات الاضافي
E23: راتب كلي سنوي | W23: =W17-W21 -> 302.31667
E24: =SUM(Data!$K$3:$K$990) -> 0
AN27: مجاميع كل الموضفين سنة 2026
AO29: راتب
AO31: سلفة
AO33: ساعات
AO35: حضور
AO37: غياب
AO39: جمعة

Sheet السلفة
E1: =SUM(F1:M1) -> 9880750 | F1: =SUM(F3:F22) -> 3777000 | G1: =SUM(G3:G22) -> 2358000 | H1: =SUM(H3:H22) -> 2284750 | I1: =SUM(I3:I22) -> 1461000 | J1: =SUM(J3:J22) -> 0
A2: التاريخ | B2: الاسم | C2: المبلغ | E2: =IFERROR(__xludf.DUMMYFUNCTION("QUERY(ARRAYFORMULA({TEXT('الحركات'!A2:A1001, ""YYYY-MM""), 'الحركات'!C2:C1001, IFERROR(VALUE(REGEXREPLACE('الحركات'!D2:D1001 & """", ""[^\d]"", """")), 0) + IFERROR(VALUE(REGEXREPLACE('الحركات'!F2:F1001 & """", ""[^\d]"", """")), 0), 'الحركات'!B2:B1001}),"&" ""select Col2, sum(Col3) where Col4 = 'سلفة' and Col2 is not null group by Col2 pivot Col1 label Col2 'اسم الموظف'"")"),"اسم الموظف") -> اسم الموظف | F2: =IFERROR(__xludf.DUMMYFUNCTION("""COMPUTED_VALUE"""),"2026-01") -> 2026-01 | G2: =IFERROR(__xludf.DUMMYFUNCTION("""COMPUTED_VALUE"""),"2026-02") -> 2026-02 | H2: =IFERROR(__xludf.DUMMYFUNCTION("""COMPUTED_VALUE"""),"2026-03") -> 2026-03 | I2: =IFERROR(__xludf.DUMMYFUNCTION("""COMPUTED_VALUE"""),"2026-04") -> 2026-04 | L2: المستحق | M2: مجموع السلفة | N2: المستلم | O2: المتبقي
A3: =IFERROR(__xludf.DUMMYFUNCTION("FILTER({'الحركات'!A2:A1001, 'الحركات'!C2:C1001, IFERROR(VALUE(REGEXREPLACE('الحركات'!D2:D1001 & """", ""[^\d]"", """")), 0) + IFERROR(VALUE(REGEXREPLACE('الحركات'!F2:F1001 & """", ""[^\d]"", """")), 0)}, 'الحركات'!B2:B1001=""سلفة"")"),46037.0) -> 46037 | B3: =IFERROR(__xludf.DUMMYFUNCTION("""COMPUTED_VALUE"""),"علي الباكستاني") -> علي الباكستاني | C3: =IFERROR(__xludf.DUMMYFUNCTION("""COMPUTED_VALUE"""),10000.0) -> 10000 | E3: =IFERROR(__xludf.DUMMYFUNCTION("""COMPUTED_VALUE"""),"احمد") -> احمد | G3: =IFERROR(__xludf.DUMMYFUNCTION("""COMPUTED_VALUE"""),5000.0) -> 5000 | L3: 5000 | M3: =SUM(F3:J3) -> 5000 | N3: 0 | O3: =M3+N3-L3 -> 0
A4: =IFERROR(__xludf.DUMMYFUNCTION("""COMPUTED_VALUE"""),46039.0) -> 46039 | B4: =IFERROR(__xludf.DUMMYFUNCTION("""COMPUTED_VALUE"""),"حيدر المحاسب") -> حيدر المحاسب | C4: =IFERROR(__xludf.DUMMYFUNCTION("""COMPUTED_VALUE"""),50000.0) -> 50000 | E4: =IFERROR(__xludf.DUMMYFUNCTION("""COMPUTED_VALUE"""),"احمد امين") -> احمد امين | G4: =IFERROR(__xludf.DUMMYFUNCTION("""COMPUTED_VALUE"""),50000.0) -> 50000 | L4: 50000 | M4: =SUM(F4:J4) -> 50000 | N4: 0 | O4: =M4+N4-L4 -> 0
A5: =IFERROR(__xludf.DUMMYFUNCTION("""COMPUTED_VALUE"""),46039.0) -> 46039 | B5: =IFERROR(__xludf.DUMMYFUNCTION("""COMPUTED_VALUE"""),"حيدر يافوز") -> حيدر يافوز | C5: =IFERROR(__xludf.DUMMYFUNCTION("""COMPUTED_VALUE"""),288000.0) -> 288000 | E5: =IFERROR(__xludf.DUMMYFUNCTION("""COMPUTED_VALUE"""),"حسين سالم") -> حسين سالم | F5: =IFERROR(__xludf.DUMMYFUNCTION("""COMPUTED_VALUE"""),2436000.0) -> 2436000 | G5: =IFERROR(__xludf.DUMMYFUNCTION("""COMPUTED_VALUE"""),425000.0) -> 425000 | H5: =IFERROR(__xludf.DUMMYFUNCTION("""COMPUTED_VALUE"""),248750.0) -> 248750 | I5: =IFERROR(__xludf.DUMMYFUNCTION("""COMPUTED_VALUE"""),260500.0) -> 260500 | L5: =861000+1342000+886000 -> 3089000 | M5: =SUM(F5:J5) -> 3370250 | N5: =750000+800000+700000+500000 -> 2750000 | O5: =L5-M5-N5 -> -3031250
A6: =IFERROR(__xludf.DUMMYFUNCTION("""COMPUTED_VALUE"""),46040.0) -> 46040 | B6: =IFERROR(__xludf.DUMMYFUNCTION("""COMPUTED_VALUE"""),"حسين سالم") -> حسين سالم | C6: =IFERROR(__xludf.DUMMYFUNCTION("""COMPUTED_VALUE"""),2226000.0) -> 2226000 | E6: =IFERROR(__xludf.DUMMYFUNCTION("""COMPUTED_VALUE"""),"حيدر المحاسب") -> حيدر المحاسب | F6: =IFERROR(__xludf.DUMMYFUNCTION("""COMPUTED_VALUE"""),233000.0) -> 233000 | G6: =IFERROR(__xludf.DUMMYFUNCTION("""COMPUTED_VALUE"""),50000.0) -> 50000 | H6: =IFERROR(__xludf.DUMMYFUNCTION("""COMPUTED_VALUE"""),418000.0) -> 418000 | L6: 1400000 | M6: =SUM(F6:J6) -> 701000 | N6: 349000 | O6: =L6-M6-N6 -> 350000
A7: =IFERROR(__xludf.DUMMYFUNCTION("""COMPUTED_VALUE"""),46041.0) -> 46041 | B7: =IFERROR(__xludf.DUMMYFUNCTION("""COMPUTED_VALUE"""),"حسين سالم") -> حسين سالم | C7: =IFERROR(__xludf.DUMMYFUNCTION("""COMPUTED_VALUE"""),5000.0) -> 5000 | E7: =IFERROR(__xludf.DUMMYFUNCTION("""COMPUTED_VALUE"""),"حيدر محمد") -> حيدر محمد | F7: =IFERROR(__xludf.DUMMYFUNCTION("""COMPUTED_VALUE"""),70000.0) -> 70000 | G7: =IFERROR(__xludf.DUMMYFUNCTION("""COMPUTED_VALUE"""),298000.0) -> 298000 | H7: =IFERROR(__xludf.DUMMYFUNCTION("""COMPUTED_VALUE"""),410000.0) -> 410000 | I7: =IFERROR(__xludf.DUMMYFUNCTION("""COMPUTED_VALUE"""),232750.0) -> 232750 | L7: 923000 | M7: =I7 -> 232750 | O7: =L7-M7-N7 -> 690250
A8: =IFERROR(__xludf.DUMMYFUNCTION("""COMPUTED_VALUE"""),46041.0) -> 46041 | B8: =IFERROR(__xludf.DUMMYFUNCTION("""COMPUTED_VALUE"""),"حسين سالم") -> حسين سالم | C8: =IFERROR(__xludf.DUMMYFUNCTION("""COMPUTED_VALUE"""),25000.0) -> 25000 | E8: =IFERROR(__xludf.DUMMYFUNCTION("""COMPUTED_VALUE"""),"حيدر يافوز") -> حيدر يافوز | F8: =IFERROR(__xludf.DUMMYFUNCTION("""COMPUTED_VALUE"""),353000.0) -> 353000 | G8: =IFERROR(__xludf.DUMMYFUNCTION("""COMPUTED_VALUE"""),415000.0) -> 415000 | H8: =IFERROR(__xludf.DUMMYFUNCTION("""COMPUTED_VALUE"""),418500.0) -> 418500 | I8: =IFERROR(__xludf.DUMMYFUNCTION("""COMPUTED_VALUE"""),461250.0) -> 461250 | L8: =1563000 -> 1563000 | M8: =SUM(F8:I8) -> 1647750 | N8: 600000 | O8: =L8-M8-N8 -> -684750
A9: =IFERROR(__xludf.DUMMYFUNCTION("""COMPUTED_VALUE"""),46041.0) -> 46041 | B9: =IFERROR(__xludf.DUMMYFUNCTION("""COMPUTED_VALUE"""),"حيدر المحاسب") -> حيدر المحاسب | C9: =IFERROR(__xludf.DUMMYFUNCTION("""COMPUTED_VALUE"""),183000.0) -> 183000 | E9: =IFERROR(__xludf.DUMMYFUNCTION("""COMPUTED_VALUE"""),"حيدر يافوز بغداد") -> حيدر يافوز بغداد | H9: =IFERROR(__xludf.DUMMYFUNCTION("""COMPUTED_VALUE"""),500000.0) -> 500000 | L9: 500000 | M9: =SUM(F9:J9) -> 500000 | O9: =L9-M9-N9 -> 0
A10: =IFERROR(__xludf.DUMMYFUNCTION("""COMPUTED_VALUE"""),46041.0) -> 46041 | B10: =IFERROR(__xludf.DUMMYFUNCTION("""COMPUTED_VALUE"""),"حيدر محمد") -> حيدر محمد | C10: =IFERROR(__xludf.DUMMYFUNCTION("""COMPUTED_VALUE"""),10000.0) -> 10000 | E10: =IFERROR(__xludf.DUMMYFUNCTION("""COMPUTED_VALUE"""),"خضر عبد الخالق") -> خضر عبد الخالق | F10: =IFERROR(__xludf.DUMMYFUNCTION("""COMPUTED_VALUE"""),605000.0) -> 605000 | G10: =IFERROR(__xludf.DUMMYFUNCTION("""COMPUTED_VALUE"""),48000.0) -> 48000 | H10: =IFERROR(__xludf.DUMMYFUNCTION("""COMPUTED_VALUE"""),68500.0) -> 68500 | L10: 1579000 | M10: 1066000 | N10: 1000000 | O10: =L10-M10-N10 -> -487000
A11: =IFERROR(__xludf.DUMMYFUNCTION("""COMPUTED_VALUE"""),46041.0) -> 46041 | B11: =IFERROR(__xludf.DUMMYFUNCTION("""COMPUTED_VALUE"""),"حيدر محمد") -> حيدر محمد | C11: =IFERROR(__xludf.DUMMYFUNCTION("""COMPUTED_VALUE"""),10000.0) -> 10000 | E11: =IFERROR(__xludf.DUMMYFUNCTION("""COMPUTED_VALUE"""),"سجاد") -> سجاد | F11: =IFERROR(__xludf.DUMMYFUNCTION("""COMPUTED_VALUE"""),25000.0) -> 25000 | G11: =IFERROR(__xludf.DUMMYFUNCTION("""COMPUTED_VALUE"""),42000.0) -> 42000 | L11: 67000 | M11: =SUM(F11:J11) -> 67000 | O11: =L11-M11-N11 -> 0
A12: =IFERROR(__xludf.DUMMYFUNCTION("""COMPUTED_VALUE"""),46041.0) -> 46041 | B12: =IFERROR(__xludf.DUMMYFUNCTION("""COMPUTED_VALUE"""),"حيدر يافوز") -> حيدر يافوز | C12: =IFERROR(__xludf.DUMMYFUNCTION("""COMPUTED_VALUE"""),5000.0) -> 5000 | E12: =IFERROR(__xludf.DUMMYFUNCTION("""COMPUTED_VALUE"""),"سجاد حديد") -> سجاد حديد | G12: =IFERROR(__xludf.DUMMYFUNCTION("""COMPUTED_VALUE"""),30000.0) -> 30000 | L12: 30000 | M12: =SUM(F12:J12) -> 30000 | O12: =L12-M12-N12 -> 0
A13: =IFERROR(__xludf.DUMMYFUNCTION("""COMPUTED_VALUE"""),46041.0) -> 46041 | B13: =IFERROR(__xludf.DUMMYFUNCTION("""COMPUTED_VALUE"""),"حيدر يافوز") -> حيدر يافوز | C13: =IFERROR(__xludf.DUMMYFUNCTION("""COMPUTED_VALUE"""),5000.0) -> 5000 | E13: =IFERROR(__xludf.DUMMYFUNCTION("""COMPUTED_VALUE"""),"سجاد رعد") -> سجاد رعد | G13: =IFERROR(__xludf.DUMMYFUNCTION("""COMPUTED_VALUE"""),15000.0) -> 15000 | L13: 15000 | M13: =SUM(F13:J13) -> 15000 | O13: =L13-M13-N13 -> 0
A14: =IFERROR(__xludf.DUMMYFUNCTION("""COMPUTED_VALUE"""),46041.0) -> 46041 | B14: =IFERROR(__xludf.DUMMYFUNCTION("""COMPUTED_VALUE"""),"علي الباكستاني") -> علي الباكستاني | C14: =IFERROR(__xludf.DUMMYFUNCTION("""COMPUTED_VALUE"""),5000.0) -> 5000 | E14: =IFERROR(__xludf.DUMMYFUNCTION("""COMPUTED_VALUE"""),"طعام") -> طعام | F14: =IFERROR(__xludf.DUMMYFUNCTION("""COMPUTED_VALUE"""),30000.0) -> 30000 | G14: =IFERROR(__xludf.DUMMYFUNCTION("""COMPUTED_VALUE"""),420000.0) -> 420000 | H14: =IFERROR(__xludf.DUMMYFUNCTION("""COMPUTED_VALUE"""),78000.0) -> 78000 | I14: =IFERROR(__xludf.DUMMYFUNCTION("""COMPUTED_VALUE"""),36000.0) -> 36000 | L14: 604000 | M14: =SUM(F14:J14) -> 564000 | O14: =L14-M14-N14 -> 40000
A15: =IFERROR(__xludf.DUMMYFUNCTION("""COMPUTED_VALUE"""),46041.0) -> 46041 | B15: =IFERROR(__xludf.DUMMYFUNCTION("""COMPUTED_VALUE"""),"علي الباكستاني") -> علي الباكستاني | C15: =IFERROR(__xludf.DUMMYFUNCTION("""COMPUTED_VALUE"""),5000.0) -> 5000 | E15: =IFERROR(__xludf.DUMMYFUNCTION("""COMPUTED_VALUE"""),"عبدالرحمن") -> عبدالرحمن | I15: =IFERROR(__xludf.DUMMYFUNCTION("""COMPUTED_VALUE"""),32000.0) -> 32000 | L15: 349000 | M15: =SUM(F15:J15) -> 32000 | O15: =L15-M15-N15 -> 317000
A16: =IFERROR(__xludf.DUMMYFUNCTION("""COMPUTED_VALUE"""),46042.0) -> 46042 | B16: =IFERROR(__xludf.DUMMYFUNCTION("""COMPUTED_VALUE"""),"طعام") -> طعام | C16: =IFERROR(__xludf.DUMMYFUNCTION("""COMPUTED_VALUE"""),25000.0) -> 25000 | E16: =IFERROR(__xludf.DUMMYFUNCTION("""COMPUTED_VALUE"""),"عبدالله هاشم") -> عبدالله هاشم | G16: =IFERROR(__xludf.DUMMYFUNCTION("""COMPUTED_VALUE"""),183000.0) -> 183000 | H16: =IFERROR(__xludf.DUMMYFUNCTION("""COMPUTED_VALUE"""),103000.0) -> 103000 | I16: =IFERROR(__xludf.DUMMYFUNCTION("""COMPUTED_VALUE"""),303250.0) -> 303250 | L16: 160000 | M16: =SUM(F16:J16) -> 589250 | O16: =L16-M16-N16 -> -429250
A17: =IFERROR(__xludf.DUMMYFUNCTION("""COMPUTED_VALUE"""),46043.0) -> 46043 | B17: =IFERROR(__xludf.DUMMYFUNCTION("""COMPUTED_VALUE"""),"حسين سالم") -> حسين سالم | C17: =IFERROR(__xludf.DUMMYFUNCTION("""COMPUTED_VALUE"""),125000.0) -> 125000 | E17: =IFERROR(__xludf.DUMMYFUNCTION("""COMPUTED_VALUE"""),"علي الباكستاني") -> علي الباكستاني | F17: =IFERROR(__xludf.DUMMYFUNCTION("""COMPUTED_VALUE"""),25000.0) -> 25000 | G17: =IFERROR(__xludf.DUMMYFUNCTION("""COMPUTED_VALUE"""),15000.0) -> 15000 | H17: =IFERROR(__xludf.DUMMYFUNCTION("""COMPUTED_VALUE"""),40000.0) -> 40000 | I17: =IFERROR(__xludf.DUMMYFUNCTION("""COMPUTED_VALUE"""),135250.0) -> 135250 | L17: 50000 | M17: =SUM(F17:J17) -> 215250 | O17: =L17-M17-N17 -> -165250
A18: =IFERROR(__xludf.DUMMYFUNCTION("""COMPUTED_VALUE"""),46043.0) -> 46043 | B18: =IFERROR(__xludf.DUMMYFUNCTION("""COMPUTED_VALUE"""),"طعام") -> طعام | C18: =IFERROR(__xludf.DUMMYFUNCTION("""COMPUTED_VALUE"""),5000.0) -> 5000 | E18: =IFERROR(__xludf.DUMMYFUNCTION("""COMPUTED_VALUE"""),"علي عارف") -> علي عارف | G18: =IFERROR(__xludf.DUMMYFUNCTION("""COMPUTED_VALUE"""),50000.0) -> 50000 | L18: 25000 | M18: =SUM(F18:J18) -> 50000 | O18: =L18-M18-N18 -> -25000
A19: =IFERROR(__xludf.DUMMYFUNCTION("""COMPUTED_VALUE"""),46043.0) -> 46043 | B19: =IFERROR(__xludf.DUMMYFUNCTION("""COMPUTED_VALUE"""),"حيدر يافوز") -> حيدر يافوز | C19: =IFERROR(__xludf.DUMMYFUNCTION("""COMPUTED_VALUE"""),25000.0) -> 25000 | E19: =IFERROR(__xludf.DUMMYFUNCTION("""COMPUTED_VALUE"""),"علي يوسف") -> علي يوسف | G19: =IFERROR(__xludf.DUMMYFUNCTION("""COMPUTED_VALUE"""),25000.0) -> 25000 | L19: 85000 | M19: =SUM(F19:J19) -> 25000 | O19: =L19-M19-N19 -> 60000
A20: =IFERROR(__xludf.DUMMYFUNCTION("""COMPUTED_VALUE"""),46043.0) -> 46043 | B20: =IFERROR(__xludf.DUMMYFUNCTION("""COMPUTED_VALUE"""),"خضر عبد الخالق") -> خضر عبد الخالق | C20: =IFERROR(__xludf.DUMMYFUNCTION("""COMPUTED_VALUE"""),500000.0) -> 500000 | E20: =IFERROR(__xludf.DUMMYFUNCTION("""COMPUTED_VALUE"""),"محمد حسين الحداد") -> محمد حسين الحداد | G20: =IFERROR(__xludf.DUMMYFUNCTION("""COMPUTED_VALUE"""),85000.0) -> 85000 | L20: 120000 | M20: =SUM(F20:J20) -> 85000 | O20: =L20-M20-N20 -> 35000
A21: =IFERROR(__xludf.DUMMYFUNCTION("""COMPUTED_VALUE"""),46047.0) -> 46047 | B21: =IFERROR(__xludf.DUMMYFUNCTION("""COMPUTED_VALUE"""),"حسين سالم") -> حسين سالم | C21: =IFERROR(__xludf.DUMMYFUNCTION("""COMPUTED_VALUE"""),5000.0) -> 5000 | E21: =IFERROR(__xludf.DUMMYFUNCTION("""COMPUTED_VALUE"""),"مصطفى عبد الخالق ") -> مصطفى عبد الخالق | G21: =IFERROR(__xludf.DUMMYFUNCTION("""COMPUTED_VALUE"""),120000.0) -> 120000 | L21: 82000 | M21: =SUM(F21:J21) -> 120000 | O21: =L21-M21-N21 -> -38000
A22: =IFERROR(__xludf.DUMMYFUNCTION("""COMPUTED_VALUE"""),46047.0) -> 46047 | B22: =IFERROR(__xludf.DUMMYFUNCTION("""COMPUTED_VALUE"""),"حيدر يافوز") -> حيدر يافوز | C22: =IFERROR(__xludf.DUMMYFUNCTION("""COMPUTED_VALUE"""),5000.0) -> 5000 | E22: =IFERROR(__xludf.DUMMYFUNCTION("""COMPUTED_VALUE"""),"يوسف احمد") -> يوسف احمد | G22: =IFERROR(__xludf.DUMMYFUNCTION("""COMPUTED_VALUE"""),82000.0) -> 82000 | M22: =SUM(F22:J22) -> 82000 | O22: =L22-M22-N22 -> -82000
A23: =IFERROR(__xludf.DUMMYFUNCTION("""COMPUTED_VALUE"""),46047.0) -> 46047 | B23: =IFERROR(__xludf.DUMMYFUNCTION("""COMPUTED_VALUE"""),"خضر عبد الخالق") -> خضر عبد الخالق | C23: =IFERROR(__xludf.DUMMYFUNCTION("""COMPUTED_VALUE"""),5000.0) -> 5000 | E23: =IFERROR(__xludf.DUMMYFUNCTION("""COMPUTED_VALUE"""),"يوسف يعقوب") -> يوسف يعقوب | H23: =IFERROR(__xludf.DUMMYFUNCTION("""COMPUTED_VALUE"""),0.0) -> 0
A24: =IFERROR(__xludf.DUMMYFUNCTION("""COMPUTED_VALUE"""),46047.0) -> 46047 | B24: =IFERROR(__xludf.DUMMYFUNCTION("""COMPUTED_VALUE"""),"خضر عبد الخالق") -> خضر عبد الخالق | C24: =IFERROR(__xludf.DUMMYFUNCTION("""COMPUTED_VALUE"""),50000.0) -> 50000
A25: =IFERROR(__xludf.DUMMYFUNCTION("""COMPUTED_VALUE"""),46047.0) -> 46047 | B25: =IFERROR(__xludf.DUMMYFUNCTION("""COMPUTED_VALUE"""),"علي الباكستاني") -> علي الباكستاني | C25: =IFERROR(__xludf.DUMMYFUNCTION("""COMPUTED_VALUE"""),5000.0) -> 5000
A26: =IFERROR(__xludf.DUMMYFUNCTION("""COMPUTED_VALUE"""),46050.0) -> 46050 | B26: =IFERROR(__xludf.DUMMYFUNCTION("""COMPUTED_VALUE"""),"حسين سالم") -> حسين سالم | C26: =IFERROR(__xludf.DUMMYFUNCTION("""COMPUTED_VALUE"""),50000.0) -> 50000
A27: =IFERROR(__xludf.DUMMYFUNCTION("""COMPUTED_VALUE"""),46050.0) -> 46050 | B27: =IFERROR(__xludf.DUMMYFUNCTION("""COMPUTED_VALUE"""),"سجاد") -> سجاد | C27: =IFERROR(__xludf.DUMMYFUNCTION("""COMPUTED_VALUE"""),25000.0) -> 25000
A28: =IFERROR(__xludf.DUMMYFUNCTION("""COMPUTED_VALUE"""),46050.0) -> 46050 | B28: =IFERROR(__xludf.DUMMYFUNCTION("""COMPUTED_VALUE"""),"حيدر محمد") -> حيدر محمد | C28: =IFERROR(__xludf.DUMMYFUNCTION("""COMPUTED_VALUE"""),50000.0) -> 50000
A29: =IFERROR(__xludf.DUMMYFUNCTION("""COMPUTED_VALUE"""),46050.0) -> 46050 | B29: =IFERROR(__xludf.DUMMYFUNCTION("""COMPUTED_VALUE"""),"حيدر يافوز") -> حيدر يافوز | C29: =IFERROR(__xludf.DUMMYFUNCTION("""COMPUTED_VALUE"""),25000.0) -> 25000
A30: =IFERROR(__xludf.DUMMYFUNCTION("""COMPUTED_VALUE"""),46050.0) -> 46050 | B30: =IFERROR(__xludf.DUMMYFUNCTION("""COMPUTED_VALUE"""),"خضر عبد الخالق") -> خضر عبد الخالق | C30: =IFERROR(__xludf.DUMMYFUNCTION("""COMPUTED_VALUE"""),25000.0) -> 25000
A31: =IFERROR(__xludf.DUMMYFUNCTION("""COMPUTED_VALUE"""),46050.0) -> 46050 | B31: =IFERROR(__xludf.DUMMYFUNCTION("""COMPUTED_VALUE"""),"خضر عبد الخالق") -> خضر عبد الخالق | C31: =IFERROR(__xludf.DUMMYFUNCTION("""COMPUTED_VALUE"""),25000.0) -> 25000
A32: =IFERROR(__xludf.DUMMYFUNCTION("""COMPUTED_VALUE"""),46055.0) -> 46055 | B32: =IFERROR(__xludf.DUMMYFUNCTION("""COMPUTED_VALUE"""),"حسين سالم") -> حسين سالم | C32: =IFERROR(__xludf.DUMMYFUNCTION("""COMPUTED_VALUE"""),5000.0) -> 5000
A33: =IFERROR(__xludf.DUMMYFUNCTION("""COMPUTED_VALUE"""),46055.0) -> 46055 | B33: =IFERROR(__xludf.DUMMYFUNCTION("""COMPUTED_VALUE"""),"حسين سالم") -> حسين سالم | C33: =IFERROR(__xludf.DUMMYFUNCTION("""COMPUTED_VALUE"""),10000.0) -> 10000
A34: =IFERROR(__xludf.DUMMYFUNCTION("""COMPUTED_VALUE"""),46055.0) -> 46055 | B34: =IFERROR(__xludf.DUMMYFUNCTION("""COMPUTED_VALUE"""),"سجاد") -> سجاد | C34: =IFERROR(__xludf.DUMMYFUNCTION("""COMPUTED_VALUE"""),5000.0) -> 5000
A35: =IFERROR(__xludf.DUMMYFUNCTION("""COMPUTED_VALUE"""),46055.0) -> 46055 | B35: =IFERROR(__xludf.DUMMYFUNCTION("""COMPUTED_VALUE"""),"حيدر محمد") -> حيدر محمد | C35: =IFERROR(__xludf.DUMMYFUNCTION("""COMPUTED_VALUE"""),5000.0) -> 5000
A36: =IFERROR(__xludf.DUMMYFUNCTION("""COMPUTED_VALUE"""),46055.0) -> 46055 | B36: =IFERROR(__xludf.DUMMYFUNCTION("""COMPUTED_VALUE"""),"حيدر محمد") -> حيدر محمد | C36: =IFERROR(__xludf.DUMMYFUNCTION("""COMPUTED_VALUE"""),10000.0) -> 10000
A37: =IFERROR(__xludf.DUMMYFUNCTION("""COMPUTED_VALUE"""),46055.0) -> 46055 | B37: =IFERROR(__xludf.DUMMYFUNCTION("""COMPUTED_VALUE"""),"حيدر محمد") -> حيدر محمد | C37: =IFERROR(__xludf.DUMMYFUNCTION("""COMPUTED_VALUE"""),5000.0) -> 5000
A38: =IFERROR(__xludf.DUMMYFUNCTION("""COMPUTED_VALUE"""),46055.0) -> 46055 | B38: =IFERROR(__xludf.DUMMYFUNCTION("""COMPUTED_VALUE"""),"حيدر محمد") -> حيدر محمد | C38: =IFERROR(__xludf.DUMMYFUNCTION("""COMPUTED_VALUE"""),10000.0) -> 10000
A39: =IFERROR(__xludf.DUMMYFUNCTION("""COMPUTED_VALUE"""),46055.0) -> 46055 | B39: =IFERROR(__xludf.DUMMYFUNCTION("""COMPUTED_VALUE"""),"خضر عبد الخالق") -> خضر عبد الخالق | C39: =IFERROR(__xludf.DUMMYFUNCTION("""COMPUTED_VALUE"""),5000.0) -> 5000
A40: =IFERROR(__xludf.DUMMYFUNCTION("""COMPUTED_VALUE"""),46055.0) -> 46055 | B40: =IFERROR(__xludf.DUMMYFUNCTION("""COMPUTED_VALUE"""),"علي الباكستاني") -> علي الباكستاني | C40: =IFERROR(__xludf.DUMMYFUNCTION("""COMPUTED_VALUE"""),5000.0) -> 5000
...

Sheet الحركات
A1: التاريخ | B1: نوع العملية | C1: البيان | D1: المبلغ بالدينار | E1: الصارف | F1: دفع | G1: الحركة اليومية للقاصة | H1: FALSE | I1: رقم المستند
A2: 46037 | B2: سند صرف | C2: سمنت مقاوم 100 . حصو + رمل 110 . جاي 5 | D2: 0 | E2: JOZYF | F2: 212000 | G2: 0 | I2: 1
A3: 46037 | B3: سلفة | C3: علي الباكستاني | D3: 0 | E3: JOZYF | F3: 10000 | G3: =G2+D3 -> 0
A4: 46038 | B4: سند دفع | C4: مبلغ تسديد الابرار | D4: 0 | E4: SIFE | F4: 2000000 | G4: =G3+D4 -> 0 | I4: 2
A5: 46039 | B5: سلفة | C5: حيدر المحاسب | D5: 0 | E5: SIFE | F5: 50000 | G5: =G4+D5 -> 0
A6: 46039 | B6: سند دفع | C6: تسديد حساب فاتورة | D6: 0 | E6: SIFE | F6: 176000 | G6: =G5+D6 -> 0 | I6: 3
A7: 46039 | B7: راتب | C7: حسين سالم | D7: 0 | E7: JOZYF | F7: 1300000 | G7: =G6+D7 -> 0
A8: 46039 | B8: سلفة | C8: حيدر يافوز | D8: 0 | E8: SIFE | F8: 288000 | G8: =G7+D8 -> 0
A9: 46040 | B9: سلفة | C9: حسين سالم | D9: 0 | E9: SIFE | F9: 2226000 | G9: 0
A10: 46040 | B10: سند دفع | C10: تسديد نعيم | D10: 0 | E10: SIFE | F10: 1000000 | G10: =G8+D10 -> 0 | I10: 4
A11: 46041 | B11: سلفة | C11: حسين سالم | D11: -5000 | E11: HUSSEN | F11: 0 | G11: =G10+D11 -> -5000 | I11: 51
A12: 46041 | B12: سلفة | C12: حسين سالم | D12: -25000 | E12: HUSSEN | F12: 0 | G12: =G11+D12 -> -30000 | I12: 53
A13: 46041 | B13: سند قبض | C13: من سيف | D13: =2710000+183000+183000 -> 3076000 | E13: SIFE | F13: 3076000 | G13: =G12+D13 -> 3046000
A14: 46041 | B14: سلفة | C14: حيدر المحاسب | D14: -183000 | E14: HUSSEN | F14: 0 | G14: =G13+D14 -> 2863000
A15: 46041 | B15: سند دفع | C15: تسديد يوسف | D15: 0 | E15: SIFE | F15: 776000 | G15: =G14+D15 -> 2863000 | I15: 5
A16: 46041 | B16: سند صرف | C16: تصليح ماييكرو | D16: -30000 | E16: HUSSEN | F16: 0 | G16: =G15+D16 -> 2833000 | I16: 22
A17: 46041 | B17: سند صرف | D17: -2000 | E17: HUSSEN | F17: 0 | G17: =G16+D17 -> 2831000 | I17: 23
A18: 46041 | B18: سند صرف | C18: بانزين | D18: -10000 | E18: HUSSEN | F18: 0 | G18: =G17+D18 -> 2821000 | I18: 24
A19: 46041 | B19: سند صرف | C19: تصليح مواد | D19: -60000 | E19: HUSSEN | F19: 0 | G19: =G18+D19 -> 2761000 | I19: 25
A20: 46041 | B20: سند صرف | C20: اجرة | D20: -15000 | E20: HUSSEN | F20: 0 | G20: =G19+D20 -> 2746000 | I20: 26
A21: 46041 | B21: سند صرف | C21: اجرة | D21: -7000 | E21: HUSSEN | F21: 0 | G21: =G20+D21 -> 2739000 | I21: 27
A22: 46041 | B22: سند صرف | C22: براغي | D22: -5000 | E22: HUSSEN | F22: 0 | G22: =G21+D22 -> 2734000 | I22: 31
A23: 46041 | B23: سند صرف | C23: تصليح مواد | D23: -60000 | E23: HUSSEN | F23: 0 | G23: =G22+D23 -> 2674000 | I23: 52
A24: 46041 | B24: سلفة | C24: حيدر محمد | D24: -10000 | E24: HUSSEN | F24: 0 | G24: =G23+D24 -> 2664000 | I24: 55
A25: 46041 | B25: سلفة | C25: حيدر محمد | D25: -10000 | E25: HUSSEN | F25: 0 | G25: =G24+D25 -> 2654000 | I25: 29
A26: 46041 | B26: سلفة | C26: حيدر يافوز | D26: -5000 | E26: HUSSEN | F26: 0 | G26: =G25+D26 -> 2649000 | I26: 30
A27: 46041 | B27: سلفة | C27: حيدر يافوز | D27: -5000 | E27: HUSSEN | F27: 0 | G27: =G26+D27 -> 2644000 | I27: 56
A28: 46041 | B28: سلفة | C28: علي الباكستاني | D28: -5000 | E28: HUSSEN | F28: 0 | G28: =G27+D28 -> 2639000 | I28: 28
A29: 46041 | B29: سلفة | C29: علي الباكستاني | D29: -5000 | E29: HUSSEN | F29: 0 | G29: =G28+D29 -> 2634000 | I29: 54
... A77: 46054 | B77: سند دفع | C77: تسديد الابرار | D77: 0 | E77: SIFE | F77: 1000000 | G77: =G76+D77 -> 471500 | I77: 15
A78: 46054 | B78: سند دفع | C78: تسديد الابرار | D78: 0 | E78: SIFE | F78: 1000000 | G78: =G77+D78 -> 471500
A79: 46055 | B79: سلفة | C79: حسين سالم | D79: -5000 | E79: HUSSEN | F79: 0 | G79: =G78+D79 -> 466500 | I79: 89
A80: 46055 | B80: سلفة | C80: حسين سالم | D80: -10000 | E80: HUSSEN | F80: 0 | G80: =G79+D80 -> 456500 | I80: 92
A81: 46055 | B81: راتب | C81: حسين سالم | D81: -750000 | E81: HUSSEN | F81: 0 | G81: =G80+D81 -> -293500 | I81: 80
A82: 46055 | B82: سند قبض | C82: صرف ورشه | D82: 1000000 | E82: SIFE | F82: 1000000 | G82: =G81+D82 -> 706500 | I82: 48
A83: 46055 | B83: سند صرف | C83: اجرة الابرار | D83: -10000 | E83: HUSSEN | F83: 0 | G83: =G82+D83 -> 696500 | I83: 16
A84: 46055 | B84: سند صرف | C84: اجرة | D84: -10000 | E84: HUSSEN | F84: 0 | G84: =G83+D84 -> 686500 | I84: 76
A85: 46055 | B85: سند صرف | C85: اجرة | D85: -7000 | E85: HUSSEN | F85: 0 | G85: =G84+D85 -> 679500 | I85: 77
A86: 46055 | B86: سند صرف | C86: جاي و شكر | D86: -5000 | E86: HUSSEN | F86: 0 | G86: =G85+D86 -> 674500 | I86: 78
A87: 46055 | B87: سند صرف | C87: معجون | D87: -6000 | E87: HUSSEN | F87: 0 | G87: =G86+D87 -> 668500 | I87: 79
...

Sheet سيف
A1: تاريخ | B1: بيان
A2: 46037 | B2: سمنت مقاوم 100 . حصو + رمل 110 . جاي 5 | C2: JOZYF | D2: 212000
A3: 46037 | B3: علي الباكستاني | C3: JOZYF | D3: 10000
A4: 46038 | B4: مبلغ تسديد الابرار | C4: SIFE | D4: 2000000
A5: 46039 | B5: حسين سالم | C5: JOZYF | D5: 1300000
A6: 46039 | B6: حيدر المحاسب | C6: SIFE | D6: 50000
A7: 46039 | B7: تسديد حساب فاتورة | C7: SIFE | D7: 176000
A8: 46040 | B8: حسين سالم | C8: SIFE | D8: 2100000
A9: 46040 | B9: تسديد نعيم | C9: SIFE | D9: 1000000
A10: 46041 | B10: من سيف | C10: SIFE | D10: 3076000
A11: 46041 | B11: تسديد يوسف | C11: SIFE | D11: 776000
A12: 46054 | B12: تسديد الابرار | C12: SIFE | D12: 1000000
A13: 46054 | B13: تسديد الابرار | C13: SIFE | D13: 1000000
... A61: 46135 | B61: علي الباكستاني | C61: SIFE | D61: 25000
A62: 46041 | B62: 30000 | C62: 46041 | D62: سلفة | E62: حسين سالم | F62: -5000
A63: 46042 | B63: 81000 | C63: 46041 | D63: سلفة | E63: حسين سالم | F63: -25000
A64: 46056 | B64: 5000 | C64: 46043 | D64: سلفة | E64: حسين سالم | F64: -125000
A65: 46058 | B65: 8000 | C65: 46047 | D65: سلفة | E65: حسين سالم | F65: -5000
A66: 46062 | B66: 10000 | C66: 46050 | D66: سلفة | E66: حسين سالم | F66: -50000
A67: 46065 | B67: 15000 | C67: 46055 | D67: سلفة | E67: حسين سالم | F67: -5000
A68: 46068 | B68: 80000 | C68: 46055 | D68: سلفة | E68: حسين سالم | F68: -10000
A69: 46069 | B69: 300000 | C69: 46055 | D69: راتب | E69: حسين سالم | F69: -750000
A70: 46069 | B70: 2100000 | C70: 46056 | D70: سلفة | E70: حسين سالم | F70: -5000
A71: 46073 | B71: 854 | C71: 46058 | D71: سلفة | E71: حسين سالم | F71: -8000
A72: 46083 | B72: 6750 | C72: 46059 | D72: سلفة | E72: حسين سالم | F72: -5000
A73: 46090 | B73: 5000 | C73: 46062 | D73: سلفة | E73: حسين سالم | F73: -10000
... A77: 46109 | B77: 32000 | C77: 46069 | D77: سلفة | E77: حسين سالم | F77: -300000
C78: 46083 | D78: سلفة | E78: حسين سالم | F78: -3250
C79: 46083 | D79: سلفة | E79: حسين سالم | F79: -3500 | K79: =SUM(B62:B77)-L79 -> -104396 | L79: =873000+B70 -> 2973000
C80: 46084 | D80: راتب | E80: حسين سالم | F80: -800000
C81: 46090 | D81: سلفة | E81: حسين سالم | F81: -5000
C82: 46097 | D82: سلفة | E82: حسين سالم | F82: -40000
C83: 46098 | D83: سلفة | E83: حسين سالم | F83: -55000
C84: 46100 | D84: سلفة | E84: حسين سالم | F84: -100000
C85: 46104 | D85: سلفة | E85: حسين سالم | F85: -32000
C86: 46112 | D86: سلفة | E86: حسين سالم | F86: 0
C87: 46114 | D87: سلفة | E87: حسين سالم | F87: -10000
C88: 46114 | D88: سلفة | E88: حسين سالم | F88: -30000
C89: 46117 | D89: راتب | E89: حسين سالم | F89: -700000
C90: 46117 | D90: سلفة | E90: حسين سالم | F90: -40000
...

Sheet الديون
A1: الاسم | B1: نوع الدين | C1: المبلغ | D1: المسدد | E1: المتبقي | F1: علينا | G1: لنا
F2: =SUMIFS(E:E,B:B,"علينا") -> 19645500 | G2: =SUMIFS(E:E,B:B,"لنا") -> 8701000
A3: يوسف يعقوب | B3: علينا | C3: =SUMIFS('السجل'!C:C,'السجل'!B:B,A3) -> 45370000 | D3: =SUMIFS('السجل'!D:D,'السجل'!B:B,A3) -> 27605000 | E3: =IF(C3="","",C3-IF(D3="",0,D3)) -> 17765000
A4: نعيم حديد | B4: علينا | C4: =SUMIFS('السجل'!C:C,'السجل'!B:B,A4) -> 6181000 | D4: =SUMIFS('السجل'!D:D,'السجل'!B:B,A4) -> 6181000 | E4: =IF(C4="","",C4-IF(D4="",0,D4)) -> 0
A5: الابرار | B5: علينا | C5: =SUMIFS('السجل'!C:C,'السجل'!B:B,A5) -> 10986500 | D5: =SUMIFS('السجل'!D:D,'السجل'!B:B,A5) -> 9201000 | E5: =IF(C5="","",C5-IF(D5="",0,D5)) -> 1785500
A6: حسين سالم | B6: لنا | C6: =SUMIFS('السجل'!C:C,'السجل'!B:B,A6) -> 2378000 | D6: =SUMIFS('السجل'!D:D,'السجل'!B:B,A6) -> 117000 | E6: =IF(C6="","",C6-IF(D6="",0,D6)) -> 2261000
A7: حيدر يافوز | B7: لنا | C7: =SUMIFS('السجل'!C:C,'السجل'!B:B,A7) -> 542000 | D7: =SUMIFS('السجل'!D:D,'السجل'!B:B,A7) -> 0 | E7: =IF(C7="","",C7-IF(D7="",0,D7)) -> 542000
A8: خضر عبد الخالق | B8: لنا | C8: =SUMIFS('السجل'!C:C,'السجل'!B:B,A8) -> 978000 | D8: =SUMIFS('السجل'!D:D,'السجل'!B:B,A8) -> 345000 | E8: =IF(C8="","",C8-IF(D8="",0,D8)) -> 633000
A9: حنان | B9: لنا | C9: =SUMIFS('السجل'!C:C,'السجل'!B:B,A9) -> 1500000 | D9: =SUMIFS('السجل'!D:D,'السجل'!B:B,A9) -> 1500000 | E9: =IF(C9="","",C9-IF(D9="",0,D9)) -> 0
A10: اشرف | B10: لنا | C10: =SUMIFS('السجل'!C:C,'السجل'!B:B,A10) -> 6000000 | D10: =SUMIFS('السجل'!D:D,'السجل'!B:B,A10) -> 750000 | E10: =IF(C10="","",C10-IF(D10="",0,D10)) -> 5250000
A11: الماجد لتجارة الاخشاب | B11: علينا | C11: =SUMIFS('السجل'!C:C,'السجل'!B:B,A11) -> 435000 | D11: =SUMIFS('السجل'!D:D,'السجل'!B:B,A11) -> 435000 | E11: =IF(C11="","",C11-IF(D11="",0,D11)) -> 0
A12: الفردان التجارية | B12: علينا | C12: =SUMIFS('السجل'!C:C,'السجل'!B:B,A12) -> 53000 | D12: =SUMIFS('السجل'!D:D,'السجل'!B:B,A12) -> 53000 | E12: =IF(C12="","",C12-IF(D12="",0,D12)) -> 0
A13: نعيم السراي للاضائة الحديثة | B13: علينا | C13: =SUMIFS('السجل'!C:C,'السجل'!B:B,A13) -> 45000 | D13: =SUMIFS('السجل'!D:D,'السجل'!B:B,A13) -> 0 | E13: =IF(C13="","",C13-IF(D13="",0,D13)) -> 45000
A14: الخورة | B14: علينا | C14: =SUMIFS('السجل'!C:C,'السجل'!B:B,A14) -> 50000 | D14: =SUMIFS('السجل'!D:D,'السجل'!B:B,A14) -> 0 | E14: =IF(C14="","",C14-IF(D14="",0,D14)) -> 50000
... A16: عبود | B16: لنا | C16: =SUMIFS('السجل'!C:C,'السجل'!B:B,A16) -> 10000 | D16: =SUMIFS('السجل'!D:D,'السجل'!B:B,A16) -> 0 | E16: =IF(C16="","",C16-IF(D16="",0,D16)) -> 10000
C17: =SUMIFS('السجل'!C:C,'السجل'!B:B,A17) -> 0 | D17: =SUMIFS('السجل'!D:D,'السجل'!B:B,A17) -> 0 | E17: =IF(C17="","",C17-IF(D17="",0,D17)) -> 0

Sheet السجل
A1: التأريخ | B1: العمود 1 | C1: العمود 2 | D1: العمود 3 | E1: العمود 4 | F1: العمود 5
B2: اشرف | C2: 2280750 | D2: 750000 | E2: =IF(C2="","",C2-IF(D2="",0,D2)) -> 1530750
B3: اشرف | C3: 3719250 | E3: =IF(C3="","",C3-IF(D3="",0,D3)) -> 3719250
B4: اعلان مون لاين | C4: 600000 | D4: 450000 | E4: =IF(C4="","",C4-IF(D4="",0,D4)) -> 150000
A5: 46054 | B5: الابرار | C5: 2139000 | D5: 2000000 | E5: =IF(C5="","",C5-IF(D5="",0,D5)) -> 139000
A6: 46055 | B6: الابرار | C6: 666000 | E6: =IF(C6="","",C6-IF(D6="",0,D6)) -> 666000
A7: 46056 | B7: الابرار | C7: 1557000 | E7: =IF(C7="","",C7-IF(D7="",0,D7)) -> 1557000
A8: 46058 | B8: الابرار | C8: 967000 | E8: =IF(C8="","",C8-IF(D8="",0,D8)) -> 967000
A9: 46060 | B9: الابرار | C9: 260000 | E9: =IF(C9="","",C9-IF(D9="",0,D9)) -> 260000
A10: 46069 | B10: الابرار | C10: 287000 | D10: 2000000 | E10: =IF(C10="","",C10-IF(D10="",0,D10)) -> -1713000
A11: 46072 | B11: الابرار | C11: 814000 | E11: =IF(C11="","",C11-IF(D11="",0,D11)) -> 814000
A12: 46075 | B12: الابرار | C12: 170000 | D12: 1000000 | E12: =IF(C12="","",C12-IF(D12="",0,D12)) -> -830000
A13: 46079 | B13: الابرار | C13: 485000 | E13: =IF(C13="","",C13-IF(D13="",0,D13)) -> 485000
A14: 46086 | B14: الابرار | C14: 232000 | D14: 2000000 | E14: =IF(C14="","",C14-IF(D14="",0,D14)) -> -1768000
A15: 46089 | B15: الابرار | C15: 488000 | E15: =IF(C15="","",C15-IF(D15="",0,D15)) -> 488000
B16: الابرار | C16: 30000 | E16: =IF(C16="","",C16-IF(D16="",0,D16)) -> 30000
A17: 46093 | B17: الابرار | C17: 374000 | E17: =IF(C17="","",C17-IF(D17="",0,D17)) -> 374000
A18: 46093 | B18: الابرار | C18: 300000 | E18: =IF(C18="","",C18-IF(D18="",0,D18)) -> 300000
A19: 46100 | B19: الابرار | C19: 385000 | E19: =IF(C19="","",C19-IF(D19="",0,D19)) -> 385000
B20: الابرار | C20: 47000 | D20: 2201000 | E20: =IF(C20="","",C20-IF(D20="",0,D20)) -> -2154000
B21: الابرار | C21: 492000 | E21: =IF(C21="","",C21-IF(D21="",0,D21)) -> 492000
B22: الابرار | C22: 32000 | E22: =IF(C22="","",C22-IF(D22="",0,D22)) -> 32000
B23: الابرار | C23: 69000 | E23: =IF(C23="","",C23-IF(D23="",0,D23)) -> 69000
B24: الابرار | C24: 452000 | E24: =IF(C24="","",C24-IF(D24="",0,D24)) -> 452000
B25: الابرار | C25: 393000 | E25: =IF(C25="","",C25-IF(D25="",0,D25)) -> 393000
B26: الابرار | C26: =53000+294500 -> 347500 | E26: =IF(C26="","",C26-IF(D26="",0,D26)) -> 347500
A27: 46095 | B27: الخورة | C27: 50000 | E27: =IF(C27="","",C27-IF(D27="",0,D27)) -> 50000
B28: الفردان التجارية | C28: =53000 -> 53000 | D28: 53000 | E28: =IF(C28="","",C28-IF(D28="",0,D28)) -> 0
B29: الماجد لتجارة الاخشاب | C29: 35000 | E29: =IF(C29="","",C29-IF(D29="",0,D29)) -> 35000
B30: الماجد لتجارة الاخشاب | C30: 330000 | D30: 435000 | E30: =IF(C30="","",C30-IF(D30="",0,D30)) -> -105000
B31: الماجد لتجارة الاخشاب | C31: 70000 | E31: =IF(C31="","",C31-IF(D31="",0,D31)) -> 70000
A32: 46056 | B32: حسين سالم | C32: 2325000 | E32: =IF(C32="","",C32-IF(D32="",0,D32)) -> 2325000
A33: 46084 | B33: حسين سالم | D33: 117000 | E33: =IF(C33="","",C33-IF(D33="",0,D33))
A34: 46115 | B34: حسين سالم | C34: 53000 | E34: =IF(C34="","",C34-IF(D34="",0,D34)) -> 53000
B35: حنان | C35: 500000 | D35: 350000 | E35: =IF(C35="","",C35-IF(D35="",0,D35)) -> 150000
B36: حنان | C36: 170000 | D36: 1150000 | E36: =IF(C36="","",C36-IF(D36="",0,D36)) -> -980000
B37: حنان | C37: 250000 | E37: =IF(C37="","",C37-IF(D37="",0,D37)) -> 250000
B38: حنان | C38: 580000 | E38: =IF(C38="","",C38-IF(D38="",0,D38)) -> 580000
B39: حيدر محمد | C39: 5000 | E39: =IF(C39="","",C39-IF(D39="",0,D39)) -> 5000
B40: حيدر محمد | C40: 260000 | D40: 260000 | E40: =IF(C40="","",C40-IF(D40="",0,D40)) -> 0
...

Sheet عرض الحركة المالية
C1: WORKSHOP AUTO SERVICE CENTERACCOUNTING DASHBOARD
C6: تسديد خارجي | D6: الرواتب | E6: قبض | F6: صرف | G6: دفع الى الورشه | H6: ديون علينا | I6: دفع سيف اجمالي
C7: =I7-G7 -> 30723000 | E7: =SUMIFS('الحركات'!D:D,'الحركات'!B:B,"سند قبض") -> 26206000 | F7: =SUMIFS('الحركات'!D:D,'الحركات'!B:B,"سند صرف") -> -5823991 | G7: =SUMIFS('الحركات'!D:D,'الحركات'!B:B,"سند دفع")+E7 -> 21661000 | H7: ='الديون'!F2 -> 19645500 | I7: =SUMIFS('الحركات'!F:F,'الحركات'!E:E,"sife") -> 52384000
D9: السلفة | E9: =SUM('الحركات'!D4:D1000) -> 0 | H9: ديون لنا
D10: =SUM('السلفة'!C3:C1000) -> 9880750 | H10: ='الديون'!G2 -> 8701000

Sheet Attendance
A1: Date | B1: Name | C1: Check-in | D1: Check-out | E1: Day | F1: month | G1: الساعات | H1: الغرامات | I1: السلفة | J1: الديون | K1: نوع اليوم
A2: 46113 | B2: عبدالله هاشم | C2: 0.39097222 | D2: 0.75208333 | E2: =TEXT(A2,"dddd") -> الأربعاء | F2: =MONTH(A2) -> 4 | G2: =(D2-C2)*24 -> 8.6666667 | K2: =IF(WEEKDAY(A2)=6, "جمعة", "يوم عادي") -> يوم عادي | L2: =(MIN(Attendance!D2, TIME(18, 0, 0)) - Attendance!C2) * 24 -> 8.6166667 | M2: =G2-L2 -> 0.05
A3: 46114 | B3: عبدالله هاشم | C3: 0.38263889 | D3: 0.75486111 | E3: =TEXT(A3,"dddd") -> الخميس | F3: =MONTH(A3) -> 4 | G3: =(D3-C3)*24 -> 8.9333333 | K3: =IF(WEEKDAY(A3)=6, "جمعة", "يوم عادي") -> يوم عادي | L3: =(MIN(Attendance!D3, TIME(18, 0, 0)) - Attendance!C3) * 24 -> 8.8166667 | M3: =G3-L3 -> 0.11666667
A4: 46116 | B4: عبدالله هاشم | C4: 0.39652778 | D4: 0.75555556 | E4: =TEXT(A4,"dddd") -> السبت | F4: =MONTH(A4) -> 4 | G4: =(D4-C4)*24 -> 8.6166667 | K4: =IF(WEEKDAY(A4)=6, "جمعة", "يوم عادي") -> يوم عادي | L4: =(MIN(Attendance!D4, TIME(18, 0, 0)) - Attendance!C4) * 24 -> 8.4833333 | M4: =G4-L4 -> 0.13333333
A5: 46117 | B5: عبدالله هاشم | C5: 0.38472222 | D5: 0.75833333 | E5: =TEXT(A5,"dddd") -> الأحد | F5: =MONTH(A5) -> 4 | G5: =(D5-C5)*24 -> 8.9666667 | K5: =IF(WEEKDAY(A5)=6, "جمعة", "يوم عادي") -> يوم عادي | L5: =(MIN(Attendance!D5, TIME(18, 0, 0)) - Attendance!C5) * 24 -> 8.7666667 | M5: =G5-L5 -> 0.2
A6: 46118 | B6: عبدالله هاشم | C6: 0.38541667 | D6: 0.77847222 | E6: =TEXT(A6,"dddd") -> الاثنين | F6: =MONTH(A6) -> 4 | G6: =(D6-C6)*24 -> 9.4333333 | K6: =IF(WEEKDAY(A6)=6, "جمعة", "يوم عادي") -> يوم عادي | L6: =(MIN(Attendance!D6, TIME(18, 0, 0)) - Attendance!C6) * 24 -> 8.75 | M6: =G6-L6 -> 0.68333333
A7: 46119 | B7: عبدالله هاشم | C7: 0.3875 | D7: 0.75902778 | E7: =TEXT(A7,"dddd") -> الثلاثاء | F7: =MONTH(A7) -> 4 | G7: =(D7-C7)*24 -> 8.9166667 | K7: =IF(WEEKDAY(A7)=6, "جمعة", "يوم عادي") -> يوم عادي | L7: =(MIN(Attendance!D7, TIME(18, 0, 0)) - Attendance!C7) * 24 -> 8.7 | M7: =G7-L7 -> 0.21666667
A8: 46120 | B8: عبدالله هاشم | C8: 0.39097222 | D8: 0.75 | E8: =TEXT(A8,"dddd") -> الأربعاء | F8: =MONTH(A8) -> 4 | G8: =(D8-C8)*24 -> 8.6166667 | K8: =IF(WEEKDAY(A8)=6, "جمعة", "يوم عادي") -> يوم عادي | L8: =(MIN(Attendance!D8, TIME(18, 0, 0)) - Attendance!C8) * 24 -> 8.6166667 | M8: =G8-L8 -> 0
A9: 46121 | B9: عبدالله هاشم | C9: 0.38819444 | D9: 0.76319444 | E9: =TEXT(A9,"dddd") -> الخميس | F9: =MONTH(A9) -> 4 | G9: =(D9-C9)*24 -> 9 | K9: =IF(WEEKDAY(A9)=6, "جمعة", "يوم عادي") -> يوم عادي | L9: =(MIN(Attendance!D9, TIME(18, 0, 0)) - Attendance!C9) * 24 -> 8.6833333 | M9: =G9-L9 -> 0.31666667
A10: 46122 | B10: عبدالله هاشم | C10: 0.35416667 | D10: 0.72430556 | E10: =TEXT(A10,"dddd") -> الجمعة | F10: =MONTH(A10) -> 4 | G10: =(D10-C10)*24 -> 8.8833333 | K10: =IF(WEEKDAY(A10)=6, "جمعة", "يوم عادي") -> جمعة | L10: =(MIN(Attendance!D10, TIME(18, 0, 0)) - Attendance!C10) * 24 -> 8.8833333 | M10: =G10-L10 -> 0
A11: 46123 | B11: عبدالله هاشم | C11: 0.39930556 | D11: 0.75277778 | E11: =TEXT(A11,"dddd") -> السبت | F11: =MONTH(A11) -> 4 | G11: =(D11-C11)*24 -> 8.4833333 | K11: =IF(WEEKDAY(A11)=6, "جمعة", "يوم عادي") -> يوم عادي | L11: =(MIN(Attendance!D11, TIME(18, 0, 0)) - Attendance!C11) * 24 -> 8.4166667 | M11: =G11-L11 -> 0.066666667
A12: 46124 | B12: عبدالله هاشم | C12: 0.40902778 | D12: 0.77361111 | E12: =TEXT(A12,"dddd") -> الأحد | F12: =MONTH(A12) -> 4 | G12: =(D12-C12)*24 -> 8.75 | K12: =IF(WEEKDAY(A12)=6, "جمعة", "يوم عادي") -> يوم عادي | L12: =(MIN(Attendance!D12, TIME(18, 0, 0)) - Attendance!C12) * 24 -> 8.1833333 | M12: =G12-L12 -> 0.56666667
A13: 46125 | B13: عبدالله هاشم | C13: 0.39375 | D13: 0.88125 | E13: =TEXT(A13,"dddd") -> الاثنين | F13: =MONTH(A13) -> 4 | G13: =(D13-C13)*24 -> 11.7 | K13: =IF(WEEKDAY(A13)=6, "جمعة", "يوم عادي") -> يوم عادي | L13: =(MIN(Attendance!D13, TIME(18, 0, 0)) - Attendance!C13) * 24 -> 8.55 | M13: =G13-L13 -> 3.15
... A116: 46133 | B116: حيدر يافوز | C116: 0.39444444 | D116: 0.82847222 | E116: =TEXT(A116,"dddd") -> الثلاثاء | F116: =MONTH(A116) -> 4 | G116: =(D116-C116)*24 -> 10.416667 | K116: =IF(WEEKDAY(A116)=6, "جمعة", "يوم عادي") -> يوم عادي | L116: =(MIN(Attendance!D116, TIME(18, 0, 0)) - Attendance!C116) * 24 -> 8.5333333 | M116: =G116-L116 -> 1.8833333
E117: =TEXT(A117,"dddd") -> السبت | F117: =MONTH(A117) -> 12 | G117: =(D117-C117)*24 -> 0 | K117: =IF(WEEKDAY(A117)=6, "جمعة", "يوم عادي") -> يوم عادي | L117: =(MIN(Attendance!D117, TIME(18, 0, 0)) - Attendance!C117) * 24 -> 18 | M117: =G117-L117 -> -18
A118: 46134 | B118: حيدر يافوز | C118: 0.37361111 | D118: 0.82083333 | E118: =TEXT(A118,"dddd") -> الأربعاء | F118: =MONTH(A118) -> 4 | G118: =(D118-C118)*24 -> 10.733333 | K118: =IF(WEEKDAY(A118)=6, "جمعة", "يوم عادي") -> يوم عادي | L118: =(MIN(Attendance!D118, TIME(18, 0, 0)) - Attendance!C118) * 24 -> 9.0333333 | M118: =G118-L118 -> 1.7
A119: 46135 | B119: حيدر يافوز | C119: 0.46180556 | D119: 0.76527778 | E119: =TEXT(A119,"dddd") -> الخميس | F119: =MONTH(A119) -> 4 | G119: =(D119-C119)*24 -> 7.2833333 | K119: =IF(WEEKDAY(A119)=6, "جمعة", "يوم عادي") -> يوم عادي | L119: =(MIN(Attendance!D119, TIME(18, 0, 0)) - Attendance!C119) * 24 -> 6.9166667 | M119: =G119-L119 -> 0.36666667
A120: 46136 | B120: حيدر يافوز | C120: 0.39097222 | D120: 0.83541667 | E120: =TEXT(A120,"dddd") -> الجمعة | F120: =MONTH(A120) -> 4 | G120: =(D120-C120)*24 -> 10.666667 | K120: =IF(WEEKDAY(A120)=6, "جمعة", "يوم عادي") -> جمعة | L120: =(MIN(Attendance!D120, TIME(18, 0, 0)) - Attendance!C120) * 24 -> 8.6166667 | M120: =G120-L120 -> 2.05
A121: 46137 | B121: حيدر يافوز | C121: 0.37986111 | D121: 0.75277778 | E121: =TEXT(A121,"dddd") -> السبت | F121: =MONTH(A121) -> 4 | G121: =(D121-C121)*24 -> 8.95 | K121: =IF(WEEKDAY(A121)=6, "جمعة", "يوم عادي") -> يوم عادي | L121: =(MIN(Attendance!D121, TIME(18, 0, 0)) - Attendance!C121) * 24 -> 8.8833333 | M121: =G121-L121 -> 0.066666667
A122: 46138 | B122: حيدر يافوز | C122: 0.33333333 | D122: 0.87916667 | E122: =TEXT(A122,"dddd") -> الأحد | F122: =MONTH(A122) -> 4 | G122: =(D122-C122)*24 -> 13.1 | K122: =IF(WEEKDAY(A122)=6, "جمعة", "يوم عادي") -> يوم عادي | L122: =(MIN(Attendance!D122, TIME(18, 0, 0)) - Attendance!C122) * 24 -> 10 | M122: =G122-L122 -> 3.1
A123: 46139 | B123: حيدر يافوز | C123: 0.34166667 | D123: 0.82638889 | E123: =TEXT(A123,"dddd") -> الاثنين | F123: =MONTH(A123) -> 4 | G123: =(D123-C123)*24 -> 11.633333 | K123: =IF(WEEKDAY(A123)=6, "جمعة", "يوم عادي") -> يوم عادي | L123: =(MIN(Attendance!D123, TIME(18, 0, 0)) - Attendance!C123) * 24 -> 9.8 | M123: =G123-L123 -> 1.8333333
A124: 46140 | B124: حيدر يافوز | C124: 0.42777778 | D124: 0.85833333 | E124: =TEXT(A124,"dddd") -> الثلاثاء | F124: =MONTH(A124) -> 4 | G124: =(D124-C124)*24 -> 10.333333 | K124: =IF(WEEKDAY(A124)=6, "جمعة", "يوم عادي") -> يوم عادي | L124: =(MIN(Attendance!D124, TIME(18, 0, 0)) - Attendance!C124) * 24 -> 7.7333333 | M124: =G124-L124 -> 2.6
A125: 46141 | B125: حيدر يافوز | C125: 0.39375 | D125: 0.9625 | E125: =TEXT(A125,"dddd") -> الأربعاء | F125: =MONTH(A125) -> 4 | G125: =(D125-C125)*24 -> 13.65 | K125: =IF(WEEKDAY(A125)=6, "جمعة", "يوم عادي") -> يوم عادي | L125: =(MIN(Attendance!D125, TIME(18, 0, 0)) - Attendance!C125) * 24 -> 8.55 | M125: =G125-L125 -> 5.1
A126: 46142 | B126: حيدر يافوز | C126: 0.27847222 | D126: 0.75208333 | E126: =TEXT(A126,"dddd") -> الخميس | F126: =MONTH(A126) -> 4 | G126: =(D126-C126)*24 -> 11.366667 | K126: =IF(WEEKDAY(A126)=6, "جمعة", "يوم عادي") -> يوم عادي | L126: =(MIN(Attendance!D126, TIME(18, 0, 0)) - Attendance!C126) * 24 -> 11.316667 | M126: =G126-L126 -> 0.05
A127: 46130 | B127: حسين سالم | C127: 0.375 | D127: 0.79166667 | E127: =TEXT(A127,"dddd") -> السبت | F127: =MONTH(A127) -> 4 | G127: =((D127-C127)*24)*2 -> 20 | K127: =IF(WEEKDAY(A127)=6, "جمعة", "يوم عادي") -> يوم عادي | L127: =(MIN(Attendance!D127, TIME(18, 0, 0)) - Attendance!C127) * 24 -> 9 | M127: =G127-L127 -> 11
A128: 46131 | B128: حسين سالم | C128: 0.375 | D128: 0.79166667 | E128: =TEXT(A128,"dddd") -> الأحد | F128: =MONTH(A128) -> 4 | G128: =((D128-C128)*24)*2 -> 20 | K128: =IF(WEEKDAY(A128)=6, "جمعة", "يوم عادي") -> يوم عادي | L128: =(MIN(Attendance!D128, TIME(18, 0, 0)) - Attendance!C128) * 24 -> 9 | M128: =G128-L128 -> 11
A129: 46132 | B129: حسين سالم | C129: 0.375 | D129: 0.79166667 | E129: =TEXT(A129,"dddd") -> الاثنين | F129: =MONTH(A129) -> 4 | G129: =((D129-C129)*24)*2 -> 20 | K129: =IF(WEEKDAY(A129)=6, "جمعة", "يوم عادي") -> يوم عادي | L129: =(MIN(Attendance!D129, TIME(18, 0, 0)) - Attendance!C129) * 24 -> 9 | M129: =G129-L129 -> 11
A130: 46133 | B130: حسين سالم | C130: 0.375 | D130: 0.79166667 | E130: =TEXT(A130,"dddd") -> الثلاثاء | F130: =MONTH(A130) -> 4 | G130: =((D130-C130)*24)*2 -> 20 | K130: =IF(WEEKDAY(A130)=6, "جمعة", "يوم عادي") -> يوم عادي | L130: =(MIN(Attendance!D130, TIME(18, 0, 0)) - Attendance!C130) * 24 -> 9 | M130: =G130-L130 -> 11
A131: 46134 | B131: حسين سالم | C131: 0.375 | D131: 0.79166667 | E131: =TEXT(A131,"dddd") -> الأربعاء | F131: =MONTH(A131) -> 4 | G131: =((D131-C131)*24)*2 -> 20 | K131: =IF(WEEKDAY(A131)=6, "جمعة", "يوم عادي") -> يوم عادي | L131: =(MIN(Attendance!D131, TIME(18, 0, 0)) - Attendance!C131) * 24 -> 9 | M131: =G131-L131 -> 11
A132: 46135 | B132: حسين سالم | C132: 0.375 | D132: 0.79166667 | E132: =TEXT(A132,"dddd") -> الخميس | F132: =MONTH(A132) -> 4 | G132: =((D132-C132)*24)*2 -> 20 | K132: =IF(WEEKDAY(A132)=6, "جمعة", "يوم عادي") -> يوم عادي | L132: =(MIN(Attendance!D132, TIME(18, 0, 0)) - Attendance!C132) * 24 -> 9 | M132: =G132-L132 -> 11
A133: 46136 | B133: حسين سالم | C133: 0.375 | D133: 0.79166667 | E133: =TEXT(A133,"dddd") -> الجمعة | F133: =MONTH(A133) -> 4 | G133: =((D133-C133)*24)*2 -> 20 | K133: =IF(WEEKDAY(A133)=6, "جمعة", "يوم عادي") -> جمعة | L133: =(MIN(Attendance!D133, TIME(18, 0, 0)) - Attendance!C133) * 24 -> 9 | M133: =G133-L133 -> 11
A134: 46137 | B134: حسين سالم | C134: 0.375 | D134: 0.79166667 | E134: =TEXT(A134,"dddd") -> السبت | F134: =MONTH(A134) -> 4 | G134: =((D134-C134)*24)*2 -> 20 | K134: =IF(WEEKDAY(A134)=6, "جمعة", "يوم عادي") -> يوم عادي | L134: =(MIN(Attendance!D134, TIME(18, 0, 0)) - Attendance!C134) * 24 -> 9 | M134: =G134-L134 -> 11
A135: 46138 | B135: حسين سالم | C135: 0.375 | D135: 0.79166667 | E135: =TEXT(A135,"dddd") -> الأحد | F135: =MONTH(A135) -> 4 | G135: =((D135-C135)*24)*2 -> 20 | K135: =IF(WEEKDAY(A135)=6, "جمعة", "يوم عادي") -> يوم عادي | L135: =(MIN(Attendance!D135, TIME(18, 0, 0)) - Attendance!C135) * 24 -> 9 | M135: =G135-L135 -> 11
A136: 46139 | B136: حسين سالم | C136: 0.375 | D136: 0.79166667 | E136: =TEXT(A136,"dddd") -> الاثنين | F136: =MONTH(A136) -> 4 | G136: =((D136-C136)*24)*2 -> 20 | K136: =IF(WEEKDAY(A136)=6, "جمعة", "يوم عادي") -> يوم عادي | L136: =(MIN(Attendance!D136, TIME(18, 0, 0)) - Attendance!C136) * 24 -> 9 | M136: =G136-L136 -> 11
A137: 46140 | B137: حسين سالم | C137: 0.375 | D137: 0.79166667 | E137: =TEXT(A137,"dddd") -> الثلاثاء | F137: =MONTH(A137) -> 4 | G137: =((D137-C137)*24)*2 -> 20 | K137: =IF(WEEKDAY(A137)=6, "جمعة", "يوم عادي") -> يوم عادي | L137: =(MIN(Attendance!D137, TIME(18, 0, 0)) - Attendance!C137) * 24 -> 9 | M137: =G137-L137 -> 11
A138: 46141 | B138: حسين سالم | C138: 0.39791667 | D138: 0.86597222 | E138: =TEXT(A138,"dddd") -> الأربعاء | F138: =MONTH(A138) -> 4 | G138: =(D138-C138)*24 -> 11.233333 | K138: =IF(WEEKDAY(A138)=6, "جمعة", "يوم عادي") -> يوم عادي | L138: =(MIN(Attendance!D138, TIME(18, 0, 0)) - Attendance!C138) * 24 -> 8.45 | M138: =G138-L138 -> 2.7833333
A139: 46142 | B139: حسين سالم | C139: 0.31111111 | D139: 0.76180556 | E139: =TEXT(A139,"dddd") -> الخميس | F139: =MONTH(A139) -> 4 | G139: =(D139-C139)*24 -> 10.816667 | K139: =IF(WEEKDAY(A139)=6, "جمعة", "يوم عادي") -> يوم عادي | L139: =(MIN(Attendance!D139, TIME(18, 0, 0)) - Attendance!C139) * 24 -> 10.533333 | M139: =G139-L139 -> 0.28333333
A140: 46130 | B140: حيدر محمد | C140: 0.375 | D140: 0.79166667 | E140: =TEXT(A140,"dddd") -> السبت | F140: =MONTH(A140) -> 4 | G140: =((D140-C140)*24)*2 -> 20 | K140: =IF(WEEKDAY(A140)=6, "جمعة", "يوم عادي") -> يوم عادي | L140: =(MIN(Attendance!D140, TIME(18, 0, 0)) - Attendance!C140) * 24 -> 9 | M140: =G140-L140 -> 11
A141: 46131 | B141: حيدر محمد | C141: 0.375 | D141: 0.79166667 | E141: =TEXT(A141,"dddd") -> الأحد | F141: =MONTH(A141) -> 4 | G141: =((D141-C141)*24)*2 -> 20 | K141: =IF(WEEKDAY(A141)=6, "جمعة", "يوم عادي") -> يوم عادي | L141: =(MIN(Attendance!D141, TIME(18, 0, 0)) - Attendance!C141) * 24 -> 9 | M141: =G141-L141 -> 11
A142: 46132 | B142: حيدر محمد | C142: 0.375 | D142: 0.79166667 | E142: =TEXT(A142,"dddd") -> الاثنين | F142: =MONTH(A142) -> 4 | G142: =((D142-C142)*24)*2 -> 20 | K142: =IF(WEEKDAY(A142)=6, "جمعة", "يوم عادي") -> يوم عادي | L142: =(MIN(Attendance!D142, TIME(18, 0, 0)) - Attendance!C142) * 24 -> 9 | M142: =G142-L142 -> 11
...

Sheet الجمعة + الغياب
A1: الاسم | B1: الشهر | C1: الإجازات | D1: الغيابات | E1: أيام الدوام | F1: الجمعات المستحقة | G1: جمعات الحضور | H1: جمعات الاستراحة | I1: أجر الجمعات النهائي
A2: حيدر المحاسب | B2: 4 | E2: =IFERROR(__xludf.DUMMYFUNCTION("COUNTUNIQUEIFS(Attendance!$A$2:$A12, Attendance!$B$2:$B12, A2, Attendance!$F$2:$F12, B2, Attendance!$K$2:$K12, ""<>جمعة"")"),26.0) -> 26 | F2: =INT((E2 + MIN(C2, 2)) / 6) -> 4 | G2: =COUNTIFS(Attendance!$B2:$B12, A2, Attendance!$F2:$F12, B2, Attendance!$K2:$K12, "جمعة") -> 0 | H2: =MAX(0, F2 - G2) -> 4 | I2: =IF(D2 = 0, G2, (G2 * 2) + H2)-D2+F2 -> 4
A3: حسين سالم | B3: 4 | E3: =IFERROR(__xludf.DUMMYFUNCTION("COUNTUNIQUEIFS(Attendance!$A$2:$A12, Attendance!$B$2:$B12, A3, Attendance!$F$2:$F12, B3, Attendance!$K$2:$K12, ""<>جمعة"")"),26.0) -> 26 | F3: =INT((E3 + MIN(C3, 2)) / 6) -> 4 | G3: =COUNTIFS(Attendance!$B3:$B12, A3, Attendance!$F3:$F12, B3, Attendance!$K3:$K12, "جمعة") -> 3 | H3: =MAX(0, F3 - G3) -> 1 | I3: =IF(D3 = 0, G3, (G3 * 2) + H3)-D3+F3 -> 7
A4: حيدر محمد | B4: 4 | E4: =IFERROR(__xludf.DUMMYFUNCTION("COUNTUNIQUEIFS(Attendance!$A$2:$A12, Attendance!$B$2:$B12, A4, Attendance!$F$2:$F12, B4, Attendance!$K$2:$K12, ""<>جمعة"")"),25.0) -> 25 | F4: =INT((E4 + MIN(C4, 2)) / 6) -> 4 | G4: =COUNTIFS(Attendance!$B4:$B12, A4, Attendance!$F4:$F12, B4, Attendance!$K4:$K12, "جمعة") -> 3 | H4: =MAX(0, F4 - G4) -> 1 | I4: =IF(D4 = 0, G4, (G4 * 2) + H4)-D4+F4 -> 7
A5: حيدر يافوز | B5: 4 | E5: =IFERROR(__xludf.DUMMYFUNCTION("COUNTUNIQUEIFS(Attendance!$A$2:$A12, Attendance!$B$2:$B12, A5, Attendance!$F$2:$F12, B5, Attendance!$K$2:$K12, ""<>جمعة"")"),26.0) -> 26 | F5: =INT((E5 + MIN(C5, 2)) / 6) -> 4 | G5: =COUNTIFS(Attendance!$B5:$B12, A5, Attendance!$F5:$F12, B5, Attendance!$K5:$K12, "جمعة") -> 3 | H5: =MAX(0, F5 - G5) -> 1 | I5: =IF(D5 = 0, G5, (G5 * 2) + H5)-D5+F5 -> 7
A6: خضر عبد الخالق | B6: 4 | D6: 2 | E6: =IFERROR(__xludf.DUMMYFUNCTION("COUNTUNIQUEIFS(Attendance!$A$2:$A12, Attendance!$B$2:$B12, A6, Attendance!$F$2:$F12, B6, Attendance!$K$2:$K12, ""<>جمعة"")"),9.0) -> 9 | F6: =INT((E6 + MIN(C6, 2)) / 6) -> 1 | G6: =COUNTIFS(Attendance!$B6:$B12, A6, Attendance!$F6:$F12, B6, Attendance!$K6:$K12, "جمعة") -> 0 | H6: =MAX(0, F6 - G6) -> 1 | I6: =IF(D6 = 0, G6, (G6 * 2) + H6)-D6+F6 -> 0
A7: عبدالله هاشم | B7: 4 | E7: =IFERROR(__xludf.DUMMYFUNCTION("COUNTUNIQUEIFS(Attendance!$A$2:$A12, Attendance!$B$2:$B12, A7, Attendance!$F$2:$F12, B7, Attendance!$K$2:$K12, ""<>جمعة"")"),25.0) -> 25 | F7: =INT((E7 + MIN(C7, 2)) / 6) -> 4 | G7: =COUNTIFS(Attendance!$B7:$B12, A7, Attendance!$F7:$F12, B7, Attendance!$K7:$K12, "جمعة") -> 2 | H7: =MAX(0, F7 - G7) -> 2 | I7: =IF(D7 = 0, G7, (G7 * 2) + H7)-D7+F7 -> 6
B8: 2 | E8: =IFERROR(__xludf.DUMMYFUNCTION("COUNTUNIQUEIFS(Attendance!$A$2:$A12, Attendance!$B$2:$B12, A8, Attendance!$F$2:$F12, B8, Attendance!$K$2:$K12, ""<>جمعة"")"),0.0) -> 0 | F8: =INT((E8 + MIN(C8, 2)) / 6) -> 0 | G8: =COUNTIFS(Attendance!$B8:$B12, A8, Attendance!$F8:$F12, B8, Attendance!$K8:$K12, "جمعة") -> 0 | H8: =MAX(0, F8 - G8) -> 0 | I8: =IF(D8 = 0, G8, (G8 * 2) + H8)-D8+F8 -> 0
B9: 2 | E9: =IFERROR(__xludf.DUMMYFUNCTION("COUNTUNIQUEIFS(Attendance!$A$2:$A12, Attendance!$B$2:$B12, A9, Attendance!$F$2:$F12, B9, Attendance!$K$2:$K12, ""<>جمعة"")"),0.0) -> 0 | F9: =INT((E9 + MIN(C9, 2)) / 6) -> 0 | G9: =COUNTIFS(Attendance!$B9:$B12, A9, Attendance!$F9:$F12, B9, Attendance!$K9:$K12, "جمعة") -> 0 | H9: =MAX(0, F9 - G9) -> 0 | I9: =IF(D9 = 0, G9, (G9 * 2) + H9)-D9+F9 -> 0
B10: 2 | E10: =IFERROR(__xludf.DUMMYFUNCTION("COUNTUNIQUEIFS(Attendance!$A$2:$A12, Attendance!$B$2:$B12, A10, Attendance!$F$2:$F12, B10, Attendance!$K$2:$K12, ""<>جمعة"")"),0.0) -> 0 | F10: =INT((E10 + MIN(C10, 2)) / 6) -> 0 | G10: =COUNTIFS(Attendance!$B10:$B12, A10, Attendance!$F10:$F12, B10, Attendance!$K10:$K12, "جمعة") -> 0 | H10: =MAX(0, F10 - G10) -> 0 | I10: =IF(D10 = 0, G10, (G10 * 2) + H10)-D10+F10 -> 0
B11: 2 | E11: =IFERROR(__xludf.DUMMYFUNCTION("COUNTUNIQUEIFS(Attendance!$A$2:$A12, Attendance!$B$2:$B12, A11, Attendance!$F$2:$F12, B11, Attendance!$K$2:$K12, ""<>جمعة"")"),0.0) -> 0 | F11: =INT((E11 + MIN(C11, 2)) / 6) -> 0 | G11: =COUNTIFS(Attendance!$B11:$B12, A11, Attendance!$F11:$F12, B11, Attendance!$K11:$K12, "جمعة") -> 0 | H11: =MAX(0, F11 - G11) -> 0 | I11: =IF(D11 = 0, G11, (G11 * 2) + H11)-D11+F11 -> 0
B12: 2 | E12: =IFERROR(__xludf.DUMMYFUNCTION("COUNTUNIQUEIFS(Attendance!$A$2:$A12, Attendance!$B$2:$B12, A12, Attendance!$F$2:$F12, B12, Attendance!$K$2:$K12, ""<>جمعة"")"),0.0) -> 0 | F12: =INT((E12 + MIN(C12, 2)) / 6) -> 0 | G12: =COUNTIFS(Attendance!$B12, A12, Attendance!$F12, B12, Attendance!$K12, "جمعة") -> 0 | H12: =MAX(0, F12 - G12) -> 0 | I12: =IF(D12 = 0, G12, (G12 * 2) + H12)-D12+F12 -> 0

Sheet Calculations
A1: سعر ساعة الموظف | B1: سعر يومية النقل والطعام | C1: مبلغ التأخير | D1: مبلغ الإضافي | E1: مبلغ النقل والطعام اليومي | F1: Calculations
A2: =VLOOKUP(F2, Employees!$A$2:$C957, 3, FALSE) -> 1481.4815 | B2: =100000 / (DAY(EOMONTH(Attendance!A29,0)) - 4) -> 3846.1538 | C2: =MAX(0, Attendance!C29 - TIME(9, 0, 0)) * 24 * A2 -> 2345.679 | D2: =MAX(0, Attendance!D29 - TIME(18, 0, 0)) * 24 * 1.5 * A2 -> 1925.9259 | E2: =IF(AND(Attendance!E29<>"Friday", Attendance!C29<>""), B2, 0) -> 3846.1538 | F2: =Attendance!B2 -> عبدالله هاشم | G2: =Attendance!A29 -> 46113 | H2: =IFERROR(__xludf.DUMMYFUNCTION("REGEXREPLACE(F2, ""\d+$"", """")"),"عبدالله هاشم") -> عبدالله هاشم
A3: =VLOOKUP(F3, Employees!$A$2:$C957, 3, FALSE) -> 1481.4815 | B3: =100000 / (DAY(EOMONTH(Attendance!A30,0)) - 4) -> 3846.1538 | C3: =MAX(0, Attendance!C30 - TIME(9, 0, 0)) * 24 * A3 -> 691.35802 | D3: =MAX(0, Attendance!D30 - TIME(18, 0, 0)) * 24 * 1.5 * A3 -> 1222.2222 | E3: =IF(AND(Attendance!E30<>"Friday", Attendance!C30<>""), B3, 0) -> 3846.1538 | F3: =Attendance!B3 -> عبدالله هاشم | G3: =Attendance!A30 -> 46114 | H3: =IFERROR(__xludf.DUMMYFUNCTION("REGEXREPLACE(F3, ""\d+$"", """")"),"عبدالله هاشم") -> عبدالله هاشم
A4: =VLOOKUP(F4, Employees!$A$2:$C957, 3, FALSE) -> 1481.4815 | B4: =100000 / (DAY(EOMONTH(Attendance!A31,0)) - 4) -> 3846.1538 | C4: =MAX(0, Attendance!C31 - TIME(9, 0, 0)) * 24 * A4 -> 666.66667 | D4: =MAX(0, Attendance!D31 - TIME(18, 0, 0)) * 24 * 1.5 * A4 -> 3555.5556 | E4: =IF(AND(Attendance!E31<>"Friday", Attendance!C31<>""), B4, 0) -> 3846.1538 | F4: =Attendance!B4 -> عبدالله هاشم | G4: =Attendance!A31 -> 46116 | H4: =IFERROR(__xludf.DUMMYFUNCTION("REGEXREPLACE(F4, ""\d+$"", """")"),"عبدالله هاشم") -> عبدالله هاشم
A5: =VLOOKUP(F5, Employees!$A$2:$C957, 3, FALSE) -> 1481.4815 | B5: =100000 / (DAY(EOMONTH(Attendance!A32,0)) - 4) -> 3846.1538 | C5: =MAX(0, Attendance!C32 - TIME(9, 0, 0)) * 24 * A5 -> 641.97531 | D5: =MAX(0, Attendance!D32 - TIME(18, 0, 0)) * 24 * 1.5 * A5 -> 0 | E5: =IF(AND(Attendance!E32<>"Friday", Attendance!C32<>""), B5, 0) -> 3846.1538 | F5: =Attendance!B5 -> عبدالله هاشم | G5: =Attendance!A32 -> 46117 | H5: =IFERROR(__xludf.DUMMYFUNCTION("REGEXREPLACE(F5, ""\d+$"", """")"),"عبدالله هاشم") -> عبدالله هاشم
A6: =VLOOKUP(F6, Employees!$A$2:$C957, 3, FALSE) -> 1481.4815 | B6: =100000 / (DAY(EOMONTH(Attendance!A33,0)) - 4) -> 3846.1538 | C6: =MAX(0, Attendance!C33 - TIME(9, 0, 0)) * 24 * A6 -> 1777.7778 | D6: =MAX(0, Attendance!D33 - TIME(18, 0, 0)) * 24 * 1.5 * A6 -> 0 | E6: =IF(AND(Attendance!E33<>"Friday", Attendance!C33<>""), B6, 0) -> 3846.1538 | F6: =Attendance!B6 -> عبدالله هاشم | G6: =Attendance!A33 -> 46118 | H6: =IFERROR(__xludf.DUMMYFUNCTION("REGEXREPLACE(F6, ""\d+$"", """")"),"عبدالله هاشم") -> عبدالله هاشم
A7: =VLOOKUP(F7, Employees!$A$2:$C957, 3, FALSE) -> 1481.4815 | B7: =100000 / (DAY(EOMONTH(Attendance!A34,0)) - 4) -> 3846.1538 | C7: =MAX(0, Attendance!C34 - TIME(9, 0, 0)) * 24 * A7 -> 1728.3951 | D7: =MAX(0, Attendance!D34 - TIME(18, 0, 0)) * 24 * 1.5 * A7 -> 481.48148 | E7: =IF(AND(Attendance!E34<>"Friday", Attendance!C34<>""), B7, 0) -> 3846.1538 | F7: =Attendance!B7 -> عبدالله هاشم | G7: =Attendance!A34 -> 46119 | H7: =IFERROR(__xludf.DUMMYFUNCTION("REGEXREPLACE(F7, ""\d+$"", """")"),"عبدالله هاشم") -> عبدالله هاشم
A8: =VLOOKUP(F8, Employees!$A$2:$C957, 3, FALSE) -> 1481.4815 | B8: =100000 / (DAY(EOMONTH(Attendance!A35,0)) - 4) -> 3846.1538 | C8: =MAX(0, Attendance!C35 - TIME(9, 0, 0)) * 24 * A8 -> 4518.5185 | D8: =MAX(0, Attendance!D35 - TIME(18, 0, 0)) * 24 * 1.5 * A8 -> 2222.2222 | E8: =IF(AND(Attendance!E35<>"Friday", Attendance!C35<>""), B8, 0) -> 3846.1538 | F8: =Attendance!B8 -> عبدالله هاشم | G8: =Attendance!A35 -> 46120 | H8: =IFERROR(__xludf.DUMMYFUNCTION("REGEXREPLACE(F8, ""\d+$"", """")"),"عبدالله هاشم") -> عبدالله هاشم
A9: =VLOOKUP(F9, Employees!$A$2:$C957, 3, FALSE) -> 1481.4815 | B9: =100000 / (DAY(EOMONTH(Attendance!A36,0)) - 4) -> 3846.1538 | C9: =MAX(0, Attendance!C36 - TIME(9, 0, 0)) * 24 * A9 -> 2444.4444 | D9: =MAX(0, Attendance!D36 - TIME(18, 0, 0)) * 24 * 1.5 * A9 -> 0 | E9: =IF(AND(Attendance!E36<>"Friday", Attendance!C36<>""), B9, 0) -> 3846.1538 | F9: =Attendance!B9 -> عبدالله هاشم | G9: =Attendance!A36 -> 46121 | H9: =IFERROR(__xludf.DUMMYFUNCTION("REGEXREPLACE(F9, ""\d+$"", """")"),"عبدالله هاشم") -> عبدالله هاشم
A10: =VLOOKUP(F10, Employees!$A$2:$C957, 3, FALSE) -> 1481.4815 | B10: =100000 / (DAY(EOMONTH(Attendance!A37,0)) - 4) -> 3846.1538 | C10: =MAX(0, Attendance!C37 - TIME(9, 0, 0)) * 24 * A10 -> 4074.0741 | D10: =MAX(0, Attendance!D37 - TIME(18, 0, 0)) * 24 * 1.5 * A10 -> 0 | E10: =IF(AND(Attendance!E37<>"Friday", Attendance!C37<>""), B10, 0) -> 3846.1538 | F10: =Attendance!B10 -> عبدالله هاشم | G10: =Attendance!A37 -> 46122 | H10: =IFERROR(__xludf.DUMMYFUNCTION("REGEXREPLACE(F10, ""\d+$"", """")"),"عبدالله هاشم") -> عبدالله هاشم
A11: =VLOOKUP(F11, Employees!$A$2:$C957, 3, FALSE) -> 1481.4815 | B11: =100000 / (DAY(EOMONTH(Attendance!A38,0)) - 4) -> 3846.1538 | C11: =MAX(0, Attendance!C38 - TIME(9, 0, 0)) * 24 * A11 -> 1629.6296 | D11: =MAX(0, Attendance!D38 - TIME(18, 0, 0)) * 24 * 1.5 * A11 -> 0 | E11: =IF(AND(Attendance!E38<>"Friday", Attendance!C38<>""), B11, 0) -> 3846.1538 | F11: =Attendance!B11 -> عبدالله هاشم | G11: =Attendance!A38 -> 46123 | H11: =IFERROR(__xludf.DUMMYFUNCTION("REGEXREPLACE(F11, ""\d+$"", """")"),"عبدالله هاشم") -> عبدالله هاشم
A12: =VLOOKUP(F12, Employees!$A$2:$C957, 3, FALSE) -> 1481.4815 | B12: =100000 / (DAY(EOMONTH(Attendance!A39,0)) - 4) -> 3846.1538 | C12: =MAX(0, Attendance!C39 - TIME(9, 0, 0)) * 24 * A12 -> 1925.9259 | D12: =MAX(0, Attendance!D39 - TIME(18, 0, 0)) * 24 * 1.5 * A12 -> 0 | E12: =IF(AND(Attendance!E39<>"Friday", Attendance!C39<>""), B12, 0) -> 3846.1538 | F12: =Attendance!B12 -> عبدالله هاشم | G12: =Attendance!A39 -> 46124 | H12: =IFERROR(__xludf.DUMMYFUNCTION("REGEXREPLACE(F12, ""\d+$"", """")"),"عبدالله هاشم") -> عبدالله هاشم
A13: =VLOOKUP(F13, Employees!$A$2:$C957, 3, FALSE) -> 1481.4815 | B13: =100000 / (DAY(EOMONTH(Attendance!A40,0)) - 4) -> 3846.1538 | C13: =MAX(0, Attendance!C40 - TIME(9, 0, 0)) * 24 * A13 -> 1950.6173 | D13: =MAX(0, Attendance!D40 - TIME(18, 0, 0)) * 24 * 1.5 * A13 -> 7074.0741 | E13: =IF(AND(Attendance!E40<>"Friday", Attendance!C40<>""), B13, 0) -> 3846.1538 | F13: =Attendance!B13 -> عبدالله هاشم | G13: =Attendance!A40 -> 46125 | H13: =IFERROR(__xludf.DUMMYFUNCTION("REGEXREPLACE(F13, ""\d+$"", """")"),"عبدالله هاشم") -> عبدالله هاشم
A14: =VLOOKUP(F14, Employees!$A$2:$C957, 3, FALSE) -> 1481.4815 | B14: =100000 / (DAY(EOMONTH(Attendance!A41,0)) - 4) -> 3846.1538 | C14: =MAX(0, Attendance!C41 - TIME(9, 0, 0)) * 24 * A14 -> 2296.2963 | D14: =MAX(0, Attendance!D41 - TIME(18, 0, 0)) * 24 * 1.5 * A14 -> 0 | E14: =IF(AND(Attendance!E41<>"Friday", Attendance!C41<>""), B14, 0) -> 3846.1538 | F14: =Attendance!B14 -> عبدالله هاشم | G14: =Attendance!A41 -> 46126 | H14: =IFERROR(__xludf.DUMMYFUNCTION("REGEXREPLACE(F14, ""\d+$"", """")"),"عبدالله هاشم") -> عبدالله هاشم
